Workbook

Sheet TTR Summary
B2: Single-Site | I2: Multi-Site | M2: 4 | O2: PTE
B3: IP | C3: CP1 TT (s) | D3: CP2 TT (s) | E3: FT1 TT (s) | F3: FT2 TT (s) | G3: Total (s) | I3: CP1 TT (s) | J3: CP2 TT (s) | K3: FT1 TT (s) | L3: FT2 TT (s) | M3: Total (s) | O3: CP1 | P3: CP2 | Q3: FT1 | R3: FT2
B4: IO_JTAG | C4: =ROUND(#REF!/1000, 2) -> #REF! | D4: =ROUND(#REF!/1000, 2) -> #REF! | E4: =ROUND(#REF!/1000, 2) -> #REF! | F4: =ROUND(#REF!/1000, 2) -> #REF! | G4: =SUM(C4:F4) -> #REF! | O4: =1-(I4-C4)/((M2-1)*C4) -> #REF! | P4: =1-(J4-D4)/((M2-1)*D4) -> #REF! | Q4: =1-(K4-E4)/((M2-1)*E4) -> #REF! | R4: =1-(L4-F4)/((M2-1)*F4) -> #REF!
B5: ADCDFT | C5: =ROUND(#REF!/1000, 2) -> #REF! | D5: =ROUND(#REF!/1000, 2) -> #REF! | E5: =ROUND(#REF!/1000, 2) -> #REF! | F5: =ROUND(#REF!/1000, 2) -> #REF! | G5: =SUM(C5:F5) -> #REF! | O5: =1-(I5-C5)/((M2-1)*C5) -> #REF! | P5: =1-(J5-D5)/((M2-1)*D5) -> #REF! | Q5: =1-(K5-E5)/((M2-1)*E5) -> #REF! | R5: =1-(L5-F5)/((M2-1)*F5) -> #REF!
B6: ADCDFT_TRIM | C6: =ROUND(#REF!/1000, 2) -> #REF! | D6: =ROUND(#REF!/1000, 2) -> #REF! | E6: =ROUND(#REF!/1000, 2) -> #REF! | F6: =ROUND(#REF!/1000, 2) -> #REF! | G6: =SUM(C6:F6) -> #REF! | O6: =1-(I6-C6)/((M2-1)*C6) -> #REF! | P6: =1-(J6-D6)/((M2-1)*D6) -> #REF! | Q6: =1-(K6-E6)/((M2-1)*E6) -> #REF! | R6: =1-(L6-F6)/((M2-1)*F6) -> #REF!
B7: MTRICTS | C7: =ROUND(#REF!/1000, 2) -> #REF! | D7: =ROUND(#REF!/1000, 2) -> #REF! | E7: =ROUND(#REF!/1000, 2) -> #REF! | F7: =ROUND(#REF!/1000, 2) -> #REF! | G7: =SUM(C7:F7) -> #REF! | O7: =1-(I7-C7)/((M2-1)*C7) -> #REF! | P7: =1-(J7-D7)/((M2-1)*D7) -> #REF! | Q7: =1-(K7-E7)/((M2-1)*E7) -> #REF! | R7: =1-(L7-F7)/((M2-1)*F7) -> #REF!
B8: NTSE | C8: =ROUND(#REF!/1000, 2) -> #REF! | D8: =ROUND(#REF!/1000, 2) -> #REF! | E8: =ROUND(#REF!/1000, 2) -> #REF! | F8: =ROUND(#REF!/1000, 2) -> #REF! | G8: =SUM(C8:F8) -> #REF! | O8: =1-(I8-C8)/((M2-1)*C8) -> #REF! | P8: =1-(J8-D8)/((M2-1)*D8) -> #REF! | Q8: =1-(K8-E8)/((M2-1)*E8) -> #REF! | R8: =1-(L8-F8)/((M2-1)*F8) -> #REF!
B9: NTSR | C9: =ROUND(#REF!/1000, 2) -> #REF! | D9: =ROUND(#REF!/1000, 2) -> #REF! | E9: =ROUND(#REF!/1000, 2) -> #REF! | F9: =ROUND(#REF!/1000, 2) -> #REF! | G9: =SUM(C9:F9) -> #REF! | O9: =1-(I9-C9)/((M2-1)*C9) -> #REF! | P9: =1-(J9-D9)/((M2-1)*D9) -> #REF! | Q9: =1-(K9-E9)/((M2-1)*E9) -> #REF! | R9: =1-(L9-F9)/((M2-1)*F9) -> #REF!
B10: ADCDFT_RETRIM | C10: =ROUND(#REF!/1000, 2) -> #REF! | D10: =ROUND(#REF!/1000, 2) -> #REF! | E10: =ROUND(#REF!/1000, 2) -> #REF! | F10: =ROUND(#REF!/1000, 2) -> #REF! | G10: =SUM(C10:F10) -> #REF! | O10: =1-(I10-C10)/((M2-1)*C10) -> #REF! | P10: =1-(J10-D10)/((M2-1)*D10) -> #REF! | Q10: =1-(K10-E10)/((M2-1)*E10) -> #REF! | R10: =1-(L10-F10)/((M2-1)*F10) -> #REF!
B11: MISC | C11: =ROUND(#REF!/1000, 2) -> #REF! | D11: =ROUND(#REF!/1000, 2) -> #REF! | E11: =ROUND(#REF!/1000, 2) -> #REF! | F11: =ROUND(#REF!/1000, 2) -> #REF! | G11: =SUM(C11:F11) -> #REF! | O11: =1-(I11-C11)/((M2-1)*C11) -> #REF! | P11: =1-(J11-D11)/((M2-1)*D11) -> #REF! | Q11: =1-(K11-E11)/((M2-1)*E11) -> #REF! | R11: =1-(L11-F11)/((M2-1)*F11) -> #REF!
B12: FRO | C12: =ROUND(#REF!/1000, 2) -> #REF! | D12: =ROUND(#REF!/1000, 2) -> #REF! | E12: =ROUND(#REF!/1000, 2) -> #REF! | F12: =ROUND(#REF!/1000, 2) -> #REF! | G12: =SUM(C12:F12) -> #REF! | O12: =1-(I12-C12)/((M2-1)*C12) -> #REF! | P12: =1-(J12-D12)/((M2-1)*D12) -> #REF! | Q12: =1-(K12-E12)/((M2-1)*E12) -> #REF! | R12: =1-(L12-F12)/((M2-1)*F12) -> #REF!
B13: CPLL | C13: =ROUND(#REF!/1000, 2) -> #REF! | D13: =ROUND(#REF!/1000, 2) -> #REF! | E13: =ROUND(#REF!/1000, 2) -> #REF! | F13: =ROUND(#REF!/1000, 2) -> #REF! | G13: =SUM(C13:F13) -> #REF! | O13: =1-(I13-C13)/((M2-1)*C13) -> #REF! | P13: =1-(J13-D13)/((M2-1)*D13) -> #REF! | Q13: =1-(K13-E13)/((M2-1)*E13) -> #REF! | R13: =1-(L13-F13)/((M2-1)*F13) -> #REF!
B14: ADCLK | C14: =ROUND(#REF!/1000, 2) -> #REF! | D14: =ROUND(#REF!/1000, 2) -> #REF! | E14: =ROUND(#REF!/1000, 2) -> #REF! | F14: =ROUND(#REF!/1000, 2) -> #REF! | G14: =SUM(C14:F14) -> #REF! | O14: =1-(I14-C14)/((M2-1)*C14) -> #REF! | P14: =1-(J14-D14)/((M2-1)*D14) -> #REF! | Q14: =1-(K14-E14)/((M2-1)*E14) -> #REF! | R14: =1-(L14-F14)/((M2-1)*F14) -> #REF!
B15: LAPLL | C15: =ROUND(#REF!/1000, 2) -> #REF! | D15: =ROUND(#REF!/1000, 2) -> #REF! | E15: =ROUND(#REF!/1000, 2) -> #REF! | F15: =ROUND(#REF!/1000, 2) -> #REF! | G15: =SUM(C15:F15) -> #REF! | O15: =1-(I15-C15)/((M2-1)*C15) -> #REF! | P15: =1-(J15-D15)/((M2-1)*D15) -> #REF! | Q15: =1-(K15-E15)/((M2-1)*E15) -> #REF! | R15: =1-(L15-F15)/((M2-1)*F15) -> #REF!
B16: LAPLL_1 | C16: =ROUND(#REF!/1000, 2) -> #REF! | D16: =ROUND(#REF!/1000, 2) -> #REF! | E16: =ROUND(#REF!/1000, 2) -> #REF! | F16: =ROUND(#REF!/1000, 2) -> #REF! | G16: =SUM(C16:F16) -> #REF! | O16: =1-(I16-C16)/((M2-1)*C16) -> #REF! | P16: =1-(J16-D16)/((M2-1)*D16) -> #REF! | Q16: =1-(K16-E16)/((M2-1)*E16) -> #REF! | R16: =1-(L16-F16)/((M2-1)*F16) -> #REF!
B17: PCIEREFGEN | C17: =ROUND(#REF!/1000, 2) -> #REF! | D17: =ROUND(#REF!/1000, 2) -> #REF! | E17: =ROUND(#REF!/1000, 2) -> #REF! | F17: =ROUND(#REF!/1000, 2) -> #REF! | G17: =SUM(C17:F17) -> #REF! | O17: =1-(I17-C17)/((M2-1)*C17) -> #REF! | P17: =1-(J17-D17)/((M2-1)*D17) -> #REF! | Q17: =1-(K17-E17)/((M2-1)*E17) -> #REF! | R17: =1-(L17-F17)/((M2-1)*F17) -> #REF!
B18: PCIE5CMN | C18: =ROUND(#REF!/1000, 2) -> #REF! | D18: =ROUND(#REF!/1000, 2) -> #REF! | E18: =ROUND(#REF!/1000, 2) -> #REF! | F18: =ROUND(#REF!/1000, 2) -> #REF! | G18: =SUM(C18:F18) -> #REF! | O18: =1-(I18-C18)/((M2-1)*C18) -> #REF! | P18: =1-(J18-D18)/((M2-1)*D18) -> #REF! | Q18: =1-(K18-E18)/((M2-1)*E18) -> #REF! | R18: =1-(L18-F18)/((M2-1)*F18) -> #REF!
B19: ACIPHYCMN | C19: =ROUND(#REF!/1000, 2) -> #REF! | D19: =ROUND(#REF!/1000, 2) -> #REF! | E19: =ROUND(#REF!/1000, 2) -> #REF! | F19: =ROUND(#REF!/1000, 2) -> #REF! | G19: =SUM(C19:F19) -> #REF! | O19: =1-(I19-C19)/((M2-1)*C19) -> #REF! | P19: =1-(J19-D19)/((M2-1)*D19) -> #REF! | Q19: =1-(K19-E19)/((M2-1)*E19) -> #REF! | R19: =1-(L19-F19)/((M2-1)*F19) -> #REF!
B20: ACIOPHYCMN | C20: =ROUND(#REF!/1000, 2) -> #REF! | D20: =ROUND(#REF!/1000, 2) -> #REF! | E20: =ROUND(#REF!/1000, 2) -> #REF! | F20: =ROUND(#REF!/1000, 2) -> #REF! | G20: =SUM(C20:F20) -> #REF! | O20: =1-(I20-C20)/((M2-1)*C20) -> #REF! | P20: =1-(J20-D20)/((M2-1)*D20) -> #REF! | Q20: =1-(K20-E20)/((M2-1)*E20) -> #REF! | R20: =1-(L20-F20)/((M2-1)*F20) -> #REF!
B21: LPDPTXCMN | C21: =ROUND(#REF!/1000, 2) -> #REF! | D21: =ROUND(#REF!/1000, 2) -> #REF! | E21: =ROUND(#REF!/1000, 2) -> #REF! | F21: =ROUND(#REF!/1000, 2) -> #REF! | G21: =SUM(C21:F21) -> #REF! | O21: =1-(I21-C21)/((M2-1)*C21) -> #REF! | P21: =1-(J21-D21)/((M2-1)*D21) -> #REF! | Q21: =1-(K21-E21)/((M2-1)*E21) -> #REF! | R21: =1-(L21-F21)/((M2-1)*F21) -> #REF!
B22: AMPCMN | C22: =ROUND(#REF!/1000, 2) -> #REF! | D22: =ROUND(#REF!/1000, 2) -> #REF! | E22: =ROUND(#REF!/1000, 2) -> #REF! | F22: =ROUND(#REF!/1000, 2) -> #REF! | G22: =SUM(C22:F22) -> #REF! | O22: =1-(I22-C22)/((M2-1)*C22) -> #REF! | P22: =1-(J22-D22)/((M2-1)*D22) -> #REF! | Q22: =1-(K22-E22)/((M2-1)*E22) -> #REF! | R22: =1-(L22-F22)/((M2-1)*F22) -> #REF!
B23: PCIEREFPLL | C23: =ROUND(#REF!/1000, 2) -> #REF! | D23: =ROUND(#REF!/1000, 2) -> #REF! | E23: =ROUND(#REF!/1000, 2) -> #REF! | F23: =ROUND(#REF!/1000, 2) -> #REF! | G23: =SUM(C23:F23) -> #REF! | O23: =1-(I23-C23)/((M2-1)*C23) -> #REF! | P23: =1-(J23-D23)/((M2-1)*D23) -> #REF! | Q23: =1-(K23-E23)/((M2-1)*E23) -> #REF! | R23: =1-(L23-F23)/((M2-1)*F23) -> #REF!
B24: PCIEPLL | C24: =ROUND(#REF!/1000, 2) -> #REF! | D24: =ROUND(#REF!/1000, 2) -> #REF! | E24: =ROUND(#REF!/1000, 2) -> #REF! | F24: =ROUND(#REF!/1000, 2) -> #REF! | G24: =SUM(C24:F24) -> #REF! | O24: =1-(I24-C24)/((M2-1)*C24) -> #REF! | P24: =1-(J24-D24)/((M2-1)*D24) -> #REF! | Q24: =1-(K24-E24)/((M2-1)*E24) -> #REF! | R24: =1-(L24-F24)/((M2-1)*F24) -> #REF!
B25: CIOCIOPLL | C25: =ROUND(#REF!/1000, 2) -> #REF! | D25: =ROUND(#REF!/1000, 2) -> #REF! | E25: =ROUND(#REF!/1000, 2) -> #REF! | F25: =ROUND(#REF!/1000, 2) -> #REF! | G25: =SUM(C25:F25) -> #REF! | O25: =1-(I25-C25)/((M2-1)*C25) -> #REF! | P25: =1-(J25-D25)/((M2-1)*D25) -> #REF! | Q25: =1-(K25-E25)/((M2-1)*E25) -> #REF! | R25: =1-(L25-F25)/((M2-1)*F25) -> #REF!
B26: CIODPPLL | C26: =ROUND(#REF!/1000, 2) -> #REF! | D26: =ROUND(#REF!/1000, 2) -> #REF! | E26: =ROUND(#REF!/1000, 2) -> #REF! | F26: =ROUND(#REF!/1000, 2) -> #REF! | G26: =SUM(C26:F26) -> #REF! | O26: =1-(I26-C26)/((M2-1)*C26) -> #REF! | P26: =1-(J26-D26)/((M2-1)*D26) -> #REF! | Q26: =1-(K26-E26)/((M2-1)*E26) -> #REF! | R26: =1-(L26-F26)/((M2-1)*F26) -> #REF!
B27: LPDPDPPLL | C27: =ROUND(#REF!/1000, 2) -> #REF! | D27: =ROUND(#REF!/1000, 2) -> #REF! | E27: =ROUND(#REF!/1000, 2) -> #REF! | F27: =ROUND(#REF!/1000, 2) -> #REF! | G27: =SUM(C27:F27) -> #REF! | O27: =1-(I27-C27)/((M2-1)*C27) -> #REF! | P27: =1-(J27-D27)/((M2-1)*D27) -> #REF! | Q27: =1-(K27-E27)/((M2-1)*E27) -> #REF! | R27: =1-(L27-F27)/((M2-1)*F27) -> #REF!
B28: LPDDRPLL | C28: =ROUND(#REF!/1000, 2) -> #REF! | D28: =ROUND(#REF!/1000, 2) -> #REF! | E28: =ROUND(#REF!/1000, 2) -> #REF! | F28: =ROUND(#REF!/1000, 2) -> #REF! | G28: =SUM(C28:F28) -> #REF! | O28: =1-(I28-C28)/((M2-1)*C28) -> #REF! | P28: =1-(J28-D28)/((M2-1)*D28) -> #REF! | Q28: =1-(K28-E28)/((M2-1)*E28) -> #REF! | R28: =1-(L28-F28)/((M2-1)*F28) -> #REF!
B29: HSCSAROSC | C29: =ROUND(#REF!/1000, 2) -> #REF! | D29: =ROUND(#REF!/1000, 2) -> #REF! | E29: =ROUND(#REF!/1000, 2) -> #REF! | F29: =ROUND(#REF!/1000, 2) -> #REF! | G29: =SUM(C29:F29) -> #REF! | O29: =1-(I29-C29)/((M2-1)*C29) -> #REF! | P29: =1-(J29-D29)/((M2-1)*D29) -> #REF! | Q29: =1-(K29-E29)/((M2-1)*E29) -> #REF! | R29: =1-(L29-F29)/((M2-1)*F29) -> #REF!
B30: ULPPLL | C30: =ROUND(#REF!/1000, 2) -> #REF! | D30: =ROUND(#REF!/1000, 2) -> #REF! | E30: =ROUND(#REF!/1000, 2) -> #REF! | F30: =ROUND(#REF!/1000, 2) -> #REF! | G30: =SUM(C30:F30) -> #REF! | O30: =1-(I30-C30)/((M2-1)*C30) -> #REF! | P30: =1-(J30-D30)/((M2-1)*D30) -> #REF! | Q30: =1-(K30-E30)/((M2-1)*E30) -> #REF! | R30: =1-(L30-F30)/((M2-1)*F30) -> #REF!
B31: FLPPLL | C31: =ROUND(#REF!/1000, 2) -> #REF! | D31: =ROUND(#REF!/1000, 2) -> #REF! | E31: =ROUND(#REF!/1000, 2) -> #REF! | F31: =ROUND(#REF!/1000, 2) -> #REF! | G31: =SUM(C31:F31) -> #REF! | O31: =1-(I31-C31)/((M2-1)*C31) -> #REF! | P31: =1-(J31-D31)/((M2-1)*D31) -> #REF! | Q31: =1-(K31-E31)/((M2-1)*E31) -> #REF! | R31: =1-(L31-F31)/((M2-1)*F31) -> #REF!
B32: SEPF2M | C32: =ROUND(#REF!/1000, 2) -> #REF! | D32: =ROUND(#REF!/1000, 2) -> #REF! | E32: =ROUND(#REF!/1000, 2) -> #REF! | F32: =ROUND(#REF!/1000, 2) -> #REF! | G32: =SUM(C32:F32) -> #REF! | O32: =1-(I32-C32)/((M2-1)*C32) -> #REF! | P32: =1-(J32-D32)/((M2-1)*D32) -> #REF! | Q32: =1-(K32-E32)/((M2-1)*E32) -> #REF! | R32: =1-(L32-F32)/((M2-1)*F32) -> #REF!
B33: SEPVMC | C33: =ROUND(#REF!/1000, 2) -> #REF! | D33: =ROUND(#REF!/1000, 2) -> #REF! | E33: =ROUND(#REF!/1000, 2) -> #REF! | F33: =ROUND(#REF!/1000, 2) -> #REF! | G33: =SUM(C33:F33) -> #REF! | O33: =1-(I33-C33)/((M2-1)*C33) -> #REF! | P33: =1-(J33-D33)/((M2-1)*D33) -> #REF! | Q33: =1-(K33-E33)/((M2-1)*E33) -> #REF! | R33: =1-(L33-F33)/((M2-1)*F33) -> #REF!
B34: MIDBIASLDO | C34: =ROUND(#REF!/1000, 2) -> #REF! | D34: =ROUND(#REF!/1000, 2) -> #REF! | E34: =ROUND(#REF!/1000, 2) -> #REF! | F34: =ROUND(#REF!/1000, 2) -> #REF! | G34: =SUM(C34:F34) -> #REF! | O34: =1-(I34-C34)/((M2-1)*C34) -> #REF! | P34: =1-(J34-D34)/((M2-1)*D34) -> #REF! | Q34: =1-(K34-E34)/((M2-1)*E34) -> #REF! | R34: =1-(L34-F34)/((M2-1)*F34) -> #REF!
B35: VMADC | C35: =ROUND(#REF!/1000, 2) -> #REF! | D35: =ROUND(#REF!/1000, 2) -> #REF! | E35: =ROUND(#REF!/1000, 2) -> #REF! | F35: =ROUND(#REF!/1000, 2) -> #REF! | G35: =SUM(C35:F35) -> #REF! | O35: =1-(I35-C35)/((M2-1)*C35) -> #REF! | P35: =1-(J35-D35)/((M2-1)*D35) -> #REF! | Q35: =1-(K35-E35)/((M2-1)*E35) -> #REF! | R35: =1-(L35-F35)/((M2-1)*F35) -> #REF!
B36: ACIOPHY | C36: =ROUND(#REF!/1000, 2) -> #REF! | D36: =ROUND(#REF!/1000, 2) -> #REF! | E36: =ROUND(#REF!/1000, 2) -> #REF! | F36: =ROUND(#REF!/1000, 2) -> #REF! | G36: =SUM(C36:F36) -> #REF! | O36: =1-(I36-C36)/((M2-1)*C36) -> #REF! | P36: =1-(J36-D36)/((M2-1)*D36) -> #REF! | Q36: =1-(K36-E36)/((M2-1)*E36) -> #REF! | R36: =1-(L36-F36)/((M2-1)*F36) -> #REF!
B37: ACIPHY | C37: =ROUND(#REF!/1000, 2) -> #REF! | D37: =ROUND(#REF!/1000, 2) -> #REF! | E37: =ROUND(#REF!/1000, 2) -> #REF! | F37: =ROUND(#REF!/1000, 2) -> #REF! | G37: =SUM(C37:F37) -> #REF! | O37: =1-(I37-C37)/((M2-1)*C37) -> #REF! | P37: =1-(J37-D37)/((M2-1)*D37) -> #REF! | Q37: =1-(K37-E37)/((M2-1)*E37) -> #REF! | R37: =1-(L37-F37)/((M2-1)*F37) -> #REF!
B38: LPDPTX | C38: =ROUND(#REF!/1000, 2) -> #REF! | D38: =ROUND(#REF!/1000, 2) -> #REF! | E38: =ROUND(#REF!/1000, 2) -> #REF! | F38: =ROUND(#REF!/1000, 2) -> #REF! | G38: =SUM(C38:F38) -> #REF! | O38: =1-(I38-C38)/((M2-1)*C38) -> #REF! | P38: =1-(J38-D38)/((M2-1)*D38) -> #REF! | Q38: =1-(K38-E38)/((M2-1)*E38) -> #REF! | R38: =1-(L38-F38)/((M2-1)*F38) -> #REF!
B39: PCIE5 | C39: =ROUND(#REF!/1000, 2) -> #REF! | D39: =ROUND(#REF!/1000, 2) -> #REF! | E39: =ROUND(#REF!/1000, 2) -> #REF! | F39: =ROUND(#REF!/1000, 2) -> #REF! | G39: =SUM(C39:F39) -> #REF! | O39: =1-(I39-C39)/((M2-1)*C39) -> #REF! | P39: =1-(J39-D39)/((M2-1)*D39) -> #REF! | Q39: =1-(K39-E39)/((M2-1)*E39) -> #REF! | R39: =1-(L39-F39)/((M2-1)*F39) -> #REF!
B40: NTSX | C40: =ROUND(#REF!/1000, 2) -> #REF! | D40: =ROUND(#REF!/1000, 2) -> #REF! | E40: =ROUND(#REF!/1000, 2) -> #REF! | F40: =ROUND(#REF!/1000, 2) -> #REF! | G40: =SUM(C40:F40) -> #REF! | O40: =1-(I40-C40)/((M2-1)*C40) -> #REF! | P40: =1-(J40-D40)/((M2-1)*D40) -> #REF! | Q40: =1-(K40-E40)/((M2-1)*E40) -> #REF! | R40: =1-(L40-F40)/((M2-1)*F40) -> #REF!
B41: PCIEREFBUF | C41: =ROUND(#REF!/1000, 2) -> #REF! | D41: =ROUND(#REF!/1000, 2) -> #REF! | E41: =ROUND(#REF!/1000, 2) -> #REF! | F41: =ROUND(#REF!/1000, 2) -> #REF! | G41: =SUM(C41:F41) -> #REF! | O41: =1-(I41-C41)/((M2-1)*C41) -> #REF! | P41: =1-(J41-D41)/((M2-1)*D41) -> #REF! | Q41: =1-(K41-E41)/((M2-1)*E41) -> #REF! | R41: =1-(L41-F41)/((M2-1)*F41) -> #REF!
...

Sheet DAPS
A2: Proposal for TTR | D2: Total (ms) | F2: =SUM(E5:G14) -> 4464.2 | I2: =SUM(H5:J14) -> 5025.54 | L2: =SUM(K5:M14) -> 0 | O2: =SUM(N5:P14) -> 0
E3: CP1 (ms) | H3: CP2 (ms) | K3: FT1 (ms) | N3: FT2 (ms)
A4: Category | B4: SubBlock | C4: Pattern | D4: HIP_FailRun | E4: LV | F4: NV | G4: HV | H4: LV | I4: NV | J4: HV | K4: LV | L4: NV | M4: HV | N4: LV | O4: NV | P4: HV | Q4: Prod CP1 | R4: Prod CP2 | S4: Prod FT1 | T4: Prod FT2 | U4: Mon | V4: T0Tx | W4: RMA Room | X4: RMA Hot
A5: DAPS | B5: MEGAPP1 | C5: PP_KMDA0_C_FULP_AN_DAPS_DLL_JTG_COD_ALLFRV_SI_MEGA_PP1 | F5: 114.67 | I5: 172.22
A6: DAPS | B6: MEGAPP2 | C6: PP_KMDA0_C_FULP_AN_DAPS_DLL_JTG_COD_ALLFRV_SI_MEGA_PP2 | F6: 128.24 | I6: 127.23
A7: DAPS | B7: MEGAPP3 | C7: PP_KMDA0_C_FULP_AN_DAPS_DLL_JTG_COD_ALLFRV_SI_MEGA_PP3 | F7: 105.57 | I7: 120.32
A8: DAPS | B8: MEGAPP4 | C8: PP_KMDA0_C_FULP_AN_DAPS_DLL_JTG_COD_ALLFRV_SI_MEGA_PP4 | F8: 121.61 | I8: 118.76
A9: DAPS | B9: MEGAPP5 | C9: PP_KMDA0_C_FULP_AN_DAPS_DLL_JTG_COD_ALLFRV_SI_MEGA_PP5 | F9: 91.04 | I9: 92.89
A10: DAPS | B10: MEGAPP6 | C10: PP_KMDA0_C_FULP_AN_DAPS_DLL_JTG_COD_ALLFRV_SI_MEGA_PP6 | F10: 86 | I10: 86.1
A11: DAPS | B11: MEGAPP7 | C11: PP_KMDA0_C_FULP_AN_DAPS_DLL_JTG_COD_ALLFRV_SI_MEGA_PP7 | F11: 112.84 | I11: 109.29
A12: DAPS | B12: MEGAPP8 | C12: PP_KMDA0_C_FULP_AN_DAPS_DLL_JTG_COD_ALLFRV_SI_MEGA_PP8 | F12: 97.11 | I12: 105.33
A13: DAPS | B13: SYSPP1 | C13: PP_KMDA0_C_FULP_AN_DAPS_DLL_JTG_COD_ALLFRV_SI_SYS_PP1 | F13: 249.05 | I13: 286.63
A14: DAPS | B14: SYSPP2 | C14: PP_KMDA0_C_FULP_AN_DAPS_DLL_JTG_COD_ALLFRV_SI_SYS_PP2 | F14: 3358.07 | I14: 3806.77

Sheet CLKMON
A2: Proposal for TTR | D2: Total (ms) | F2: =SUM(E5:G18) -> 743.4
E3: CP1 (ms)
A4: Category | B4: SubBlock | C4: Pattern | D4: HIP_FailRun | E4: LV | F4: NV | G4: HV | H4: Prod CP1 | I4: Prod CP2 | J4: Prod FT1 | K4: Prod FT2 | L4: Mon | M4: T0Tx | N4: RMA Room | O4: RMA Hot
A5: CLKMON | B5: DCDMEAST1P1 | C5: PP_KMDA0_C_FULP_AN_CM00_DLL_JTG_DYC_ALLFRV_SI_DCDMEAS_T1P1 | F5: 29.17
A6: CLKMON | B6: DCDMEAST1P2 | C6: PP_KMDA0_C_FULP_AN_CM00_DLL_JTG_DYC_ALLFRV_SI_DCDMEAS_T1P2 | F6: 29.4
A7: CLKMON | B7: DCDCALT2P1 | C7: PP_KMDA0_C_FULP_AN_CM00_DLL_JTG_DYC_ALLFRV_SI_DCDCAL_T2P1 | F7: 31.39
A8: CLKMON | B8: DCDCALT2P2 | C8: PP_KMDA0_C_FULP_AN_CM00_DLL_JTG_DYC_ALLFRV_SI_DCDCAL_T2P2 | F8: 31.47
A9: CLKMON | B9: DCDMEAST1P1FINAL | C9: PP_KMDA0_C_FULP_AN_CM00_DLL_JTG_DYC_ALLFRV_SI_DCDMEAS_T1P1 | F9: 38.39
A10: CLKMON | B10: DCDMEAST1P2FINAL | C10: PP_KMDA0_C_FULP_AN_CM00_DLL_JTG_DYC_ALLFRV_SI_DCDMEAS_T1P2 | F10: 29.38
A11: CLKMON | B11: DCDMEAST3P1RAW | C11: PP_KMDA0_C_FULP_AN_CM00_DLL_JTG_DYC_ALLFRV_SI_DCDMEAS_T3P1 | F11: 59.47
A12: CLKMON | B12: DCDMEAST3P2RAW | C12: PP_KMDA0_C_FULP_AN_CM00_DLL_JTG_DYC_ALLFRV_SI_DCDMEAS_T3P2 | F12: 59.32
A13: CLKMON | B13: DCDMEAST3P1 | C13: PP_KMDA0_C_FULP_AN_CM00_DLL_JTG_DYC_ALLFRV_SI_DCDMEAS_T3P1 | F13: 59.23
A14: CLKMON | B14: DCDMEAST3P2 | C14: PP_KMDA0_C_FULP_AN_CM00_DLL_JTG_DYC_ALLFRV_SI_DCDMEAS_T3P2 | F14: 59.4
A15: CLKMON | B15: DCDCALT4P1 | C15: PP_KMDA0_C_FULP_AN_CM00_DLL_JTG_DYC_ALLFRV_SI_DCDCAL_T4P1 | F15: 105.15
A16: CLKMON | B16: DCDCALT4P2 | C16: PP_KMDA0_C_FULP_AN_CM00_DLL_JTG_DYC_ALLFRV_SI_DCDCAL_T4P2 | F16: 93.12
... A18: CLKMON | B18: DCDMEAST3P2FINAL | C18: PP_KMDA0_C_FULP_AN_CM00_DLL_JTG_DYC_ALLFRV_SI_DCDMEAS_T3P2 | F18: 59.23

Sheet PWRDET 
A2: Proposal for TTR | D2: Total (ms) | F2: =SUM(E5:G24) -> 358.07 | I2: =SUM(H5:J20) -> 0 | L2: =SUM(K5:M20) -> 0 | O2: =SUM(N5:P20) -> 0
E3: CP2 (ms) | H3: CP2 (ms) | K3: FT1 (ms) | N3: FT1 (ms)
A4: Category | B4: SubBlock | C4: Pattern | D4: HIP_FailRun | E4: LV | F4: NV | G4: HV | H4: LV | I4: NV | J4: HV | K4: LV | L4: NV | M4: HV | N4: LV | O4: NV | P4: HV | Q4: Prod CP1 | R4: Prod CP2 | S4: Prod FT1 | T4: Prod FT2 | U4: Mon | V4: T0Tx | W4: RMA Room | X4: RMA Hot
A5: PWRDET | B5: PWRAONINITDIGCH | C5: PP_KMDA0_S_IN00_PW_PTSX_XXX_XXX_PWR_ALLFRV_SI_PWRAON_INIT
A6: PWRDET | B6: PWRAONDIGCH | C6: PP_KMDA0_C_FULP_PW_PTSX_PFF_DAA_PWR_ALLFRV_SI_PWR_AONDIGC
A7: PWRDET | B7: PWRAONINITDIGCL | C7: PP_KMDA0_S_IN00_PW_PTSX_XXX_XXX_PWR_ALLFRV_SI_PWRAON_INIT
A8: PWRDET | B8: PWRAONDIGCL | C8: PP_KMDA0_C_FULP_PW_PTSX_PFF_DAA_PWR_ALLFRV_SI_PWR_AONDIGC
A9: PWRDET | B9: PWRAONINITEXPH | C9: PP_KMDA0_S_IN00_PW_PTSX_XXX_XXX_PWR_ALLFRV_SI_PWRAON_INIT | E9: 12.96 | G9: 16.41 | Q9: LV,HV
A10: PWRDET | B10: PWRAONEXPH | C10: PP_KMDA0_C_FULP_PW_PTSX_PFF_DAA_PWR_ALLFRV_SI_PWR_AONEXPH | E10: 25.2 | G10: 16.64 | Q10: LV,HV
A11: PWRDET | B11: PWRAONINITEXPL | C11: PP_KMDA0_S_IN00_PW_PTSX_XXX_XXX_PWR_ALLFRV_SI_PWRAON_INIT | E11: 12.77 | G11: 22.64 | Q11: LV,HV
A12: PWRDET | B12: PWRAONEXPL | C12: PP_KMDA0_C_FULP_PW_PTSX_PFF_DAA_PWR_ALLFRV_SI_PWR_AONEXPL | E12: 16.5 | G12: 16.51 | Q12: LV,HV
A13: PWRDET | B13: PWRSOCINITDIGCH | C13: PP_KMDA0_S_IN00_PW_PTSX_XXX_XXX_PWR_ALLFRV_SI_PWRSOC_INIT
A14: PWRDET | B14: PWRSOCDIGCH | C14: PP_KMDA0_C_FULP_PW_PTSX_PFF_DAA_PWR_ALLFRV_SI_PWR_SOCDIGC
A15: PWRDET | B15: PWRSOCINITDIGCL | C15: PP_KMDA0_S_IN00_PW_PTSX_XXX_XXX_PWR_ALLFRV_SI_PWRSOC_INIT
A16: PWRDET | B16: PWRSOCDIGCL | C16: PP_KMDA0_C_FULP_PW_PTSX_PFF_DAA_PWR_ALLFRV_SI_PWR_SOCDIGC
A17: PWRDET | B17: PWRSOCINITEXPH | C17: PP_KMDA0_S_IN00_PW_PTSX_XXX_XXX_PWR_ALLFRV_SI_PWRSOC_INIT | E17: 17.14 | G17: 26.55 | Q17: LV,HV
A18: PWRDET | B18: PWRSOCEXPH | C18: PP_KMDA0_C_FULP_PW_PTSX_PFF_DAA_PWR_ALLFRV_SI_PWR_SOCEXPH | E18: 14.45 | G18: 14.56 | Q18: LV,HV
A19: PWRDET | B19: PWRSOCINITEXPL | C19: PP_KMDA0_S_IN00_PW_PTSX_XXX_XXX_PWR_ALLFRV_SI_PWRSOC_INIT | E19: 15.66 | G19: 12.7 | Q19: LV,HV
A20: PWRDET | B20: PWRSOCEXPL | C20: PP_KMDA0_C_FULP_PW_PTSX_PFF_DAA_PWR_ALLFRV_SI_PWR_SOCEXPL | E20: 17.85 | G20: 14.43 | Q20: LV,HV
A21: PWRDET | B21: PWRCIOINITEXPH | C21: PP_KMDA0_S_IN00_PW_PTSX_XXX_XXX_PWR_ALLFRV_SI_PWRCIO_INIT | E21: 10.6 | G21: 10.43 | Q21: LV,HV
A22: PWRDET | B22: PWRCIOEXPH | C22: PP_KMDA0_C_FULP_PW_PTSX_PFF_DAA_PWR_ALLFRV_SI_PWR_CIOEXPH | E22: 8.29 | G22: 9.96 | Q22: LV,HV
A23: PWRDET | B23: PWRCIOINITEXPL | C23: PP_KMDA0_S_IN00_PW_PTSX_XXX_XXX_PWR_ALLFRV_SI_PWRCIO_INIT | E23: 10.02 | G23: 12.04 | Q23: LV,HV
A24: PWRDET | B24: PWRCIOEXPL | C24: PP_KMDA0_C_FULP_PW_PTSX_PFF_DAA_PWR_ALLFRV_SI_PWR_CIOEXPL | E24: 15.44 | G24: 8.32 | Q24: LV,HV

Sheet DSGVTHSENSOR
A2: Proposal for TTR | D2: Total (ms) | F2: =SUM(E5:G24) -> 26427.16 | I2: =SUM(H5:J24) -> 0 | L2: =SUM(K5:M24) -> 0 | O2: =SUM(N5:P24) -> 0
E3: CP1 (ms) | H3: CP2 (ms) | K3: FT1 (ms) | N3: FT2 (ms)
A4: Category | B4: SubBlock | C4: Pattern | D4: HIP_FailRun | E4: LV | F4: NV | G4: HV | H4: LV | I4: NV | J4: HV | K4: LV | L4: NV | M4: HV | N4: LV | O4: NV | P4: HV | Q4: Prod CP1 | R4: Prod CP2 | S4: Prod FT1 | T4: Prod FT2 | U4: Mon | V4: T0Tx | W4: RMA Room | X4: RMA Hot
A5: DSGVTHSENSOR | B5: VTHSPT42P253UA | C5: PP_KMDA0_C_FULP_AN_VSNR_DLL_JTG_FRQ_ALLFRV_SI_VTHSP_T4T5 | F5: 895.1 | Q5: NV
A6: DSGVTHSENSOR | B6: VTHSPT42P28UA | C6: PP_KMDA0_C_FULP_AN_VSNR_DLL_JTG_FRQ_ALLFRV_SI_VTHSP_T4T5 | F6: 1208.09 | Q6: NV
A7: DSGVTHSENSOR | B7: VTHSPT42P32UA | C7: PP_KMDA0_C_FULP_AN_VSNR_DLL_JTG_FRQ_ALLFRV_SI_VTHSP_T4T5 | F7: 463.45 | Q7: NV
A8: DSGVTHSENSOR | B8: VTHSPT42P4UA | C8: PP_KMDA0_C_FULP_AN_VSNR_DLL_JTG_FRQ_ALLFRV_SI_VTHSP_T4T5 | F8: 3328.65 | Q8: NV
A9: DSGVTHSENSOR | B9: VTHSPT42P133UA | C9: PP_KMDA0_C_FULP_AN_VSNR_DLL_JTG_FRQ_ALLFRV_SI_VTHSP_T4T5 | F9: 757.63 | Q9: NV
A10: DSGVTHSENSOR | B10: VTHSPT52P253UA | C10: PP_KMDA0_C_FULP_AN_VSNR_DLL_JTG_FRQ_ALLFRV_SI_VTHSP_T4T5 | F10: 920.11 | Q10: NV
A11: DSGVTHSENSOR | B11: VTHSPT52P28 | C11: PP_KMDA0_C_FULP_AN_VSNR_DLL_JTG_FRQ_ALLFRV_SI_VTHSP_T4T5 | F11: 1164.74 | Q11: NV
A12: DSGVTHSENSOR | B12: VTHSPT52P32UA | C12: PP_KMDA0_C_FULP_AN_VSNR_DLL_JTG_FRQ_ALLFRV_SI_VTHSP_T4T5 | F12: 441.17 | Q12: NV
A13: DSGVTHSENSOR | B13: VTHSPT52P4UA | C13: PP_KMDA0_C_FULP_AN_VSNR_DLL_JTG_FRQ_ALLFRV_SI_VTHSP_T4T5 | F13: 3355.55 | Q13: NV
A14: DSGVTHSENSOR | B14: VTHSPT52P133UA | C14: PP_KMDA0_C_FULP_AN_VSNR_DLL_JTG_FRQ_ALLFRV_SI_VTHSP_T4T5 | F14: 723.82 | Q14: NV
A15: DSGVTHSENSOR | B15: VTHSET42P253UA | C15: PP_KMDA0_C_FULP_AN_VSNR_DLL_JTG_FRQ_ALLFRV_SI_VTHSE_T4T5 | F15: 888.05
A16: DSGVTHSENSOR | B16: VTHSET42P28UA | C16: PP_KMDA0_C_FULP_AN_VSNR_DLL_JTG_FRQ_ALLFRV_SI_VTHSE_T4T5 | F16: 1179.44
A17: DSGVTHSENSOR | B17: VTHSET42P32UA | C17: PP_KMDA0_C_FULP_AN_VSNR_DLL_JTG_FRQ_ALLFRV_SI_VTHSE_T4T5 | F17: 488.06
A18: DSGVTHSENSOR | B18: VTHSET42P4UA | C18: PP_KMDA0_C_FULP_AN_VSNR_DLL_JTG_FRQ_ALLFRV_SI_VTHSE_T4T5 | F18: 3378.46
A19: DSGVTHSENSOR | B19: VTHSET42P133UA | C19: PP_KMDA0_C_FULP_AN_VSNR_DLL_JTG_FRQ_ALLFRV_SI_VTHSE_T4T5 | F19: 730.53
A20: DSGVTHSENSOR | B20: VTHSET52P253UA | C20: PP_KMDA0_C_FULP_AN_VSNR_DLL_JTG_FRQ_ALLFRV_SI_VTHSE_T4T5 | F20: 891.07
A21: DSGVTHSENSOR | B21: VTHSET52P28UA | C21: PP_KMDA0_C_FULP_AN_VSNR_DLL_JTG_FRQ_ALLFRV_SI_VTHSE_T4T5 | F21: 1141.11
A22: DSGVTHSENSOR | B22: VTHSET52P32UA | C22: PP_KMDA0_C_FULP_AN_VSNR_DLL_JTG_FRQ_ALLFRV_SI_VTHSE_T4T5 | F22: 458.33
A23: DSGVTHSENSOR | B23: VTHSET52P4UA | C23: PP_KMDA0_C_FULP_AN_VSNR_DLL_JTG_FRQ_ALLFRV_SI_VTHSE_T4T5 | F23: 3280.58
A24: DSGVTHSENSOR | B24: VTHSET52P133UA | C24: PP_KMDA0_C_FULP_AN_VSNR_DLL_JTG_FRQ_ALLFRV_SI_VTHSE_T4T5 | F24: 733.22
E29: CP1 | F29: =SUM(F5:F14) -> 13258.31

Sheet IVDM
A2: Proposal for TTR | D2: Total (ms) | F2: =SUM(E5:G38) -> 0 | I2: =SUM(H5:J38) -> 0 | L2: =SUM(K5:M38) -> 325.64 | O2: =SUM(N5:P38) -> 106.94
E3: CP1 (ms) | H3: CP2 (ms) | K3: FT1 (ms) | N3: FT2 (ms)
A4: Category | B4: SubBlock | C4: Pattern | D4: HIP_FailRun | E4: LV | F4: NV | G4: HV | H4: LV | I4: NV | J4: HV | K4: LV | L4: NV | M4: HV | N4: LV | O4: NV | P4: HV | Q4: Prod CP1 | R4: Prod CP2 | S4: Prod FT1 | T4: Prod FT2 | U4: Mon | V4: T0Tx | W4: RMA Room | X4: RMA Hot
A5: IVDM | B5: PCPUFMINPTRIM3X0P750 | C5: PP_KMDA0_C_FULP_AN_IVDM_FRQ_JTG_RCR_ALLFRV_SI_PCPUFMIN_PTRIM3X | L5: 26.87 | S5: NV
A6: IVDM | B6: PCPUFMINPTRIM3X1P000 | C6: PP_KMDA0_C_FULP_AN_IVDM_FRQ_JTG_RCR_ALLFRV_SI_PCPUFMIN_PTRIM3X | L6: 25.1 | S6: NV
A7: IVDM | B7: PCPUFMINPTRIM10X0P750 | C7: PP_KMDA0_C_FULP_AN_IVDM_FRQ_JTG_RCR_ALLFRV_SI_PCPUFMIN_PTRIM10X | S7: NV
A8: IVDM | B8: OTHER | C8: IVDM_FUSE_PREWRITE1 | L8: 0.48 | S8: NV
A9: IVDM | B9: OTHER | C9: IVDM_FUSE_PREWRITE2 | L9: 0.42 | S9: NV
A10: IVDM | B10: OTHER | C10: IVDM_FUSE_PREWRITE3 | O10: 6.72 | T10: NV
A11: IVDM | B11: OTHER | C11: IVDM_FUSE_PREWRITE4 | L11: 2.7 | S11: NV
A12: IVDM | B12: OTHER | C12: IVDM_FUSE_PREWRITE5 | L12: 2.63 | S12: NV
A13: IVDM | B13: OTHER | C13: IVDM_FUSE_PREWRITE6 | L13: 2.54 | S13: NV
A14: IVDM | B14: PCPUFMINPTRIM10X1P000 | C14: PP_KMDA0_C_FULP_AN_IVDM_FRQ_JTG_RCR_ALLFRV_SI_PCPUFMIN_PTRIM10X | S14: NV
A15: IVDM | B15: GPUFMINGTRIM3X0P650HT | C15: PP_KMDA0_C_FULP_AN_IVDM_FRQ_JTG_RCR_ALLFRV_SI_GPUFMIN_GTRIM3X | O15: 100.22 | T15: NV
A16: IVDM | B16: GPUFMINGTRIM3X0P650RT | C16: PP_KMDA0_C_FULP_AN_IVDM_FRQ_JTG_RCR_ALLFRV_SI_GPUFMIN_GTRIM3X | L16: 92.28 | S16: NV
A17: IVDM | B17: GPUFMINGTRIM3X0P750MID | C17: PP_KMDA0_C_FULP_AN_IVDM_FRQ_JTG_RCR_ALLFRV_SI_GPUFMIN_GTRIM3X | L17: 79.25 | S17: NV
A18: IVDM | B18: GPUFMINGTRIM3X1P000 | C18: PP_KMDA0_C_FULP_AN_IVDM_FRQ_JTG_RCR_ALLFRV_SI_GPUFMIN_GTRIM3X | L18: 93.37 | S18: NV
A19: IVDM | B19: GPUFMINGTRIM10X0P650HT | C19: PP_KMDA0_C_FULP_AN_IVDM_FRQ_JTG_RCR_ALLFRV_SI_GPUFMIN_GTRIM10X | T19: NV
A20: IVDM | B20: GPUFMINGTRIM10X0P650RT | C20: PP_KMDA0_C_FULP_AN_IVDM_FRQ_JTG_RCR_ALLFRV_SI_GPUFMIN_GTRIM10X | S20: NV
A21: IVDM | B21: GPUFMINGTRIM10X0P750MID | C21: PP_KMDA0_C_FULP_AN_IVDM_FRQ_JTG_RCR_ALLFRV_SI_GPUFMIN_GTRIM10X | S21: NV
A22: IVDM | B22: GPUFMINGTRIM10X1P000 | C22: PP_KMDA0_C_FULP_AN_IVDM_FRQ_JTG_RCR_ALLFRV_SI_GPUFMIN_GTRIM10X | S22: NV
A23: IVDM | B23: GPUFMINGTR1B3X0P650HT | C23: PP_KMDA0_C_FULP_AN_IVDM_FRQ_JTG_RCR_ALLFRV_SI_GPUFMIN_GTR1B3X
A24: IVDM | B24: GPUFMINGTR1B3X0P650RT | C24: PP_KMDA0_C_FULP_AN_IVDM_FRQ_JTG_RCR_ALLFRV_SI_GPUFMIN_GTR1B3X
A25: IVDM | B25: GPUFMINGTR1B3X0P750MID | C25: PP_KMDA0_C_FULP_AN_IVDM_FRQ_JTG_RCR_ALLFRV_SI_GPUFMIN_GTR1B3X
A26: IVDM | B26: GPUFMINGTR1B3X1P000 | C26: PP_KMDA0_C_FULP_AN_IVDM_FRQ_JTG_RCR_ALLFRV_SI_GPUFMIN_GTR1B3X
A27: IVDM | B27: GPUFMINGTR1B10X0P650HT | C27: PP_KMDA0_C_FULP_AN_IVDM_FRQ_JTG_RCR_ALLFRV_SI_GPUFMIN_GTR1B10X
A28: IVDM | B28: GPUFMINGTR1B10X0P650RT | C28: PP_KMDA0_C_FULP_AN_IVDM_FRQ_JTG_RCR_ALLFRV_SI_GPUFMIN_GTR1B10X
A29: IVDM | B29: GPUFMINGTR1B10X0P750MID | C29: PP_KMDA0_C_FULP_AN_IVDM_FRQ_JTG_RCR_ALLFRV_SI_GPUFMIN_GTR1B10X
A30: IVDM | B30: GPUFMINGTR1B10X1P000 | C30: PP_KMDA0_C_FULP_AN_IVDM_FRQ_JTG_RCR_ALLFRV_SI_GPUFMIN_GTR1B10X
A31: IVDM | B31: GPUFMINGTR4B3X0P650HT | C31: PP_KMDA0_C_FULP_AN_IVDM_FRQ_JTG_RCR_ALLFRV_SI_GPUFMIN_GTR4B3X
A32: IVDM | B32: GPUFMINGTR4B3X0P650RT | C32: PP_KMDA0_C_FULP_AN_IVDM_FRQ_JTG_RCR_ALLFRV_SI_GPUFMIN_GTR4B3X
A33: IVDM | B33: GPUFMINGTR4B3X0P750MID | C33: PP_KMDA0_C_FULP_AN_IVDM_FRQ_JTG_RCR_ALLFRV_SI_GPUFMIN_GTR4B3X
A34: IVDM | B34: GPUFMINGTR4B3X1P000 | C34: PP_KMDA0_C_FULP_AN_IVDM_FRQ_JTG_RCR_ALLFRV_SI_GPUFMIN_GTR4B3X
... A38: IVDM | B38: GPUFMINGTR4B10X1P000 | C38: PP_KMDA0_C_FULP_AN_IVDM_FRQ_JTG_RCR_ALLFRV_SI_GPUFMIN_GTR4B10X

Sheet ABSMIN
A2: Proposal for TTR | D2: Total (ms) | F2: =SUM(E5:G20) -> 443.37 | I2: =SUM(H5:J20) -> 0 | L2: =SUM(K5:M20) -> 0 | O2: =SUM(N5:P20) -> 0
E3: CP1 (ms) | H3: CP2 (ms) | K3: FT1 (ms) | N3: FT2 (ms)
A4: Category | B4: SubBlock | C4: Pattern | D4: HIP_FailRun | E4: LV | F4: NV | G4: HV | H4: LV | I4: NV | J4: HV | K4: LV | L4: NV | M4: HV | N4: LV | O4: NV | P4: HV | Q4: Prod CP1 | R4: Prod CP2 | S4: Prod FT1 | T4: Prod FT2 | U4: Mon | V4: T0Tx | W4: RMA Room | X4: RMA Hot
A5: ABSMIN | B5: CPUCON1A | C5: PP_KMDA0_C_FULP_AN_ABSM_VOT_JTG_DSG_ALLFRV_SI_CPU_CON1A | F5: 30.1 | V5: NV
A6: ABSMIN | B6: CPUCON1B | C6: PP_KMDA0_C_FULP_AN_ABSM_VOT_JTG_DSG_ALLFRV_SI_CPU_CON1B | F6: 25.68 | V6: NV
A7: ABSMIN | B7: CPUCON2 | C7: PP_KMDA0_C_FULP_AN_ABSM_VOT_JTG_DSG_ALLFRV_SI_CPU_CON2 | F7: 25.92 | V7: NV
A8: ABSMIN | B8: CPUCON3 | C8: PP_KMDA0_C_FULP_AN_ABSM_VOT_JTG_DSG_ALLFRV_SI_CPU_CON3 | F8: 35.11 | V8: NV
A9: ABSMIN | B9: CPUCON4 | C9: PP_KMDA0_C_FULP_AN_ABSM_VOT_JTG_DSG_ALLFRV_SI_CPU_CON4 | F9: 25.56 | V9: NV
A10: ABSMIN | B10: CPUCON5 | C10: PP_KMDA0_C_FULP_AN_ABSM_VOT_JTG_DSG_ALLFRV_SI_CPU_CON5 | F10: 25.32 | V10: NV
A11: ABSMIN | B11: CPUCON6 | C11: PP_KMDA0_C_FULP_AN_ABSM_VOT_JTG_DSG_ALLFRV_SI_CPU_CON6 | F11: 26.74 | V11: NV
A12: ABSMIN | B12: CPUCON7 | C12: PP_KMDA0_C_FULP_AN_ABSM_VOT_JTG_DSG_ALLFRV_SI_CPU_CON7 | F12: 28.3 | V12: NV
A13: ABSMIN | B13: CPUCON8 | C13: PP_KMDA0_C_FULP_AN_ABSM_VOT_JTG_DSG_ALLFRV_SI_CPU_CON8 | F13: 24.84 | V13: NV
A14: ABSMIN | B14: CPUCON9 | C14: PP_KMDA0_C_FULP_AN_ABSM_VOT_JTG_DSG_ALLFRV_SI_CPU_CON9 | F14: 27.16 | V14: NV
A15: ABSMIN | B15: CPUCON10 | C15: PP_KMDA0_C_FULP_AN_ABSM_VOT_JTG_DSG_ALLFRV_SI_CPU_CON10 | F15: 26.88 | V15: NV
A16: ABSMIN | B16: CPUCON11 | C16: PP_KMDA0_C_FULP_AN_ABSM_VOT_JTG_DSG_ALLFRV_SI_CPU_CON11 | F16: 25.5 | V16: NV
... A20: ABSMIN | B20: CPUCON15 | C20: PP_KMDA0_C_FULP_AN_ABSM_VOT_JTG_DSG_ALLFRV_SI_CPU_CON15 | F20: 28.93 | V20: NV

Sheet LLPSMN
A2: Proposal for TTR | D2: Total (ms) | F2: =SUM(E5:G7) -> 0 | I2: =SUM(H5:J7) -> 0 | L2: =SUM(K5:M7) -> 0 | O2: =SUM(N5:P7) -> 0 | U2: WAT
E3: CP1 (ms) | H3: CP2 (ms) | K3: FT1 (ms) | N3: FT2 (ms)
A4: Category | B4: SubBlock | C4: Pattern | D4: HIP_FailRun | E4: LV | F4: NV | G4: HV | H4: LV | I4: NV | J4: HV | K4: LV | L4: NV | M4: HV | N4: LV | O4: NV | P4: HV | Q4: Prod CP1 | R4: Prod CP2 | S4: Prod FT1 | T4: Prod FT2 | U4: Mon | V4: T0Tx | W4: RMA Room | X4: RMA Hot
A5: LLPSMN | B5: MNLLPSOFFT3 | C5: MN_KMDA0_C_FULP_AN_LLPS_DLL_JTG_CAL_ALLFRV_SI_LLPSOFF_T3 | U5: NV
A6: LLPSMN | B6: MNLLPSONT4A | C6: MN_KMDA0_C_FULP_AN_LLPS_DLL_JTG_CAL_ALLFRV_SI_LLPSON_T4A | U6: NV | V6: NV
A7: LLPSMN | B7: MNLLPSONT10 | C7: MN_KMDA0_C_FULP_AN_LLPS_DLL_JTG_CAL_ALLFRV_SI_LLPSON_T10 | U7: NV | V7: NV

Sheet NCKM
A2: Proposal for TTR | D2: Total (ms) | F2: =SUM(E5:G19) -> 0 | I2: =SUM(H5:J19) -> 0 | L2: =SUM(K5:M19) -> 0 | O2: =SUM(N5:P19) -> 0 | U2: WAT-CP!
E3: CP1 (ms) | H3: CP2 (ms) | K3: FT1 (ms) | N3: FT2 (ms)
A4: Category | B4: SubBlock | C4: Pattern | D4: HIP_FailRun | E4: LV | F4: NV | G4: HV | H4: LV | I4: NV | J4: HV | K4: LV | L4: NV | M4: HV | N4: LV | O4: NV | P4: HV | Q4: Prod CP1 | R4: Prod CP2 | S4: Prod FT1 | T4: Prod FT2 | U4: Mon | V4: T0Tx | W4: RMA Room | X4: RMA Hot
A5: NCKM | B5: MNDCMTESTTS1P1 | C5: MN_KMDA0_S_FULP_AN_NPR0_DLL_JTG_COD_ALLFRV_SI_DCMTEST_TS1P1 | U5: NV
A6: NCKM | B6: MNDCMTESTTS1P4 | C6: MN_KMDA0_S_FULP_AN_NPR0_DLL_JTG_COD_ALLFRV_SI_DCMTEST_TS1P4 | U6: NV
A7: NCKM | B7: MNDCMTESTTS1P12 | C7: MN_KMDA0_S_FULP_AN_NPR0_DLL_JTG_COD_ALLFRV_SI_DCMTEST_TS1P12 | U7: NV
A8: NCKM | B8: MNDCMTESTTS2P1 | C8: MN_KMDA0_S_FULP_AN_NPR0_DLL_JTG_COD_ALLFRV_SI_DCMTEST_TS2P1 | U8: NV
A9: NCKM | B9: MNDCMTESTTS2P2 | C9: MN_KMDA0_S_FULP_AN_NPR0_DLL_JTG_COD_ALLFRV_SI_DCMTEST_TS2P2 | U9: NV
A10: NCKM | B10: MNDCMTESTTS2P3 | C10: MN_KMDA0_S_FULP_AN_NPR0_DLL_JTG_COD_ALLFRV_SI_DCMTEST_TS2P3 | U10: NV
A11: NCKM | B11: MNDCMTESTTS2P4 | C11: MN_KMDA0_S_FULP_AN_NPR0_DLL_JTG_COD_ALLFRV_SI_DCMTEST_TS2P4 | U11: NV
A12: NCKM | B12: MNDCMTESTTS2P5 | C12: MN_KMDA0_S_FULP_AN_NPR0_DLL_JTG_COD_ALLFRV_SI_DCMTEST_TS2P5 | U12: NV
A13: NCKM | B13: MNDCMTESTTS2P6 | C13: MN_KMDA0_S_FULP_AN_NPR0_DLL_JTG_COD_ALLFRV_SI_DCMTEST_TS2P6 | U13: NV
A14: NCKM | B14: MNDCMTESTTS2P7 | C14: MN_KMDA0_S_FULP_AN_NPR0_DLL_JTG_COD_ALLFRV_SI_DCMTEST_TS2P7 | U14: NV
A15: NCKM | B15: MNDCMTESTTS2P8 | C15: MN_KMDA0_S_FULP_AN_NPR0_DLL_JTG_COD_ALLFRV_SI_DCMTEST_TS2P8 | U15: NV
A16: NCKM | B16: MNDCMTESTTS2P9 | C16: MN_KMDA0_S_FULP_AN_NPR0_DLL_JTG_COD_ALLFRV_SI_DCMTEST_TS2P9 | U16: NV
... A19: NCKM | B19: MNDCMTESTTS2P12 | C19: MN_KMDA0_S_FULP_AN_NPR0_DLL_JTG_COD_ALLFRV_SI_DCMTEST_TS2P12 | U19: NV

Sheet NPMS
A2: Proposal for TTR | D2: Total (ms) | F2: =SUM(E5:G9) -> 4833.55 | I2: =SUM(H5:J9) -> 0 | L2: =SUM(K5:M9) -> 0 | O2: =SUM(N5:P9) -> 0
E3: CP1 (ms) | H3: CP2 (ms) | K3: FT1 (ms) | N3: FT2 (ms)
A4: Category | B4: SubBlock | C4: Pattern | D4: HIP_FailRun | E4: LV | F4: NV | G4: HV | H4: LV | I4: NV | J4: HV | K4: LV | L4: NV | M4: HV | N4: LV | O4: NV | P4: HV | Q4: Prod CP1 | R4: Prod CP2 | S4: Prod FT1 | T4: Prod FT2 | U4: Mon | V4: T0Tx | W4: RMA Room | X4: RMA Hot
A5: NPMS | B5: NPMST3 | C5: PP_KMDA0_S_FULP_AN_NPMS_FRQ_JTG_COD_ALLFRV_SI_NPMS_T3 | F5: 1856.68
A6: NPMS | B6: NPMST4 | C6: PP_KMDA0_S_FULP_AN_NPMS_FRQ_JTG_COD_ALLFRV_SI_NPMS_T4 | F6: 2976.87
A7: NPMS | B7: MNNPMST5 | C7: MN_KMDA0_S_FULP_AN_NPMS_FRQ_JTG_COD_ALLFRV_SI_NPMS_T5
A8: NPMS | B8: MNNPMST3 | C8: MN_KMDA0_S_FULP_AN_NPMS_FRQ_JTG_COD_ALLFRV_SI_NPMS_T3
A9: NPMS | B9: MNNPMST4 | C9: MN_KMDA0_S_FULP_AN_NPMS_FRQ_JTG_COD_ALLFRV_SI_NPMS_T4

Sheet DSGRINGS
A2: Proposal for TTR | D2: Total (ms) | F2: =SUM(E5:G15) -> 2957.8 | I2: =SUM(H5:J15) -> 0 | L2: =SUM(K5:M15) -> 0 | O2: =SUM(N5:P15) -> 0
E3: CP1 (ms) | H3: CP2 (ms) | K3: FT1 (ms) | N3: FT2 (ms)
A4: Category | B4: SubBlock | C4: Pattern | D4: HIP_FailRun | E4: LV | F4: NV | G4: HV | H4: LV | I4: NV | J4: HV | K4: LV | L4: NV | M4: HV | N4: LV | O4: NV | P4: HV | Q4: Prod CP1 | R4: Prod CP2 | S4: Prod FT1 | T4: Prod FT2 | U4: Mon | V4: T0Tx | W4: RMA Room | X4: RMA Hot
A5: DSGRINGS | B5: RNGLITEVAOPDC0 | C5: PP_KMDA0_C_FULP_AN_RING_FRQ_JTG_RNG_ALLFRV_SI_RNGLITE_VAOPDC0 | F5: 188.33 | Q5: NV
A6: DSGRINGS | B6: MNRNGLITEVSOCDC0 | C6: MN_KMDA0_C_FULP_AN_RING_FRQ_JTG_RNG_ALLFRV_SI_RNGLITE_VSOCDC0
A7: DSGRINGS | B7: RNGSTDVSOCDC0 | C7: PP_KMDA0_C_FULP_AN_RING_FRQ_JTG_RNG_ALLFRV_SI_RNGSTD_VSOCDC0 | F7: 323.99 | Q7: NV
A8: DSGRINGS | B8: MNRNGSTDVSOCDC0 | C8: MN_KMDA0_C_FULP_AN_RING_FRQ_JTG_RNG_ALLFRV_SI_RNGSTD_VSOCDC0
A9: DSGRINGS | B9: RNGLITEPCOREDC1 | C9: PP_KMDA0_C_FULP_AN_RING_FRQ_JTG_RNG_ALLFRV_SI_RNGLITE_PCOREDC1 | F9: 193.33 | Q9: NV
A10: DSGRINGS | B10: RNGCPUHV | C10: PP_KMDA0_C_FULP_AN_RING_FRQ_JTG_RCR_ALLFRV_SI_RNG_CPUHV | F10: 352.97 | Q10: NV
A11: DSGRINGS | B11: RNGCPUVER | C11: PP_KMDA0_C_FULP_AN_RING_FRQ_JTG_RCR_ALLFRV_SI_RNG_CPUVER | F11: 947.66 | Q11: NV
A12: DSGRINGS | B12: RNGCPUHORI | C12: PP_KMDA0_C_FULP_AN_RING_FRQ_JTG_RCR_ALLFRV_SI_RNG_CPUHORI | F12: 951.52 | Q12: NV
A13: DSGRINGS | B13: MNRNGCPUHV | C13: MN_KMDA0_C_FULP_AN_RING_FRQ_JTG_RCR_ALLFRV_SI_RNG_CPUHV
A14: DSGRINGS | B14: MNRNGCPUVER | C14: MN_KMDA0_C_FULP_AN_RING_FRQ_JTG_RCR_ALLFRV_SI_RNG_CPUVER
A15: DSGRINGS | B15: MNRNGCPUHORI | C15: MN_KMDA0_C_FULP_AN_RING_FRQ_JTG_RCR_ALLFRV_SI_RNG_CPUHORI
A16: DSGRINGS | B16: RNGLITEPCORETTR | C16: PP_KMDA0_C_FULP_AN_RING_FRQ_JTG_RNG_ALLFRV_SI_RNGLITE_PCORETTR | Q16: NV

Sheet dsg_pm
A3: Proposal for TTR | D3: Total (ms) | F3: =SUM(E6:G15) -> 0 | I3: =SUM(H6:J15) -> 0 | L3: =SUM(K6:M15) -> 0 | O3: =SUM(N6:P15) -> 0
E4: CP1 (ms) | H4: CP2 (ms) | K4: FT1 (ms) | N4: FT2 (ms)
A5: Category | B5: SubBlock | C5: Pattern | D5: HIP_FailRun | E5: LV | F5: NV | G5: HV | H5: LV | I5: NV | J5: HV | K5: LV | L5: NV | M5: HV | N5: LV | O5: NV | P5: HV | Q5: Prod CP1 | R5: Prod CP2 | S5: Prod FT1 | T5: Prod FT2 | U5: Mon | V5: T0Tx | W5: RMA Room | X5: RMA Hot
B6: CZ_PPM_CZ7 | C6: CZ_KMDA0_C_FULP_AN_PDPM_FRQ_JTG_FRQ_ALLFRV_SI_PPM_CZ7
B7: CZ_PPM_CZ91 | C7: CZ_KMDA0_C_FULP_AN_PDPM_FRQ_JTG_COD_ALLFRV_SI_PPM_CZ9
B8: CZ_PPM_CZ92 | C8: CZ_KMDA0_C_FULP_AN_PDPM_FRQ_JTG_COD_ALLFRV_SI_PPM_CZ9
B9: CZ_EPM_CZ7 | C9: CZ_KMDA0_C_FULP_AN_PDPM_FRQ_JTG_FRQ_ALLFRV_SI_EPM_CZ7
B10: CZ_EPM_CZ9 | C10: CZ_KMDA0_C_FULP_AN_PDPM_FRQ_JTG_COD_ALLFRV_SI_EPM_CZ9
