Workbook

Sheet Sheet1
D2: VBT_LIB_DACTrim_AP | E2: VBT_LIB_HardIP_AP | F2: VBT_LIB_HardIP_Customize | G2: VBT_LIB_K_ADDRIO_AP | J2: LIB_DACTrim_AP | K2: SiteEXpand | L2: LIB_HardIP | M2: Addstorecapture_Trim | N2: LIB_HardIP_Calc | O2: LP5_LB_DLL | P2: TX_EQ
D3: DACTrimPrint | E3: HIP_eFuse_Read_TMPS_Coeff | F3: AMP_EYE_VT_Setup | G3: ReadEfuseDecimal_from_Dictionary | J3: BinDSP2Str | K3: SiteEXpandDSPWf | L3: IO_Power_Split | M3: DSSC_Search_par_run_LDO | N3: Calc_2S_Complement_To_SignDec_Modified | O3: LP5_LB_RDDLL | P3: LIB_HardIP_Calc_Turks_AP
D4: PrintAllTrimResult | E4: TMPS | F4: CUS_AMP_SDLL_SWP_Init | G4: SetWriteDecimalPassFlagToEFuse | J4: DACTrim_DigSrcSetting | K4: CalcTarget_V2 | L4: PATT_EXculdePath | M4: Rtn_Dic_count | N4: Calc_2S_Complement_To_SignDec_Modified_Nolimit | O4: Calc_MTR_BinStr2HeXStr | P4: Calc_PVTX
D5: VBT_LIB_HardIP | E5: ADC_Trim | F5: ADCLK_MatriX_Loading | G5: TrimImpedance_M9 | J5: DecomposePatternSet | K5: Do_All | L5: Decide_Measure_Pin | M5: Split_GrayDSP_to_Dec | N5: Calc_MDLL_Monotonicity_DevideBlock | O5: Calc_Voff_t6p2_MetrologyGR | P5: Calc_MDLL_BIST
D6: Opt_DdrLpBkFunc3 | E6: MTR_Sense_Calibration_Coeff_Verification | F6: VBT_LIB_HardIP_JitterEye_AP | G6: Show_Fuse_Check | J6: DACTrim_WriteFuncResult | K6: TransitionSearch | L6: Decide_MeasureI_CurrentRange | M6: LIB_HardIP_Calc | N6: Calc_Metrology_GainError | O6: Calc_Ratio_off_average_t6p2_MetrologyGR | P6: Calc_NAND_PHY_MDLL
D7: DigSrc_DigCap_Universal_func | E7: Metrology_CAL_eFuse_Write | F7: Time_Measure_kit_UP1600 | G7: HIP_eFuse_Read_and_Set_SiteVar | J7: StartFRC | K7: BinarySearch | L7: PinNameDuplicateCheck | M7: Calc_delay | N7: Calc_MIPI_CodeTolerance | O7: Calc_2S_Complement_To_SignDec_DivConst | P7: Wave2Str_Single
D8: TMPS_Voltage_Print | E8: HIP_eFuse_Write_by_MTRGSNS | F8: DDR_RO_Time_Measure_KIT_UP1600 | G8: Show_Num_Of_Data_In_Fuse | J8: StopFRC | K8: Boundary | L8: HardIP_Characterization_ShmooEndFunction | M8: Calc_SetFlag | N8: Calc_Metrology_GainErrorOffset | O8: Calc_Metrology_Trim_Vdiff | P8: Calc_PVTP
D9: ReMeasImpedByAveTrimCode | E9: Check_MTRGSNS_25C_Fuse | F9: VBT_LIB_HardIP_Metrology_AP | G9: CombineTrimCodeInEFuseAndTrimII | J9: Select_Measure_Pin | K9: LinearSearch | L9: IPF_CZ_PrintFreq | M9: Calc_GrayCode | N9: Calc_Metrology_EncodeActualTemp | O9: Calc_MetrologyGR_t5p5 | P9: Calc_PVTN
D10: TMPS_Bin2Dec | E10: MTR_REL_Fuse_Calc_Verification | F10: MetrologySense_Calibration | G10: TrimImpedance_M9_Check_TrimCode | J10: Select_MeasureI_CurrentRange | K10: Interpolate | L10: SrcVoltFromFlowForLoop | M10: CMRR | N10: Calc_Metrology_DecodeActualTemp | O10: Calc_MetrologyGR_t1p0 | P10: Calc_ONE_MAX_COUNT
D11: TMPS_Dec2Bin | E11: MTR_Sense_Alignment_Calc | F11: MTRTMPS_OffSet_AVG | G11: RemoveAllEfuseDecimal_to_Dictionary | J11: DACTrim_FrequencyMeasureSingleEnd | K11: GetTrimName | L11: Rev_BinArray | M11: PSRR | N11: Calc_Metrology_adc_tfe_temp_fuses | O11: Calc_PCIE_RXTERM | P11: Calc_Abs_Res
D12: TrimCodeDig_SeaHawk | E12: MTR_Sense_Calibration_Coeff_Calc | F12: MTRTMPS_Gain_Cal | G12: TrimImpedance_M9_Check_TrimCode_V1 | J12: DiscriminateMeasV_PinType | K12: GetTrimCode | L12: PLL_calibration_calc | M12: Calc_RXEye | N12: Calc_MTR_REL_Freq_Diff_Percentage | O12: Auth_Debug | P12: Calc_ROSC_Freq
D13: TrimCodeBasicDig | E13: MTRG_t5p2a_DigSrc_Coefficient_PreCalc | F13: VBT_LIB_HardIP_PCIE_PI_AP | G13: K_ADDRIO_FUSE_WRITE | J13: DACTrim_SetupAndMeasureVolt_UVI80 | K13: GetTrimVal | L13: VFI_ProcessWaitTimeString | M13: Calc_AverageDSP | N13: Calc_MIPID_VCMTX | O13: Calc_DigCap_MeanWithVariance | P13: Calc_SweepV_COMPE
... D16: PCIE_Eye_Diagram_2 | E16: DSSC_Search_LDO | F16: PCIE_PI_Pat2 | G16: K_Merge_TrimCode_From_Fuse_n_Trim | J16: DACTrim_MeasureI_Combine2TestCondition | K16: TrimVallimit | L16: DSSC_Search_par_run | M16: Calc_TMPS_Coeff_1point | N16: Calc_DigCapAvg | O16: Calc_DiCap_ParallelMode_For_IPPM | P16: Public_AddStoredCaptureData
D17: PCIE_Eye_Diagram_3 | E17: TrimUVI80Code_VFI_2sComplement | F17: PCIE_PI_Pat3 | J17: DiscriminateMeasI_TestCondition | K17: TrimVallimit_V2 | L17: Freq_WalkingStrobe_Meas_VOD_Diff | M17: ADDRIO_TrimCodeAverage | N17: Calc_CalR_FVMI_IO | O17: prasing_ADC | P17: Public_GetStoredCaptureData
D18: PCIE_Eye_Diagram_4 | E18: TrimUVI80Code_VFI | F18: PCIE_PI_Pat4 | J18: DACTrim_NC_Pin | K18: fuseCode | L18: UP1600_PPMU_Measure_R_SE | M18: Calc_MDLL_Monotonicity | N18: Calc_CalZ_FVMI | O18: Calc_12bADC_MeanWithVariance | P18: LIB_HardIP_Metrology_AP
D19: PCIE_Eye_Diagram_5 | E19: TrimCodeFreq_new_0828 | F19: PI_continuous_fai_count | J19: IsEmptyArray | K19: FuseVal | L19: SubMeasR | M19: Calc_MDLL_Monotonicity_Analyze | N19: Sub_MDLL | O19: DebugPrintRawDigCap | P19: MTRTMPS_Gain_AVG
D20: LPDPRX_Eye_Diagram | E20: TrimCodeImpedence | F20: EyeCount | J20: TrimPinNameDuplicate | K20: GetCustomSearch | L20: SimulateOutputImped | M20: Calc_LPDPTX_FXCode | N20: Calc_FromLoad_MTR_SE_CAL_Coeff | O20: Calc_ADC_average | P20: Calc_MetrologyGR_RPSRSPARE0
D21: Enable_HIP_Datalog_Format_CZ | E21: MTR_Verification_Calculate | F21: EyeWidth | J21: DACTrim_SetupAndMeasureCurrent_UVI80 | K21: InverseBinStr | L21: UP1600_PPMU_Measure_R_DI | M21: Calc_ADCPLL_fuse | N21: MTR_Cal_DecimalToBinary | O21: Calc_D2D_MAX_MIN_V2 | P21: Calc_MetrologyBTS_Select
D22: Set_SEPVM_Ref_Level_Div | E22: HardIP_Trim_Set_PrePoint | J22: DACTrim_SetupAndMeasureCurrent_HeXVS | K22: InverseDec | L22: CreateSimulateMDLL_Data | M22: Calc_GrayCodeToBin | N22: TX_Low_Level | O22: P2PBundle_eye | P22: Calc_MetrologyTMPS_MaX_Min
D23: SEPVM_Ref_measurement | E23: HardIP_Trim_Set_PostPoint | J23: DACTrim_HeXVS__MI_StoreCondition | K23: MapSearchMethod | L23: IPF_Connect_PPMU_ForceV | M23: CalcDutyDelay | N23: Calc_MIPI_Tolerance | O23: P2PBundle_Unflipeye | P23: Calc_MetrologyBTS_Temperature_MaX_Min_Avg
D24: SEPVM_Ref2_Calibration | J24: DACTrim_HeXVS__MI_RestoreCondition | K24: DACTrim_ProcessCalcEquation | L24: IPF_Connect_Digital | M24: CalcDutyDelay_Delta | N24: Calc_ADC_Error_code | O24: LB_Error_Count
D25: ReSet_SEPVM_Ref_Level_Div | J25: DACTrim_SetupAndMeasureCurrent_UVS256 | K25: AddDSPWf2Dic | L25: DictDSPToSiteLong | M25: CalcDelayJitter | N25: ADC_code_toV | O25: Calc_EQcal_DigSrc
J26: DACTrim_UVS256__MI_StoreCondition | K26: Trim_DiscriminateMeasureV_TestCondition | L26: HardIP_Duty_Frequency | M26: CalcJitter | N26: Calc_MTR_REL_Freq_Diff_AVG | O26: Calc_DCSkew_IN_CLK
J27: DACDigSrcDspWave | K27: ReplStr | L27: TrimUVI80_Meas_VFI | M27: Calc_2S_Complement_To_SignDec | N27: Calc_MTR_AVG | O27: Functional_Parametric_LoopFunction
J28: DACTrim_UVS256__MI_RestoreCondition | K28: EqMapping | L28: Trim_CIOTXbyTable | M28: Calc_TMPS_Code2Temperature | N28: USB3_ADC | O28: Calc_RAW_DCO_DAC
J29: DisConnectMeasureVoltPins | K29: TrimReturn | L29: Trim_SetupandmeasureF_UVI80 | M29: Calc_PCIE_ADC | N29: Print_Shmoo_Voltage | O29: Calc_GRPPercentageF
J30: DACTrim_DigSrc_Data | K30: ArrayCheck | L30: Trim_SetupandmeasureI_UVI80 | M30: Calc_LPDPRX_Bin2HeX | N30: Calc_memcheck | O30: P2PBundle_Unflipeye_NewCal
J31: CheckInputStringAt | K31: BinStr2Dec | L31: Trim_SetupandmeasureV_UVI80 | M31: TX_EQXXXXXXX | N31: LP5_LB_PI | O31: Check_Powerrails_check
D38: DSP_LIB_HardIP | E38: CombineDSPWave | F38: DSP_NAND_HARDIP | G38: DSP_LIB_DACTrim_AP
D39: Measure_DutyCycle | E39: SelectCertainBitsToDec | F39: MergeWave | G39: Trim_ConvertToLongAndSerialToParrel
D40: trim_calc | E40: AveWithStdev | F40: NANDIO_DigCap | G40: DSPWf_Merge
D41: trim_conveter | E41: SeprateDSP_TTR_Single | F41: NANDIO_CAL_UD_Wave | G41: RPIndeXSetting
D42: MeasureJitter_US10G | E42: SeprateDSP_TTR | F42: NANDIO_CAL_DOWN_Wave | G42: TrimSrcRP
D43: Measure_Eye_US10G | E43: MTR_ASGMTR_Freq_Calculation | F43: NANDIO_CAL_UP_Wave
D44: Measure_DutyCycle_Freq_US10G | E44: MTR_DSGMTR_Freq_Calculation | F44: NANDIO_CAL_UD
D45: LoopEyeMeas | E45: Split_Dspwave_PCIETXPLL_Central_bak | F45: NAND_PVTP
D46: duty_freq_meas | E46: Split_Dspwave_CIOCALC | F46: NAND_PVTN
D47: pulseMeas | E47: Split_Dspwave_AUS | F47: NAND_PVTR
D48: LoopJitterMeas | E48: Split_Dspwave_CIO | F48: RepeatWave
D49: DDR_LoopJitterMeas | E49: Split_Dspwave_CIOREFPLL | F49: MergeBit
...

Sheet DSP_LIB_HardIP
A1: DSP Function | B1: T-Pal(QG40_CP1) | C1: T-Pal(QG40_CZ) | D1: Leda | E1: Leda_CZ | F1: T-Cai(QW67_CP1) | G1: T-Cai(QW67_CZ) | H1: T-Lob(QG39_CP2) | I1: Dip_CZ(RF98) | J1: T-Dip(RF98_CP1) | K1: T-Col(QG367_CP1) | L1: T-Col(QG40_CZ) | M1: T-Ibi(QN98_CP1) | N1: Crete(NV38) | O1: Crete(CZ) | P1: Rhode(NM31) | Q1: Rhode(CZ) | R1: T-Staten | S1: T-Staten CZ | X1: %
A2: Measure_DutyCycle | B2: X | C2: X | D2: X | E2: X | F2: X | G2: X | H2: X | I2: X | J2: X | K2: X | L2: X | M2: X | N2: X | O2: X | P2: X | Q2: X | R2: X | S2: X | V2: total count | W2: 101
A3: trim_calc | B3: X | C3: X | D3: X | E3: X | F3: X | G3: X | H3: X | I3: X | J3: X | K3: X | L3: X | M3: X | N3: X | O3: X | P3: X | Q3: X | R3: X | S3: X | V3: un-use | W3: 45 | X3: =W3/W2*100 -> 44.554455
A4: trim_conveter | B4: X | C4: X | D4: X | E4: X | F4: X | G4: X | H4: X | I4: X | J4: X | K4: X | L4: X | M4: X | N4: X | O4: X | P4: X | Q4: X | R4: X | S4: X | V4: used | W4: =W2-W3 -> 56 | X4: =100-X3 -> 55.445545
A5: MeasureJitter_US10G | B5: X | C5: X | D5: X | E5: X | F5: X | G5: X | H5: X | I5: X | J5: X | K5: X | L5: X | M5: X | N5: X | O5: X | P5: X | Q5: X | R5: X | S5: X
A6: Measure_Eye_US10G | B6: X | C6: X | D6: X | E6: X | F6: X | G6: X | H6: X | I6: X | J6: X | K6: X | L6: X | M6: X | N6: X | O6: X | P6: X | Q6: X | R6: X | S6: X
A7: Measure_DutyCycle_Freq_US10G | B7: X | C7: X | D7: X | E7: X | F7: X | G7: X | H7: X | I7: X | J7: X | K7: X | L7: X | M7: X | N7: X | O7: X | P7: X | Q7: X | R7: X | S7: X
A8: LoopEyeMeas | B8: X | C8: X | D8: X | E8: X | F8: X | G8: X | H8: X | I8: X | J8: X | K8: X | L8: X | M8: X | N8: X | O8: X | P8: X | Q8: X | R8: X | S8: X
A9: duty_freq_meas | B9: X | C9: X | D9: X | E9: X | F9: X | G9: X | H9: X | I9: X | J9: X | K9: X | L9: X | M9: X | N9: X | O9: X | P9: X | Q9: X | R9: X | S9: X
A10: pulseMeas | B10: X | C10: X | D10: X | E10: X | F10: X | G10: X | H10: X | I10: X | J10: X | K10: X | L10: X | M10: X | N10: X | O10: X | P10: X | Q10: X | R10: X | S10: X
A11: LoopJitterMeas | B11: X | C11: X | D11: X | E11: X | F11: X | G11: X | H11: X | I11: X | J11: X | K11: X | L11: X | M11: X | N11: X | O11: X | P11: X | Q11: X | R11: X | S11: X
A12: DDR_LoopJitterMeas | B12: X | C12: X | D12: X | E12: X | F12: X | G12: X | H12: X | I12: X | J12: X | K12: X | L12: X | M12: X | N12: X | O12: X | P12: X | Q12: X | R12: X | S12: X
A13: Measure_Eye | B13: X | C13: X | D13: X | E13: X | F13: X | G13: X | H13: X | I13: X | J13: X | K13: X | L13: X | M13: X | N13: X | O13: X | P13: X | Q13: X | R13: X | S13: X
A14: Measure_Jitter | B14: X | C14: X | D14: X | E14: X | F14: X | G14: X | H14: X | I14: X | J14: X | K14: X | L14: X | M14: X | N14: X | O14: X | P14: X | Q14: X | R14: X | S14: X
A15: MeasureJitter_vb | B15: X | C15: X | D15: X | E15: X | F15: X | G15: X | H15: X | I15: X | J15: X | K15: X | L15: X | M15: X | N15: X | O15: X | P15: X | Q15: X | R15: X | S15: X
A16: analyzeEye_vb | B16: X | C16: X | D16: X | E16: X | F16: X | G16: X | H16: X | I16: X | J16: X | K16: X | L16: X | M16: X | N16: X | O16: X | P16: X | Q16: X | R16: X | S16: X
A17: Measuredutycycle | B17: X | C17: X | D17: X | E17: X | F17: X | G17: X | H17: X | I17: X | J17: X | K17: X | L17: X | M17: X | N17: X | O17: X | P17: X | Q17: X | R17: X | S17: X
A18: BitWf2Arry | B18: V | C18: X | D18: V | E18: V | F18: V | G18: V | H18: V | M18: V
A19: DdrSwpWf2Arry | B19: X | C19: X | D19: V | E19: X | F19: X | G19: X | H19: X | I19: X | J19: X | K19: X | L19: X | M19: X | N19: X | O19: X | P19: X | Q19: X | R19: X | S19: X
A20: FindMaXEyeWidth | B20: X | C20: X | D20: V | E20: X | F20: X | G20: X | H20: X | M20: X
A21: FleXibleBitWf2Arry | B21: X | C21: X | D21: X | E21: X | F21: X | G21: X | H21: X | I21: X | J21: X | K21: X | L21: X | M21: X | N21: X | O21: X | P21: X | Q21: X | R21: X | S21: X
A22: Split_Dspwave | B22: V | C22: V | D22: V | E22: V | F22: V | G22: V | H22: V | M22: V
A23: CreatSerDigSrc | B23: X | C23: X | D23: X | E23: X | F23: X | G23: X | H23: X | I23: X | J23: X | K23: X | L23: X | M23: X | N23: X | O23: X | P23: X | Q23: X | R23: X | S23: X
A24: CreateFleXibleDSPWave | B24: V | C24: V | D24: X | E24: X | F24: V | G24: X | H24: V | M24: V
A25: CreateFleXibleDSPWave_lpro | B25: V | C25: V | D25: X | E25: X | F25: X | G25: X | H25: X | M25: X
A26: SetupTrimCodeBit | B26: V | C26: X | D26: X | E26: X | F26: V | G26: V | H26: V | M26: V
A27: ConvertToLongAndSerialToParrel | B27: V | C27: V | D27: V | E27: V | F27: V | G27: V | H27: V | M27: V
A28: CombineDSPWave_and_ConvertToLongAndSerialToParrel | B28: V | C28: X | D28: V | E28: X | F28: X | G28: X | H28: X | M28: X
A29: FindMaXEyeWidth_reverse | B29: X | C29: X | D29: V | E29: V | F29: X | G29: X | H29: X | M29: X
A30: DSP_Add | B30: V | C30: V | D30: X | E30: X | F30: V | G30: V | H30: V | M30: V
A31: DSP_Subtract | B31: X | C31: X | D31: X | E31: X | F31: X | G31: X | H31: X | I31: X | J31: X | K31: X | L31: X | M31: X | N31: X | O31: X | P31: X | Q31: X | R31: X | S31: X
A32: DSP_Multiply | B32: X | C32: X | D32: X | E32: X | F32: X | G32: X | H32: X | I32: X | J32: X | K32: X | L32: X | M32: X | N32: X | O32: X | P32: X | Q32: X | R32: X | S32: X
A33: DSP_Divide | B33: X | C33: X | D33: X | E33: X | F33: X | G33: X | H33: X | I33: X | J33: X | K33: X | L33: X | M33: X | N33: X | O33: X | P33: X | Q33: X | R33: X | S33: X
A34: DSPWaveDecToBinary | B34: X | C34: X | D34: V | E34: V | F34: V | G34: V | H34: V | M34: V
A35: Transfer2GrayCode | B35: X | C35: X | D35: V | E35: V | F35: V | G35: V | H35: V | M35: V
A36: PreCheckMinMaXTrimCode | B36: V | C36: V | D36: X | E36: X | F36: V | G36: V | H36: V | M36: V
A37: DSP_DivideConstant | B37: V | C37: V | D37: X | E37: X | F37: V | G37: V | H37: V | M37: V
A38: CombineDSPWave | B38: X | C38: X | D38: X | E38: X | F38: X | G38: X | H38: X | I38: X | J38: X | K38: X | L38: X | M38: X | N38: X | O38: X | P38: X | Q38: X | R38: X | S38: X
A39: SelectCertainBitsToDec | B39: X | C39: X | D39: X | E39: X | F39: X | G39: X | H39: X | I39: X | J39: X | K39: X | L39: X | M39: X | N39: X | O39: X | P39: X | Q39: X | R39: X | S39: X
A40: ConcatenateDSP | B40: X | C40: X | D40: X | E40: X | F40: X | G40: X | H40: X | M40: X
...

Sheet DSP_NAND_HARDIP
A1: DSP Function | B1: T-Pal(QG40_CP1) | C1: T-Pal(QG40_CZ) | D1: Leda | E1: Leda_CZ | F1: T-Cai(QW67_CP1) | G1: T-Cai(QW67_CZ) | H1: T-Lob(QG39_CP2) | I1: Dip_CZ(RF98) | J1: T-Dip(RF98_CP1) | K1: T-Col(QG367_CP1) | L1: T-Col(QG40_CZ) | M1: T-Ibi(QN98_CP1) | N1: T-Ibi(QN98_CP1) | O1: Crete(NV38) | P1: Crete(CZ) | Q1: Rhode(NM31) | R1: Rhode(CZ) | S1: T-Staten | T1: T-Staten CZ
A2: MergeWave | B2: X | C2: X | D2: X | E2: X | F2: X | G2: X | H2: X | I2: X | J2: X | K2: X | L2: X | M2: X | N2: X | O2: X | P2: X | Q2: X | R2: X | S2: X | T2: X | X2: %
A3: NANDIO_DigCap | B3: X | C3: X | D3: X | E3: X | F3: X | G3: X | H3: X | I3: X | J3: X | K3: X | L3: X | M3: X | N3: X | O3: X | P3: X | Q3: X | R3: X | S3: X | T3: X | V3: total count | W3: 21
A4: NANDIO_CAL_UD_Wave | B4: X | C4: X | D4: X | E4: X | F4: X | G4: X | H4: X | I4: X | J4: X | K4: X | L4: X | M4: X | N4: X | O4: X | P4: X | Q4: X | R4: X | S4: X | T4: X | V4: un-use | W4: 21 | X4: =W4/W3*100 -> 100
A5: NANDIO_CAL_DOWN_Wave | B5: X | C5: X | D5: X | E5: X | F5: X | G5: X | H5: X | I5: X | J5: X | K5: X | L5: X | M5: X | N5: X | O5: X | P5: X | Q5: X | R5: X | S5: X | T5: X | V5: used | W5: =W3-W4 -> 0 | X5: =100-X4 -> 0
A6: NANDIO_CAL_UP_Wave | B6: X | C6: X | D6: X | E6: X | F6: X | G6: X | H6: X | I6: X | J6: X | K6: X | L6: X | M6: X | O6: X | P6: X | Q6: X | R6: X | S6: X | T6: X
A7: NANDIO_CAL_UD | B7: X | C7: X | D7: X | E7: X | F7: X | G7: X | H7: X | I7: X | J7: X | K7: X | L7: X | M7: X | O7: X | P7: X | Q7: X | R7: X | S7: X | T7: X
A8: NAND_PVTP | B8: X | C8: X | D8: X | E8: X | F8: X | G8: X | H8: X | I8: X | J8: X | K8: X | L8: X | M8: X | O8: X | P8: X | Q8: X | R8: X | S8: X | T8: X
A9: NAND_PVTN | B9: X | C9: X | D9: X | E9: X | F9: X | G9: X | H9: X | I9: X | J9: X | K9: X | L9: X | M9: X | O9: X | P9: X | Q9: X | R9: X | S9: X | T9: X
A10: NAND_PVTR | B10: X | C10: X | D10: X | E10: X | F10: X | G10: X | H10: X | I10: X | J10: X | K10: X | L10: X | M10: X | O10: X | P10: X | Q10: X | R10: X | S10: X | T10: X
A11: RepeatWave | B11: X | C11: X | D11: X | E11: X | F11: X | G11: X | H11: X | I11: X | J11: X | K11: X | L11: X | M11: X | O11: X | P11: X | Q11: X | R11: X | S11: X | T11: X
A12: MergeBit | B12: X | C12: X | D12: X | E12: X | F12: X | G12: X | H12: X | I12: X | J12: X | K12: X | L12: X | M12: X | O12: X | P12: X | Q12: X | R12: X | S12: X | T12: X
A13: CAL_WAVE_CREATE | B13: X | C13: X | D13: X | E13: X | F13: X | G13: X | H13: X | I13: X | J13: X | K13: X | L13: X | M13: X | O13: X | P13: X | Q13: X | R13: X | S13: X | T13: X
A14: CAL_WAVE_CREATE_1 | B14: X | C14: X | D14: X | E14: X | F14: X | G14: X | H14: X | I14: X | J14: X | K14: X | L14: X | M14: X | O14: X | P14: X | Q14: X | R14: X | S14: X | T14: X
A15: CAL_WAVE_CREATE_2 | B15: X | C15: X | D15: X | E15: X | F15: X | G15: X | H15: X | I15: X | J15: X | K15: X | L15: X | M15: X | O15: X | P15: X | Q15: X | R15: X | S15: X | T15: X
A16: CAL_WAVE_CREATE_3 | B16: X | C16: X | D16: X | E16: X | F16: X | G16: X | H16: X | I16: X | J16: X | K16: X | L16: X | M16: X | O16: X | P16: X | Q16: X | R16: X | S16: X | T16: X
A17: CAL_WAVE_CREATE_4 | B17: X | C17: X | D17: X | E17: X | F17: X | G17: X | H17: X | I17: X | J17: X | K17: X | L17: X | M17: X | O17: X | P17: X | Q17: X | R17: X | S17: X | T17: X
... A22: Calc_NAND_PHY_MDLL_DSP | B22: X | C22: X | D22: X | E22: X | F22: X | G22: X | H22: X | I22: X | J22: X | K22: X | L22: X | M22: X | O22: X | P22: X | Q22: X | R22: X | S22: X | T22: X

Sheet DSP_LIB_DACTrim_AP
A1: DSP Function | B1: T-Pal(QG40_CP1) | C1: T-Pal(QG40_CZ) | D1: Leda | E1: Leda_CZ | F1: T-Cai(QW67_CP1) | G1: T-Cai(QW67_CZ) | H1: T-Lob(QG39_CP2) | I1: Dip_CZ(RF98) | J1: T-Dip(RF98_CP1) | K1: T-Col(QG367_CP1) | L1: T-Col(QG40_CZ) | M1: Crete(NV38) | N1: Crete(CZ) | O1: Rhode(NM31) | P1: Rhode(CZ) | Q1: T-Staten | R1: T-Staten CZ
A2: Trim_ConvertToLongAndSerialToParrel | B2: X | C2: X | D2: X | E2: X | F2: X | G2: X | H2: X | I2: X | J2: X | K2: X | L2: X | M2: X | N2: X | O2: X | P2: X | Q2: X | R2: X | V2: %
A3: DSPWf_Merge | B3: X | C3: X | D3: X | E3: X | F3: X | G3: X | H3: X | I3: X | J3: X | K3: X | L3: X | M3: X | N3: X | O3: X | P3: X | Q3: X | R3: X | T3: total count | U3: 4
A4: RPIndeXSetting | B4: X | C4: X | D4: X | E4: X | F4: X | G4: X | H4: X | I4: X | J4: X | K4: X | L4: X | M4: X | N4: X | O4: X | P4: X | Q4: X | R4: X | T4: un-use | U4: 4 | V4: =U4/U3*100 -> 100
A5: TrimSrcRP | B5: X | C5: X | D5: X | E5: X | F5: X | G5: X | H5: X | I5: X | J5: X | K5: X | L5: X | M5: X | N5: X | O5: X | P5: X | Q5: X | R5: X | T5: used | U5: =U3-U4 -> 0 | V5: =100-V4 -> 0

Sheet VBT_LIB_DACTrim_AP
A1: DSP Function | B1: T-Ibi(QN98_CP1) | C1: T-Cai(QW67_CP1) | D1: T-Lob(QG39_CP2) | E1: T-Col(QG367_CP1) | F1: T-Pal(QG40_CP1) | G1: T-Pal(QG40_CZ) | H1: Leda | I1: Leda_cz | J1: T-Cai(QW67_CP1) | K1: T-Cai(QW67_CZ) | L1: Dip_CZ(RF98) | M1: T-Dip(RF98_CP1) | N1: T-Col(QG40_CZ) | O1: Rhode(NM31) | P1: Crete(NV38) | Q1: T-Staten | R1: T-Staten CZ
A2: DACTrimPrint | B2: X | C2: X | D2: X | E2: X | F2: X | G2: X | H2: X | I2: X | J2: X | K2: X | L2: X | M2: X | N2: X | O2: X | P2: X | Q2: X | R2: X | U2: %
A3: PrintAllTrimResult | B3: X | C3: X | D3: X | E3: X | F3: X | G3: X | H3: X | I3: X | J3: X | K3: X | L3: X | M3: X | N3: X | O3: X | P3: X | Q3: X | R3: X | S3: total count | T3: 2
S4: un-use | T4: 2 | U4: =T4/T3*100 -> 100
S5: used | T5: =T3-T4 -> 0 | U5: =100-U4 -> 0

Sheet VBT_LIB_HardIP
A1: DSP Function | B1: T-Ibi(QN98_CP1) | C1: T-Cai(QW67_CP1) | D1: T-Cai(QW67_CZ) | E1: T-Lob(QG39_CP2) | F1: T-Col(QG367_CP1) | G1: T-Pal(QG40_CP1) | H1: T-Pal(QG40_CZ) | I1: Leda | J1: Leda_cz | K1: Dip_CZ(RF98) | L1: T-Dip(RF98_CP1) | M1: T-Col(QG40_CZ) | N1: Rhode(NM31) | O1: Crete(NV38) | P1: Crete(CZ) | Q1: T-Staten | R1: T-Staten CZ
A2: Meas_Vdiff_func | B2: V | C2: X | D2: X | E2: V | F2: V | G2: V | H2: V | I2: V | J2: V | Q2: V | Y2: %
A3: Meas_VIR_IO_Universal_func | B3: X | C3: X | D3: X | E3: V | F3: X | G3: X | H3: X | I3: V | J3: V | Q3: X | W3: total count | X3: 31
A4: Meas_FreqVoltCurr_Universal_func | B4: V | C4: V | D4: V | E4: V | F4: V | G4: V | H4: V | I4: V | J4: V | Q4: V | W4: un-use | X4: 20 | Y4: =X4/X3*100 -> 64.516129
A5: Opt_DdrLpBkFunc2 | B5: X | C5: X | D5: X | E5: X | F5: X | G5: X | H5: X | I5: V | J5: V | Q5: X | W5: used | X5: =X3-X4 -> 11 | Y5: =100-Y4 -> 35.483871
A6: Opt_DdrLpBkFunc3 | B6: X | C6: X | D6: X | E6: X | F6: X | G6: X | H6: X | I6: X | J6: X | K6: X | L6: X | M6: X | N6: X | O6: X | P6: X | Q6: X | R6: X
A7: DigSrc_DigCap_Universal_func | B7: X | C7: X | D7: X | E7: X | F7: X | G7: X | H7: X | I7: X | J7: X | K7: X | L7: X | M7: X | N7: X | O7: X | P7: X | Q7: X | R7: X
A8: TMPS_Voltage_Print | B8: X | C8: X | D8: X | E8: X | F8: X | G8: X | H8: X | I8: X | J8: X | K8: X | L8: X | M8: X | N8: X | O8: X | P8: X | Q8: X | R8: X
A9: ReMeasImpedByAveTrimCode | B9: X | C9: X | D9: X | E9: X | F9: X | G9: X | H9: X | I9: X | J9: X | K9: X | L9: X | M9: X | N9: X | O9: X | P9: X | Q9: X | R9: X
A10: TMPS_Bin2Dec | B10: X | C10: X | D10: X | E10: X | F10: X | G10: X | H10: X | I10: X | J10: X | K10: X | L10: X | M10: X | N10: X | O10: X | P10: X | Q10: X | R10: X
A11: TMPS_Dec2Bin | B11: X | C11: X | D11: X | E11: X | F11: X | G11: X | H11: X | I11: X | J11: X | K11: X | L11: X | M11: X | N11: X | O11: X | P11: X | Q11: X | R11: X
A12: Eye_Diagram | B12: V | C12: V | D12: V | E12: V | F12: V | G12: V | H12: V | I12: V | J12: V | Q12: X | R12: X
A13: PPMU_Impedance_Function | B13: V | C13: V | D13: V | E13: V | F13: V | G13: V | H13: V | I13: V | J13: V | Q13: V
A14: TrimCodeDig | B14: V | C14: V | D14: V | E14: V | F14: V | G14: V | H14: V | I14: X | J14: X | Q14: X
A15: TrimCodeDig_Reverse_Ellis | B15: X | C15: X | D15: X | E15: X | F15: X | G15: X | H15: X | I15: X | J15: X | K15: X | L15: ? | Q15: X | R15: X
A16: TrimCodeDig_SeaHawk | B16: X | C16: X | D16: X | E16: X | F16: X | G16: X | H16: X | I16: X | J16: X | K16: X | L16: X | M16: X | N16: X | O16: X | P16: X | Q16: X | R16: X
A17: TrimCodeBasicDig | B17: X | C17: X | D17: X | E17: X | F17: X | G17: X | H17: X | I17: X | J17: X | K17: X | L17: X | M17: X | N17: X | O17: X | P17: X | Q17: X | R17: X
A18: PCIE_Eye_Diagram_0 | B18: X | C18: X | D18: X | E18: X | F18: X | G18: X | H18: X | I18: X | J18: X | K18: X | L18: X | M18: X | N18: X | O18: X | P18: X | Q18: X | R18: X
A19: PCIE_Eye_Diagram_1 | B19: X | C19: X | D19: X | E19: X | F19: X | G19: X | H19: X | I19: X | J19: X | K19: X | L19: X | M19: X | N19: X | O19: X | P19: X | Q19: X | R19: X
A20: PCIE_Eye_Diagram_2 | B20: X | C20: X | D20: X | E20: X | F20: X | G20: X | H20: X | I20: X | J20: X | K20: X | L20: X | M20: X | N20: X | O20: X | P20: X | Q20: X | R20: X
A21: PCIE_Eye_Diagram_3 | B21: X | C21: X | D21: X | E21: X | F21: X | G21: X | H21: X | I21: X | J21: X | K21: X | L21: X | M21: X | N21: X | O21: X | P21: X | Q21: X | R21: X
A22: PCIE_Eye_Diagram_4 | B22: X | C22: X | D22: X | E22: X | F22: X | G22: X | H22: X | I22: X | J22: X | K22: X | L22: X | M22: X | N22: X | O22: X | P22: X | Q22: X | R22: X
A23: PCIE_Eye_Diagram_5 | B23: X | C23: X | D23: X | E23: X | F23: X | G23: X | H23: X | I23: X | J23: X | K23: X | L23: X | M23: X | N23: X | O23: X | P23: X | Q23: X | R23: X
A24: LPDPRX_Eye_Diagram | B24: X | C24: X | D24: X | E24: X | F24: X | G24: X | H24: X | I24: X | J24: X | K24: X | L24: X | M24: X | N24: X | O24: X | P24: X | Q24: X | R24: X
A25: Enable_HIP_Datalog_Format | B25: V | C25: V | D25: V | E25: V | F25: V | G25: V | H25: V | I25: V | J25: V | Q25: V
A26: Enable_HIP_Datalog_Format_CZ | B26: X | C26: X | D26: X | E26: X | F26: X | G26: X | H26: X | I26: X | J26: X | K26: X | L26: X | M26: X | N26: X | O26: X | P26: X | Q26: X | R26: X
A27: Disable_HIP_Datalog_Format | B27: V | C27: V | D27: V | E27: V | F27: V | G27: V | H27: V | I27: V | J27: V | Q27: V
A28: Set_SEPVM_Ref_Level_Div | B28: X | C28: X | D28: X | E28: X | F28: X | G28: X | H28: X | I28: X | J28: X | K28: X | L28: X | M28: X | N28: X | O28: X | P28: X | Q28: X | R28: X
A29: SEPVM_Ref_measurement | B29: X | C29: X | D29: X | E29: X | F29: X | G29: X | H29: X | I29: X | J29: X | K29: X | L29: X | M29: X | N29: X | O29: X | P29: X | Q29: X | R29: X
A30: SEPVM_Ref2_Calibration | B30: X | C30: X | D30: X | E30: X | F30: X | G30: X | H30: X | I30: X | J30: X | K30: X | L30: X | M30: X | N30: X | O30: X | P30: X | Q30: X | R30: X
A31: ReSet_SEPVM_Ref_Level_Div | B31: X | C31: X | D31: X | E31: X | F31: X | G31: X | H31: X | I31: X | J31: X | K31: X | L31: X | M31: X | N31: X | O31: X | P31: X | Q31: X | R31: X
A32: LDO_Calibration | B32: V | C32: X | D32: X | E32: X | F32: V | G32: V | H32: V | I32: V | J32: X | Q32: V

Sheet VBT_LIB_HardIP_ADC_AP
A1: DSP Function | B1: T-Ibi(QN98_CP1) | C1: T-Cai(QW67_CP1) | D1: T-Cai(QW67_CZ) | E1: T-Lob(QG39_CP2) | F1: T-Col(QG367_CP1) | G1: T-Pal(QG40_CP1) | H1: T-Pal(QG40_CZ) | I1: Leda | J1: Leda_cz | K1: Dip_CZ(RF98) | L1: T-Dip(RF98_CP1) | M1: T-Col(QG40_CZ) | N1: Rhode(NM31) | O1: Crete(NV38) | P1: T-Staten | Q1: T-Staten CZ
A2: ADC_BandGap_Calibration | B2: V | C2: X | D2: X | E2: V | F2: V | G2: V | H2: V | I2: X | J2: X | P2: V | Q2: V | V2: %
A3: ADC_LDO_Calibration | B3: X | C3: X | D3: X | E3: X | F3: X | G3: X | H3: X | I3: X | J3: X | K3: X | L3: X | M3: X | N3: V | O3: V | P3: V | Q3: V | T3: total count | U3: 2
T4: un-use | U4: 0 | V4: =U4/U3*100 -> 0
T5: used | U5: =U3-U4 -> 2 | V5: =100-V4 -> 100

Sheet VBT_LIB_HardIP_AP
A1: DSP Function | B1: T-Ibi(QN98_CP1) | C1: T-Cai(QW67_CP1) | D1: T-Cai(QW67_CZ) | E1: T-Lob(QG39_CP2) | F1: T-Col(QG367_CP1) | G1: T-Pal(QG40_CP1) | H1: T-Pal(QG40_CZ) | I1: Leda | J1: Leda_cz | K1: Dip_CZ(RF98) | L1: T-Dip(RF98_CP1) | M1: T-Col(QG40_CZ) | N1: Rhode(NM31) | O1: Crete(NV38) | P1: Crete(CZ) | Q1: T-Staten | R1: T-Staten CZ
A2: HIP_eFuse_Read_TMPS_Coeff | B2: X | C2: X | D2: X | E2: X | F2: X | G2: X | H2: X | I2: X | J2: X | K2: X | L2: X | M2: X | N2: X | O2: X | P2: X | Q2: X | R2: X | W2: %
A3: TMPS | B3: X | C3: X | D3: X | E3: X | F3: X | G3: X | H3: X | I3: X | J3: X | K3: X | L3: X | M3: X | N3: X | O3: X | P3: X | Q3: X | R3: X | U3: total count | V3: 30
A4: HIP_eFuse_Write | B4: V | C4: V | D4: V | E4: V | F4: V | G4: V | H4: V | I4: V | J4: V | Q4: V | U4: un-use | V4: 21 | W4: =V4/V3*100 -> 70
A5: ADC_Trim | B5: X | C5: X | D5: X | E5: X | F5: X | G5: X | H5: X | I5: X | J5: X | N5: X | O5: X | P5: X | Q5: X | R5: X | U5: used | V5: =V3-V4 -> 9 | W5: =100-W4 -> 30
A6: MTR_Sense_Calibration_Coeff_Verification | B6: X | C6: X | D6: X | E6: X | F6: X | G6: X | H6: X | I6: X | J6: X | K6: X | L6: X | M6: X | N6: X | O6: X | P6: X | Q6: X | R6: X
A7: Metrology_CAL_eFuse_Write | B7: X | C7: X | D7: X | E7: X | F7: X | G7: X | H7: X | I7: X | J7: X | K7: X | L7: X | M7: X | N7: X | O7: X | P7: X | Q7: X | R7: X
A8: HIP_eFuse_Write_by_MTRGSNS | B8: X | C8: X | D8: X | E8: X | F8: X | G8: X | H8: X | I8: X | J8: X | K8: X | L8: X | M8: X | N8: X | O8: X | P8: X | Q8: X | R8: X
A9: Check_MTRGSNS_25C_Fuse | B9: X | C9: X | D9: X | E9: X | F9: X | G9: X | H9: X | I9: X | J9: X | K9: X | L9: X | M9: X | N9: X | O9: X | P9: X | Q9: X | R9: X
A10: MTR_REL_Fuse_Calc_Verification | B10: X | C10: X | D10: X | E10: X | F10: X | G10: X | H10: X | I10: X | J10: X | K10: X | L10: X | M10: X | N10: X | O10: X | P10: X | Q10: X | R10: X
A11: MTR_Sense_Alignment_Calc | B11: X | C11: X | D11: X | E11: X | F11: X | G11: X | H11: X | I11: X | J11: X | K11: X | L11: X | M11: X | N11: X | O11: X | P11: X | Q11: X | R11: X
A12: MTR_Sense_Calibration_Coeff_Calc | B12: X | C12: X | D12: X | E12: X | F12: X | G12: X | H12: X | I12: X | J12: X | K12: X | L12: X | M12: X | N12: X | O12: X | P12: X | Q12: X | R12: X
A13: MTRG_t5p2a_DigSrc_Coefficient_PreCalc | B13: X | C13: X | D13: X | E13: X | F13: X | G13: X | H13: X | I13: X | J13: X | K13: X | L13: X | M13: X | N13: X | O13: X | P13: X | Q13: X | R13: X
A14: MTRG_t6p3abc_DigSrc_Coefficient_PreCalc | B14: X | C14: X | D14: X | E14: X | F14: X | G14: X | H14: X | I14: X | J14: X | K14: X | L14: X | M14: X | N14: X | O14: X | P14: X | Q14: X | R14: X
A15: DSSC_Search | B15: X | C15: X | D15: X | E15: X | F15: X | G15: X | H15: X | I15: X | J15: X | K15: X | L15: X | M15: X | N15: X | O15: X | P15: X | Q15: X | R15: X
A16: DSSC_Search_LDO | B16: X | C16: X | D16: X | E16: X | F16: X | G16: X | H16: X | I16: X | J16: X | K16: X | L16: X | M16: X | N16: X | O16: X | P16: X | Q16: X | R16: X
A17: TrimUVI80Code_VFI_2sComplement | B17: X | C17: X | D17: X | E17: X | F17: X | G17: X | H17: X | I17: X | J17: X | K17: X | L17: X | M17: X | N17: X | O17: X | P17: X | Q17: X | R17: X
A18: TrimUVI80Code_VFI | B18: X | C18: X | D18: X | E18: X | F18: X | G18: X | H18: X | I18: X | J18: X | K18: X | L18: X | M18: X | N18: X | O18: X | P18: X | Q18: X | R18: X
A19: TrimUVI80Code_VFI_ADC | B19: X | C19: X | D19: X | E19: X | F19: X | G19: X | H19: X | I19: X | J19: X | K19: X | L19: X | M19: X | N19: X | O19: X | P19: X | Q19: V
A20: TrimCodeFreq_new | B20: X | C20: X | D20: X | E20: X | F20: X | G20: V | H20: V | I20: X | J20: X | Q20: X
A21: TrimCodeFreq_new_0828 | B21: X | C21: X | D21: X | E21: X | F21: X | G21: X | H21: X | I21: X | J21: X | K21: X | L21: X | M21: X | N21: X | O21: X | P21: X | Q21: X | R21: X
A22: TrimCodeFreq | B22: V | C22: V | D22: V | E22: X | F22: X | G22: X | H22: X | I22: X | J22: X | Q22: V
A23: TrimCodeFreq_DSSC | B23: V | C23: X | D23: X | E23: V | F23: V | G23: X | H23: X | I23: X | J23: X | L23: V | Q23: X
A24: TrimCodeImpedence | B24: X | C24: X | D24: X | E24: X | F24: X | G24: X | H24: X | I24: X | J24: X | K24: X | L24: X | M24: X | N24: X | O24: X | P24: X | Q24: X | R24: X
A25: HIP_eFuse_Read | B25: V | C25: V | D25: V | E25: V | F25: V | G25: V | H25: V | I25: V | J25: V | Q25: V
A26: MTR_Verification_Calculate | B26: X | C26: X | D26: X | E26: X | F26: X | G26: X | H26: X | I26: X | J26: X | K26: X | L26: X | M26: X | N26: X | O26: X | P26: X | Q26: X | R26: X
A27: TrimCodeFreq_New_ALG | B27: X | C27: X | D27: X | E27: X | F27: X | G27: V | H27: V | I27: X | J27: X | Q27: X
A28: TrimCodeFreq_RunPat_and_MeasF | B28: X | C28: X | D28: X | E28: X | F28: X | G28: V | H28: V | I28: X | J28: X | Q28: X
A29: TrimCodeFreq_WriteComment_DspTrimCode | B29: X | C29: X | D29: X | E29: X | F29: X | G29: V | H29: V | I29: X | J29: X | Q29: X
A30: HardIP_Trim_Set_PrePoint | B30: X | C30: X | D30: X | E30: X | F30: X | G30: X | H30: X | I30: X | J30: X | K30: X | L30: X | M30: X | N30: X | O30: X | P30: X | Q30: X | R30: X
A31: HardIP_Trim_Set_PostPoint | B31: X | C31: X | D31: X | E31: X | F31: X | G31: X | H31: X | I31: X | J31: X | K31: X | L31: X | M31: X | N31: X | O31: X | P31: X | Q31: X | R31: X

Sheet VBT_LIB_HardIP_Customize
A1: DSP Function | B1: T-Ibi(QN98_CP1) | C1: T-Cai(QW67_CP1) | D1: T-Cai(QW67_CZ) | E1: T-Lob(QG39_CP2) | F1: T-Col(QG367_CP1) | G1: T-Pal(QG40_CP1) | H1: T-Pal(QG40_CZ) | I1: Leda | J1: Leda_CZ | K1: Dip_CZ(RF98) | L1: T-Dip(RF98_CP1) | M1: T-Col(QG40_CZ) | N1: Rhode(NM31) | O1: Crete(NV31) | P1: Crete(CZ) | Q1: T-Staten | R1: T-Staten CZ
A2: AMP_EYE_VT_Setup | B2: X | C2: X | D2: X | E2: X | F2: X | G2: X | H2: X | I2: X | J2: X | K2: X | L2: X | M2: X | N2: X | O2: X | P2: X | Q2: X | R2: X | W2: %
A3: CUS_AMP_SDLL_SWP_Init | B3: X | C3: X | D3: X | E3: X | F3: X | G3: X | H3: X | I3: X | J3: X | K3: X | L3: X | M3: X | N3: X | O3: X | P3: X | Q3: X | R3: X | U3: total count | V3: 13
A4: CUS_VIR_MainProgram_MeasV_CalR | B4: V | C4: V | D4: V | E4: V | F4: V | G4: V | H4: X | I4: V | J4: V | Q4: X | U4: un-use | V4: 3 | W4: =V4/V3*100 -> 23.076923
A5: AnalyzeCusStrToCalcR | B5: V | C5: V | D5: V | E5: V | F5: V | G5: V | H5: X | I5: V | J5: V | Q5: X | U5: used | V5: =V3-V4 -> 10 | W5: =100-W4 -> 76.923077
A6: Cust_Sweep_V | B6: X | C6: X | D6: X | E6: V | F6: V | G6: X | H6: X | I6: V | J6: V | Q6: X
A7: VOLH_Sweep | B7: V | C7: V | D7: V | E7: V | F7: V | G7: V | H7: X | I7: V | J7: V | Q7: X
A8: MTR_UVI80_Setup | B8: V | C8: V | D8: V | E8: V | F8: V | G8: V | H8: X | I8: V | J8: V | Q8: X
A9: CUS_DDR_Emulate_Const_Res_Loading | B9: V | C9: V | D9: V | E9: V | F9: V | G9: V | H9: X | I9: V | J9: V | Q9: X
A10: CUS_DDR_DCS_PrintOut | B10: X | C10: X | D10: X | E10: X | F10: X | G10: X | H10: X | I10: V | J10: V | Q10: X
A11: MEAS_I_ABS | B11: V | C11: V | D11: V | E11: V | F11: V | G11: V | H11: X | I11: V | J11: V | Q11: X
A12: CUS_RREF_Rak_Calc | B12: V | C12: V | D12: V | E12: V | F12: V | G12: V | H12: X | I12: V | J12: V | Q12: X
A13: CUS_AMP_SDLL_SWP | B13: V | C13: V | D13: V | E13: V | F13: V | G13: V | H13: X | I13: V | J13: V | Q13: X
A14: ADCLK_MatriX_Loading | B14: X | C14: X | D14: X | E14: X | F14: X | G14: X | H14: X | I14: X | J14: X | K14: X | L14: X | M14: X | N14: X | O14: X | P14: X | Q14: X | R14: X

Sheet VBT_LIB_HardIP_JitterEye_AP
A1: DSP Function | B1: T-Ibi(QN98_CP1) | C1: T-Cai(QW67_CP1) | D1: T-Cai(QW67_CZ) | E1: T-Lob(QG39_CP2) | F1: T-Col(QG367_CP1) | G1: T-Pal(QG40_CP1) | H1: T-Pal(QG40_CZ) | I1: Leda | J1: Leda_CZ | K1: Dip_CZ(RF98) | L1: T-Dip(RF98_CP1) | M1: T-Col(QG40_CZ) | N1: Rhode(NM31) | O1: Crete(NV38) | P1: Crete(CZ) | Q1: T-Staten | R1: T-Staten CZ
A2: Time_Measure_kit_UP1600 | B2: X | C2: X | D2: X | E2: X | F2: X | G2: X | H2: X | I2: X | J2: X | K2: X | L2: X | M2: X | N2: X | O2: X | P2: X | Q2: X | R2: X | U2: %
A3: DDR_RO_Time_Measure_KIT_UP1600 | B3: X | C3: X | D3: X | E3: X | F3: X | G3: X | H3: X | I3: X | J3: X | K3: X | L3: X | M3: X | N3: X | O3: X | P3: X | Q3: X | R3: X | S3: total count | T3: 2
S4: un-use | T4: 2 | U4: =T4/T3*100 -> 100
S5: used | T5: =T3-T4 -> 0 | U5: =100-U4 -> 0

Sheet VBT_LIB_HardIP_Metrology_AP
A1: DSP Function | B1: T-Ibi(QN98_CP1) | C1: T-Cai(QW67_CP1) | D1: T-Cai(QW67_CZ) | E1: T-Lob(QG39_CP2) | F1: T-Col(QG367_CP1) | G1: T-Pal(QG40_CP1) | H1: T-Pal(QG40_CZ) | I1: Leda | J1: Leda_CZ | K1: Dip_CZ(RF98) | L1: T-Dip(RF98_CP1) | M1: T-Col(QG40_CZ) | N1: Rhode(NM31) | O1: Crete(NV38) | P1: Crete(CZ) | Q1: T-Staten | R1: T-Staten CZ
A2: MetrologyTMPS_Calibration | B2: X | C2: V | D2: V | E2: V | F2: X | G2: V | H2: V | I2: V | J2: V | Q2: V | X2: %
A3: MetrologySense_Calibration | B3: X | C3: X | D3: X | E3: X | F3: X | G3: X | H3: X | I3: X | J3: X | K3: X | L3: X | M3: X | N3: X | O3: X | P3: X | Q3: X | R3: X | V3: total count | W3: 5
A4: MTRTMPS_OffSet_AVG | B4: X | C4: X | D4: X | E4: X | F4: X | G4: X | H4: X | I4: X | J4: X | K4: X | L4: X | M4: X | N4: X | O4: X | P4: X | Q4: X | R4: X | V4: un-use | W4: 3 | X4: =W4/W3*100 -> 60
A5: MTRTMPS_Gain_Cal | B5: X | C5: X | D5: X | E5: X | F5: X | G5: X | H5: X | I5: X | J5: X | K5: X | L5: X | M5: X | N5: X | O5: X | P5: X | Q5: X | R5: X | V5: used | W5: =W3-W4 -> 2 | X5: =100-X4 -> 40
A6: MetrologyGR_Calibration | B6: X | C6: X | D6: X | E6: X | F6: X | G6: X | H6: X | I6: X | J6: X | K6: X | L6: X | M6: X | N6: V | O6: X | P6: X | Q6: V

Sheet VBT_LIB_HardIP_PCIE_PI_AP
A1: DSP Function | B1: T-Ibi(QN98_CP1) | C1: T-Cai(QW67_CP1) | D1: T-Cai(QW67_CZ) | E1: T-Lob(QG39_CP2) | F1: T-Col(QG367_CP1) | G1: T-Pal(QG40_CP1) | H1: T-Pal(QG40_CZ) | I1: Leda | J1: Leda_CZ | K1: Dip_CZ(RF98) | L1: T-Dip(RF98_CP1) | M1: T-Col(QG40_CZ) | N1: Rhode(NM31) | O1: Crete(NV38) | P1: Crete(CZ) | Q1: T-Staten | R1: T-Staten CZ
A2: PCIE_PI_TEST | B2: X | C2: X | D2: X | E2: X | F2: X | G2: X | H2: X | I2: X | J2: X | K2: X | L2: X | M2: X | N2: X | O2: X | P2: X | Q2: X | R2: X | X2: %
A3: PCIE_PI_Pat1 | B3: X | C3: X | D3: X | E3: X | F3: X | G3: X | H3: X | I3: X | J3: X | K3: X | L3: X | M3: X | N3: X | O3: X | P3: X | Q3: X | R3: X | V3: total count | W3: 8
A4: PCIE_PI_Pat2 | B4: X | C4: X | D4: X | E4: X | F4: X | G4: X | H4: X | I4: X | J4: X | K4: X | L4: X | M4: X | N4: X | O4: X | P4: X | Q4: X | R4: X | V4: un-use | W4: 8 | X4: =W4/W3*100 -> 100
A5: PCIE_PI_Pat3 | B5: X | C5: X | D5: X | E5: X | F5: X | G5: X | H5: X | I5: X | J5: X | K5: X | L5: X | M5: X | N5: X | O5: X | P5: X | Q5: X | R5: X | V5: used | W5: =W3-W4 -> 0 | X5: =100-X4 -> 0
A6: PCIE_PI_Pat4 | B6: X | C6: X | D6: X | E6: X | F6: X | G6: X | H6: X | I6: X | J6: X | K6: X | L6: X | M6: X | N6: X | O6: X | P6: X | Q6: X | R6: X
A7: PI_continuous_fai_count | B7: X | C7: X | D7: X | E7: X | F7: X | G7: X | H7: X | I7: X | J7: X | K7: X | L7: X | M7: X | N7: X | O7: X | P7: X | Q7: X | R7: X
A8: EyeCount | B8: X | C8: X | D8: X | E8: X | F8: X | G8: X | H8: X | I8: X | J8: X | K8: X | L8: X | M8: X | N8: X | O8: X | P8: X | Q8: X | R8: X
A9: EyeWidth | B9: X | C9: X | D9: X | E9: X | F9: X | G9: X | H9: X | I9: X | J9: X | K9: X | L9: X | M9: X | N9: X | O9: X | P9: X | Q9: X | R9: X

Sheet VBT_LIB_K_ADDRIO_AP
A1: DSP Function | B1: T-Ibi(QN98_CP1) | C1: T-Cai(QW67_CP1) | D1: T-Cai(QW67_CZ) | E1: T-Lob(QG39_CP2) | F1: T-Col(QG367_CP1) | G1: T-Pal(QG40_CP1) | H1: T-Pal(QG40_CZ) | I1: Leda | J1: Leda_CZ | K1: Dip_CZ(RF98) | L1: T-Dip(RF98_CP1) | M1: T-Col(QG40_CZ) | N1: Rhode(NM31) | O1: Crete(NV38) | P1: Crete(CZ) | Q1: T-Staten | R1: T-Staten CZ
A2: ReadEfuseDecimal_from_Dictionary | B2: X | C2: X | D2: X | E2: X | F2: X | G2: X | H2: X | I2: X | J2: X | K2: X | L2: X | M2: X | N2: X | O2: X | P2: X | Q2: X | R2: X | W2: %
A3: SaveEfuseDecimal_to_Dictionary | B3: V | C3: X | D3: X | E3: X | F3: X | G3: X | H3: X | I3: X | J3: X | K3: X | Q3: X | U3: total count | V3: 24
A4: SetWriteDecimalPassFlagToEFuse | B4: X | C4: X | D4: X | E4: X | F4: X | G4: X | H4: X | I4: X | J4: X | K4: X | L4: X | M4: X | N4: X | O4: X | P4: X | Q4: X | R4: X | U4: un-use | V4: 14 | W4: =V4/V3*100 -> 58.333333
A5: TrimImpedance_M9 | B5: X | C5: X | D5: X | E5: X | F5: X | G5: X | H5: X | I5: X | J5: X | K5: X | L5: X | M5: X | N5: X | O5: X | P5: X | Q5: X | R5: X | U5: used | V5: =V3-V4 -> 10 | W5: =100-W4 -> 41.666667
A6: TrimImpedance_MeasR | B6: V | C6: X | D6: X | E6: X | F6: X | G6: X | H6: X | I6: X | J6: X | K6: X | Q6: X
A7: UP1600_PPMU_Measure_R_SingleEnd | B7: V | C7: X | D7: X | E7: X | F7: X | G7: X | H7: X | I7: X | J7: X | K7: X | Q7: X
A8: UP1600_PPMU_Measure_R_Differential | B8: V | C8: X | D8: X | E8: X | F8: X | G8: X | H8: X | I8: X | J8: X | K8: X | Q8: X
A9: MeasurePins_to_Differential_Pair | B9: V | C9: X | D9: X | E9: X | F9: X | G9: X | H9: X | I9: X | J9: X | K9: X | Q9: X
A10: Show_Fuse_Check | B10: X | C10: X | D10: X | E10: X | F10: X | G10: X | H10: X | I10: X | J10: X | K10: X | L10: X | M10: X | N10: X | O10: X | P10: X | Q10: X | R10: X
A11: HIP_eFuse_Read_and_Set_SiteVar | B11: X | C11: X | D11: X | E11: X | F11: X | G11: X | H11: X | I11: X | J11: X | K11: X | L11: X | M11: X | N11: X | O11: X | P11: X | Q11: X | R11: X
A12: Show_Num_Of_Data_In_Fuse | B12: X | C12: X | D12: X | E12: X | F12: X | G12: X | H12: X | I12: X | J12: X | K12: X | L12: X | M12: X | N12: X | O12: X | P12: X | Q12: X | R12: X
A13: CombineTrimCodeInEFuseAndTrimII | B13: X | C13: X | D13: X | E13: X | F13: X | G13: X | H13: X | I13: X | J13: X | K13: X | L13: X | M13: X | N13: X | O13: X | P13: X | Q13: X | R13: X
A14: TrimImpedance_M9_Check_TrimCode | B14: X | C14: X | D14: X | E14: X | F14: X | G14: X | H14: X | I14: X | J14: X | K14: X | L14: X | M14: X | N14: X | O14: X | P14: X | Q14: X | R14: X
A15: RemoveAllEfuseDecimal_to_Dictionary | B15: X | C15: X | D15: X | E15: X | F15: X | G15: X | H15: X | I15: X | J15: X | K15: X | L15: X | M15: X | N15: X | O15: X | P15: X | Q15: X | R15: X
A16: K_TrimImpedance_Turks_TTR | B16: X | C16: X | D16: X | E16: X | F16: X | G16: X | H16: X | I16: X | J16: X | K16: X | Q16: X
A17: TrimImpedance_M9_Check_TrimCode_V1 | B17: X | C17: X | D17: X | E17: X | F17: X | G17: X | H17: X | I17: X | J17: X | K17: X | L17: X | M17: X | N17: X | O17: X | P17: X | Q17: X | R17: X
A18: K_TrimImpedance_Turks_V1 | B18: X | C18: X | D18: X | E18: X | F18: X | G18: X | H18: X | I18: X | J18: X | K18: X | Q18: X
A19: K_ADDRIO_FUSE_WRITE | B19: X | C19: X | D19: X | E19: X | F19: X | G19: X | H19: X | I19: X | J19: X | K19: X | L19: X | M19: X | N19: X | O19: X | P19: X | Q19: X | R19: X
A20: K_ADDRIO_FUSE_READ | B20: X | C20: X | D20: X | E20: X | F20: X | G20: X | H20: X | I20: X | J20: X | K20: X | L20: X | M20: X | N20: X | O20: X | P20: X | Q20: X | R20: X
A21: K_Show_Data_Count_In_Fuse | B21: X | C21: X | D21: X | E21: X | F21: X | G21: X | H21: X | I21: X | J21: X | K21: X | L21: X | M21: X | N21: X | O21: X | P21: X | Q21: X | R21: X
A22: K_Merge_TrimCode_From_Fuse_n_Trim | B22: X | C22: X | D22: X | E22: X | F22: X | G22: X | H22: X | I22: X | J22: X | K22: X | L22: X | M22: X | N22: X | O22: X | P22: X | Q22: X | R22: X
A23: K_TrimImpedance_CodeCheck_V1 | B23: X | C23: X | D23: X | E23: X | F23: X | G23: X | H23: X | I23: X | J23: X | K23: X | Q23: X
A24: K_Str_DumpDspWave | B24: X | C24: X | D24: X | E24: X | F24: X | G24: X | H24: X | I24: X | J24: X | K24: X | L24: X | Q24: X
A25: CZ_Style_TName_InstanceInfo_Clear | B25: V | C25: X | D25: X | E25: X | F25: X | G25: X | H25: X | I25: X | J25: X | K25: X | Q25: X

Sheet LIB_DACTrim_AP
A1: DSP Function | B1: T-Pal(QG40_CP1) | C1: T-Pal(QG40_CZ) | D1: Leda | E1: Leda_CZ | F1: T-Cai(QW67_CP1) | G1: T-Cai(QW67_CZ) | H1: T-Lob(QG39_CP2) | I1: Dip_CZ(RF98) | J1: T-Dip(RF98_CP1) | K1: T-Col(QG367_CP1) | L1: T-Col(QG40_CZ) | M1: T-Ibi(QN98_CP1) | N1: Rhode(NM31) | O1: Crete(NV38) | P1: Crete(CZ) | Q1: Rhode(NM31) | R1: Rhode(CZ) | S1: T-Staten | T1: T-Staten CZ
A2: BinDSP2Str | B2: X | C2: X | D2: X | E2: X | F2: X | G2: X | H2: X | I2: X | J2: X | K2: X | L2: X | M2: X | O2: X | P2: X | S2: X | T2: X | W2: %
A3: DACTrim_DigSrcSetting | B3: X | C3: X | D3: X | E3: X | F3: X | G3: X | H3: X | I3: X | J3: X | K3: X | L3: X | M3: X | O3: X | P3: X | Q3: X | R3: X | S3: X | T3: X | U3: total count | V3: 61
A4: DecomposePatternSet | B4: X | C4: X | D4: X | E4: X | F4: X | G4: X | H4: X | I4: X | J4: X | K4: X | L4: X | M4: X | O4: X | P4: X | Q4: X | R4: X | S4: X | T4: X | U4: un-use | V4: 59 | W4: =V4/V3*100 -> 96.721311
A5: DACTrim_WriteFuncResult | B5: X | C5: X | D5: X | E5: X | F5: X | G5: X | H5: X | I5: X | J5: X | K5: X | L5: X | M5: X | O5: X | P5: X | Q5: X | R5: X | S5: X | T5: X | U5: used | V5: =V3-V4 -> 2 | W5: =100-W4 -> 3.2786885
A6: StartFRC | B6: X | C6: X | D6: X | E6: X | F6: X | G6: X | H6: X | I6: X | J6: X | K6: X | L6: X | M6: X | O6: X | P6: X | Q6: X | R6: X | S6: X | T6: X
A7: StopFRC | B7: X | C7: X | D7: X | E7: X | F7: X | G7: X | H7: X | I7: X | J7: X | K7: X | L7: X | M7: X | O7: X | P7: X | Q7: X | R7: X | S7: X | T7: X
A8: Select_Measure_Pin | B8: X | C8: X | D8: X | E8: X | F8: X | G8: X | H8: X | I8: X | J8: X | K8: X | L8: X | M8: X | O8: X | P8: X | Q8: X | R8: X | S8: X | T8: X
A9: Select_MeasureI_CurrentRange | B9: X | C9: X | D9: X | E9: X | F9: X | G9: X | H9: X | I9: X | J9: X | K9: X | L9: X | M9: X | O9: X | P9: X | Q9: X | R9: X | S9: X | T9: X
A10: DACTrim_FrequencyMeasureSingleEnd | B10: X | C10: X | D10: X | E10: X | F10: X | G10: X | H10: X | I10: X | J10: X | K10: X | L10: X | M10: X | O10: X | P10: X | Q10: X | R10: X | S10: X | T10: X
A11: DiscriminateMeasV_PinType | B11: X | C11: X | D11: X | E11: X | F11: X | G11: X | H11: X | I11: X | J11: X | K11: X | L11: X | M11: X | O11: X | P11: X | Q11: X | R11: X | S11: X | T11: X
A12: GetInstrumentType | B12: X | C12: X | D12: X | E12: X | F12: X | G12: V | H12: X | M12: X
A13: DACTrim_SetupAndMeasureVolt_UVI80 | B13: X | C13: X | D13: X | E13: X | F13: X | G13: X | H13: X | I13: X | J13: X | K13: X | L13: X | M13: X | O13: X | P13: X | Q13: X | R13: X | S13: X | T13: X
A14: DACTrim_MergePinListData | B14: X | C14: X | D14: X | E14: X | F14: X | G14: X | H14: X | I14: X | J14: X | K14: X | L14: X | M14: X | O14: X | P14: X | Q14: X | R14: X | S14: X | T14: X
A15: DACTrim_MeasureCurrent | B15: X | C15: X | D15: X | E15: X | F15: X | G15: X | H15: X | I15: X | J15: X | K15: X | L15: X | M15: X | O15: X | P15: X | Q15: X | R15: X | S15: X | T15: X
A16: DACTrim_MeasureI_Combine2TestCondition | B16: X | C16: X | D16: X | E16: X | F16: X | G16: X | H16: X | I16: X | J16: X | K16: X | L16: X | M16: X | O16: X | P16: X | Q16: X | R16: X | S16: X | T16: X
A17: DiscriminateMeasI_TestCondition | B17: X | C17: X | D17: X | E17: X | F17: X | G17: X | H17: X | I17: X | J17: X | K17: X | L17: X | M17: X | O17: X | P17: X | Q17: X | R17: X | S17: X | T17: X
A18: DACTrim_NC_Pin | B18: X | C18: X | D18: X | E18: X | F18: X | G18: X | H18: X | I18: X | J18: X | K18: X | L18: X | M18: X | O18: X | P18: X | Q18: X | R18: X | S18: X | T18: X
A19: IsEmptyArray | B19: X | C19: X | D19: X | E19: X | F19: X | G19: X | H19: X | I19: X | J19: X | K19: X | L19: X | M19: X | O19: X | P19: X | Q19: X | R19: X | S19: X | T19: X
A20: TrimPinNameDuplicate | B20: X | C20: X | D20: X | E20: X | F20: X | G20: X | H20: X | I20: X | J20: X | K20: X | L20: X | M20: X | O20: X | P20: X | Q20: X | R20: X | S20: X | T20: X
A21: DACTrim_SetupAndMeasureCurrent_UVI80 | B21: X | C21: X | D21: X | E21: X | F21: X | G21: X | H21: X | I21: X | J21: X | K21: X | L21: X | M21: X | O21: X | P21: X | Q21: X | R21: X | S21: X | T21: X
A22: DACTrim_SetupAndMeasureCurrent_HeXVS | B22: X | C22: X | D22: X | E22: X | F22: X | G22: X | H22: X | I22: X | J22: X | K22: X | L22: X | M22: X | O22: X | P22: X | Q22: X | R22: X | S22: X | T22: X
A23: DACTrim_HeXVS__MI_StoreCondition | B23: X | C23: X | D23: X | E23: X | F23: X | G23: X | H23: X | I23: X | J23: X | K23: X | L23: X | M23: X | O23: X | P23: X | Q23: X | R23: X | S23: X | T23: X
A24: DACTrim_HeXVS__MI_RestoreCondition | B24: X | C24: X | D24: X | E24: X | F24: X | G24: X | H24: X | I24: X | J24: X | K24: X | L24: X | M24: X | O24: X | P24: X | Q24: X | R24: X | S24: X | T24: X
... A31: CheckInputStringAt | B31: X | C31: X | D31: X | E31: X | F31: X | G31: X | H31: X | I31: X | J31: X | K31: X | L31: X | M31: X | O31: X | P31: X | Q31: X | R31: X | S31: X | T31: X
A32: BinStr2Dec | B32: X | C32: X | D32: X | E32: X | F32: X | G32: X | H32: X | I32: X | L32: X | M32: X | O32: X | R32: X | S32: X | T32: X
A33: Dec2BinStr | B33: X | C33: X | D33: X | E33: X | F33: X | G33: X | H33: X | I33: X | L33: X | M33: X | O33: V | S33: X | T33: X
A34: SiteEXpand | B34: X | C34: X | D34: X | E34: X | F34: X | G34: X | H34: X | I34: X | J34: X | K34: X | L34: X | M34: X | O34: X | P34: X | Q34: X | R34: X | S34: X | T34: X
A35: SiteEXpandDSPWf | B35: X | C35: X | D35: X | E35: X | F35: X | G35: X | H35: X | I35: X | J35: X | K35: X | L35: X | M35: X | O35: X | P35: X | Q35: X | R35: X | S35: X | T35: X
A36: CalcTarget_V2 | B36: X | C36: X | D36: X | E36: X | F36: X | G36: X | H36: X | I36: X | J36: X | K36: X | L36: X | M36: X | O36: X | P36: X | Q36: X | R36: X | S36: X | T36: X
A37: Do_All | B37: X | C37: X | D37: X | E37: X | F37: X | G37: X | H37: X | I37: X | J37: X | K37: X | L37: X | M37: X | O37: X | P37: X | Q37: X | R37: X | S37: X | T37: X
A38: TransitionSearch | B38: X | C38: X | D38: X | E38: X | F38: X | G38: X | H38: X | I38: X | J38: X | K38: X | L38: X | M38: X | O38: X | P38: X | Q38: X | R38: X | S38: X | T38: X
A39: BinarySearch | B39: X | C39: X | D39: X | E39: X | F39: X | G39: X | H39: X | I39: X | J39: X | K39: X | L39: X | M39: X | O39: X | P39: X | Q39: X | R39: X | S39: X | T39: X
A40: Boundary | B40: X | C40: X | D40: X | E40: X | F40: X | G40: X | H40: X | I40: X | J40: X | K40: X | L40: X | M40: X | O40: X | P40: X | Q40: X | R40: X | S40: X | T40: X
A41: LinearSearch | B41: X | C41: X | D41: X | E41: X | F41: X | G41: X | H41: X | I41: X | J41: X | K41: X | L41: X | M41: X | O41: X | P41: X | Q41: X | R41: X | S41: X | T41: X
A42: Interpolate | B42: X | C42: X | D42: X | E42: X | F42: X | G42: X | H42: X | I42: X | J42: X | K42: X | L42: X | M42: X | O42: X | P42: X | Q42: X | R42: X | S42: X | T42: X
A43: GetTrimName | B43: X | C43: X | D43: X | E43: X | F43: X | G43: X | H43: X | I43: X | J43: X | K43: X | L43: X | M43: X | O43: X | P43: X | Q43: X | R43: X | S43: X | T43: X
A44: GetTrimCode | B44: X | C44: X | D44: X | E44: X | F44: X | G44: X | H44: X | I44: X | K44: X | L44: X | M44: X | O44: X | P44: X | Q44: X | R44: X | S44: X | T44: X
A45: GetTrimVal | B45: X | C45: X | D45: X | E45: X | F45: X | G45: X | H45: X | I45: X | K45: X | L45: X | M45: X | O45: X | P45: X | Q45: X | R45: X | S45: X | T45: X
A46: TrimLimit_V2 | B46: X | C46: X | D46: X | E46: X | F46: X | G46: X | H46: X | I46: X | J46: X | K46: X | L46: X | M46: X | O46: X | P46: X | Q46: X | R46: X | S46: X | T46: X
...

Sheet LIB_HardIP
A1: DSP Function | B1: T-Pal(QG40_CP1) | C1: T-Pal(QG40_CZ) | D1: Leda | E1: Leda_CZ | F1: T-Cai(QW67_CP1) | G1: T-Cai(QW67_CZ) | H1: T-Lob(QG39_CP2) | I1: Dip_CZ(RF98) | J1: T-Dip(RF98_CP1) | K1: T-Col(QG367_CP1) | L1: T-Col(QG40_CZ) | M1: Rhode(NM31) | N1: Crete(NV38) | O1: Crete(CZ) | P1: Rhode(NM31) | Q1: Rhode(CZ) | R1: T-Staten | S1: T-Staten CZ
A2: Description_on_RINGS | B2: V | C2: V | D2: V | E2: V | F2: V | G2: V | H2: V | R2: X | V2: %
A3: HardIP_waittime_trimming | B3: V | C3: V | D3: V | E3: V | F3: V | G3: V | H3: V | R3: X | T3: total count | U3: 230
A4: IO_Power_Split | B4: X | C4: X | D4: X | E4: X | F4: X | G4: X | H4: X | I4: X | J4: X | K4: X | L4: X | N4: X | O4: X | P4: X | Q4: X | R4: X | S4: X | T4: un-use | U4: 33 | V4: =U4/U3*100 -> 14.347826
A5: PATT_EXculdePath | B5: X | C5: X | D5: X | E5: X | F5: X | G5: X | H5: X | I5: X | J5: X | K5: X | L5: X | N5: X | O5: X | P5: X | Q5: X | R5: X | S5: X | T5: used | U5: =U3-U4 -> 197 | V5: =100-V4 -> 85.652174
A6: PATT_GetPatListFromPatternSet | B6: ? | C6: v | D6: V | E6: V | F6: V | G6: V | H6: V
A7: Decide_Measure_Pin | B7: X | C7: X | D7: X | E7: X | F7: X | G7: X | H7: X | I7: X | J7: X | K7: X | L7: X | N7: X | O7: X | P7: X | Q7: X | R7: X | S7: X
A8: Decide_MeasureI_CurrentRange | B8: X | C8: X | D8: X | E8: X | F8: X | G8: X | H8: X | I8: X | J8: X | K8: X | L8: X | N8: X | O8: X | P8: X | Q8: X | R8: X | S8: X
A9: HardIP_WriteFuncResult | B9: ? | C9: v | D9: ? | E9: V | F9: X | G9: ? | H9: V
A10: GetFlowSingleUseLimit | B10: ? | C10: V | D10: X | E10: V | F10: V | G10: V | H10: V
A11: Find_Assignement | B11: V | C11: X | D11: V | E11: V | F11: V | G11: V | H11: V
A12: HardIP_MeasureVolt | B12: V | C12: v | D12: V | E12: V | F12: V | G12: V | H12: V
A13: DSSCSrcBitFromFlowForLoop | B13: V | C13: v | D13: V | E13: V | F13: V | G13: V | H13: V
A14: EndSetupForMeasureVoltPins | B14: V | C14: V | D14: V | E14: V | F14: V | G14: V | H14: V
A15: PinNameDuplicateCheck | B15: X | C15: X | D15: X | E15: X | F15: X | G15: X | H15: X | I15: X | J15: X | K15: X | L15: X | N15: X | O15: X | P15: X | Q15: X | R15: X | S15: X
A16: Printout_DigSrc | B16: V | C16: V | D16: X | E16: V | F16: V | G16: X | H16: V
A17: Printout_DigSrc_Newformat | B17: V | C17: V | D17: V | E17: V | F17: V | G17: V | H17: V
A18: Create_DigSrc_Data | B18: V | C18: V | D18: X | E18: V | F18: V | G18: V | H18: V
A19: SetupDigSrcDspWave | B19: V | C19: V | D19: X | E19: V | F19: V | G19: V | H19: V
A20: DigCapSetup | B20: V | C20: V | D20: X | E20: V | F20: V | G20: V | H20: V
A21: MergePinListData | B21: V | C21: V | D21: X | E21: V | F21: V | G21: V | H21: V
A22: Freq_PPMU_Meas_VOH | B22: V | C22: V | D22: X | E22: V | F22: V | G22: V | H22: V
A23: IO_HardIP_PPMU_Measure_V | B23: ? | C23: X | D23: ? | E23: V | F23: ? | G23: ? | H23: ?
A24: IO_HardIP_PPMU_Measure_I | B24: X | C24: X | D24: V | E24: V | F24: ? | G24: X | H24: V
A25: IO_HardIP_PPMU_Measure_R | B25: ? | C25: X | D25: V | E25: V | F25: ? | G25: ? | H25: V
A26: HardIP_SetupAndMeasureR | B26: V | C26: X | D26: V | E26: V | F26: V | G26: V | H26: V
A27: Meas_VIR_IO_PreSetupBeforeMeasurement | B27: ? | C27: X | D27: V | E27: V | F27: ? | G27: ? | H27: ?
... A29: HardIP_MeasureCurrent | B29: V | C29: V | D29: V | E29: V | F29: V | G29: V | H29: V
A30: PPMU_Reset | B30: X | C30: X | D30: X | E30: X | F30: X | G30: X | H30: X | I30: X | J30: X | K30: X | L30: X | N30: X | O30: X | P30: X | Q30: X | R30: V
A31: UVI80_Reset | B31: ? | C31: ? | D31: ? | E31: ? | F31: ? | G31: ? | H31: ?
A32: HardIP_SetupAndMeasureVolt_UVI80_old | B32: X | C32: X | D32: V | E32: X | F32: V | G32: X | H32: X
A33: HardIP_SetupAndMeasureVolt_UVI80 | B33: V | C33: V | D33: V | E33: V | F33: V | G33: V | H33: V
A34: HardIP_Characterization_ShmooEndFunction | B34: X | C34: X | D34: X | E34: X | F34: X | G34: X | H34: X | I34: X | J34: X | K34: X | L34: X | N34: X | O34: X | P34: X | Q34: X | R34: X | S34: X
A35: HardIP_SetupAndMeasureVolt_UVI80_Diff | B35: V | C35: V | D35: V | E35: V | F35: V | G35: V | H35: V
A36: HardIP_SetupAndMeasureVolt_PPMU | B36: V | C36: V | D36: V | E36: V | F36: V | G36: V | H36: V
A37: HardIP_SetupAndMeasureCurrent_UVI80 | B37: V | C37: V | D37: V | E37: V | F37: V | G37: V | H37: V
A38: HardIP_SetupAndMeasureCurrent_HeXVS | B38: V | C38: V | D38: V | E38: V | F38: V | G38: V | H38: V
A39: HardIP_SetupAndMeasureCurrent_VSM | B39: V | C39: V | D39: V | E39: V | F39: V | G39: V | H39: V
A40: HardIP_SetupAndMeasureCurrent_UVS256 | B40: V | C40: V | D40: V | E40: V | F40: V | G40: V | H40: V
A41: HardIP_UVS256_autorange | B41: X | C41: X | D41: V | E41: V | F41: X | G41: X | H41: X
...

Sheet LIB_HardIP_ADC_AP
A1: DSP Function | B1: T-Pal(QG40_CP1) | C1: T-Pal(QG40_CZ) | D1: Leda | E1: Leda_CZ | F1: T-Cai(QW67_CP1) | G1: T-Cai(QW67_CZ) | H1: T-Lob(QG39_CP2) | I1: Dip_CZ(RF98) | J1: T-Dip(RF98_CP1) | K1: T-Col(QG367_CP1) | L1: T-Col(QG40_CZ) | M1: Rhode(NM31)
A2: ADC_BandGap_DigCapDataProcessByDSP | B2: V | C2: V | D2: X | E2: X | F2: X | G2: X | H2: V | R2: %
A3: Calc_ADC_Dict_Store | B3: X | C3: X | D3: X | E3: X | F3: X | G3: X | H3: X | I3: X | J3: X | K3: V | L3: V | P3: total count | Q3: 3
A4: Calc_ADC_REF_Dict_Store | B4: X | C4: X | D4: X | E4: X | F4: X | G4: X | H4: X | I4: X | J4: X | K4: V | L4: V | P4: un-use | Q4: 0 | R4: =Q4/Q3*100 -> 0
P5: used | Q5: =Q3-Q4 -> 3 | R5: =100-R4 -> 100

Sheet LIB_HardIP_AP
A1: DSP Function | B1: T-Pal(QG40_CP1) | C1: T-Pal(QG40_CZ) | D1: Leda | E1: Leda_CZ | F1: T-Cai(QW67_CP1) | G1: T-Cai(QW67_CZ) | H1: T-Lob(QG39_CP2) | I1: T-Dip(RF98_CP1) | J1: T-Col(QG367_CP1) | K1: T-Col(QG40_CZ) | L1: Rhode(NM31)
A2: HeX2Base64 | B2: V | C2: X | D2: X | E2: X | F2: X | G2: X | H2: X | Q2: %
A3: Server_Connection | B3: V | C3: X | D3: X | E3: X | F3: X | G3: X | H3: X | O3: total count | P3: 6
A4: binToDecStr | B4: V | C4: X | D4: X | E4: X | F4: X | G4: X | H4: X | O4: un-use | P4: 0 | Q4: =P4/P3*100 -> 0
A5: HardIP_Decide_Switching_Bit | B5: X | C5: X | D5: X | E5: X | F5: X | G5: X | H5: V | O5: used | P5: =P3-P4 -> 6 | Q5: =100-Q4 -> 100
A6: HardIP_Decide_DSSC_Switching_Voltage | B6: X | C6: X | D6: X | E6: X | F6: X | G6: X | H6: V
A7: Printout_BCCallHIP_DigSrc | B7: V | C7: V | D7: X | E7: X | F7: X | G7: X | H7: V

Sheet LIB_HardIP_Calc
A1: DSP Function | B1: T-Pal(QG40_CP1) | C1: T-Pal(QG40_CZ) | D1: Leda | E1: Leda_CZ | F1: T-Cai(QW67_CP1) | G1: T-Cai(QW67_CZ) | H1: T-Lob(QG39_CP2) | I1: Dip_CZ(RF98) | J1: T-Dip(RF98_CP1) | K1: T-Col(QG367_CP1) | L1: T-Col(QG40_CZ) | M1: Rhode(NM31) | N1: Crete(NV38) | O1: Crete(CZ) | P1: T-Staten | Q1: Rhode(CZ) | R1: T-Staten | S1: T-Staten CZ
A2: Calc_ADC_LDO_TRIM_TTR | B2: X | C2: X | D2: X | E2: X | F2: X | G2: X | H2: X | I2: X | J2: X | K2: X | L2: X | M2: X | N2: X | O2: X | P2: X | R2: X | V2: %
A3: Calc_delay | B3: X | C3: X | D3: X | E3: X | F3: X | G3: X | H3: X | I3: X | J3: X | K3: X | L3: X | M3: X | N3: X | O3: X | P3: X | R3: X | S3: X | T3: total count | U3: 126
A4: Calc_delay_Sicily | B4: X | C4: X | D4: X | E4: V | F4: X | G4: X | H4: X | P4: X | R4: X | T4: un-use | U4: 85 | V4: =U4/U3*100 -> 67.460317
A5: Calc_SetFlag | B5: X | C5: X | D5: X | E5: X | F5: X | G5: X | H5: X | I5: X | J5: X | K5: X | L5: X | M5: X | N5: X | O5: X | P5: X | R5: X | S5: X | T5: used | U5: =U3-U4 -> 41 | V5: =100-V4 -> 32.539683
A6: Calc_GrayCode | B6: X | C6: X | D6: X | E6: X | F6: X | G6: X | H6: X | I6: X | J6: X | K6: X | L6: X | M6: X | N6: X | O6: X | P6: X | R6: X | S6: X
A7: CMRR | B7: X | C7: X | D7: X | E7: X | F7: X | G7: X | H7: X | I7: X | J7: X | K7: X | L7: X | M7: X | N7: X | O7: X | P7: X | R7: X | S7: X
A8: PSRR | B8: X | C8: X | D8: X | E8: X | F8: X | G8: X | H8: X | I8: X | J8: X | K8: X | L8: X | M8: X | N8: X | O8: X | P8: X | R8: X | S8: X
A9: Calc_RXEye | B9: X | C9: X | D9: X | E9: X | F9: X | G9: X | H9: X | I9: X | J9: X | K9: X | L9: X | M9: X | N9: X | O9: X | P9: X | R9: X | S9: X
A10: Calc_R_Path_Cal | B10: X | C10: X | D10: X | E10: V | F10: V | G10: V | H10: X | P10: X | R10: X
A11: Calc_ConcatenateDSP | B11: V | C11: V | D11: V | E11: V | F11: V | G11: V | H11: V | P11: V | R11: V
A12: Calc_AverageDSP | B12: X | C12: X | D12: X | E12: X | F12: X | G12: X | H12: X | I12: X | J12: X | K12: X | L12: X | M12: X | N12: X | O12: X | P12: X | R12: X | S12: X
A13: Calc_BitwiseDSP | B13: X | C13: X | D13: X | E13: V | F13: X | G13: X | H13: X | P13: X | R13: X
A14: Calc_Dict_Store | B14: X | C14: X | D14: X | E14: X | F14: X | G14: X | H14: X | I14: X | J14: X | K14: X | L14: X | M14: X | N14: X | O14: X | P14: X | R14: X | S14: X
A15: Calc_2S_Complement_DSP | B15: V | C15: V | D15: V | E15: V | F15: V | G15: V | H15: V | P15: V | R15: V
A16: MSBNEGATE | B16: V | C16: V | D16: X | E16: X | F16: X | G16: X | H16: V | P16: X | R16: X
A17: Calc_TMPS_Coeff | B17: X | C17: X | D17: X | E17: X | F17: X | G17: X | H17: X | I17: X | J17: X | K17: X | L17: X | M17: X | N17: X | O17: X | P17: X | R17: X | S17: X
A18: Calc_TMPS_Coeff_1point | B18: X | C18: X | D18: X | E18: X | F18: X | G18: X | H18: X | I18: X | J18: X | K18: X | L18: X | M18: X | N18: X | O18: X | P18: X | R18: X | S18: X
A19: ADDRIO_TrimCodeAverage | B19: X | C19: X | D19: X | E19: X | F19: X | G19: X | H19: X | I19: X | J19: X | K19: X | L19: X | M19: X | N19: X | O19: X | P19: X | R19: X | S19: X
A20: Calc_MDLL_Monotonicity | B20: X | C20: X | D20: X | E20: X | F20: X | G20: X | H20: X | I20: X | J20: X | K20: X | L20: X | M20: X | N20: X | O20: X | P20: X | R20: X | S20: X
A21: Calc_DDR_MDCC_Freq | B21: X | C21: X | D21: V | E21: V | F21: X | G21: X | H21: X | P21: X | R21: X
A22: Calc_MDLL_Monotonicity_DevideBlock_SEG | B22: X | C22: X | D22: X | E22: X | F22: X | G22: X | H22: X | I22: X | J22: X | K22: X | L22: X | M22: X | N22: X | O22: X | P22: V | R22: V
A23: Calc_MDLL_Monotonicity_Analyze | B23: X | C23: X | D23: X | E23: X | F23: X | G23: X | H23: X | I23: X | J23: X | K23: X | L23: X | M23: X | N23: X | O23: X | P23: X | R23: X | S23: X
A24: Calc_LPDPTX_FXCode | B24: X | C24: X | D24: X | E24: X | F24: X | G24: X | H24: X | I24: X | J24: X | K24: X | L24: X | M24: X | N24: X | O24: X | P24: X | R24: X | S24: X
A25: Calc_ADCPLL_fuse | B25: X | C25: X | D25: X | E25: X | F25: X | G25: X | H25: X | I25: X | J25: X | K25: X | L25: X | M25: X | N25: X | O25: X | P25: X | R25: X | S25: X
A26: Calc_GrayCodeToBin | B26: X | C26: X | D26: X | E26: X | F26: X | G26: X | H26: X | I26: X | J26: X | K26: X | L26: X | M26: X | N26: X | O26: X | P26: X | R26: X | S26: X
A27: CalcDutyDelay | B27: X | C27: X | D27: X | E27: X | F27: X | G27: X | H27: X | I27: X | J27: X | K27: X | L27: X | M27: X | N27: X | O27: X | P27: X | R27: X | S27: X
A28: CalcDelayDelta_Sicily | B28: X | C28: X | D28: X | E28: V | F28: X | G28: X | H28: X | P28: X | R28: X
A29: CalcDutyDelay_Delta | B29: X | C29: X | D29: X | E29: X | F29: X | G29: X | H29: X | I29: X | J29: X | K29: X | L29: X | M29: X | N29: X | O29: X | P29: X | R29: X | S29: X
