Workbook

Sheet Revision
A1: Revision | B1: Date | C1: By | D1: Notes Tab | E1: Binning Tab | F1: ATE Test Conditions Tab
A2: 0.01 | B2: 45720 | C2: Ben Blackman | D2: initial structural binning doc. Base Voltage is 125mV
A3: 0.02 | B3: 45733 | C3: Ben Blackman | F3: Updated mode mapping
A4: 0.03 | B4: 45742 | C4: Ben Blackman | D4: IDDQ updated | E4: CPIDSmax, IDSMax_HOT updated. C, BinningVmax, BinningGB updated
A5: 0.04 | B5: 45746 | C5: Ben Blackman | E5: C, BinningVmax updated
A6: 0.05 | B6: 45748 | C6: Ben Blackman | E6: C, BinningVmax updated. Monotonicity Offset updated | F6: HBV condition updated
A7: 0.06 | B7: 45757 | C7: Ben Blackman | E7: FT_GB_HOT, CP_GB_HOT updated. SLTGB updated.
A8: 0.1 | B8: 45771 | C8: Ben Blackman | D8: fuse_revision updated | E8: C, BinningVmax, BinningVmin updated. CP_GB_HOT updated
A9: 0.11 | B9: 45779 | C9: Fred Chan | E9: CP2 IDS relaxed to 1.75x
A10: 0.12 | B10: 45785 | C10: Ben Blackman | E10: IDSMax_HOT updated
A11: 0.2 | B11: 45811 | C11: Ben Blackman | D11: fuse_revision updated | E11: C, BinningVmax, BinningGB updated. CPIDSmax updated.
A12: 0.3 | B12: 45813 | C12: Ben Blackman | E12: C, BinningVmax, BinningGB updated.
A13: 0.31 | B13: 45818 | C13: Fred Chan | E13: C adjustment for MES004+ (+100)
A14: 0.311 | B14: 45841 | C14: Ben Blackman | F14: Added static selsram
A15: 0.4 | B15: 45855 | C15: Ben Blackman | D15: fuse_revision updated | E15: C, BinningVmax, BinningVmin, BinningGB updated. CP_GB_HOT updated.
A16: 0.5 | B16: 45862 | C16: Ben Blackman | E16: BinningGB updated.
A17: 0.6 | B17: 45867 | C17: Ben Blackman | E17: C, BinningVmax, BinningGB updated.
A18: 0.61 | B18: 45877 | C18: Ben Blackman | E18: BinningGB updated for SRAM to reflect PV in system
A19: 0.62 | B19: 45883 | C19: Ben Blackman | E19: FT_GB_ROOM, SLTGB updated. | F19: HBV condition updated
A20: 0.63 | B20: 45889 | C20: Ben Blackman | E20: FT_GB_HOT updated

Sheet Notes
A1: Formulae: | F1: Comment
A2: SearchVoltage | B2: MIN(MAX(Step * Floor( [C - M * Log10(IDS)] / Step), BinningVmin), BinningVmax) | F2: Rounded down to a multiple of Step=5mV, must be less than or equal to CPVmax and greater than or equal to CPVmin
A3: Product | B3: SearchVoltage + BinningGB | F3: GB will be rounded up to 5mV
A4: CP_HOT | B4: Product - CP_GB_HOT | F4: Hot Temp
A5: FT_ROOM | B5: Product - FT_GB_ROOM | F5: Room Temp
A6: FT_HOT | B6: Product - FT_GB_HOT | F6: Hot Temp
A7: IDSMax_HOT | B7: CPIDSmax * (Hot / Room) Ratio | F7: Hot Temp IDS. Spec is for CP_HOT which runs at hot temp and NOT FT_HOT. FT_HOT spec provided by PE DRI
A8: SLT | B8: Product - SLTGB
A9: ATE_FQA | B9: Product | F9: FQA voltage runs at PV
A10: SLT_FQA | B10: Product | F10: FQA voltage runs at PV
A11: HTOL_ROOM | B11: Product-HTOL_T0TX_GB_ROOM
A12: HTOL_HOT | B12: Product-HTOL_T0TX_GB_HOT
A13: CPHV | B13: Default is typically (CPVmax + CPGB) * 1.1, but check Binning tab.
A14: FTHV | B14: Default is typically (CPVmax + CPGB) * 1.05 but now plan to use 1.1 to match CP. Check Binning tab.
A15: QAHV | B15: Default is typically (CPVmax + CPGB) * 1.03, but check Binning tab.
A17: Notes:
A18: For non-binned rail PMU voltages, use Pvmax column for desired row.
A19: SOS on GB sheet only includes sigma contribution. Means added directly to BinningGB.
A20: BinningGB - Used to compute the Product Voltage if bin search has not occurred yet. Includes examples like "ME005 E1 Product +10%" and "MG001 E3 Product"
A21: ...Example: E1 Product = MIN(MAX(Step * Floor( [E1_C - E1_M * Log10(IDS)] / Step), E1_BinningVmin), E1_BinningVmax) + E1_BinningGB
A24: PE / TE USE ONLY
A25: Base Voltage (mV) | B25: 125 | C25: This base voltage is the ATE base voltage which is used to determine what value to fuse.
A26: fuse_revision | B26: 6
A27: binning_type | B27: POR | C27: Identify whether this is for POR or SHADOW binning
A29: IDS fuse is calculated by rounding up IDS to the next step and then using that fuse value to calculate CP1 value. Procedure for using IDS to calculate CP1 for binning below.
A30: 1. Measure IDS value.
A31: 2. Round measured IDS value UP to next IDS step size for that rail. This is the value that will be fused into device.
A32: 3. Use this rounded up value as IDS in the CP1 equation at the top.
A34: PE Reference only | B34: All units are mA | C34: DO NOT DELETE (rev 15#1, 6/4) | M34: 95C
A35: Domain | B35: 25C IDS Step Size | C35: IDS1X_FFG_25C | D35: IDS1X_FFG_85C | E35: IDS1X_FFG_95C | F35: SOD_Ratio | G35: IDS1X_TTG_25C | H35: IDS1X_SSG_25C | I35: Num_Bits | J35: CP1 Per 1xFFG | K35: CP1 mA | L35: CP2 Per 1xFFG | M35: CP2 mA | N35: HOT IDS Step Size | O35: Hot_Num_Bits | P35: MaxIDS_CP1 | Q35: MaxIDS_HOT | R35: BinX CP1 Per 1xFFG | S35: BinX CP1 mA | T35: BinX CP2 Per 1xFFG | U35: BinX CP2 mA
A36: PCPU | B36: 0.2 | C36: 594.18522 | D36: 4001.6848 | E36: 5243.1357 | F36: =CEILING(D36/C36,0.1) -> 6.8 | G36: 375.67718 | H36: 222.81685 | I36: 14 | J36: 1.1 | K36: =$B36*ROUND((J36*$C36/$B36),0) -> 653.6 | L36: 1.5 | M36: =IF(N36="",E36*L36,$N36*CEILING((L36*$E36/$N36),1)) -> 7866 | N36: 2 | O36: 14 | P36: =2^I36*B36 -> 3276.8 | Q36: =2^O36*N36 -> 32768 | R36: 0 | S36: =MIN(CEILING(K36*(R36/J36)/B36,1)*B36,P36-2*B36) -> 0 | T36: =L36*(R36/J36) -> 0 | U36: =MIN(CEILING(M36*(T36/L36)/N36,1)*N36,Q36-2*N36) -> 0
A37: ECPU | B37: 0.2 | C37: 203.34645 | D37: 1171.2157 | E37: 1539.6667 | F37: =CEILING(D37/C37,0.1) -> 5.8 | G37: 134.69521 | H37: 79.657294 | I37: 12 | J37: 1.35 | K37: =$B37*ROUND((J37*$C37/$B37),0) -> 274.6 | L37: 1.948 | M37: =IF(N37="",E37*L37,$N37*CEILING((L37*$E37/$N37),1)) -> 3000 | N37: 2 | O37: 12 | P37: =2^I37*B37 -> 819.2 | Q37: =2^O37*N37 -> 8192 | R37: 0 | S37: =MIN(CEILING(K37*(R37/J37)/B37,1)*B37,P37-2*B37) -> 0 | T37: =L37*(R37/J37) -> 0 | U37: =MIN(CEILING(M37*(T37/L37)/N37,1)*N37,Q37-2*N37) -> 0
A38: CPU_SRAM | B38: 0.2 | C38: 78.258233 | D38: 518.46008 | E38: 690.79702 | F38: =CEILING(D38/C38,0.1) -> 6.7 | G38: 43.838231 | H38: 34.200775 | I38: 11 | J38: 1.5 | K38: =$B38*ROUND((J38*$C38/$B38),0) -> 117.4 | L38: 1.5 | M38: =IF(N38="",E38*L38,$N38*CEILING((L38*$E38/$N38),1)) -> 1037 | N38: 1 | O38: 11 | P38: =2^I38*B38 -> 409.6 | Q38: =2^O38*N38 -> 2048 | R38: 0 | S38: =MIN(CEILING(K38*(R38/J38)/B38,1)*B38,P38-2*B38) -> 0 | T38: =L38*(R38/J38) -> 0 | U38: =MIN(CEILING(M38*(T38/L38)/N38,1)*N38,Q38-2*N38) -> 0
A39: GPU | B39: 0.2 | C39: 342.4526 | D39: 2474.256 | E39: 3344.2373 | F39: =CEILING(D39/C39,0.1) -> 7.3 | G39: 192.29359 | H39: 118.34335 | I39: 13 | J39: 1.4 | K39: =$B39*ROUND((J39*$C39/$B39),0) -> 479.4 | L39: 1.8 | M39: =IF(N39="",E39*L39,$N39*CEILING((L39*$E39/$N39),1)) -> 6020 | N39: 2 | O39: 13 | P39: =2^I39*B39 -> 1638.4 | Q39: =2^O39*N39 -> 16384 | R39: 0 | S39: =MIN(CEILING(K39*(R39/J39)/B39,1)*B39,P39-2*B39) -> 0 | T39: =L39*(R39/J39) -> 0 | U39: =MIN(CEILING(M39*(T39/L39)/N39,1)*N39,Q39-2*N39) -> 0
A40: SRAM_GPU | B40: 0.1 | C40: 16.254702 | D40: 109.91922 | E40: 147.09099 | F40: =CEILING(D40/C40,0.1) -> 6.8 | G40: 11.321917 | H40: 8.5373408 | I40: 9 | J40: 1.45 | K40: =$B40*ROUND((J40*$C40/$B40),0) -> 23.6 | L40: 1.9 | M40: =IF(N40="",E40*L40,$N40*CEILING((L40*$E40/$N40),1)) -> 280 | N40: 1 | O40: 9 | P40: =2^I40*B40 -> 51.2 | Q40: =2^O40*N40 -> 512 | R40: 0 | S40: =MIN(CEILING(K40*(R40/J40)/B40,1)*B40,P40-2*B40) -> 0 | T40: =L40*(R40/J40) -> 0 | U40: =MIN(CEILING(M40*(T40/L40)/N40,1)*N40,Q40-2*N40) -> 0
A41: SOC | B41: 0.1 | C41: 112.77051 | D41: 675.52306 | E41: 915.95443 | F41: =CEILING(D41/C41,0.1) -> 6 | G41: 69.190425 | H41: 44.663436 | I41: 12 | J41: 1.25 | K41: =$B41*ROUND((J41*$C41/$B41),0) -> 141 | L41: 2.1 | M41: =IF(N41="",E41*L41,$N41*CEILING((L41*$E41/$N41),1)) -> 1924 | N41: 1 | O41: 12 | P41: =2^I41*B41 -> 409.6 | Q41: =2^O41*N41 -> 4096 | R41: 0 | S41: =MIN(CEILING(K41*(R41/J41)/B41,1)*B41,P41-2*B41) -> 0 | T41: =L41*(R41/J41) -> 0 | U41: =MIN(CEILING(M41*(T41/L41)/N41,1)*N41,Q41-2*N41) -> 0
A42: DCS_DDR | B42: 0.1 | C42: 12.93 | D42: 83.33 | E42: 110.91145 | F42: =CEILING(D42/C42,0.1) -> 6.5 | G42: 10.749129 | H42: 6.4518574 | I42: 10 | J42: 1 | K42: =$B42*ROUND((J42*$C42/$B42),0) -> 12.9 | L42: 1.5 | M42: =IF(N42="",E42*L42,$N42*CEILING((L42*$E42/$N42),1)) -> 167 | N42: 1 | O42: 10 | P42: =2^I42*B42 -> 102.4 | Q42: =2^O42*N42 -> 1024 | R42: 0 | S42: =MIN(CEILING(K42*(R42/J42)/B42,1)*B42,P42-2*B42) -> 0 | T42: =L42*(R42/J42) -> 0 | U42: =MIN(CEILING(M42*(T42/L42)/N42,1)*N42,Q42-2*N42) -> 0
A43: LOW | B43: 0.1 | C43: 6.84 | D43: 30.78 | E43: 41.38192 | F43: =CEILING(D43/C43,0.1) -> 4.5 | G43: 3.3685745 | H43: 3.556566 | I43: 8 | J43: 1 | K43: =$B43*ROUND((J43*$C43/$B43),0) -> 6.8 | L43: 1.5 | M43: =IF(N43="",E43*L43,$N43*CEILING((L43*$E43/$N43),1)) -> 62.5 | N43: 0.5 | O43: 8 | P43: =2^I43*B43 -> 25.6 | Q43: =2^O43*N43 -> 128 | R43: 0 | S43: =MIN(CEILING(K43*(R43/J43)/B43,1)*B43,P43-2*B43) -> 0 | T43: =L43*(R43/J43) -> 0 | U43: =MIN(CEILING(M43*(T43/L43)/N43,1)*N43,Q43-2*N43) -> 0
A44: CIO | B44: 0.1 | C44: 4.93 | D44: 35.99 | E44: 48.518468 | F44: =CEILING(D44/C44,0.1) -> 7.4 | G44: 8.4426105 | H44: 5.4624799 | I44: 9 | J44: 1 | K44: =$B44*ROUND((J44*$C44/$B44),0) -> 4.9 | L44: 1.5 | M44: =IF(N44="",E44*L44,$N44*CEILING((L44*$E44/$N44),1)) -> 73 | N44: 0.5 | O44: 10 | P44: =2^I44*B44 -> 51.2 | Q44: =2^O44*N44 -> 512 | R44: 0 | S44: =MIN(CEILING(K44*(R44/J44)/B44,1)*B44,P44-2*B44) -> 0 | T44: =L44*(R44/J44) -> 0 | U44: =MIN(CEILING(M44*(T44/L44)/N44,1)*N44,Q44-2*N44) -> 0
A45: DISP | B45: 0.1 | C45: 30.15 | D45: 230.59 | E45: 312.18816 | F45: =CEILING(D45/C45,0.1) -> 7.7 | G45: 20.310089 | H45: 13.313353 | I45: 11 | J45: 1.55 | K45: =$B45*ROUND((J45*$C45/$B45),0) -> 46.7 | L45: 2 | M45: =IF(N45="",E45*L45,$N45*CEILING((L45*$E45/$N45),1)) -> 626 | N45: 2 | O45: 11 | P45: =2^I45*B45 -> 204.8 | Q45: =2^O45*N45 -> 4096 | R45: 0 | S45: =MIN(CEILING(K45*(R45/J45)/B45,1)*B45,P45-2*B45) -> 0 | T45: =L45*(R45/J45) -> 0 | U45: =MIN(CEILING(M45*(T45/L45)/N45,1)*N45,Q45-2*N45) -> 0
...

Sheet Binning
A1: Rev: | B1: =MAX(Revision!A:A) -> 0.63
A2: Binned | B2: Domain | C2: Mode | D2: EQN | E2: ID | F2: Mode_EQN | G2: EQN_Bin | H2: C | I2: M | J2: CPIDSMax | K2: =CONCATENATE("BinX_",J2) -> BinX_CPIDSMax | L2: =Notes!B54 -> BinningVmax | M2: =Notes!B55 -> BinningVmin | N2: =Notes!B53 -> BinningGB | O2: =GB!S1 -> CP_GB_HOT | P2: =GB!T1 -> FT_GB_ROOM | Q2: =GB!U1 -> FT_GB_HOT | R2: IDSMax_HOT | S2: =CONCATENATE("BinX_",R2) -> BinX_IDSMax_HOT | T2: =GB!V1 -> SLTGB | U2: =GB!W1 -> ATE_FQAGB | V2: =GB!X1 -> SLT_FQA_GB | W2: =GB!Y1 -> HTOL_T0TX_GB_ROOM | X2: =GB!Z1 -> HTOL_T0TX_GB_HOT | Y2: PMU_Step | Z2: SLT_PMU_Max | AA2: SLT_PMU_Min | AB2: CPHV | AC2: FTHV | AD2: QAHV | AE2: Allow Equal | AF2: Monotonicity_Offset | AG2: SRAMthresh_Product | AH2: SRAMthresh_binSearch | AI2: Int_Mode_L | AJ2: Int_Mode_H | AK2: Int_MF | AL2: Int_Offset | AM2: Int_SkipTest | AN2: Offset_CP1_TD | AO2: Offset_CP1_BIST | AP2: Offset_CP1_FUNC | AQ2: Offset_CP2_TD | AR2: Offset_CP2_BIST | AS2: Offset_CP2_FUNC | AT2: BincutCalc_IDSrail | AU2: BincutCalc_IDSmax | AV2: =CONCATENATE("BinX_",AU2) -> BinX_BincutCalc_IDSmax | AW2: Comment | AX2: Pvmax | AY2: Pvmin | AZ2: =Notes!C35 -> IDS1X_FFG_25C | BA2: CP_V_1xIDS | BB2: Pv_1xIDS | BC2: CP_V_IDSMax | BD2: Pv_IDSMax | BF2: PE USE ONLY | BG2: SRAMRefMode | BH2: Vmax_Capability | BI2: Vmin_Capability | BJ2: SRAMmin_PV | BK2: Logic E1 PVmax | BL2: Logic E1 PV_1xIDS | BM2: Pvmax Logic - SRAM | BN2: PV_1xIDS Logic-SRAM | BO2: PE_IDSmax | BP2: Mode Number | BQ2: Equation Number | BR2: InterpolationEnable_Flag | BS2: LowMode | BT2: HighMode | BU2: MultFactor | BV2: Offset
A3: TRUE | B3: PCPU | C3: MP001 | D3: E1 | E3: =1000000+BP3*1000+BQ3 -> 1001001 | F3: =CONCATENATE(C3,"_",D3) -> MP001_E1 | G3: Bin1 | H3: =VLOOKUP(C3,BinningParamNotes!A:D,3,0) -> 850 | I3: =VLOOKUP(C3,BinningParamNotes!A:D,2,0) -> 80 | J3: =INDEX(Notes!$A$36:$N$47,MATCH(Binning!$B3,Notes!$A$36:$A$47,0),MATCH(Notes!$K$35,Notes!$A$35:$N$35,0)) -> 653.6 | L3: =VLOOKUP(C3,BinningParamNotes!A:D,4,0) -> 660 | M3: 480 | N3: =INDEX(GB!$A$2:$AD$96,MATCH($C3,GB!$A$2:$A$96,0),MATCH(N$2,GB!$A$1:$AD$1,0)) -> 90 | O3: =INDEX(GB!$A$2:$AD$96,MATCH($C3,GB!$A$2:$A$96,0),MATCH(O$2,GB!$A$1:$AD$1,0)) -> 95 | P3: =INDEX(GB!$A$2:$AD$96,MATCH($C3,GB!$A$2:$A$96,0),MATCH(P$2,GB!$A$1:$AD$1,0)) -> 70 | Q3: =INDEX(GB!$A$2:$AD$96,MATCH($C3,GB!$A$2:$A$96,0),MATCH(Q$2,GB!$A$1:$AD$1,0)) -> 80 | R3: =INDEX(Notes!$A$36:$N$47,MATCH(Binning!$B3,Notes!$A$36:$A$47,0),MATCH(Notes!$M$35,Notes!$A$35:$N$35,0)) -> 7866 | T3: =INDEX(GB!$A$2:$AD$96,MATCH($C3,GB!$A$2:$A$96,0),MATCH(T$2,GB!$A$1:$AD$1,0)) -> 70 | U3: =INDEX(GB!$A$2:$AD$96,MATCH($C3,GB!$A$2:$A$96,0),MATCH(U$2,GB!$A$1:$AD$1,0)) -> 0 | V3: =INDEX(GB!$A$2:$AD$96,MATCH($C3,GB!$A$2:$A$96,0),MATCH(V$2,GB!$A$1:$AD$1,0)) -> 0 | W3: =INDEX(GB!$A$2:$AD$96,MATCH($C3,GB!$A$2:$A$96,0),MATCH(W$2,GB!$A$1:$AD$1,0)) -> 45 | X3: =INDEX(GB!$A$2:$AD$96,MATCH($C3,GB!$A$2:$A$96,0),MATCH(X$2,GB!$A$1:$AD$1,0)) -> 55 | Y3: 5 | Z3: 1250 | AA3: 400 | AF3: 0 | AI3: =IF($BR3=1,BS3,"") | AJ3: =IF($BR3=1,BT3,"") | AK3: =IF($BR3=1,BU3,"") | AL3: =IF($BR3=1,BV3,"") | AM3: =IF($BR3=1,"YES","") | AT3: =B3 -> PCPU | AU3: =J3 -> 653.6 | AX3: =L3+N3 -> 750 | AY3: =M3+N3 -> 570 | AZ3: =INDEX(Notes!$A$36:$O$47,MATCH($B3,Notes!A$36:A$47,0),MATCH(AZ$2,Notes!A$35:O$35,0)) -> 594.18522 | BA3: =MAX(MIN(Y3*FLOOR((H3-I3*LOG10(AZ3))/Y3,1),L3),M3) -> 625 | BB3: =BA3+N3 -> 715 | BC3: =MAX(MIN(Y3*FLOOR((H3-I3*LOG10(J3))/Y3,1),L3),M3) -> 620 | BD3: =BC3+N3 -> 710 | BO3: =MAX(J3:J9) -> 653.6 | BP3: =IF(CODE(RIGHT($C3,1))<58,CODE(RIGHT($C3,1))-48,CODE(RIGHT($C3,1))-55) -> 1 | BQ3: =MID($D3,2,2) -> 1 | BR3: 0
A4: TRUE | B4: PCPU | C4: MP001 | D4: =CONCATENATE("E",MID(D3,2,2)+1) -> E2 | E4: =1000000+BP4*1000+BQ4 -> 1001002 | F4: =CONCATENATE(C4,"_",D4) -> MP001_E2 | G4: Bin1 | H4: =H3-15 -> 835 | I4: =I3 -> 80 | J4: =INDEX(Notes!$A$36:$N$47,MATCH(Binning!$B4,Notes!$A$36:$A$47,0),MATCH(Notes!$K$35,Notes!$A$35:$N$35,0)) -> 653.6 | L4: =L3-10 -> 650 | M4: =M3 -> 480 | N4: =INDEX(GB!$A$2:$AD$96,MATCH($C4,GB!$A$2:$A$96,0),MATCH(N$2,GB!$A$1:$AD$1,0)) -> 90 | O4: =INDEX(GB!$A$2:$AD$96,MATCH($C4,GB!$A$2:$A$96,0),MATCH(O$2,GB!$A$1:$AD$1,0)) -> 95 | P4: =INDEX(GB!$A$2:$AD$96,MATCH($C4,GB!$A$2:$A$96,0),MATCH(P$2,GB!$A$1:$AD$1,0)) -> 70 | Q4: =INDEX(GB!$A$2:$AD$96,MATCH($C4,GB!$A$2:$A$96,0),MATCH(Q$2,GB!$A$1:$AD$1,0)) -> 80 | R4: =INDEX(Notes!$A$36:$N$47,MATCH(Binning!$B4,Notes!$A$36:$A$47,0),MATCH(Notes!$M$35,Notes!$A$35:$N$35,0)) -> 7866 | T4: =INDEX(GB!$A$2:$AD$96,MATCH($C4,GB!$A$2:$A$96,0),MATCH(T$2,GB!$A$1:$AD$1,0)) -> 70 | U4: =INDEX(GB!$A$2:$AD$96,MATCH($C4,GB!$A$2:$A$96,0),MATCH(U$2,GB!$A$1:$AD$1,0)) -> 0 | V4: =INDEX(GB!$A$2:$AD$96,MATCH($C4,GB!$A$2:$A$96,0),MATCH(V$2,GB!$A$1:$AD$1,0)) -> 0 | W4: =INDEX(GB!$A$2:$AD$96,MATCH($C4,GB!$A$2:$A$96,0),MATCH(W$2,GB!$A$1:$AD$1,0)) -> 45 | X4: =INDEX(GB!$A$2:$AD$96,MATCH($C4,GB!$A$2:$A$96,0),MATCH(X$2,GB!$A$1:$AD$1,0)) -> 55 | Y4: 5 | Z4: 1250 | AA4: 400 | AF4: =AF3 -> 0 | AI4: =IF($BR4=1,BS4,"") | AJ4: =IF($BR4=1,BT4,"") | AK4: =IF($BR4=1,BU4,"") | AL4: =IF($BR4=1,BV4,"") | AM4: =IF($BR4=1,"YES","") | AT4: =B4 -> PCPU | AU4: =J4 -> 653.6 | AX4: =L4+N4 -> 740 | AY4: =M4+N4 -> 570 | AZ4: =INDEX(Notes!$A$36:$O$47,MATCH($B4,Notes!A$36:A$47,0),MATCH(AZ$2,Notes!A$35:O$35,0)) -> 594.18522 | BA4: =MAX(MIN(Y4*FLOOR((H4-I4*LOG10(AZ4))/Y4,1),L4),M4) -> 610 | BB4: =BA4+N4 -> 700 | BC4: =MAX(MIN(Y4*FLOOR((H4-I4*LOG10(J4))/Y4,1),L4),M4) -> 605 | BD4: =BC4+N4 -> 695 | BO4: =BO3 -> 653.6 | BP4: =IF(CODE(RIGHT($C4,1))<58,CODE(RIGHT($C4,1))-48,CODE(RIGHT($C4,1))-55) -> 1 | BQ4: =MID($D4,2,2) -> 2 | BR4: =IF(BR3="","",BR3) -> 0 | BS4: =IF(BS3="","",BS3) | BT4: =IF(BT3="","",BT3) | BU4: =IF(BU3="","",BU3) | BV4: =IF(BV3="","",BV3)
A5: TRUE | B5: PCPU | C5: MP001 | D5: =CONCATENATE("E",MID(D4,2,2)+1) -> E3 | E5: =1000000+BP5*1000+BQ5 -> 1001003 | F5: =CONCATENATE(C5,"_",D5) -> MP001_E3 | G5: Bin1 | H5: =H4-15 -> 820 | I5: =I4 -> 80 | J5: =INDEX(Notes!$A$36:$N$47,MATCH(Binning!$B5,Notes!$A$36:$A$47,0),MATCH(Notes!$K$35,Notes!$A$35:$N$35,0)) -> 653.6 | L5: =L4-10 -> 640 | M5: =M4 -> 480 | N5: =INDEX(GB!$A$2:$AD$96,MATCH($C5,GB!$A$2:$A$96,0),MATCH(N$2,GB!$A$1:$AD$1,0)) -> 90 | O5: =INDEX(GB!$A$2:$AD$96,MATCH($C5,GB!$A$2:$A$96,0),MATCH(O$2,GB!$A$1:$AD$1,0)) -> 95 | P5: =INDEX(GB!$A$2:$AD$96,MATCH($C5,GB!$A$2:$A$96,0),MATCH(P$2,GB!$A$1:$AD$1,0)) -> 70 | Q5: =INDEX(GB!$A$2:$AD$96,MATCH($C5,GB!$A$2:$A$96,0),MATCH(Q$2,GB!$A$1:$AD$1,0)) -> 80 | R5: =INDEX(Notes!$A$36:$N$47,MATCH(Binning!$B5,Notes!$A$36:$A$47,0),MATCH(Notes!$M$35,Notes!$A$35:$N$35,0)) -> 7866 | T5: =INDEX(GB!$A$2:$AD$96,MATCH($C5,GB!$A$2:$A$96,0),MATCH(T$2,GB!$A$1:$AD$1,0)) -> 70 | U5: =INDEX(GB!$A$2:$AD$96,MATCH($C5,GB!$A$2:$A$96,0),MATCH(U$2,GB!$A$1:$AD$1,0)) -> 0 | V5: =INDEX(GB!$A$2:$AD$96,MATCH($C5,GB!$A$2:$A$96,0),MATCH(V$2,GB!$A$1:$AD$1,0)) -> 0 | W5: =INDEX(GB!$A$2:$AD$96,MATCH($C5,GB!$A$2:$A$96,0),MATCH(W$2,GB!$A$1:$AD$1,0)) -> 45 | X5: =INDEX(GB!$A$2:$AD$96,MATCH($C5,GB!$A$2:$A$96,0),MATCH(X$2,GB!$A$1:$AD$1,0)) -> 55 | Y5: 5 | Z5: 1250 | AA5: 400 | AF5: =AF4 -> 0 | AI5: =IF($BR5=1,BS5,"") | AJ5: =IF($BR5=1,BT5,"") | AK5: =IF($BR5=1,BU5,"") | AL5: =IF($BR5=1,BV5,"") | AM5: =IF($BR5=1,"YES","") | AT5: =B5 -> PCPU | AU5: =J5 -> 653.6 | AX5: =L5+N5 -> 730 | AY5: =M5+N5 -> 570 | AZ5: =INDEX(Notes!$A$36:$O$47,MATCH($B5,Notes!A$36:A$47,0),MATCH(AZ$2,Notes!A$35:O$35,0)) -> 594.18522 | BA5: =MAX(MIN(Y5*FLOOR((H5-I5*LOG10(AZ5))/Y5,1),L5),M5) -> 595 | BB5: =BA5+N5 -> 685 | BC5: =MAX(MIN(Y5*FLOOR((H5-I5*LOG10(J5))/Y5,1),L5),M5) -> 590 | BD5: =BC5+N5 -> 680 | BO5: =BO4 -> 653.6 | BP5: =IF(CODE(RIGHT($C5,1))<58,CODE(RIGHT($C5,1))-48,CODE(RIGHT($C5,1))-55) -> 1 | BQ5: =MID($D5,2,2) -> 3 | BR5: =IF(BR4="","",BR4) -> 0 | BS5: =IF(BS4="","",BS4) | BT5: =IF(BT4="","",BT4) | BU5: =IF(BU4="","",BU4) | BV5: =IF(BV4="","",BV4)
A6: TRUE | B6: PCPU | C6: MP001 | D6: =CONCATENATE("E",MID(D5,2,2)+1) -> E4 | E6: =1000000+BP6*1000+BQ6 -> 1001004 | F6: =CONCATENATE(C6,"_",D6) -> MP001_E4 | G6: Bin1 | H6: =H5-15 -> 805 | I6: =I5 -> 80 | J6: =INDEX(Notes!$A$36:$N$47,MATCH(Binning!$B6,Notes!$A$36:$A$47,0),MATCH(Notes!$K$35,Notes!$A$35:$N$35,0)) -> 653.6 | L6: =L5 -> 640 | M6: =M5 -> 480 | N6: =INDEX(GB!$A$2:$AD$96,MATCH($C6,GB!$A$2:$A$96,0),MATCH(N$2,GB!$A$1:$AD$1,0)) -> 90 | O6: =INDEX(GB!$A$2:$AD$96,MATCH($C6,GB!$A$2:$A$96,0),MATCH(O$2,GB!$A$1:$AD$1,0)) -> 95 | P6: =INDEX(GB!$A$2:$AD$96,MATCH($C6,GB!$A$2:$A$96,0),MATCH(P$2,GB!$A$1:$AD$1,0)) -> 70 | Q6: =INDEX(GB!$A$2:$AD$96,MATCH($C6,GB!$A$2:$A$96,0),MATCH(Q$2,GB!$A$1:$AD$1,0)) -> 80 | R6: =INDEX(Notes!$A$36:$N$47,MATCH(Binning!$B6,Notes!$A$36:$A$47,0),MATCH(Notes!$M$35,Notes!$A$35:$N$35,0)) -> 7866 | T6: =INDEX(GB!$A$2:$AD$96,MATCH($C6,GB!$A$2:$A$96,0),MATCH(T$2,GB!$A$1:$AD$1,0)) -> 70 | U6: =INDEX(GB!$A$2:$AD$96,MATCH($C6,GB!$A$2:$A$96,0),MATCH(U$2,GB!$A$1:$AD$1,0)) -> 0 | V6: =INDEX(GB!$A$2:$AD$96,MATCH($C6,GB!$A$2:$A$96,0),MATCH(V$2,GB!$A$1:$AD$1,0)) -> 0 | W6: =INDEX(GB!$A$2:$AD$96,MATCH($C6,GB!$A$2:$A$96,0),MATCH(W$2,GB!$A$1:$AD$1,0)) -> 45 | X6: =INDEX(GB!$A$2:$AD$96,MATCH($C6,GB!$A$2:$A$96,0),MATCH(X$2,GB!$A$1:$AD$1,0)) -> 55 | Y6: 5 | Z6: 1250 | AA6: 400 | AF6: =AF5 -> 0 | AI6: =IF($BR6=1,BS6,"") | AJ6: =IF($BR6=1,BT6,"") | AK6: =IF($BR6=1,BU6,"") | AL6: =IF($BR6=1,BV6,"") | AM6: =IF($BR6=1,"YES","") | AT6: =B6 -> PCPU | AU6: =J6 -> 653.6 | AX6: =L6+N6 -> 730 | AY6: =M6+N6 -> 570 | AZ6: =INDEX(Notes!$A$36:$O$47,MATCH($B6,Notes!A$36:A$47,0),MATCH(AZ$2,Notes!A$35:O$35,0)) -> 594.18522 | BA6: =MAX(MIN(Y6*FLOOR((H6-I6*LOG10(AZ6))/Y6,1),L6),M6) -> 580 | BB6: =BA6+N6 -> 670 | BC6: =MAX(MIN(Y6*FLOOR((H6-I6*LOG10(J6))/Y6,1),L6),M6) -> 575 | BD6: =BC6+N6 -> 665 | BO6: =BO5 -> 653.6 | BP6: =IF(CODE(RIGHT($C6,1))<58,CODE(RIGHT($C6,1))-48,CODE(RIGHT($C6,1))-55) -> 1 | BQ6: =MID($D6,2,2) -> 4 | BR6: =IF(BR5="","",BR5) -> 0 | BS6: =IF(BS5="","",BS5) | BT6: =IF(BT5="","",BT5) | BU6: =IF(BU5="","",BU5) | BV6: =IF(BV5="","",BV5)
A7: TRUE | B7: PCPU | C7: MP001 | D7: =CONCATENATE("E",MID(D6,2,2)+1) -> E5 | E7: =1000000+BP7*1000+BQ7 -> 1001005 | F7: =CONCATENATE(C7,"_",D7) -> MP001_E5 | G7: Bin1 | H7: =H6-15 -> 790 | I7: =I6 -> 80 | J7: =INDEX(Notes!$A$36:$N$47,MATCH(Binning!$B7,Notes!$A$36:$A$47,0),MATCH(Notes!$K$35,Notes!$A$35:$N$35,0)) -> 653.6 | L7: =L6 -> 640 | M7: =M6 -> 480 | N7: =INDEX(GB!$A$2:$AD$96,MATCH($C7,GB!$A$2:$A$96,0),MATCH(N$2,GB!$A$1:$AD$1,0)) -> 90 | O7: =INDEX(GB!$A$2:$AD$96,MATCH($C7,GB!$A$2:$A$96,0),MATCH(O$2,GB!$A$1:$AD$1,0)) -> 95 | P7: =INDEX(GB!$A$2:$AD$96,MATCH($C7,GB!$A$2:$A$96,0),MATCH(P$2,GB!$A$1:$AD$1,0)) -> 70 | Q7: =INDEX(GB!$A$2:$AD$96,MATCH($C7,GB!$A$2:$A$96,0),MATCH(Q$2,GB!$A$1:$AD$1,0)) -> 80 | R7: =INDEX(Notes!$A$36:$N$47,MATCH(Binning!$B7,Notes!$A$36:$A$47,0),MATCH(Notes!$M$35,Notes!$A$35:$N$35,0)) -> 7866 | T7: =INDEX(GB!$A$2:$AD$96,MATCH($C7,GB!$A$2:$A$96,0),MATCH(T$2,GB!$A$1:$AD$1,0)) -> 70 | U7: =INDEX(GB!$A$2:$AD$96,MATCH($C7,GB!$A$2:$A$96,0),MATCH(U$2,GB!$A$1:$AD$1,0)) -> 0 | V7: =INDEX(GB!$A$2:$AD$96,MATCH($C7,GB!$A$2:$A$96,0),MATCH(V$2,GB!$A$1:$AD$1,0)) -> 0 | W7: =INDEX(GB!$A$2:$AD$96,MATCH($C7,GB!$A$2:$A$96,0),MATCH(W$2,GB!$A$1:$AD$1,0)) -> 45 | X7: =INDEX(GB!$A$2:$AD$96,MATCH($C7,GB!$A$2:$A$96,0),MATCH(X$2,GB!$A$1:$AD$1,0)) -> 55 | Y7: 5 | Z7: 1250 | AA7: 400 | AF7: =AF6 -> 0 | AI7: =IF($BR7=1,BS7,"") | AJ7: =IF($BR7=1,BT7,"") | AK7: =IF($BR7=1,BU7,"") | AL7: =IF($BR7=1,BV7,"") | AM7: =IF($BR7=1,"YES","") | AT7: =B7 -> PCPU | AU7: =J7 -> 653.6 | AX7: =L7+N7 -> 730 | AY7: =M7+N7 -> 570 | AZ7: =INDEX(Notes!$A$36:$O$47,MATCH($B7,Notes!A$36:A$47,0),MATCH(AZ$2,Notes!A$35:O$35,0)) -> 594.18522 | BA7: =MAX(MIN(Y7*FLOOR((H7-I7*LOG10(AZ7))/Y7,1),L7),M7) -> 565 | BB7: =BA7+N7 -> 655 | BC7: =MAX(MIN(Y7*FLOOR((H7-I7*LOG10(J7))/Y7,1),L7),M7) -> 560 | BD7: =BC7+N7 -> 650 | BO7: =BO6 -> 653.6 | BP7: =IF(CODE(RIGHT($C7,1))<58,CODE(RIGHT($C7,1))-48,CODE(RIGHT($C7,1))-55) -> 1 | BQ7: =MID($D7,2,2) -> 5 | BR7: =IF(BR6="","",BR6) -> 0 | BS7: =IF(BS6="","",BS6) | BT7: =IF(BT6="","",BT6) | BU7: =IF(BU6="","",BU6) | BV7: =IF(BV6="","",BV6)
A8: TRUE | B8: PCPU | C8: MP001 | D8: =CONCATENATE("E",MID(D7,2,2)+1) -> E6 | E8: =1000000+BP8*1000+BQ8 -> 1001006 | F8: =CONCATENATE(C8,"_",D8) -> MP001_E6 | G8: Bin1 | H8: =H7-15 -> 775 | I8: =I7 -> 80 | J8: =INDEX(Notes!$A$36:$N$47,MATCH(Binning!$B8,Notes!$A$36:$A$47,0),MATCH(Notes!$K$35,Notes!$A$35:$N$35,0)) -> 653.6 | L8: =L7 -> 640 | M8: =M7 -> 480 | N8: =INDEX(GB!$A$2:$AD$96,MATCH($C8,GB!$A$2:$A$96,0),MATCH(N$2,GB!$A$1:$AD$1,0)) -> 90 | O8: =INDEX(GB!$A$2:$AD$96,MATCH($C8,GB!$A$2:$A$96,0),MATCH(O$2,GB!$A$1:$AD$1,0)) -> 95 | P8: =INDEX(GB!$A$2:$AD$96,MATCH($C8,GB!$A$2:$A$96,0),MATCH(P$2,GB!$A$1:$AD$1,0)) -> 70 | Q8: =INDEX(GB!$A$2:$AD$96,MATCH($C8,GB!$A$2:$A$96,0),MATCH(Q$2,GB!$A$1:$AD$1,0)) -> 80 | R8: =INDEX(Notes!$A$36:$N$47,MATCH(Binning!$B8,Notes!$A$36:$A$47,0),MATCH(Notes!$M$35,Notes!$A$35:$N$35,0)) -> 7866 | T8: =INDEX(GB!$A$2:$AD$96,MATCH($C8,GB!$A$2:$A$96,0),MATCH(T$2,GB!$A$1:$AD$1,0)) -> 70 | U8: =INDEX(GB!$A$2:$AD$96,MATCH($C8,GB!$A$2:$A$96,0),MATCH(U$2,GB!$A$1:$AD$1,0)) -> 0 | V8: =INDEX(GB!$A$2:$AD$96,MATCH($C8,GB!$A$2:$A$96,0),MATCH(V$2,GB!$A$1:$AD$1,0)) -> 0 | W8: =INDEX(GB!$A$2:$AD$96,MATCH($C8,GB!$A$2:$A$96,0),MATCH(W$2,GB!$A$1:$AD$1,0)) -> 45 | X8: =INDEX(GB!$A$2:$AD$96,MATCH($C8,GB!$A$2:$A$96,0),MATCH(X$2,GB!$A$1:$AD$1,0)) -> 55 | Y8: 5 | Z8: 1250 | AA8: 400 | AF8: =AF7 -> 0 | AI8: =IF($BR8=1,BS8,"") | AJ8: =IF($BR8=1,BT8,"") | AK8: =IF($BR8=1,BU8,"") | AL8: =IF($BR8=1,BV8,"") | AM8: =IF($BR8=1,"YES","") | AT8: =B8 -> PCPU | AU8: =J8 -> 653.6 | AX8: =L8+N8 -> 730 | AY8: =M8+N8 -> 570 | AZ8: =INDEX(Notes!$A$36:$O$47,MATCH($B8,Notes!A$36:A$47,0),MATCH(AZ$2,Notes!A$35:O$35,0)) -> 594.18522 | BA8: =MAX(MIN(Y8*FLOOR((H8-I8*LOG10(AZ8))/Y8,1),L8),M8) -> 550 | BB8: =BA8+N8 -> 640 | BC8: =MAX(MIN(Y8*FLOOR((H8-I8*LOG10(J8))/Y8,1),L8),M8) -> 545 | BD8: =BC8+N8 -> 635 | BO8: =BO7 -> 653.6 | BP8: =IF(CODE(RIGHT($C8,1))<58,CODE(RIGHT($C8,1))-48,CODE(RIGHT($C8,1))-55) -> 1 | BQ8: =MID($D8,2,2) -> 6 | BR8: =IF(BR7="","",BR7) -> 0 | BS8: =IF(BS7="","",BS7) | BT8: =IF(BT7="","",BT7) | BU8: =IF(BU7="","",BU7) | BV8: =IF(BV7="","",BV7)
A9: TRUE | B9: PCPU | C9: MP001 | D9: =CONCATENATE("E",MID(D8,2,2)+1) -> E7 | E9: =1000000+BP9*1000+BQ9 -> 1001007 | F9: =CONCATENATE(C9,"_",D9) -> MP001_E7 | G9: Bin1 | H9: =H8-15 -> 760 | I9: =I8 -> 80 | J9: =INDEX(Notes!$A$36:$N$47,MATCH(Binning!$B9,Notes!$A$36:$A$47,0),MATCH(Notes!$K$35,Notes!$A$35:$N$35,0)) -> 653.6 | L9: =L8 -> 640 | M9: =M8 -> 480 | N9: =INDEX(GB!$A$2:$AD$96,MATCH($C9,GB!$A$2:$A$96,0),MATCH(N$2,GB!$A$1:$AD$1,0)) -> 90 | O9: =INDEX(GB!$A$2:$AD$96,MATCH($C9,GB!$A$2:$A$96,0),MATCH(O$2,GB!$A$1:$AD$1,0)) -> 95 | P9: =INDEX(GB!$A$2:$AD$96,MATCH($C9,GB!$A$2:$A$96,0),MATCH(P$2,GB!$A$1:$AD$1,0)) -> 70 | Q9: =INDEX(GB!$A$2:$AD$96,MATCH($C9,GB!$A$2:$A$96,0),MATCH(Q$2,GB!$A$1:$AD$1,0)) -> 80 | R9: =INDEX(Notes!$A$36:$N$47,MATCH(Binning!$B9,Notes!$A$36:$A$47,0),MATCH(Notes!$M$35,Notes!$A$35:$N$35,0)) -> 7866 | T9: =INDEX(GB!$A$2:$AD$96,MATCH($C9,GB!$A$2:$A$96,0),MATCH(T$2,GB!$A$1:$AD$1,0)) -> 70 | U9: =INDEX(GB!$A$2:$AD$96,MATCH($C9,GB!$A$2:$A$96,0),MATCH(U$2,GB!$A$1:$AD$1,0)) -> 0 | V9: =INDEX(GB!$A$2:$AD$96,MATCH($C9,GB!$A$2:$A$96,0),MATCH(V$2,GB!$A$1:$AD$1,0)) -> 0 | W9: =INDEX(GB!$A$2:$AD$96,MATCH($C9,GB!$A$2:$A$96,0),MATCH(W$2,GB!$A$1:$AD$1,0)) -> 45 | X9: =INDEX(GB!$A$2:$AD$96,MATCH($C9,GB!$A$2:$A$96,0),MATCH(X$2,GB!$A$1:$AD$1,0)) -> 55 | Y9: 5 | Z9: 1250 | AA9: 400 | AF9: =AF8 -> 0 | AI9: =IF($BR9=1,BS9,"") | AJ9: =IF($BR9=1,BT9,"") | AK9: =IF($BR9=1,BU9,"") | AL9: =IF($BR9=1,BV9,"") | AM9: =IF($BR9=1,"YES","") | AT9: =B9 -> PCPU | AU9: =J9 -> 653.6 | AX9: =L9+N9 -> 730 | AY9: =M9+N9 -> 570 | AZ9: =INDEX(Notes!$A$36:$O$47,MATCH($B9,Notes!A$36:A$47,0),MATCH(AZ$2,Notes!A$35:O$35,0)) -> 594.18522 | BA9: =MAX(MIN(Y9*FLOOR((H9-I9*LOG10(AZ9))/Y9,1),L9),M9) -> 535 | BB9: =BA9+N9 -> 625 | BC9: =MAX(MIN(Y9*FLOOR((H9-I9*LOG10(J9))/Y9,1),L9),M9) -> 530 | BD9: =BC9+N9 -> 620 | BO9: =BO8 -> 653.6 | BP9: =IF(CODE(RIGHT($C9,1))<58,CODE(RIGHT($C9,1))-48,CODE(RIGHT($C9,1))-55) -> 1 | BQ9: =MID($D9,2,2) -> 7 | BR9: =IF(BR8="","",BR8) -> 0 | BS9: =IF(BS8="","",BS8) | BT9: =IF(BT8="","",BT8) | BU9: =IF(BU8="","",BU8) | BV9: =IF(BV8="","",BV8)
A10: TRUE | B10: PCPU | C10: MP001 | D10: =CONCATENATE("E",MID(D9,2,2)+1) -> E8 | E10: =1000000+BP10*1000+BQ10 -> 1001008 | F10: =CONCATENATE(C10,"_",D10) -> MP001_E8 | G10: Bin1 | H10: =H9-15 -> 745 | I10: =I9 -> 80 | J10: =INDEX(Notes!$A$36:$N$47,MATCH(Binning!$B10,Notes!$A$36:$A$47,0),MATCH(Notes!$K$35,Notes!$A$35:$N$35,0)) -> 653.6 | L10: =L9 -> 640 | M10: =M9 -> 480 | N10: =INDEX(GB!$A$2:$AD$96,MATCH($C10,GB!$A$2:$A$96,0),MATCH(N$2,GB!$A$1:$AD$1,0)) -> 90 | O10: =INDEX(GB!$A$2:$AD$96,MATCH($C10,GB!$A$2:$A$96,0),MATCH(O$2,GB!$A$1:$AD$1,0)) -> 95 | P10: =INDEX(GB!$A$2:$AD$96,MATCH($C10,GB!$A$2:$A$96,0),MATCH(P$2,GB!$A$1:$AD$1,0)) -> 70 | Q10: =INDEX(GB!$A$2:$AD$96,MATCH($C10,GB!$A$2:$A$96,0),MATCH(Q$2,GB!$A$1:$AD$1,0)) -> 80 | R10: =INDEX(Notes!$A$36:$N$47,MATCH(Binning!$B10,Notes!$A$36:$A$47,0),MATCH(Notes!$M$35,Notes!$A$35:$N$35,0)) -> 7866 | T10: =INDEX(GB!$A$2:$AD$96,MATCH($C10,GB!$A$2:$A$96,0),MATCH(T$2,GB!$A$1:$AD$1,0)) -> 70 | U10: =INDEX(GB!$A$2:$AD$96,MATCH($C10,GB!$A$2:$A$96,0),MATCH(U$2,GB!$A$1:$AD$1,0)) -> 0 | V10: =INDEX(GB!$A$2:$AD$96,MATCH($C10,GB!$A$2:$A$96,0),MATCH(V$2,GB!$A$1:$AD$1,0)) -> 0 | W10: =INDEX(GB!$A$2:$AD$96,MATCH($C10,GB!$A$2:$A$96,0),MATCH(W$2,GB!$A$1:$AD$1,0)) -> 45 | X10: =INDEX(GB!$A$2:$AD$96,MATCH($C10,GB!$A$2:$A$96,0),MATCH(X$2,GB!$A$1:$AD$1,0)) -> 55 | Y10: 5 | Z10: 1250 | AA10: 400 | AF10: =AF9 -> 0 | AI10: =IF($BR10=1,BS10,"") | AJ10: =IF($BR10=1,BT10,"") | AK10: =IF($BR10=1,BU10,"") | AL10: =IF($BR10=1,BV10,"") | AM10: =IF($BR10=1,"YES","") | AT10: =B10 -> PCPU | AU10: =J10 -> 653.6 | AX10: =L10+N10 -> 730 | AY10: =M10+N10 -> 570 | AZ10: =INDEX(Notes!$A$36:$O$47,MATCH($B10,Notes!A$36:A$47,0),MATCH(AZ$2,Notes!A$35:O$35,0)) -> 594.18522 | BA10: =MAX(MIN(Y10*FLOOR((H10-I10*LOG10(AZ10))/Y10,1),L10),M10) -> 520 | BB10: =BA10+N10 -> 610 | BC10: =MAX(MIN(Y10*FLOOR((H10-I10*LOG10(J10))/Y10,1),L10),M10) -> 515 | BD10: =BC10+N10 -> 605 | BO10: =BO9 -> 653.6 | BP10: =IF(CODE(RIGHT($C10,1))<58,CODE(RIGHT($C10,1))-48,CODE(RIGHT($C10,1))-55) -> 1 | BQ10: =MID($D10,2,2) -> 8 | BR10: =IF(BR9="","",BR9) -> 0 | BS10: =IF(BS9="","",BS9) | BT10: =IF(BT9="","",BT9) | BU10: =IF(BU9="","",BU9) | BV10: =IF(BV9="","",BV9)
A11: TRUE | B11: PCPU | C11: MP001 | D11: =CONCATENATE("E",MID(D10,2,2)+1) -> E9 | E11: =1000000+BP11*1000+BQ11 -> 1001009 | F11: =CONCATENATE(C11,"_",D11) -> MP001_E9 | G11: Bin1 | H11: =H10-15 -> 730 | I11: =I10 -> 80 | J11: =INDEX(Notes!$A$36:$N$47,MATCH(Binning!$B11,Notes!$A$36:$A$47,0),MATCH(Notes!$K$35,Notes!$A$35:$N$35,0)) -> 653.6 | L11: =L10 -> 640 | M11: =M10 -> 480 | N11: =INDEX(GB!$A$2:$AD$96,MATCH($C11,GB!$A$2:$A$96,0),MATCH(N$2,GB!$A$1:$AD$1,0)) -> 90 | O11: =INDEX(GB!$A$2:$AD$96,MATCH($C11,GB!$A$2:$A$96,0),MATCH(O$2,GB!$A$1:$AD$1,0)) -> 95 | P11: =INDEX(GB!$A$2:$AD$96,MATCH($C11,GB!$A$2:$A$96,0),MATCH(P$2,GB!$A$1:$AD$1,0)) -> 70 | Q11: =INDEX(GB!$A$2:$AD$96,MATCH($C11,GB!$A$2:$A$96,0),MATCH(Q$2,GB!$A$1:$AD$1,0)) -> 80 | R11: =INDEX(Notes!$A$36:$N$47,MATCH(Binning!$B11,Notes!$A$36:$A$47,0),MATCH(Notes!$M$35,Notes!$A$35:$N$35,0)) -> 7866 | T11: =INDEX(GB!$A$2:$AD$96,MATCH($C11,GB!$A$2:$A$96,0),MATCH(T$2,GB!$A$1:$AD$1,0)) -> 70 | U11: =INDEX(GB!$A$2:$AD$96,MATCH($C11,GB!$A$2:$A$96,0),MATCH(U$2,GB!$A$1:$AD$1,0)) -> 0 | V11: =INDEX(GB!$A$2:$AD$96,MATCH($C11,GB!$A$2:$A$96,0),MATCH(V$2,GB!$A$1:$AD$1,0)) -> 0 | W11: =INDEX(GB!$A$2:$AD$96,MATCH($C11,GB!$A$2:$A$96,0),MATCH(W$2,GB!$A$1:$AD$1,0)) -> 45 | X11: =INDEX(GB!$A$2:$AD$96,MATCH($C11,GB!$A$2:$A$96,0),MATCH(X$2,GB!$A$1:$AD$1,0)) -> 55 | Y11: 5 | Z11: 1250 | AA11: 400 | AF11: =AF10 -> 0 | AI11: =IF($BR11=1,BS11,"") | AJ11: =IF($BR11=1,BT11,"") | AK11: =IF($BR11=1,BU11,"") | AL11: =IF($BR11=1,BV11,"") | AM11: =IF($BR11=1,"YES","") | AT11: =B11 -> PCPU | AU11: =J11 -> 653.6 | AX11: =L11+N11 -> 730 | AY11: =M11+N11 -> 570 | AZ11: =INDEX(Notes!$A$36:$O$47,MATCH($B11,Notes!A$36:A$47,0),MATCH(AZ$2,Notes!A$35:O$35,0)) -> 594.18522 | BA11: =MAX(MIN(Y11*FLOOR((H11-I11*LOG10(AZ11))/Y11,1),L11),M11) -> 505 | BB11: =BA11+N11 -> 595 | BC11: =MAX(MIN(Y11*FLOOR((H11-I11*LOG10(J11))/Y11,1),L11),M11) -> 500 | BD11: =BC11+N11 -> 590 | BO11: =BO10 -> 653.6 | BP11: =IF(CODE(RIGHT($C11,1))<58,CODE(RIGHT($C11,1))-48,CODE(RIGHT($C11,1))-55) -> 1 | BQ11: =MID($D11,2,2) -> 9 | BR11: =IF(BR10="","",BR10) -> 0 | BS11: =IF(BS10="","",BS10) | BT11: =IF(BT10="","",BT10) | BU11: =IF(BU10="","",BU10) | BV11: =IF(BV10="","",BV10)
A12: TRUE | B12: PCPU | C12: MP001 | D12: =CONCATENATE("E",MID(D11,2,2)+1) -> E10 | E12: =1000000+BP12*1000+BQ12 -> 1001010 | F12: =CONCATENATE(C12,"_",D12) -> MP001_E10 | G12: Bin1 | H12: =H11-15 -> 715 | I12: =I11 -> 80 | J12: =INDEX(Notes!$A$36:$N$47,MATCH(Binning!$B12,Notes!$A$36:$A$47,0),MATCH(Notes!$K$35,Notes!$A$35:$N$35,0)) -> 653.6 | L12: =L11 -> 640 | M12: =M11 -> 480 | N12: =INDEX(GB!$A$2:$AD$96,MATCH($C12,GB!$A$2:$A$96,0),MATCH(N$2,GB!$A$1:$AD$1,0)) -> 90 | O12: =INDEX(GB!$A$2:$AD$96,MATCH($C12,GB!$A$2:$A$96,0),MATCH(O$2,GB!$A$1:$AD$1,0)) -> 95 | P12: =INDEX(GB!$A$2:$AD$96,MATCH($C12,GB!$A$2:$A$96,0),MATCH(P$2,GB!$A$1:$AD$1,0)) -> 70 | Q12: =INDEX(GB!$A$2:$AD$96,MATCH($C12,GB!$A$2:$A$96,0),MATCH(Q$2,GB!$A$1:$AD$1,0)) -> 80 | R12: =INDEX(Notes!$A$36:$N$47,MATCH(Binning!$B12,Notes!$A$36:$A$47,0),MATCH(Notes!$M$35,Notes!$A$35:$N$35,0)) -> 7866 | T12: =INDEX(GB!$A$2:$AD$96,MATCH($C12,GB!$A$2:$A$96,0),MATCH(T$2,GB!$A$1:$AD$1,0)) -> 70 | U12: =INDEX(GB!$A$2:$AD$96,MATCH($C12,GB!$A$2:$A$96,0),MATCH(U$2,GB!$A$1:$AD$1,0)) -> 0 | V12: =INDEX(GB!$A$2:$AD$96,MATCH($C12,GB!$A$2:$A$96,0),MATCH(V$2,GB!$A$1:$AD$1,0)) -> 0 | W12: =INDEX(GB!$A$2:$AD$96,MATCH($C12,GB!$A$2:$A$96,0),MATCH(W$2,GB!$A$1:$AD$1,0)) -> 45 | X12: =INDEX(GB!$A$2:$AD$96,MATCH($C12,GB!$A$2:$A$96,0),MATCH(X$2,GB!$A$1:$AD$1,0)) -> 55 | Y12: 5 | Z12: 1250 | AA12: 400 | AF12: =AF11 -> 0 | AI12: =IF($BR12=1,BS12,"") | AJ12: =IF($BR12=1,BT12,"") | AK12: =IF($BR12=1,BU12,"") | AL12: =IF($BR12=1,BV12,"") | AM12: =IF($BR12=1,"YES","") | AT12: =B12 -> PCPU | AU12: =J12 -> 653.6 | AX12: =L12+N12 -> 730 | AY12: =M12+N12 -> 570 | AZ12: =INDEX(Notes!$A$36:$O$47,MATCH($B12,Notes!A$36:A$47,0),MATCH(AZ$2,Notes!A$35:O$35,0)) -> 594.18522 | BA12: =MAX(MIN(Y12*FLOOR((H12-I12*LOG10(AZ12))/Y12,1),L12),M12) -> 490 | BB12: =BA12+N12 -> 580 | BC12: =MAX(MIN(Y12*FLOOR((H12-I12*LOG10(J12))/Y12,1),L12),M12) -> 485 | BD12: =BC12+N12 -> 575 | BO12: =BO11 -> 653.6 | BP12: =IF(CODE(RIGHT($C12,1))<58,CODE(RIGHT($C12,1))-48,CODE(RIGHT($C12,1))-55) -> 1 | BQ12: =MID($D12,2,2) -> 10 | BR12: =IF(BR11="","",BR11) -> 0 | BS12: =IF(BS11="","",BS11) | BT12: =IF(BT11="","",BT11) | BU12: =IF(BU11="","",BU11) | BV12: =IF(BV11="","",BV11)
A13: TRUE | B13: PCPU | C13: MP001 | D13: =CONCATENATE("E",MID(D12,2,2)+1) -> E11 | E13: =1000000+BP13*1000+BQ13 -> 1001011 | F13: =CONCATENATE(C13,"_",D13) -> MP001_E11 | G13: Bin1 | H13: =H12-15 -> 700 | I13: =I12 -> 80 | J13: =INDEX(Notes!$A$36:$N$47,MATCH(Binning!$B13,Notes!$A$36:$A$47,0),MATCH(Notes!$K$35,Notes!$A$35:$N$35,0)) -> 653.6 | L13: =L12 -> 640 | M13: =M12 -> 480 | N13: =INDEX(GB!$A$2:$AD$96,MATCH($C13,GB!$A$2:$A$96,0),MATCH(N$2,GB!$A$1:$AD$1,0)) -> 90 | O13: =INDEX(GB!$A$2:$AD$96,MATCH($C13,GB!$A$2:$A$96,0),MATCH(O$2,GB!$A$1:$AD$1,0)) -> 95 | P13: =INDEX(GB!$A$2:$AD$96,MATCH($C13,GB!$A$2:$A$96,0),MATCH(P$2,GB!$A$1:$AD$1,0)) -> 70 | Q13: =INDEX(GB!$A$2:$AD$96,MATCH($C13,GB!$A$2:$A$96,0),MATCH(Q$2,GB!$A$1:$AD$1,0)) -> 80 | R13: =INDEX(Notes!$A$36:$N$47,MATCH(Binning!$B13,Notes!$A$36:$A$47,0),MATCH(Notes!$M$35,Notes!$A$35:$N$35,0)) -> 7866 | T13: =INDEX(GB!$A$2:$AD$96,MATCH($C13,GB!$A$2:$A$96,0),MATCH(T$2,GB!$A$1:$AD$1,0)) -> 70 | U13: =INDEX(GB!$A$2:$AD$96,MATCH($C13,GB!$A$2:$A$96,0),MATCH(U$2,GB!$A$1:$AD$1,0)) -> 0 | V13: =INDEX(GB!$A$2:$AD$96,MATCH($C13,GB!$A$2:$A$96,0),MATCH(V$2,GB!$A$1:$AD$1,0)) -> 0 | W13: =INDEX(GB!$A$2:$AD$96,MATCH($C13,GB!$A$2:$A$96,0),MATCH(W$2,GB!$A$1:$AD$1,0)) -> 45 | X13: =INDEX(GB!$A$2:$AD$96,MATCH($C13,GB!$A$2:$A$96,0),MATCH(X$2,GB!$A$1:$AD$1,0)) -> 55 | Y13: 5 | Z13: 1250 | AA13: 400 | AF13: =AF12 -> 0 | AI13: =IF($BR13=1,BS13,"") | AJ13: =IF($BR13=1,BT13,"") | AK13: =IF($BR13=1,BU13,"") | AL13: =IF($BR13=1,BV13,"") | AM13: =IF($BR13=1,"YES","") | AT13: =B13 -> PCPU | AU13: =J13 -> 653.6 | AX13: =L13+N13 -> 730 | AY13: =M13+N13 -> 570 | AZ13: =INDEX(Notes!$A$36:$O$47,MATCH($B13,Notes!A$36:A$47,0),MATCH(AZ$2,Notes!A$35:O$35,0)) -> 594.18522 | BA13: =MAX(MIN(Y13*FLOOR((H13-I13*LOG10(AZ13))/Y13,1),L13),M13) -> 480 | BB13: =BA13+N13 -> 570 | BC13: =MAX(MIN(Y13*FLOOR((H13-I13*LOG10(J13))/Y13,1),L13),M13) -> 480 | BD13: =BC13+N13 -> 570 | BO13: =BO12 -> 653.6 | BP13: =IF(CODE(RIGHT($C13,1))<58,CODE(RIGHT($C13,1))-48,CODE(RIGHT($C13,1))-55) -> 1 | BQ13: =MID($D13,2,2) -> 11 | BR13: =IF(BR12="","",BR12) -> 0 | BS13: =IF(BS12="","",BS12) | BT13: =IF(BT12="","",BT12) | BU13: =IF(BU12="","",BU12) | BV13: =IF(BV12="","",BV12)
A14: TRUE | B14: PCPU | C14: MP001 | D14: =CONCATENATE("E",MID(D13,2,2)+1) -> E12 | E14: =1000000+BP14*1000+BQ14 -> 1001012 | F14: =CONCATENATE(C14,"_",D14) -> MP001_E12 | G14: Bin1 | H14: =H13-15 -> 685 | I14: =I13 -> 80 | J14: =INDEX(Notes!$A$36:$N$47,MATCH(Binning!$B14,Notes!$A$36:$A$47,0),MATCH(Notes!$K$35,Notes!$A$35:$N$35,0)) -> 653.6 | L14: =L13 -> 640 | M14: =M13 -> 480 | N14: =INDEX(GB!$A$2:$AD$96,MATCH($C14,GB!$A$2:$A$96,0),MATCH(N$2,GB!$A$1:$AD$1,0)) -> 90 | O14: =INDEX(GB!$A$2:$AD$96,MATCH($C14,GB!$A$2:$A$96,0),MATCH(O$2,GB!$A$1:$AD$1,0)) -> 95 | P14: =INDEX(GB!$A$2:$AD$96,MATCH($C14,GB!$A$2:$A$96,0),MATCH(P$2,GB!$A$1:$AD$1,0)) -> 70 | Q14: =INDEX(GB!$A$2:$AD$96,MATCH($C14,GB!$A$2:$A$96,0),MATCH(Q$2,GB!$A$1:$AD$1,0)) -> 80 | R14: =INDEX(Notes!$A$36:$N$47,MATCH(Binning!$B14,Notes!$A$36:$A$47,0),MATCH(Notes!$M$35,Notes!$A$35:$N$35,0)) -> 7866 | T14: =INDEX(GB!$A$2:$AD$96,MATCH($C14,GB!$A$2:$A$96,0),MATCH(T$2,GB!$A$1:$AD$1,0)) -> 70 | U14: =INDEX(GB!$A$2:$AD$96,MATCH($C14,GB!$A$2:$A$96,0),MATCH(U$2,GB!$A$1:$AD$1,0)) -> 0 | V14: =INDEX(GB!$A$2:$AD$96,MATCH($C14,GB!$A$2:$A$96,0),MATCH(V$2,GB!$A$1:$AD$1,0)) -> 0 | W14: =INDEX(GB!$A$2:$AD$96,MATCH($C14,GB!$A$2:$A$96,0),MATCH(W$2,GB!$A$1:$AD$1,0)) -> 45 | X14: =INDEX(GB!$A$2:$AD$96,MATCH($C14,GB!$A$2:$A$96,0),MATCH(X$2,GB!$A$1:$AD$1,0)) -> 55 | Y14: 5 | Z14: 1250 | AA14: 400 | AF14: =AF13 -> 0 | AI14: =IF($BR14=1,BS14,"") | AJ14: =IF($BR14=1,BT14,"") | AK14: =IF($BR14=1,BU14,"") | AL14: =IF($BR14=1,BV14,"") | AM14: =IF($BR14=1,"YES","") | AT14: =B14 -> PCPU | AU14: =J14 -> 653.6 | AX14: =L14+N14 -> 730 | AY14: =M14+N14 -> 570 | AZ14: =INDEX(Notes!$A$36:$O$47,MATCH($B14,Notes!A$36:A$47,0),MATCH(AZ$2,Notes!A$35:O$35,0)) -> 594.18522 | BA14: =MAX(MIN(Y14*FLOOR((H14-I14*LOG10(AZ14))/Y14,1),L14),M14) -> 480 | BB14: =BA14+N14 -> 570 | BC14: =MAX(MIN(Y14*FLOOR((H14-I14*LOG10(J14))/Y14,1),L14),M14) -> 480 | BD14: =BC14+N14 -> 570 | BO14: =BO13 -> 653.6 | BP14: =IF(CODE(RIGHT($C14,1))<58,CODE(RIGHT($C14,1))-48,CODE(RIGHT($C14,1))-55) -> 1 | BQ14: =MID($D14,2,2) -> 12 | BR14: =IF(BR13="","",BR13) -> 0 | BS14: =IF(BS13="","",BS13) | BT14: =IF(BT13="","",BT13) | BU14: =IF(BU13="","",BU13) | BV14: =IF(BV13="","",BV13)
A15: TRUE | B15: PCPU | C15: MP002 | D15: E1 | E15: =1000000+BP15*1000+BQ15 -> 1002001 | F15: =CONCATENATE(C15,"_",D15) -> MP002_E1 | G15: Bin1 | H15: =VLOOKUP(C15,BinningParamNotes!A:D,3,0) -> 885 | I15: =VLOOKUP(C15,BinningParamNotes!A:D,2,0) -> 85 | J15: =INDEX(Notes!$A$36:$N$47,MATCH(Binning!$B15,Notes!$A$36:$A$47,0),MATCH(Notes!$K$35,Notes!$A$35:$N$35,0)) -> 653.6 | L15: =VLOOKUP(C15,BinningParamNotes!A:D,4,0) -> 685 | M15: 495 | N15: =INDEX(GB!$A$2:$AD$96,MATCH($C15,GB!$A$2:$A$96,0),MATCH(N$2,GB!$A$1:$AD$1,0)) -> 80 | O15: =INDEX(GB!$A$2:$AD$96,MATCH($C15,GB!$A$2:$A$96,0),MATCH(O$2,GB!$A$1:$AD$1,0)) -> 60 | P15: =INDEX(GB!$A$2:$AD$96,MATCH($C15,GB!$A$2:$A$96,0),MATCH(P$2,GB!$A$1:$AD$1,0)) -> 70 | Q15: =INDEX(GB!$A$2:$AD$96,MATCH($C15,GB!$A$2:$A$96,0),MATCH(Q$2,GB!$A$1:$AD$1,0)) -> 60 | R15: =INDEX(Notes!$A$36:$N$47,MATCH(Binning!$B15,Notes!$A$36:$A$47,0),MATCH(Notes!$M$35,Notes!$A$35:$N$35,0)) -> 7866 | T15: =INDEX(GB!$A$2:$AD$96,MATCH($C15,GB!$A$2:$A$96,0),MATCH(T$2,GB!$A$1:$AD$1,0)) -> 65 | U15: =INDEX(GB!$A$2:$AD$96,MATCH($C15,GB!$A$2:$A$96,0),MATCH(U$2,GB!$A$1:$AD$1,0)) -> 0 | V15: =INDEX(GB!$A$2:$AD$96,MATCH($C15,GB!$A$2:$A$96,0),MATCH(V$2,GB!$A$1:$AD$1,0)) -> 0 | W15: =INDEX(GB!$A$2:$AD$96,MATCH($C15,GB!$A$2:$A$96,0),MATCH(W$2,GB!$A$1:$AD$1,0)) -> 45 | X15: =INDEX(GB!$A$2:$AD$96,MATCH($C15,GB!$A$2:$A$96,0),MATCH(X$2,GB!$A$1:$AD$1,0)) -> 35 | Y15: 5 | Z15: 1250 | AA15: 400 | AF15: 5 | AI15: =IF($BR15=1,BS15,"") | AJ15: =IF($BR15=1,BT15,"") | AK15: =IF($BR15=1,BU15,"") | AL15: =IF($BR15=1,BV15,"") | AM15: =IF($BR15=1,"YES","") | AT15: =B15 -> PCPU | AU15: =J15 -> 653.6 | AX15: =L15+N15 -> 765 | AY15: =M15+N15 -> 575 | AZ15: =INDEX(Notes!$A$36:$O$47,MATCH($B15,Notes!A$36:A$47,0),MATCH(AZ$2,Notes!A$35:O$35,0)) -> 594.18522 | BA15: =MAX(MIN(Y15*FLOOR((H15-I15*LOG10(AZ15))/Y15,1),L15),M15) -> 645 | BB15: =BA15+N15 -> 725 | BC15: =MAX(MIN(Y15*FLOOR((H15-I15*LOG10(J15))/Y15,1),L15),M15) -> 645 | BD15: =BC15+N15 -> 725 | BO15: =MAX(J15:J21) -> 653.6 | BP15: =IF(CODE(RIGHT($C15,1))<58,CODE(RIGHT($C15,1))-48,CODE(RIGHT($C15,1))-55) -> 2 | BQ15: =MID($D15,2,2) -> 1 | BR15: 0
A16: TRUE | B16: PCPU | C16: MP002 | D16: =CONCATENATE("E",MID(D15,2,2)+1) -> E2 | E16: =1000000+BP16*1000+BQ16 -> 1002002 | F16: =CONCATENATE(C16,"_",D16) -> MP002_E2 | G16: Bin1 | H16: =H15-15 -> 870 | I16: =I15 -> 85 | J16: =INDEX(Notes!$A$36:$N$47,MATCH(Binning!$B16,Notes!$A$36:$A$47,0),MATCH(Notes!$K$35,Notes!$A$35:$N$35,0)) -> 653.6 | L16: =L15-10 -> 675 | M16: =M15 -> 495 | N16: =INDEX(GB!$A$2:$AD$96,MATCH($C16,GB!$A$2:$A$96,0),MATCH(N$2,GB!$A$1:$AD$1,0)) -> 80 | O16: =INDEX(GB!$A$2:$AD$96,MATCH($C16,GB!$A$2:$A$96,0),MATCH(O$2,GB!$A$1:$AD$1,0)) -> 60 | P16: =INDEX(GB!$A$2:$AD$96,MATCH($C16,GB!$A$2:$A$96,0),MATCH(P$2,GB!$A$1:$AD$1,0)) -> 70 | Q16: =INDEX(GB!$A$2:$AD$96,MATCH($C16,GB!$A$2:$A$96,0),MATCH(Q$2,GB!$A$1:$AD$1,0)) -> 60 | R16: =INDEX(Notes!$A$36:$N$47,MATCH(Binning!$B16,Notes!$A$36:$A$47,0),MATCH(Notes!$M$35,Notes!$A$35:$N$35,0)) -> 7866 | T16: =INDEX(GB!$A$2:$AD$96,MATCH($C16,GB!$A$2:$A$96,0),MATCH(T$2,GB!$A$1:$AD$1,0)) -> 65 | U16: =INDEX(GB!$A$2:$AD$96,MATCH($C16,GB!$A$2:$A$96,0),MATCH(U$2,GB!$A$1:$AD$1,0)) -> 0 | V16: =INDEX(GB!$A$2:$AD$96,MATCH($C16,GB!$A$2:$A$96,0),MATCH(V$2,GB!$A$1:$AD$1,0)) -> 0 | W16: =INDEX(GB!$A$2:$AD$96,MATCH($C16,GB!$A$2:$A$96,0),MATCH(W$2,GB!$A$1:$AD$1,0)) -> 45 | X16: =INDEX(GB!$A$2:$AD$96,MATCH($C16,GB!$A$2:$A$96,0),MATCH(X$2,GB!$A$1:$AD$1,0)) -> 35 | Y16: 5 | Z16: 1250 | AA16: 400 | AF16: =AF15 -> 5 | AI16: =IF($BR16=1,BS16,"") | AJ16: =IF($BR16=1,BT16,"") | AK16: =IF($BR16=1,BU16,"") | AL16: =IF($BR16=1,BV16,"") | AM16: =IF($BR16=1,"YES","") | AT16: =B16 -> PCPU | AU16: =J16 -> 653.6 | AX16: =L16+N16 -> 755 | AY16: =M16+N16 -> 575 | AZ16: =INDEX(Notes!$A$36:$O$47,MATCH($B16,Notes!A$36:A$47,0),MATCH(AZ$2,Notes!A$35:O$35,0)) -> 594.18522 | BA16: =MAX(MIN(Y16*FLOOR((H16-I16*LOG10(AZ16))/Y16,1),L16),M16) -> 630 | BB16: =BA16+N16 -> 710 | BC16: =MAX(MIN(Y16*FLOOR((H16-I16*LOG10(J16))/Y16,1),L16),M16) -> 630 | BD16: =BC16+N16 -> 710 | BO16: =BO15 -> 653.6 | BP16: =IF(CODE(RIGHT($C16,1))<58,CODE(RIGHT($C16,1))-48,CODE(RIGHT($C16,1))-55) -> 2 | BQ16: =MID($D16,2,2) -> 2 | BR16: =IF(BR15="","",BR15) -> 0 | BS16: =IF(BS15="","",BS15) | BT16: =IF(BT15="","",BT15) | BU16: =IF(BU15="","",BU15) | BV16: =IF(BV15="","",BV15)
A17: TRUE | B17: PCPU | C17: MP002 | D17: =CONCATENATE("E",MID(D16,2,2)+1) -> E3 | E17: =1000000+BP17*1000+BQ17 -> 1002003 | F17: =CONCATENATE(C17,"_",D17) -> MP002_E3 | G17: Bin1 | H17: =H16-15 -> 855 | I17: =I16 -> 85 | J17: =INDEX(Notes!$A$36:$N$47,MATCH(Binning!$B17,Notes!$A$36:$A$47,0),MATCH(Notes!$K$35,Notes!$A$35:$N$35,0)) -> 653.6 | L17: =L16-10 -> 665 | M17: =M16 -> 495 | N17: =INDEX(GB!$A$2:$AD$96,MATCH($C17,GB!$A$2:$A$96,0),MATCH(N$2,GB!$A$1:$AD$1,0)) -> 80 | O17: =INDEX(GB!$A$2:$AD$96,MATCH($C17,GB!$A$2:$A$96,0),MATCH(O$2,GB!$A$1:$AD$1,0)) -> 60 | P17: =INDEX(GB!$A$2:$AD$96,MATCH($C17,GB!$A$2:$A$96,0),MATCH(P$2,GB!$A$1:$AD$1,0)) -> 70 | Q17: =INDEX(GB!$A$2:$AD$96,MATCH($C17,GB!$A$2:$A$96,0),MATCH(Q$2,GB!$A$1:$AD$1,0)) -> 60 | R17: =INDEX(Notes!$A$36:$N$47,MATCH(Binning!$B17,Notes!$A$36:$A$47,0),MATCH(Notes!$M$35,Notes!$A$35:$N$35,0)) -> 7866 | T17: =INDEX(GB!$A$2:$AD$96,MATCH($C17,GB!$A$2:$A$96,0),MATCH(T$2,GB!$A$1:$AD$1,0)) -> 65 | U17: =INDEX(GB!$A$2:$AD$96,MATCH($C17,GB!$A$2:$A$96,0),MATCH(U$2,GB!$A$1:$AD$1,0)) -> 0 | V17: =INDEX(GB!$A$2:$AD$96,MATCH($C17,GB!$A$2:$A$96,0),MATCH(V$2,GB!$A$1:$AD$1,0)) -> 0 | W17: =INDEX(GB!$A$2:$AD$96,MATCH($C17,GB!$A$2:$A$96,0),MATCH(W$2,GB!$A$1:$AD$1,0)) -> 45 | X17: =INDEX(GB!$A$2:$AD$96,MATCH($C17,GB!$A$2:$A$96,0),MATCH(X$2,GB!$A$1:$AD$1,0)) -> 35 | Y17: 5 | Z17: 1250 | AA17: 400 | AF17: =AF16 -> 5 | AI17: =IF($BR17=1,BS17,"") | AJ17: =IF($BR17=1,BT17,"") | AK17: =IF($BR17=1,BU17,"") | AL17: =IF($BR17=1,BV17,"") | AM17: =IF($BR17=1,"YES","") | AT17: =B17 -> PCPU | AU17: =J17 -> 653.6 | AX17: =L17+N17 -> 745 | AY17: =M17+N17 -> 575 | AZ17: =INDEX(Notes!$A$36:$O$47,MATCH($B17,Notes!A$36:A$47,0),MATCH(AZ$2,Notes!A$35:O$35,0)) -> 594.18522 | BA17: =MAX(MIN(Y17*FLOOR((H17-I17*LOG10(AZ17))/Y17,1),L17),M17) -> 615 | BB17: =BA17+N17 -> 695 | BC17: =MAX(MIN(Y17*FLOOR((H17-I17*LOG10(J17))/Y17,1),L17),M17) -> 615 | BD17: =BC17+N17 -> 695 | BO17: =BO16 -> 653.6 | BP17: =IF(CODE(RIGHT($C17,1))<58,CODE(RIGHT($C17,1))-48,CODE(RIGHT($C17,1))-55) -> 2 | BQ17: =MID($D17,2,2) -> 3 | BR17: =IF(BR16="","",BR16) -> 0 | BS17: =IF(BS16="","",BS16) | BT17: =IF(BT16="","",BT16) | BU17: =IF(BU16="","",BU16) | BV17: =IF(BV16="","",BV16)
A18: TRUE | B18: PCPU | C18: MP002 | D18: =CONCATENATE("E",MID(D17,2,2)+1) -> E4 | E18: =1000000+BP18*1000+BQ18 -> 1002004 | F18: =CONCATENATE(C18,"_",D18) -> MP002_E4 | G18: Bin1 | H18: =H17-15 -> 840 | I18: =I17 -> 85 | J18: =INDEX(Notes!$A$36:$N$47,MATCH(Binning!$B18,Notes!$A$36:$A$47,0),MATCH(Notes!$K$35,Notes!$A$35:$N$35,0)) -> 653.6 | L18: =L17 -> 665 | M18: =M17 -> 495 | N18: =INDEX(GB!$A$2:$AD$96,MATCH($C18,GB!$A$2:$A$96,0),MATCH(N$2,GB!$A$1:$AD$1,0)) -> 80 | O18: =INDEX(GB!$A$2:$AD$96,MATCH($C18,GB!$A$2:$A$96,0),MATCH(O$2,GB!$A$1:$AD$1,0)) -> 60 | P18: =INDEX(GB!$A$2:$AD$96,MATCH($C18,GB!$A$2:$A$96,0),MATCH(P$2,GB!$A$1:$AD$1,0)) -> 70 | Q18: =INDEX(GB!$A$2:$AD$96,MATCH($C18,GB!$A$2:$A$96,0),MATCH(Q$2,GB!$A$1:$AD$1,0)) -> 60 | R18: =INDEX(Notes!$A$36:$N$47,MATCH(Binning!$B18,Notes!$A$36:$A$47,0),MATCH(Notes!$M$35,Notes!$A$35:$N$35,0)) -> 7866 | T18: =INDEX(GB!$A$2:$AD$96,MATCH($C18,GB!$A$2:$A$96,0),MATCH(T$2,GB!$A$1:$AD$1,0)) -> 65 | U18: =INDEX(GB!$A$2:$AD$96,MATCH($C18,GB!$A$2:$A$96,0),MATCH(U$2,GB!$A$1:$AD$1,0)) -> 0 | V18: =INDEX(GB!$A$2:$AD$96,MATCH($C18,GB!$A$2:$A$96,0),MATCH(V$2,GB!$A$1:$AD$1,0)) -> 0 | W18: =INDEX(GB!$A$2:$AD$96,MATCH($C18,GB!$A$2:$A$96,0),MATCH(W$2,GB!$A$1:$AD$1,0)) -> 45 | X18: =INDEX(GB!$A$2:$AD$96,MATCH($C18,GB!$A$2:$A$96,0),MATCH(X$2,GB!$A$1:$AD$1,0)) -> 35 | Y18: 5 | Z18: 1250 | AA18: 400 | AF18: =AF17 -> 5 | AI18: =IF($BR18=1,BS18,"") | AJ18: =IF($BR18=1,BT18,"") | AK18: =IF($BR18=1,BU18,"") | AL18: =IF($BR18=1,BV18,"") | AM18: =IF($BR18=1,"YES","") | AT18: =B18 -> PCPU | AU18: =J18 -> 653.6 | AX18: =L18+N18 -> 745 | AY18: =M18+N18 -> 575 | AZ18: =INDEX(Notes!$A$36:$O$47,MATCH($B18,Notes!A$36:A$47,0),MATCH(AZ$2,Notes!A$35:O$35,0)) -> 594.18522 | BA18: =MAX(MIN(Y18*FLOOR((H18-I18*LOG10(AZ18))/Y18,1),L18),M18) -> 600 | BB18: =BA18+N18 -> 680 | BC18: =MAX(MIN(Y18*FLOOR((H18-I18*LOG10(J18))/Y18,1),L18),M18) -> 600 | BD18: =BC18+N18 -> 680 | BO18: =BO17 -> 653.6 | BP18: =IF(CODE(RIGHT($C18,1))<58,CODE(RIGHT($C18,1))-48,CODE(RIGHT($C18,1))-55) -> 2 | BQ18: =MID($D18,2,2) -> 4 | BR18: =IF(BR17="","",BR17) -> 0 | BS18: =IF(BS17="","",BS17) | BT18: =IF(BT17="","",BT17) | BU18: =IF(BU17="","",BU17) | BV18: =IF(BV17="","",BV17)
A19: TRUE | B19: PCPU | C19: MP002 | D19: =CONCATENATE("E",MID(D18,2,2)+1) -> E5 | E19: =1000000+BP19*1000+BQ19 -> 1002005 | F19: =CONCATENATE(C19,"_",D19) -> MP002_E5 | G19: Bin1 | H19: =H18-15 -> 825 | I19: =I18 -> 85 | J19: =INDEX(Notes!$A$36:$N$47,MATCH(Binning!$B19,Notes!$A$36:$A$47,0),MATCH(Notes!$K$35,Notes!$A$35:$N$35,0)) -> 653.6 | L19: =L18 -> 665 | M19: =M18 -> 495 | N19: =INDEX(GB!$A$2:$AD$96,MATCH($C19,GB!$A$2:$A$96,0),MATCH(N$2,GB!$A$1:$AD$1,0)) -> 80 | O19: =INDEX(GB!$A$2:$AD$96,MATCH($C19,GB!$A$2:$A$96,0),MATCH(O$2,GB!$A$1:$AD$1,0)) -> 60 | P19: =INDEX(GB!$A$2:$AD$96,MATCH($C19,GB!$A$2:$A$96,0),MATCH(P$2,GB!$A$1:$AD$1,0)) -> 70 | Q19: =INDEX(GB!$A$2:$AD$96,MATCH($C19,GB!$A$2:$A$96,0),MATCH(Q$2,GB!$A$1:$AD$1,0)) -> 60 | R19: =INDEX(Notes!$A$36:$N$47,MATCH(Binning!$B19,Notes!$A$36:$A$47,0),MATCH(Notes!$M$35,Notes!$A$35:$N$35,0)) -> 7866 | T19: =INDEX(GB!$A$2:$AD$96,MATCH($C19,GB!$A$2:$A$96,0),MATCH(T$2,GB!$A$1:$AD$1,0)) -> 65 | U19: =INDEX(GB!$A$2:$AD$96,MATCH($C19,GB!$A$2:$A$96,0),MATCH(U$2,GB!$A$1:$AD$1,0)) -> 0 | V19: =INDEX(GB!$A$2:$AD$96,MATCH($C19,GB!$A$2:$A$96,0),MATCH(V$2,GB!$A$1:$AD$1,0)) -> 0 | W19: =INDEX(GB!$A$2:$AD$96,MATCH($C19,GB!$A$2:$A$96,0),MATCH(W$2,GB!$A$1:$AD$1,0)) -> 45 | X19: =INDEX(GB!$A$2:$AD$96,MATCH($C19,GB!$A$2:$A$96,0),MATCH(X$2,GB!$A$1:$AD$1,0)) -> 35 | Y19: 5 | Z19: 1250 | AA19: 400 | AF19: =AF18 -> 5 | AI19: =IF($BR19=1,BS19,"") | AJ19: =IF($BR19=1,BT19,"") | AK19: =IF($BR19=1,BU19,"") | AL19: =IF($BR19=1,BV19,"") | AM19: =IF($BR19=1,"YES","") | AT19: =B19 -> PCPU | AU19: =J19 -> 653.6 | AX19: =L19+N19 -> 745 | AY19: =M19+N19 -> 575 | AZ19: =INDEX(Notes!$A$36:$O$47,MATCH($B19,Notes!A$36:A$47,0),MATCH(AZ$2,Notes!A$35:O$35,0)) -> 594.18522 | BA19: =MAX(MIN(Y19*FLOOR((H19-I19*LOG10(AZ19))/Y19,1),L19),M19) -> 585 | BB19: =BA19+N19 -> 665 | BC19: =MAX(MIN(Y19*FLOOR((H19-I19*LOG10(J19))/Y19,1),L19),M19) -> 585 | BD19: =BC19+N19 -> 665 | BO19: =BO18 -> 653.6 | BP19: =IF(CODE(RIGHT($C19,1))<58,CODE(RIGHT($C19,1))-48,CODE(RIGHT($C19,1))-55) -> 2 | BQ19: =MID($D19,2,2) -> 5 | BR19: =IF(BR18="","",BR18) -> 0 | BS19: =IF(BS18="","",BS18) | BT19: =IF(BT18="","",BT18) | BU19: =IF(BU18="","",BU18) | BV19: =IF(BV18="","",BV18)
A20: TRUE | B20: PCPU | C20: MP002 | D20: =CONCATENATE("E",MID(D19,2,2)+1) -> E6 | E20: =1000000+BP20*1000+BQ20 -> 1002006 | F20: =CONCATENATE(C20,"_",D20) -> MP002_E6 | G20: Bin1 | H20: =H19-15 -> 810 | I20: =I19 -> 85 | J20: =INDEX(Notes!$A$36:$N$47,MATCH(Binning!$B20,Notes!$A$36:$A$47,0),MATCH(Notes!$K$35,Notes!$A$35:$N$35,0)) -> 653.6 | L20: =L19 -> 665 | M20: =M19 -> 495 | N20: =INDEX(GB!$A$2:$AD$96,MATCH($C20,GB!$A$2:$A$96,0),MATCH(N$2,GB!$A$1:$AD$1,0)) -> 80 | O20: =INDEX(GB!$A$2:$AD$96,MATCH($C20,GB!$A$2:$A$96,0),MATCH(O$2,GB!$A$1:$AD$1,0)) -> 60 | P20: =INDEX(GB!$A$2:$AD$96,MATCH($C20,GB!$A$2:$A$96,0),MATCH(P$2,GB!$A$1:$AD$1,0)) -> 70 | Q20: =INDEX(GB!$A$2:$AD$96,MATCH($C20,GB!$A$2:$A$96,0),MATCH(Q$2,GB!$A$1:$AD$1,0)) -> 60 | R20: =INDEX(Notes!$A$36:$N$47,MATCH(Binning!$B20,Notes!$A$36:$A$47,0),MATCH(Notes!$M$35,Notes!$A$35:$N$35,0)) -> 7866 | T20: =INDEX(GB!$A$2:$AD$96,MATCH($C20,GB!$A$2:$A$96,0),MATCH(T$2,GB!$A$1:$AD$1,0)) -> 65 | U20: =INDEX(GB!$A$2:$AD$96,MATCH($C20,GB!$A$2:$A$96,0),MATCH(U$2,GB!$A$1:$AD$1,0)) -> 0 | V20: =INDEX(GB!$A$2:$AD$96,MATCH($C20,GB!$A$2:$A$96,0),MATCH(V$2,GB!$A$1:$AD$1,0)) -> 0 | W20: =INDEX(GB!$A$2:$AD$96,MATCH($C20,GB!$A$2:$A$96,0),MATCH(W$2,GB!$A$1:$AD$1,0)) -> 45 | X20: =INDEX(GB!$A$2:$AD$96,MATCH($C20,GB!$A$2:$A$96,0),MATCH(X$2,GB!$A$1:$AD$1,0)) -> 35 | Y20: 5 | Z20: 1250 | AA20: 400 | AF20: =AF19 -> 5 | AI20: =IF($BR20=1,BS20,"") | AJ20: =IF($BR20=1,BT20,"") | AK20: =IF($BR20=1,BU20,"") | AL20: =IF($BR20=1,BV20,"") | AM20: =IF($BR20=1,"YES","") | AT20: =B20 -> PCPU | AU20: =J20 -> 653.6 | AX20: =L20+N20 -> 745 | AY20: =M20+N20 -> 575 | AZ20: =INDEX(Notes!$A$36:$O$47,MATCH($B20,Notes!A$36:A$47,0),MATCH(AZ$2,Notes!A$35:O$35,0)) -> 594.18522 | BA20: =MAX(MIN(Y20*FLOOR((H20-I20*LOG10(AZ20))/Y20,1),L20),M20) -> 570 | BB20: =BA20+N20 -> 650 | BC20: =MAX(MIN(Y20*FLOOR((H20-I20*LOG10(J20))/Y20,1),L20),M20) -> 570 | BD20: =BC20+N20 -> 650 | BO20: =BO19 -> 653.6 | BP20: =IF(CODE(RIGHT($C20,1))<58,CODE(RIGHT($C20,1))-48,CODE(RIGHT($C20,1))-55) -> 2 | BQ20: =MID($D20,2,2) -> 6 | BR20: =IF(BR19="","",BR19) -> 0 | BS20: =IF(BS19="","",BS19) | BT20: =IF(BT19="","",BT19) | BU20: =IF(BU19="","",BU19) | BV20: =IF(BV19="","",BV19)
A21: TRUE | B21: PCPU | C21: MP002 | D21: =CONCATENATE("E",MID(D20,2,2)+1) -> E7 | E21: =1000000+BP21*1000+BQ21 -> 1002007 | F21: =CONCATENATE(C21,"_",D21) -> MP002_E7 | G21: Bin1 | H21: =H20-15 -> 795 | I21: =I20 -> 85 | J21: =INDEX(Notes!$A$36:$N$47,MATCH(Binning!$B21,Notes!$A$36:$A$47,0),MATCH(Notes!$K$35,Notes!$A$35:$N$35,0)) -> 653.6 | L21: =L20 -> 665 | M21: =M20 -> 495 | N21: =INDEX(GB!$A$2:$AD$96,MATCH($C21,GB!$A$2:$A$96,0),MATCH(N$2,GB!$A$1:$AD$1,0)) -> 80 | O21: =INDEX(GB!$A$2:$AD$96,MATCH($C21,GB!$A$2:$A$96,0),MATCH(O$2,GB!$A$1:$AD$1,0)) -> 60 | P21: =INDEX(GB!$A$2:$AD$96,MATCH($C21,GB!$A$2:$A$96,0),MATCH(P$2,GB!$A$1:$AD$1,0)) -> 70 | Q21: =INDEX(GB!$A$2:$AD$96,MATCH($C21,GB!$A$2:$A$96,0),MATCH(Q$2,GB!$A$1:$AD$1,0)) -> 60 | R21: =INDEX(Notes!$A$36:$N$47,MATCH(Binning!$B21,Notes!$A$36:$A$47,0),MATCH(Notes!$M$35,Notes!$A$35:$N$35,0)) -> 7866 | T21: =INDEX(GB!$A$2:$AD$96,MATCH($C21,GB!$A$2:$A$96,0),MATCH(T$2,GB!$A$1:$AD$1,0)) -> 65 | U21: =INDEX(GB!$A$2:$AD$96,MATCH($C21,GB!$A$2:$A$96,0),MATCH(U$2,GB!$A$1:$AD$1,0)) -> 0 | V21: =INDEX(GB!$A$2:$AD$96,MATCH($C21,GB!$A$2:$A$96,0),MATCH(V$2,GB!$A$1:$AD$1,0)) -> 0 | W21: =INDEX(GB!$A$2:$AD$96,MATCH($C21,GB!$A$2:$A$96,0),MATCH(W$2,GB!$A$1:$AD$1,0)) -> 45 | X21: =INDEX(GB!$A$2:$AD$96,MATCH($C21,GB!$A$2:$A$96,0),MATCH(X$2,GB!$A$1:$AD$1,0)) -> 35 | Y21: 5 | Z21: 1250 | AA21: 400 | AF21: =AF20 -> 5 | AI21: =IF($BR21=1,BS21,"") | AJ21: =IF($BR21=1,BT21,"") | AK21: =IF($BR21=1,BU21,"") | AL21: =IF($BR21=1,BV21,"") | AM21: =IF($BR21=1,"YES","") | AT21: =B21 -> PCPU | AU21: =J21 -> 653.6 | AX21: =L21+N21 -> 745 | AY21: =M21+N21 -> 575 | AZ21: =INDEX(Notes!$A$36:$O$47,MATCH($B21,Notes!A$36:A$47,0),MATCH(AZ$2,Notes!A$35:O$35,0)) -> 594.18522 | BA21: =MAX(MIN(Y21*FLOOR((H21-I21*LOG10(AZ21))/Y21,1),L21),M21) -> 555 | BB21: =BA21+N21 -> 635 | BC21: =MAX(MIN(Y21*FLOOR((H21-I21*LOG10(J21))/Y21,1),L21),M21) -> 555 | BD21: =BC21+N21 -> 635 | BO21: =BO20 -> 653.6 | BP21: =IF(CODE(RIGHT($C21,1))<58,CODE(RIGHT($C21,1))-48,CODE(RIGHT($C21,1))-55) -> 2 | BQ21: =MID($D21,2,2) -> 7 | BR21: =IF(BR20="","",BR20) -> 0 | BS21: =IF(BS20="","",BS20) | BT21: =IF(BT20="","",BT20) | BU21: =IF(BU20="","",BU20) | BV21: =IF(BV20="","",BV20)
A22: TRUE | B22: PCPU | C22: MP002 | D22: =CONCATENATE("E",MID(D21,2,2)+1) -> E8 | E22: =1000000+BP22*1000+BQ22 -> 1002008 | F22: =CONCATENATE(C22,"_",D22) -> MP002_E8 | G22: Bin1 | H22: =H21-15 -> 780 | I22: =I21 -> 85 | J22: =INDEX(Notes!$A$36:$N$47,MATCH(Binning!$B22,Notes!$A$36:$A$47,0),MATCH(Notes!$K$35,Notes!$A$35:$N$35,0)) -> 653.6 | L22: =L21 -> 665 | M22: =M21 -> 495 | N22: =INDEX(GB!$A$2:$AD$96,MATCH($C22,GB!$A$2:$A$96,0),MATCH(N$2,GB!$A$1:$AD$1,0)) -> 80 | O22: =INDEX(GB!$A$2:$AD$96,MATCH($C22,GB!$A$2:$A$96,0),MATCH(O$2,GB!$A$1:$AD$1,0)) -> 60 | P22: =INDEX(GB!$A$2:$AD$96,MATCH($C22,GB!$A$2:$A$96,0),MATCH(P$2,GB!$A$1:$AD$1,0)) -> 70 | Q22: =INDEX(GB!$A$2:$AD$96,MATCH($C22,GB!$A$2:$A$96,0),MATCH(Q$2,GB!$A$1:$AD$1,0)) -> 60 | R22: =INDEX(Notes!$A$36:$N$47,MATCH(Binning!$B22,Notes!$A$36:$A$47,0),MATCH(Notes!$M$35,Notes!$A$35:$N$35,0)) -> 7866 | T22: =INDEX(GB!$A$2:$AD$96,MATCH($C22,GB!$A$2:$A$96,0),MATCH(T$2,GB!$A$1:$AD$1,0)) -> 65 | U22: =INDEX(GB!$A$2:$AD$96,MATCH($C22,GB!$A$2:$A$96,0),MATCH(U$2,GB!$A$1:$AD$1,0)) -> 0 | V22: =INDEX(GB!$A$2:$AD$96,MATCH($C22,GB!$A$2:$A$96,0),MATCH(V$2,GB!$A$1:$AD$1,0)) -> 0 | W22: =INDEX(GB!$A$2:$AD$96,MATCH($C22,GB!$A$2:$A$96,0),MATCH(W$2,GB!$A$1:$AD$1,0)) -> 45 | X22: =INDEX(GB!$A$2:$AD$96,MATCH($C22,GB!$A$2:$A$96,0),MATCH(X$2,GB!$A$1:$AD$1,0)) -> 35 | Y22: 5 | Z22: 1250 | AA22: 400 | AF22: =AF21 -> 5 | AI22: =IF($BR22=1,BS22,"") | AJ22: =IF($BR22=1,BT22,"") | AK22: =IF($BR22=1,BU22,"") | AL22: =IF($BR22=1,BV22,"") | AM22: =IF($BR22=1,"YES","") | AT22: =B22 -> PCPU | AU22: =J22 -> 653.6 | AX22: =L22+N22 -> 745 | AY22: =M22+N22 -> 575 | AZ22: =INDEX(Notes!$A$36:$O$47,MATCH($B22,Notes!A$36:A$47,0),MATCH(AZ$2,Notes!A$35:O$35,0)) -> 594.18522 | BA22: =MAX(MIN(Y22*FLOOR((H22-I22*LOG10(AZ22))/Y22,1),L22),M22) -> 540 | BB22: =BA22+N22 -> 620 | BC22: =MAX(MIN(Y22*FLOOR((H22-I22*LOG10(J22))/Y22,1),L22),M22) -> 540 | BD22: =BC22+N22 -> 620 | BO22: =BO21 -> 653.6 | BP22: =IF(CODE(RIGHT($C22,1))<58,CODE(RIGHT($C22,1))-48,CODE(RIGHT($C22,1))-55) -> 2 | BQ22: =MID($D22,2,2) -> 8 | BR22: =IF(BR21="","",BR21) -> 0 | BS22: =IF(BS21="","",BS21) | BT22: =IF(BT21="","",BT21) | BU22: =IF(BU21="","",BU21) | BV22: =IF(BV21="","",BV21)
A23: TRUE | B23: PCPU | C23: MP002 | D23: =CONCATENATE("E",MID(D22,2,2)+1) -> E9 | E23: =1000000+BP23*1000+BQ23 -> 1002009 | F23: =CONCATENATE(C23,"_",D23) -> MP002_E9 | G23: Bin1 | H23: =H22-15 -> 765 | I23: =I22 -> 85 | J23: =INDEX(Notes!$A$36:$N$47,MATCH(Binning!$B23,Notes!$A$36:$A$47,0),MATCH(Notes!$K$35,Notes!$A$35:$N$35,0)) -> 653.6 | L23: =L22 -> 665 | M23: =M22 -> 495 | N23: =INDEX(GB!$A$2:$AD$96,MATCH($C23,GB!$A$2:$A$96,0),MATCH(N$2,GB!$A$1:$AD$1,0)) -> 80 | O23: =INDEX(GB!$A$2:$AD$96,MATCH($C23,GB!$A$2:$A$96,0),MATCH(O$2,GB!$A$1:$AD$1,0)) -> 60 | P23: =INDEX(GB!$A$2:$AD$96,MATCH($C23,GB!$A$2:$A$96,0),MATCH(P$2,GB!$A$1:$AD$1,0)) -> 70 | Q23: =INDEX(GB!$A$2:$AD$96,MATCH($C23,GB!$A$2:$A$96,0),MATCH(Q$2,GB!$A$1:$AD$1,0)) -> 60 | R23: =INDEX(Notes!$A$36:$N$47,MATCH(Binning!$B23,Notes!$A$36:$A$47,0),MATCH(Notes!$M$35,Notes!$A$35:$N$35,0)) -> 7866 | T23: =INDEX(GB!$A$2:$AD$96,MATCH($C23,GB!$A$2:$A$96,0),MATCH(T$2,GB!$A$1:$AD$1,0)) -> 65 | U23: =INDEX(GB!$A$2:$AD$96,MATCH($C23,GB!$A$2:$A$96,0),MATCH(U$2,GB!$A$1:$AD$1,0)) -> 0 | V23: =INDEX(GB!$A$2:$AD$96,MATCH($C23,GB!$A$2:$A$96,0),MATCH(V$2,GB!$A$1:$AD$1,0)) -> 0 | W23: =INDEX(GB!$A$2:$AD$96,MATCH($C23,GB!$A$2:$A$96,0),MATCH(W$2,GB!$A$1:$AD$1,0)) -> 45 | X23: =INDEX(GB!$A$2:$AD$96,MATCH($C23,GB!$A$2:$A$96,0),MATCH(X$2,GB!$A$1:$AD$1,0)) -> 35 | Y23: 5 | Z23: 1250 | AA23: 400 | AF23: =AF22 -> 5 | AI23: =IF($BR23=1,BS23,"") | AJ23: =IF($BR23=1,BT23,"") | AK23: =IF($BR23=1,BU23,"") | AL23: =IF($BR23=1,BV23,"") | AM23: =IF($BR23=1,"YES","") | AT23: =B23 -> PCPU | AU23: =J23 -> 653.6 | AX23: =L23+N23 -> 745 | AY23: =M23+N23 -> 575 | AZ23: =INDEX(Notes!$A$36:$O$47,MATCH($B23,Notes!A$36:A$47,0),MATCH(AZ$2,Notes!A$35:O$35,0)) -> 594.18522 | BA23: =MAX(MIN(Y23*FLOOR((H23-I23*LOG10(AZ23))/Y23,1),L23),M23) -> 525 | BB23: =BA23+N23 -> 605 | BC23: =MAX(MIN(Y23*FLOOR((H23-I23*LOG10(J23))/Y23,1),L23),M23) -> 525 | BD23: =BC23+N23 -> 605 | BO23: =BO22 -> 653.6 | BP23: =IF(CODE(RIGHT($C23,1))<58,CODE(RIGHT($C23,1))-48,CODE(RIGHT($C23,1))-55) -> 2 | BQ23: =MID($D23,2,2) -> 9 | BR23: =IF(BR22="","",BR22) -> 0 | BS23: =IF(BS22="","",BS22) | BT23: =IF(BT22="","",BT22) | BU23: =IF(BU22="","",BU22) | BV23: =IF(BV22="","",BV22)
A24: TRUE | B24: PCPU | C24: MP002 | D24: =CONCATENATE("E",MID(D23,2,2)+1) -> E10 | E24: =1000000+BP24*1000+BQ24 -> 1002010 | F24: =CONCATENATE(C24,"_",D24) -> MP002_E10 | G24: Bin1 | H24: =H23-15 -> 750 | I24: =I23 -> 85 | J24: =INDEX(Notes!$A$36:$N$47,MATCH(Binning!$B24,Notes!$A$36:$A$47,0),MATCH(Notes!$K$35,Notes!$A$35:$N$35,0)) -> 653.6 | L24: =L23 -> 665 | M24: =M23 -> 495 | N24: =INDEX(GB!$A$2:$AD$96,MATCH($C24,GB!$A$2:$A$96,0),MATCH(N$2,GB!$A$1:$AD$1,0)) -> 80 | O24: =INDEX(GB!$A$2:$AD$96,MATCH($C24,GB!$A$2:$A$96,0),MATCH(O$2,GB!$A$1:$AD$1,0)) -> 60 | P24: =INDEX(GB!$A$2:$AD$96,MATCH($C24,GB!$A$2:$A$96,0),MATCH(P$2,GB!$A$1:$AD$1,0)) -> 70 | Q24: =INDEX(GB!$A$2:$AD$96,MATCH($C24,GB!$A$2:$A$96,0),MATCH(Q$2,GB!$A$1:$AD$1,0)) -> 60 | R24: =INDEX(Notes!$A$36:$N$47,MATCH(Binning!$B24,Notes!$A$36:$A$47,0),MATCH(Notes!$M$35,Notes!$A$35:$N$35,0)) -> 7866 | T24: =INDEX(GB!$A$2:$AD$96,MATCH($C24,GB!$A$2:$A$96,0),MATCH(T$2,GB!$A$1:$AD$1,0)) -> 65 | U24: =INDEX(GB!$A$2:$AD$96,MATCH($C24,GB!$A$2:$A$96,0),MATCH(U$2,GB!$A$1:$AD$1,0)) -> 0 | V24: =INDEX(GB!$A$2:$AD$96,MATCH($C24,GB!$A$2:$A$96,0),MATCH(V$2,GB!$A$1:$AD$1,0)) -> 0 | W24: =INDEX(GB!$A$2:$AD$96,MATCH($C24,GB!$A$2:$A$96,0),MATCH(W$2,GB!$A$1:$AD$1,0)) -> 45 | X24: =INDEX(GB!$A$2:$AD$96,MATCH($C24,GB!$A$2:$A$96,0),MATCH(X$2,GB!$A$1:$AD$1,0)) -> 35 | Y24: 5 | Z24: 1250 | AA24: 400 | AF24: =AF23 -> 5 | AI24: =IF($BR24=1,BS24,"") | AJ24: =IF($BR24=1,BT24,"") | AK24: =IF($BR24=1,BU24,"") | AL24: =IF($BR24=1,BV24,"") | AM24: =IF($BR24=1,"YES","") | AT24: =B24 -> PCPU | AU24: =J24 -> 653.6 | AX24: =L24+N24 -> 745 | AY24: =M24+N24 -> 575 | AZ24: =INDEX(Notes!$A$36:$O$47,MATCH($B24,Notes!A$36:A$47,0),MATCH(AZ$2,Notes!A$35:O$35,0)) -> 594.18522 | BA24: =MAX(MIN(Y24*FLOOR((H24-I24*LOG10(AZ24))/Y24,1),L24),M24) -> 510 | BB24: =BA24+N24 -> 590 | BC24: =MAX(MIN(Y24*FLOOR((H24-I24*LOG10(J24))/Y24,1),L24),M24) -> 510 | BD24: =BC24+N24 -> 590 | BO24: =BO23 -> 653.6 | BP24: =IF(CODE(RIGHT($C24,1))<58,CODE(RIGHT($C24,1))-48,CODE(RIGHT($C24,1))-55) -> 2 | BQ24: =MID($D24,2,2) -> 10 | BR24: =IF(BR23="","",BR23) -> 0 | BS24: =IF(BS23="","",BS23) | BT24: =IF(BT23="","",BT23) | BU24: =IF(BU23="","",BU23) | BV24: =IF(BV23="","",BV23)
