Workbook

Sheet TTR Summary
B2: Single-Site | I2: Multi-Site | M2: 4 | O2: PTE
B3: IP | C3: CP1 TT (s) | D3: CP2 TT (s) | E3: FT1 TT (s) | F3: FT2 TT (s) | G3: Total (s) | I3: CP1 TT (s) | J3: CP2 TT (s) | K3: FT1 TT (s) | L3: FT2 TT (s) | M3: Total (s) | O3: CP1 | P3: CP2 | Q3: FT1 | R3: FT2
B4: IO_JTAG | C4: =ROUND(IO_JTAG!F2/1000, 2) -> 1.12 | D4: =ROUND(IO_JTAG!I2/1000, 2) -> 1.12 | E4: =ROUND(IO_JTAG!L2/1000, 2) -> 1.12 | F4: =ROUND(IO_JTAG!O2/1000, 2) -> 1.12 | G4: =SUM(C4:F4) -> 4.48 | O4: =1-(I4-C4)/((M2-1)*C4) -> 1.3333333 | P4: =1-(J4-D4)/((M2-1)*D4) -> 1.3333333 | Q4: =1-(K4-E4)/((M2-1)*E4) -> 1.3333333 | R4: =1-(L4-F4)/((M2-1)*F4) -> 1.3333333
B5: ADCDFT | C5: =ROUND(ADCDFT!F2/1000, 2) -> 0.88 | D5: =ROUND(ADCDFT!I2/1000, 2) -> 0.88 | E5: =ROUND(ADCDFT!L2/1000, 2) -> 0.88 | F5: =ROUND(ADCDFT!O2/1000, 2) -> 0.88 | G5: =SUM(C5:F5) -> 3.52 | O5: =1-(I5-C5)/((M2-1)*C5) -> 1.3333333 | P5: =1-(J5-D5)/((M2-1)*D5) -> 1.3333333 | Q5: =1-(K5-E5)/((M2-1)*E5) -> 1.3333333 | R5: =1-(L5-F5)/((M2-1)*F5) -> 1.3333333
B6: MTRICTS | C6: =ROUND(MTRICTS!F2/1000, 2) -> 7.61 | D6: =ROUND(MTRICTS!I2/1000, 2) -> 7.61 | E6: =ROUND(MTRICTS!L2/1000, 2) -> 7.61 | F6: =ROUND(MTRICTS!O2/1000, 2) -> 7.61 | G6: =SUM(C6:F6) -> 30.44 | O6: =1-(I6-C6)/((M2-1)*C6) -> 1.3333333 | P6: =1-(J6-D6)/((M2-1)*D6) -> 1.3333333 | Q6: =1-(K6-E6)/((M2-1)*E6) -> 1.3333333 | R6: =1-(L6-F6)/((M2-1)*F6) -> 1.3333333
B7: NTSE | C7: =ROUND(NTSE!F2/1000, 2) -> 4.35 | D7: =ROUND(NTSE!I2/1000, 2) -> 4.35 | E7: =ROUND(NTSE!L2/1000, 2) -> 4.35 | F7: =ROUND(NTSE!O2/1000, 2) -> 4.35 | G7: =SUM(C7:F7) -> 17.4 | O7: =1-(I7-C7)/((M2-1)*C7) -> 1.3333333 | P7: =1-(J7-D7)/((M2-1)*D7) -> 1.3333333 | Q7: =1-(K7-E7)/((M2-1)*E7) -> 1.3333333 | R7: =1-(L7-F7)/((M2-1)*F7) -> 1.3333333
B8: NTSR | C8: =ROUND(NTSR!F2/1000, 2) -> 0.26 | D8: =ROUND(NTSR!I2/1000, 2) -> 0.26 | E8: =ROUND(NTSR!L2/1000, 2) -> 0.26 | F8: =ROUND(NTSR!O2/1000, 2) -> 0.26 | G8: =SUM(C8:F8) -> 1.04 | O8: =1-(I8-C8)/((M2-1)*C8) -> 1.3333333 | P8: =1-(J8-D8)/((M2-1)*D8) -> 1.3333333 | Q8: =1-(K8-E8)/((M2-1)*E8) -> 1.3333333 | R8: =1-(L8-F8)/((M2-1)*F8) -> 1.3333333
B9: MISC | C9: =ROUND(MISC!F2/1000, 2) -> 0.37 | D9: =ROUND(MISC!I2/1000, 2) -> 0.37 | E9: =ROUND(MISC!L2/1000, 2) -> 0.37 | F9: =ROUND(MISC!O2/1000, 2) -> 0.37 | G9: =SUM(C9:F9) -> 1.48 | O9: =1-(I9-C9)/((M2-1)*C9) -> 1.3333333 | P9: =1-(J9-D9)/((M2-1)*D9) -> 1.3333333 | Q9: =1-(K9-E9)/((M2-1)*E9) -> 1.3333333 | R9: =1-(L9-F9)/((M2-1)*F9) -> 1.3333333
B10: FRO | C10: =ROUND(FRO!F2/1000, 2) -> 0.01 | D10: =ROUND(FRO!I2/1000, 2) -> 0.01 | E10: =ROUND(FRO!L2/1000, 2) -> 0.01 | F10: =ROUND(FRO!O2/1000, 2) -> 0.01 | G10: =SUM(C10:F10) -> 0.04 | O10: =1-(I10-C10)/((M2-1)*C10) -> 1.3333333 | P10: =1-(J10-D10)/((M2-1)*D10) -> 1.3333333 | Q10: =1-(K10-E10)/((M2-1)*E10) -> 1.3333333 | R10: =1-(L10-F10)/((M2-1)*F10) -> 1.3333333
B11: CPLL | C11: =ROUND(CPLL!F2/1000, 2) -> 3.47 | D11: =ROUND(CPLL!I2/1000, 2) -> 3.47 | E11: =ROUND(CPLL!L2/1000, 2) -> 3.47 | F11: =ROUND(CPLL!O2/1000, 2) -> 3.47 | G11: =SUM(C11:F11) -> 13.88 | O11: =1-(I11-C11)/((M2-1)*C11) -> 1.3333333 | P11: =1-(J11-D11)/((M2-1)*D11) -> 1.3333333 | Q11: =1-(K11-E11)/((M2-1)*E11) -> 1.3333333 | R11: =1-(L11-F11)/((M2-1)*F11) -> 1.3333333
B12: ADCLK | C12: =ROUND(ADCLK!F2/1000, 2) -> 7.79 | D12: =ROUND(ADCLK!I2/1000, 2) -> 7.79 | E12: =ROUND(ADCLK!L2/1000, 2) -> 7.79 | F12: =ROUND(ADCLK!O2/1000, 2) -> 7.79 | G12: =SUM(C12:F12) -> 31.16 | O12: =1-(I12-C12)/((M2-1)*C12) -> 1.3333333 | P12: =1-(J12-D12)/((M2-1)*D12) -> 1.3333333 | Q12: =1-(K12-E12)/((M2-1)*E12) -> 1.3333333 | R12: =1-(L12-F12)/((M2-1)*F12) -> 1.3333333
B13: LAPLL | C13: =ROUND(LAPLL!F2/1000, 2) -> 4.58 | D13: =ROUND(LAPLL!I2/1000, 2) -> 4.58 | E13: =ROUND(LAPLL!L2/1000, 2) -> 4.58 | F13: =ROUND(LAPLL!O2/1000, 2) -> 4.58 | G13: =SUM(C13:F13) -> 18.32 | O13: =1-(I13-C13)/((M2-1)*C13) -> 1.3333333 | P13: =1-(J13-D13)/((M2-1)*D13) -> 1.3333333 | Q13: =1-(K13-E13)/((M2-1)*E13) -> 1.3333333 | R13: =1-(L13-F13)/((M2-1)*F13) -> 1.3333333
B14: PCIEREFGEN | C14: =ROUND(PCIEREFGEN!F2/1000, 2) -> 3.74 | D14: =ROUND(PCIEREFGEN!I2/1000, 2) -> 3.74 | E14: =ROUND(PCIEREFGEN!L2/1000, 2) -> 3.74 | F14: =ROUND(PCIEREFGEN!O2/1000, 2) -> 3.74 | G14: =SUM(C14:F14) -> 14.96 | O14: =1-(I14-C14)/((M2-1)*C14) -> 1.3333333 | P14: =1-(J14-D14)/((M2-1)*D14) -> 1.3333333 | Q14: =1-(K14-E14)/((M2-1)*E14) -> 1.3333333 | R14: =1-(L14-F14)/((M2-1)*F14) -> 1.3333333
B15: PCIE5CMN | C15: =ROUND(PCIE5CMN!F2/1000, 2) -> 0.84 | D15: =ROUND(PCIE5CMN!I2/1000, 2) -> 0.84 | E15: =ROUND(PCIE5CMN!L2/1000, 2) -> 0.84 | F15: =ROUND(PCIE5CMN!O2/1000, 2) -> 0.84 | G15: =SUM(C15:F15) -> 3.36 | O15: =1-(I15-C15)/((M2-1)*C15) -> 1.3333333 | P15: =1-(J15-D15)/((M2-1)*D15) -> 1.3333333 | Q15: =1-(K15-E15)/((M2-1)*E15) -> 1.3333333 | R15: =1-(L15-F15)/((M2-1)*F15) -> 1.3333333
B16: ACIPHYCMN | C16: =ROUND(ACIPHYCMN!F2/1000, 2) -> 0.37 | D16: =ROUND(ACIPHYCMN!I2/1000, 2) -> 0.37 | E16: =ROUND(ACIPHYCMN!L2/1000, 2) -> 0.37 | F16: =ROUND(ACIPHYCMN!O2/1000, 2) -> 0.37 | G16: =SUM(C16:F16) -> 1.48 | O16: =1-(I16-C16)/((M2-1)*C16) -> 1.3333333 | P16: =1-(J16-D16)/((M2-1)*D16) -> 1.3333333 | Q16: =1-(K16-E16)/((M2-1)*E16) -> 1.3333333 | R16: =1-(L16-F16)/((M2-1)*F16) -> 1.3333333
B17: ACIOPHYCMN | C17: =ROUND(ACIOPHYCMN!F2/1000, 2) -> 0.52 | D17: =ROUND(ACIOPHYCMN!I2/1000, 2) -> 0.52 | E17: =ROUND(ACIOPHYCMN!L2/1000, 2) -> 0.52 | F17: =ROUND(ACIOPHYCMN!O2/1000, 2) -> 0.52 | G17: =SUM(C17:F17) -> 2.08 | O17: =1-(I17-C17)/((M2-1)*C17) -> 1.3333333 | P17: =1-(J17-D17)/((M2-1)*D17) -> 1.3333333 | Q17: =1-(K17-E17)/((M2-1)*E17) -> 1.3333333 | R17: =1-(L17-F17)/((M2-1)*F17) -> 1.3333333
B18: LPDPTXCMN | C18: =ROUND(LPDPTXCMN!F2/1000, 2) -> 0.38 | D18: =ROUND(LPDPTXCMN!I2/1000, 2) -> 0.38 | E18: =ROUND(LPDPTXCMN!L2/1000, 2) -> 0.38 | F18: =ROUND(LPDPTXCMN!O2/1000, 2) -> 0.38 | G18: =SUM(C18:F18) -> 1.52 | O18: =1-(I18-C18)/((M2-1)*C18) -> 1.3333333 | P18: =1-(J18-D18)/((M2-1)*D18) -> 1.3333333 | Q18: =1-(K18-E18)/((M2-1)*E18) -> 1.3333333 | R18: =1-(L18-F18)/((M2-1)*F18) -> 1.3333333
B19: AMPCMN | C19: =ROUND(AMPCMN!F2/1000, 2) -> 1.58 | D19: =ROUND(AMPCMN!I2/1000, 2) -> 1.58 | E19: =ROUND(AMPCMN!L2/1000, 2) -> 1.58 | F19: =ROUND(AMPCMN!O2/1000, 2) -> 1.58 | G19: =SUM(C19:F19) -> 6.32 | O19: =1-(I19-C19)/((M2-1)*C19) -> 1.3333333 | P19: =1-(J19-D19)/((M2-1)*D19) -> 1.3333333 | Q19: =1-(K19-E19)/((M2-1)*E19) -> 1.3333333 | R19: =1-(L19-F19)/((M2-1)*F19) -> 1.3333333
B20: PCIEREFPLL | C20: =ROUND(PCIEREFPLL!F2/1000, 2) -> 1.69 | D20: =ROUND(PCIEREFPLL!I2/1000, 2) -> 1.69 | E20: =ROUND(PCIEREFPLL!L2/1000, 2) -> 1.69 | F20: =ROUND(PCIEREFPLL!O2/1000, 2) -> 1.69 | G20: =SUM(C20:F20) -> 6.76 | O20: =1-(I20-C20)/((M2-1)*C20) -> 1.3333333 | P20: =1-(J20-D20)/((M2-1)*D20) -> 1.3333333 | Q20: =1-(K20-E20)/((M2-1)*E20) -> 1.3333333 | R20: =1-(L20-F20)/((M2-1)*F20) -> 1.3333333
B21: PCIEPLL | C21: =ROUND(PCIEPLL!F2/1000, 2) -> 5.38 | D21: =ROUND(PCIEPLL!I2/1000, 2) -> 5.38 | E21: =ROUND(PCIEPLL!L2/1000, 2) -> 5.38 | F21: =ROUND(PCIEPLL!O2/1000, 2) -> 5.38 | G21: =SUM(C21:F21) -> 21.52 | O21: =1-(I21-C21)/((M2-1)*C21) -> 1.3333333 | P21: =1-(J21-D21)/((M2-1)*D21) -> 1.3333333 | Q21: =1-(K21-E21)/((M2-1)*E21) -> 1.3333333 | R21: =1-(L21-F21)/((M2-1)*F21) -> 1.3333333
B22: CIOCIOPLL | C22: =ROUND(CIOCIOPLL!F2/1000, 2) -> 4.74 | D22: =ROUND(CIOCIOPLL!I2/1000, 2) -> 4.74 | E22: =ROUND(CIOCIOPLL!L2/1000, 2) -> 4.74 | F22: =ROUND(CIOCIOPLL!O2/1000, 2) -> 4.74 | G22: =SUM(C22:F22) -> 18.96 | O22: =1-(I22-C22)/((M2-1)*C22) -> 1.3333333 | P22: =1-(J22-D22)/((M2-1)*D22) -> 1.3333333 | Q22: =1-(K22-E22)/((M2-1)*E22) -> 1.3333333 | R22: =1-(L22-F22)/((M2-1)*F22) -> 1.3333333
B23: CIODPPLL | C23: =ROUND(CIODPPLL!F2/1000, 2) -> 2.18 | D23: =ROUND(CIODPPLL!I2/1000, 2) -> 2.18 | E23: =ROUND(CIODPPLL!L2/1000, 2) -> 2.18 | F23: =ROUND(CIODPPLL!O2/1000, 2) -> 2.18 | G23: =SUM(C23:F23) -> 8.72 | O23: =1-(I23-C23)/((M2-1)*C23) -> 1.3333333 | P23: =1-(J23-D23)/((M2-1)*D23) -> 1.3333333 | Q23: =1-(K23-E23)/((M2-1)*E23) -> 1.3333333 | R23: =1-(L23-F23)/((M2-1)*F23) -> 1.3333333
B24: LPDPDPPLL | C24: =ROUND(LPDPDPPLL!F2/1000, 2) -> 2.24 | D24: =ROUND(LPDPDPPLL!I2/1000, 2) -> 2.24 | E24: =ROUND(LPDPDPPLL!L2/1000, 2) -> 2.24 | F24: =ROUND(LPDPDPPLL!O2/1000, 2) -> 2.24 | G24: =SUM(C24:F24) -> 8.96 | O24: =1-(I24-C24)/((M2-1)*C24) -> 1.3333333 | P24: =1-(J24-D24)/((M2-1)*D24) -> 1.3333333 | Q24: =1-(K24-E24)/((M2-1)*E24) -> 1.3333333 | R24: =1-(L24-F24)/((M2-1)*F24) -> 1.3333333
B25: LPDDRPLL | C25: =ROUND(LPDDRPLL!F2/1000, 2) -> 7.16 | D25: =ROUND(LPDDRPLL!I2/1000, 2) -> 7.16 | E25: =ROUND(LPDDRPLL!L2/1000, 2) -> 7.16 | F25: =ROUND(LPDDRPLL!O2/1000, 2) -> 7.16 | G25: =SUM(C25:F25) -> 28.64 | O25: =1-(I25-C25)/((M2-1)*C25) -> 1.3333333 | P25: =1-(J25-D25)/((M2-1)*D25) -> 1.3333333 | Q25: =1-(K25-E25)/((M2-1)*E25) -> 1.3333333 | R25: =1-(L25-F25)/((M2-1)*F25) -> 1.3333333
B26: HSCSAROSC | C26: =ROUND(HSCSAROSC!F2/1000, 2) -> 0.26 | D26: =ROUND(HSCSAROSC!I2/1000, 2) -> 0.26 | E26: =ROUND(HSCSAROSC!L2/1000, 2) -> 0.26 | F26: =ROUND(HSCSAROSC!O2/1000, 2) -> 0.26 | G26: =SUM(C26:F26) -> 1.04 | O26: =1-(I26-C26)/((M2-1)*C26) -> 1.3333333 | P26: =1-(J26-D26)/((M2-1)*D26) -> 1.3333333 | Q26: =1-(K26-E26)/((M2-1)*E26) -> 1.3333333 | R26: =1-(L26-F26)/((M2-1)*F26) -> 1.3333333
B27: ULPPLL | C27: =ROUND(ULPPLL!F2/1000, 2) -> 0.42 | D27: =ROUND(ULPPLL!I2/1000, 2) -> 0.42 | E27: =ROUND(ULPPLL!L2/1000, 2) -> 0.42 | F27: =ROUND(ULPPLL!O2/1000, 2) -> 0.42 | G27: =SUM(C27:F27) -> 1.68 | O27: =1-(I27-C27)/((M2-1)*C27) -> 1.3333333 | P27: =1-(J27-D27)/((M2-1)*D27) -> 1.3333333 | Q27: =1-(K27-E27)/((M2-1)*E27) -> 1.3333333 | R27: =1-(L27-F27)/((M2-1)*F27) -> 1.3333333
B28: FLPPLL | C28: =ROUND(FLPPLL!F2/1000, 2) -> 0.78 | D28: =ROUND(FLPPLL!I2/1000, 2) -> 0.78 | E28: =ROUND(FLPPLL!L2/1000, 2) -> 0.78 | F28: =ROUND(FLPPLL!O2/1000, 2) -> 0.78 | G28: =SUM(C28:F28) -> 3.12 | O28: =1-(I28-C28)/((M2-1)*C28) -> 1.3333333 | P28: =1-(J28-D28)/((M2-1)*D28) -> 1.3333333 | Q28: =1-(K28-E28)/((M2-1)*E28) -> 1.3333333 | R28: =1-(L28-F28)/((M2-1)*F28) -> 1.3333333
B29: SEPVMC | C29: =ROUND(SEPVMC!F2/1000, 2) -> 1.38 | D29: =ROUND(SEPVMC!I2/1000, 2) -> 1.38 | E29: =ROUND(SEPVMC!L2/1000, 2) -> 1.38 | F29: =ROUND(SEPVMC!O2/1000, 2) -> 1.38 | G29: =SUM(C29:F29) -> 5.52 | O29: =1-(I29-C29)/((M2-1)*C29) -> 1.3333333 | P29: =1-(J29-D29)/((M2-1)*D29) -> 1.3333333 | Q29: =1-(K29-E29)/((M2-1)*E29) -> 1.3333333 | R29: =1-(L29-F29)/((M2-1)*F29) -> 1.3333333
B30: SEPF2M | C30: =ROUND(SEPF2M!F2/1000, 2) -> 0.92 | D30: =ROUND(SEPF2M!I2/1000, 2) -> 0.92 | E30: =ROUND(SEPF2M!L2/1000, 2) -> 0.92 | F30: =ROUND(SEPF2M!O2/1000, 2) -> 0.92 | G30: =SUM(C30:F30) -> 3.68 | O30: =1-(I30-C30)/((M2-1)*C30) -> 1.3333333 | P30: =1-(J30-D30)/((M2-1)*D30) -> 1.3333333 | Q30: =1-(K30-E30)/((M2-1)*E30) -> 1.3333333 | R30: =1-(L30-F30)/((M2-1)*F30) -> 1.3333333
B31: MIDBIASLDO | C31: =ROUND(MIDBIASLDO!F2/1000, 2) -> 0.06 | D31: =ROUND(MIDBIASLDO!I2/1000, 2) -> 0.06 | E31: =ROUND(MIDBIASLDO!L2/1000, 2) -> 0.06 | F31: =ROUND(MIDBIASLDO!O2/1000, 2) -> 0.06 | G31: =SUM(C31:F31) -> 0.24 | O31: =1-(I31-C31)/((M2-1)*C31) -> 1.3333333 | P31: =1-(J31-D31)/((M2-1)*D31) -> 1.3333333 | Q31: =1-(K31-E31)/((M2-1)*E31) -> 1.3333333 | R31: =1-(L31-F31)/((M2-1)*F31) -> 1.3333333
B32: VMADC | C32: =ROUND(VMADC!F2/1000, 2) -> 0.44 | D32: =ROUND(VMADC!I2/1000, 2) -> 0.44 | E32: =ROUND(VMADC!L2/1000, 2) -> 0.44 | F32: =ROUND(VMADC!O2/1000, 2) -> 0.44 | G32: =SUM(C32:F32) -> 1.76 | O32: =1-(I32-C32)/((M2-1)*C32) -> 1.3333333 | P32: =1-(J32-D32)/((M2-1)*D32) -> 1.3333333 | Q32: =1-(K32-E32)/((M2-1)*E32) -> 1.3333333 | R32: =1-(L32-F32)/((M2-1)*F32) -> 1.3333333
B33: ACIOPHY | C33: =ROUND(ACIOPHY!F2/1000, 2) -> 6.41 | D33: =ROUND(ACIOPHY!I2/1000, 2) -> 6.41 | E33: =ROUND(ACIOPHY!L2/1000, 2) -> 6.41 | F33: =ROUND(ACIOPHY!O2/1000, 2) -> 6.41 | G33: =SUM(C33:F33) -> 25.64 | O33: =1-(I33-C33)/((M2-1)*C33) -> 1.3333333 | P33: =1-(J33-D33)/((M2-1)*D33) -> 1.3333333 | Q33: =1-(K33-E33)/((M2-1)*E33) -> 1.3333333 | R33: =1-(L33-F33)/((M2-1)*F33) -> 1.3333333
B34: ACIPHY | C34: =ROUND(ACIPHY!F2/1000, 2) -> 12.69 | D34: =ROUND(ACIPHY!I2/1000, 2) -> 12.69 | E34: =ROUND(ACIPHY!L2/1000, 2) -> 12.69 | F34: =ROUND(ACIPHY!O2/1000, 2) -> 12.69 | G34: =SUM(C34:F34) -> 50.76 | O34: =1-(I34-C34)/((M2-1)*C34) -> 1.3333333 | P34: =1-(J34-D34)/((M2-1)*D34) -> 1.3333333 | Q34: =1-(K34-E34)/((M2-1)*E34) -> 1.3333333 | R34: =1-(L34-F34)/((M2-1)*F34) -> 1.3333333
B35: LPDPTX | C35: =ROUND(LPDPTX!F2/1000, 2) -> 1.05 | D35: =ROUND(LPDPTX!I2/1000, 2) -> 1.05 | E35: =ROUND(LPDPTX!L2/1000, 2) -> 1.05 | F35: =ROUND(LPDPTX!O2/1000, 2) -> 1.05 | G35: =SUM(C35:F35) -> 4.2 | O35: =1-(I35-C35)/((M2-1)*C35) -> 1.3333333 | P35: =1-(J35-D35)/((M2-1)*D35) -> 1.3333333 | Q35: =1-(K35-E35)/((M2-1)*E35) -> 1.3333333 | R35: =1-(L35-F35)/((M2-1)*F35) -> 1.3333333
B36: PCIE5 | C36: =ROUND(PCIE5!F2/1000, 2) -> 7 | D36: =ROUND(PCIE5!I2/1000, 2) -> 7 | E36: =ROUND(PCIE5!L2/1000, 2) -> 7 | F36: =ROUND(PCIE5!O2/1000, 2) -> 7 | G36: =SUM(C36:F36) -> 28 | O36: =1-(I36-C36)/((M2-1)*C36) -> 1.3333333 | P36: =1-(J36-D36)/((M2-1)*D36) -> 1.3333333 | Q36: =1-(K36-E36)/((M2-1)*E36) -> 1.3333333 | R36: =1-(L36-F36)/((M2-1)*F36) -> 1.3333333
B37: NTSX | C37: =ROUND(NTSX!F2/1000, 2) -> 0.09 | D37: =ROUND(NTSX!I2/1000, 2) -> 0.09 | E37: =ROUND(NTSX!L2/1000, 2) -> 0.09 | F37: =ROUND(NTSX!O2/1000, 2) -> 0.09 | G37: =SUM(C37:F37) -> 0.36 | O37: =1-(I37-C37)/((M2-1)*C37) -> 1.3333333 | P37: =1-(J37-D37)/((M2-1)*D37) -> 1.3333333 | Q37: =1-(K37-E37)/((M2-1)*E37) -> 1.3333333 | R37: =1-(L37-F37)/((M2-1)*F37) -> 1.3333333
B38: PCIEREFBUF | C38: =ROUND(PCIEREFBUF!F2/1000, 2) -> 0.08 | D38: =ROUND(PCIEREFBUF!I2/1000, 2) -> 0.08 | E38: =ROUND(PCIEREFBUF!L2/1000, 2) -> 0.08 | F38: =ROUND(PCIEREFBUF!O2/1000, 2) -> 0.08 | G38: =SUM(C38:F38) -> 0.32 | O38: =1-(I38-C38)/((M2-1)*C38) -> 1.3333333 | P38: =1-(J38-D38)/((M2-1)*D38) -> 1.3333333 | Q38: =1-(K38-E38)/((M2-1)*E38) -> 1.3333333 | R38: =1-(L38-F38)/((M2-1)*F38) -> 1.3333333
B39: EUSB | C39: =ROUND(EUSB!F2/1000, 2) -> 0.11 | D39: =ROUND(EUSB!I2/1000, 2) -> 0.11 | E39: =ROUND(EUSB!L2/1000, 2) -> 0.11 | F39: =ROUND(EUSB!O2/1000, 2) -> 0.11 | G39: =SUM(C39:F39) -> 0.44 | O39: =1-(I39-C39)/((M2-1)*C39) -> 1.3333333 | P39: =1-(J39-D39)/((M2-1)*D39) -> 1.3333333 | Q39: =1-(K39-E39)/((M2-1)*E39) -> 1.3333333 | R39: =1-(L39-F39)/((M2-1)*F39) -> 1.3333333
B40: DSGRINGS | C40: =ROUND(#REF!/1000, 2) -> #REF! | D40: =ROUND(#REF!/1000, 2) -> #REF! | E40: =ROUND(#REF!/1000, 2) -> #REF! | F40: =ROUND(#REF!/1000, 2) -> #REF! | G40: =SUM(C40:F40) -> #REF! | O40: =1-(I40-C40)/((M2-1)*C40) -> #REF! | P40: =1-(J40-D40)/((M2-1)*D40) -> #REF! | Q40: =1-(K40-E40)/((M2-1)*E40) -> #REF! | R40: =1-(L40-F40)/((M2-1)*F40) -> #REF!
B41: AMP | C41: =ROUND(AMP!F2/1000, 2) -> 8.66 | D41: =ROUND(AMP!I2/1000, 2) -> 8.66 | E41: =ROUND(AMP!L2/1000, 2) -> 8.66 | F41: =ROUND(AMP!O2/1000, 2) -> 8.66 | G41: =SUM(C41:F41) -> 34.64 | O41: =1-(I41-C41)/((M2-1)*C41) -> 1.3333333 | P41: =1-(J41-D41)/((M2-1)*D41) -> 1.3333333 | Q41: =1-(K41-E41)/((M2-1)*E41) -> 1.3333333 | R41: =1-(L41-F41)/((M2-1)*F41) -> 1.3333333
...

Sheet IO_JTAG
A2: Proposal for TTR | D2: Total (ms) | F2: =SUM(E5:G21) -> 1118.72 | I2: =SUM(H5:J21) -> 1118.72 | L2: =SUM(K5:M21) -> 1118.72 | O2: =SUM(N5:P21) -> 1118.72
E3: CP1 (ms) | H3: CP2 (ms) | K3: FT1 (ms) | N3: FT2 (ms)
A4: Category | B4: SubBlock | C4: Pattern | D4: Run If Fail | E4: LV | F4: NV | G4: HV | H4: LV | I4: NV | J4: HV | K4: LV | L4: NV | M4: HV | N4: LV | O4: NV | P4: HV | Q4: Prod CP1 | R4: Prod CP2 | S4: Prod FT1 | T4: Prod FT2 | U4: Mon | V4: T0Tx | W4: RMA Room | X4: RMA Hot
A5: IO_JTAG | B5: TAPBSD | C5: PP_KMDA0_S_FULP_IO_BSCN_BSD_JIO_UNS_ALLFRV_SI_TAP_BSD | E5: 24.32 | G5: 24.75 | H5: 24.32 | J5: 24.75 | K5: 24.32 | M5: 24.75 | N5: 24.32 | P5: 24.75 | Q5: LV,HV | R5: LV,HV | S5: NV
A6: IO_JTAG | B6: DAPIDBYP | C6: PP_KMDA0_S_FULP_FU_BSCN_PFF_JTG_JCC_ALLFRV_SI_DAP_IDBYP | R6: LV,HV | T6: LV,HV
A7: IO_JTAG | B7: DCLP | C7: PP_KMDA0_S_FULP_IO_BSCN_DCT_DAA_DIO_ALLFRV_SI_DC_LP | E7: 43.62 | G7: 8.95 | H7: 43.62 | J7: 8.95 | K7: 43.62 | M7: 8.95 | N7: 43.62 | P7: 8.95 | Q7: LV,HV | R7: LV,HV
A8: IO_JTAG | B8: FUNCVILH | C8: PP_KMDA0_S_FULP_IO_POPX_NAN_DAA_DIO_ALLFRV_SI_FUNC_VILH | E8: 83.85 | G8: 83.48 | H8: 83.85 | J8: 83.48 | K8: 83.85 | M8: 83.48 | N8: 83.85 | P8: 83.48 | Q8: LV,HV | R8: LV,HV
A9: IO_JTAG | B9: IMPDPU | C9: PP_KMDA0_S_FULP_IO_POPU_NAN_DAA_DIO_ALLFRV_SI_IMPD_PU | G9: 159.93 | J9: 159.93 | M9: 159.93 | P9: 159.93 | Q9: HV | R9: LV
A10: IO_JTAG | B10: DCDS4TRIM | C10: PP_KMDA0_S_FULP_IO_BSCN_DCT_DAA_DIO_ALLFRV_SI_DC_DS4 | F10: 25.57 | I10: 25.57 | L10: 25.57 | O10: 25.57
A11: IO_JTAG | B11: DCDS8TRIM | C11: PP_KMDA0_S_FULP_IO_BSCN_DCT_DAA_DIO_ALLFRV_SI_DC_DS8 | F11: 22.95 | I11: 22.95 | L11: 22.95 | O11: 22.95
A12: IO_JTAG | B12: DCDS14TRIM | C12: PP_KMDA0_S_FULP_IO_BSCN_DCT_DAA_DIO_ALLFRV_SI_DC_DS14 | F12: 22.8 | I12: 22.8 | L12: 22.8 | O12: 22.8
A13: IO_JTAG | B13: DCDS4ALLD13 | C13: PP_KMDA0_S_FULP_IO_BSCN_DCT_DAA_DIO_ALLFRV_SI_DC_DS4 | G13: 37.93 | J13: 37.93 | M13: 37.93 | P13: 37.93 | Q13: HV | R13: LV
A14: IO_JTAG | B14: DCDS4ALLD22 | C14: PP_KMDA0_S_FULP_IO_BSCN_DCT_DAA_DIO_ALLFRV_SI_DC_DS4 | G14: 29.04 | J14: 29.04 | M14: 29.04 | P14: 29.04 | Q14: HV | R14: LV
A15: IO_JTAG | B15: DCDS8ALLD13 | C15: PP_KMDA0_S_FULP_IO_BSCN_DCT_DAA_DIO_ALLFRV_SI_DC_DS8 | G15: 38.45 | J15: 38.45 | M15: 38.45 | P15: 38.45 | Q15: HV | R15: LV
A16: IO_JTAG | B16: DCDS8ALLD22 | C16: PP_KMDA0_S_FULP_IO_BSCN_DCT_DAA_DIO_ALLFRV_SI_DC_DS8 | G16: 29.07 | J16: 29.07 | M16: 29.07 | P16: 29.07 | Q16: HV | R16: LV
A17: IO_JTAG | B17: DCDS14ALLD13 | C17: PP_KMDA0_S_FULP_IO_BSCN_DCT_DAA_DIO_ALLFRV_SI_DC_DS14 | G17: 56.1 | J17: 56.1 | M17: 56.1 | P17: 56.1 | Q17: HV | R17: LV
A18: IO_JTAG | B18: DCDS14ALLD22 | C18: PP_KMDA0_S_FULP_IO_BSCN_DCT_DAA_DIO_ALLFRV_SI_DC_DS14 | G18: 42.51 | J18: 42.51 | M18: 42.51 | P18: 42.51 | Q18: HV | R18: LV
A19: IO_JTAG | B19: IOLEAK | C19: PP_KMDA0_S_FULP_IO_BSCN_BSD_JIO_UNS_ALLFRV_SI_IO_LEAK | G19: 57.67 | J19: 57.67 | M19: 57.67 | P19: 57.67 | Q19: HV | R19: HV
A20: IO_JTAG | B20: VOHFUNCD22 | C20: PP_KMDA0_S_FULP_IO_BSCN_DCT_DAA_DIO_ALLFRV_SI_FUNC_VOLHD22 | G20: 162.76 | J20: 162.76 | M20: 162.76 | P20: 162.76 | Q20: HV | R20: LV
A21: IO_JTAG | B21: VOHFUNCD13 | C21: PP_KMDA0_S_FULP_IO_BSCN_DCT_DAA_DIO_ALLFRV_SI_FUNC_VOLHD13 | G21: 164.97 | J21: 164.97 | M21: 164.97 | P21: 164.97 | Q21: HV | R21: LV

Sheet ADCDFT
A2: Proposal for TTR | D2: Total (ms) | F2: =SUM(E5:G28) -> 878.24 | I2: =SUM(H5:J28) -> 878.24 | L2: =SUM(K5:M28) -> 878.24 | O2: =SUM(N5:P28) -> 878.24
E3: CP1 (ms) | H3: CP2 (ms) | K3: FT1 (ms) | N3: FT2 (ms)
A4: Category | B4: SubBlock | C4: Pattern | D4: Run If Fail | E4: LV | F4: NV | G4: HV | H4: LV | I4: NV | J4: HV | K4: LV | L4: NV | M4: HV | N4: LV | O4: NV | P4: HV | Q4: Prod CP1 | R4: Prod CP2 | S4: Prod FT1 | T4: Prod FT2 | U4: Mon | V4: T0Tx | W4: RMA Room | X4: RMA Hot
A5: ADCDFT | B5: OTHER | C5: ADCDFT_RELAY_ON_K80_K83 | F5: 3.34 | I5: 3.34 | L5: 3.34 | O5: 3.34 | Q5: NV,LV,HV | R5: NV,LV,HV | S5: NV,LV,HV | T5: NV,LV,HV | U5: NV,LV,HV | V5: NV,LV,HV | W5: NV,LV,HV | X5: NV,LV,HV
A6: ADCDFT | B6: OTHER | C6: ADCDFT_RELAY_OFF_K80_K83 | Q6: NV,LV,HV | R6: NV,LV,HV | S6: NV,LV,HV | T6: NV,LV,HV | U6: NV,LV,HV | V6: NV,LV,HV | W6: NV,LV,HV | X6: NV,LV,HV
A7: ADCDFT | B7: OTHER | C7: ADCDFT_FUSE_PREWRITE_HSC_UCSDM0_DFT_NREFG | Q7: NV
A8: ADCDFT | B8: OTHER | C8: ADCDFT_FUSE_READ_HSC_UCSDM0_DFT_NREFG | R8: NV | S8: NV | T8: NV
A9: ADCDFT | B9: OTHER | C9: ADCDFT_FUSE_PREWRITE_HSC_UCSDM1_DFT_NREFG | Q9: NV
A10: ADCDFT | B10: OTHER | C10: ADCDFT_FUSE_READ_HSC_UCSDM1_DFT_NREFG | F10: 3.57 | I10: 3.57 | L10: 3.57 | O10: 3.57 | R10: NV | S10: NV | T10: NV
A11: ADCDFT | B11: UCSDMT1 | C11: PP_KMDA0_S_FULP_AN_AA07_MEA_JTG_VIX_ALLFRV_SI_UCSDM_T1 | F11: 241.4 | I11: 241.4 | L11: 241.4 | O11: 241.4 | Q11: NV
A12: ADCDFT | B12: UCSDMCALT3A | C12: PP_KMDA0_S_FULP_AN_AA07_MEA_JTG_VIX_ALLFRV_SI_UCSDM_T3A | F12: 103.33 | I12: 103.33 | L12: 103.33 | O12: 103.33 | Q12: NV | R12: NV | S12: NV | T12: NV
A13: ADCDFT | B13: UCSDMVER0P139 | C13: PP_KMDA0_S_FULP_AN_AA07_MEA_JTG_VIX_ALLFRV_SI_UCSDM_T3B | F13: 80.69 | I13: 80.69 | L13: 80.69 | O13: 80.69 | Q13: NV
A14: ADCDFT | B14: UCSDMVER0P558 | C14: PP_KMDA0_S_FULP_AN_AA07_MEA_JTG_VIX_ALLFRV_SI_UCSDM_T3B | F14: 66.29 | I14: 66.29 | L14: 66.29 | O14: 66.29 | Q14: NV
A15: ADCDFT | B15: UCSDMVER0P837 | C15: PP_KMDA0_S_FULP_AN_AA07_MEA_JTG_VIX_ALLFRV_SI_UCSDM_T3B | F15: 65.77 | I15: 65.77 | L15: 65.77 | O15: 65.77 | Q15: NV
A16: ADCDFT | B16: UCSDMVER0P976 | C16: PP_KMDA0_S_FULP_AN_AA07_MEA_JTG_VIX_ALLFRV_SI_UCSDM_T3B | F16: 65.77 | I16: 65.77 | L16: 65.77 | O16: 65.77 | Q16: NV
A17: ADCDFT | B17: UCSDMT4A | C17: PP_KMDA0_S_FULP_AN_AA07_MEA_JTG_VIX_ALLFRV_SI_UCSDM_T4A | F17: 52.18 | I17: 52.18 | L17: 52.18 | O17: 52.18 | Q17: NV
A18: ADCDFT | B18: UCSDMT4B | C18: PP_KMDA0_S_FULP_AN_AA07_MEA_JTG_VIX_ALLFRV_SI_UCSDM_T4B | F18: 125.59 | I18: 125.59 | L18: 125.59 | O18: 125.59 | Q18: NV
A19: ADCDFT | B19: UCSDMT8 | C19: PP_KMDA0_S_FULP_AN_AA07_MEA_JTG_VIX_ALLFRV_SI_UCSDM_T8 | F19: 70.31 | I19: 70.31 | L19: 70.31 | O19: 70.31 | Q19: NV
A20: ADCDFT | B20: UCSDMCALT5A | C20: MN_KMDA0_S_FULP_AN_AA07_MEA_JTG_VIX_ALLFRV_SI_UCSDM_T5A | U20: LV,HV
A21: ADCDFT | B21: UCSDMMNVER0P139 | C21: MN_KMDA0_S_FULP_AN_AA07_MEA_JTG_VIX_ALLFRV_SI_UCSDM_T5B | U21: LV,HV
A22: ADCDFT | B22: UCSDMMNVER0P558 | C22: MN_KMDA0_S_FULP_AN_AA07_MEA_JTG_VIX_ALLFRV_SI_UCSDM_T5B | U22: LV,HV
A23: ADCDFT | B23: UCSDMMNVER0P837 | C23: MN_KMDA0_S_FULP_AN_AA07_MEA_JTG_VIX_ALLFRV_SI_UCSDM_T5B | U23: LV,HV
A24: ADCDFT | B24: MNUCSDMT6 | C24: MN_KMDA0_S_FULP_AN_AA07_MEA_JTG_VIX_ALLFRV_SI_UCSDM_T6 | U24: LV,HV
A25: ADCDFT | B25: MNUCSDMT9A | C25: MN_KMDA0_S_FULP_AN_AA07_MEA_JTG_VIX_ALLFRV_SI_UCSDM_T9A | U25: LV,HV
A26: ADCDFT | B26: MNUCSDMT9B | C26: MN_KMDA0_S_FULP_AN_AA07_MEA_JTG_VIX_ALLFRV_SI_UCSDM_T9B | U26: LV,HV
A27: ADCDFT | B27: MNUCSDMT9C | C27: MN_KMDA0_S_FULP_AN_AA07_MEA_JTG_VIX_ALLFRV_SI_UCSDM_T9C | U27: LV,HV
A28: ADCDFT | B28: MNUCSDMT9D | C28: MN_KMDA0_S_FULP_AN_AA07_MEA_JTG_VIX_ALLFRV_SI_UCSDM_T9D | U28: LV,HV

Sheet MTRICTS
A2: Proposal for TTR | D2: Total (ms) | F2: =SUM(E5:G27) -> 7607.59 | I2: =SUM(H5:J27) -> 7607.59 | L2: =SUM(K5:M27) -> 7607.59 | O2: =SUM(N5:P27) -> 7607.59
E3: CP1 (ms) | H3: CP2 (ms) | K3: FT1 (ms) | N3: FT2 (ms)
A4: Category | B4: SubBlock | C4: Pattern | D4: Run If Fail | E4: LV | F4: NV | G4: HV | H4: LV | I4: NV | J4: HV | K4: LV | L4: NV | M4: HV | N4: LV | O4: NV | P4: HV | Q4: Prod CP1 | R4: Prod CP2 | S4: Prod FT1 | T4: Prod FT2 | U4: Mon | V4: T0Tx | W4: RMA Room | X4: RMA Hot
A5: MTRICTS | B5: NBRIDGET2P1 | C5: PP_KMDA0_S_FULP_AN_ICTS_DLL_JTG_COD_ALLFRV_SI_NBRIDGE_T2P1 | F5: 344.08 | I5: 344.08 | L5: 344.08 | O5: 344.08 | Q5: NV
A6: MTRICTS | B6: OTHER | C6: MTRICTS_T2P1_FUSE_PREWRITE_CAL | Q6: NV
A7: MTRICTS | B7: OTHER | C7: MTRICTS_T2P1_FUSE_READ_CAL | R7: NV | S7: NV | T7: NV
A8: MTRICTS | B8: OTHER | C8: MTRICTS_T2P1P1_FUSE_PREWRITE_CAL | R8: NV
A9: MTRICTS | B9: OTHER | C9: MTRICTS_T2P1P1_FUSE_READ_CAL | S9: NV | T9: NV
A10: MTRICTS | B10: OTHER | C10: MTRICTS_T3P2_FUSE_PREWRITE_CAL | Q10: NV
A11: MTRICTS | B11: OTHER | C11: MTRICTS_T3P2_FUSE_READ_CAL | R11: NV | S11: NV | T11: NV
A12: MTRICTS | B12: OTHER | C12: MTRICTS_BPBN_ASSIGMENT | Q12: NV
A13: MTRICTS | B13: OTHER | C13: MTRICTS_T4P1_FUSE_PREWRITE_CAL | Q13: NV
A14: MTRICTS | B14: OTHER | C14: MTRICTS_T4P1_FUSE_READ_CAL | R14: NV | S14: NV | T14: NV
A15: MTRICTS | B15: OTHER | C15: MTRICTS_T5P1P1_FUSE_PREWRITE_CAL | R15: NV
A16: MTRICTS | B16: OTHER | C16: MTRICTS_T5P1P1_FUSE_READ_CAL | S16: NV | T16: NV
A17: MTRICTS | B17: NBRIDGET2P1A | C17: PP_KMDA0_S_FULP_AN_ICTS_DLL_JTG_COD_ALLFRV_SI_NBRIDGE_T2P1A | F17: 248.68 | I17: 248.68 | L17: 248.68 | O17: 248.68 | Q17: NV | R17: NV
A18: MTRICTS | B18: NBRIDGET2P1P1 | C18: PP_KMDA0_S_FULP_AN_ICTS_DLL_JTG_COD_ALLFRV_SI_NBRIDGE_T2P1P1 | F18: 30.42 | I18: 30.42 | L18: 30.42 | O18: 30.42 | Q18: NV | R18: NV
A19: MTRICTS | B19: RBRIDGET3P1 | C19: PP_KMDA0_S_FULP_AN_ICTS_DLL_JTG_COD_ALLFRV_SI_RBRIDGE_T3P1 | F19: 227.65 | I19: 227.65 | L19: 227.65 | O19: 227.65 | Q19: NV
A20: MTRICTS | B20: RBRIDGET3P2 | C20: PP_KMDA0_S_FULP_AN_ICTS_DLL_JTG_COD_ALLFRV_SI_RBRIDGE_T3P2 | F20: 1262.89 | I20: 1262.89 | L20: 1262.89 | O20: 1262.89 | Q20: NV
A21: MTRICTS | B21: READT4P1 | C21: PP_KMDA0_S_FULP_AN_ICTS_DLL_JTG_COD_ALLFRV_SI_READ_T4P1 | F21: 1172.05 | I21: 1172.05 | L21: 1172.05 | O21: 1172.05 | Q21: NV
A22: MTRICTS | B22: TEMPT5P1 | C22: PP_KMDA0_S_FULP_AN_ICTS_DLL_JTG_COD_ALLFRV_SI_TEMP_T5P1 | F22: 4074.13 | I22: 4074.13 | L22: 4074.13 | O22: 4074.13 | Q22: LV,HV.NV | R22: LV,HV.NV | S22: LV,HV.NV | T22: LV,HV.NV
A23: MTRICTS | B23: TEMPT5P1P1 | C23: PP_KMDA0_S_FULP_AN_ICTS_DLL_JTG_COD_ALLFRV_SI_TEMP_T5P1P1 | F23: 247.69 | I23: 247.69 | L23: 247.69 | O23: 247.69 | Q23: NV | R23: NV | S23: NV | T23: NV
A24: MTRICTS | B24: MNPWRT1P1 | C24: MN_KMDA0_S_FULP_AN_ICTS_DLL_JTG_COD_ALLFRV_SI_PWR_T1P1 | U24: LV,HV
A25: MTRICTS | B25: MNIREFT1P2 | C25: MN_KMDA0_S_FULP_AN_ICTS_DLL_JTG_COD_ALLFRV_SI_IREF_T1P2 | U25: LV,HV
A26: MTRICTS | B26: MNANATESTT1P3 | C26: MN_KMDA0_S_FULP_AN_ICTS_DLL_JTG_COD_ALLFRV_SI_ANATEST_T1P3 | U26: LV,HV
A27: MTRICTS | B27: MNOSCT6P1 | C27: MN_KMDA0_S_FULP_AN_ICTS_DLL_JTG_COD_ALLFRV_SI_OSC_T6P1 | U27: LV,HV

Sheet NTSE
A2: Proposal for TTR | D2: Total (ms) | F2: =SUM(E5:G20) -> 4350.88 | I2: =SUM(H5:J20) -> 4350.88 | L2: =SUM(K5:M20) -> 4350.88 | O2: =SUM(N5:P20) -> 4350.88
E3: CP1 (ms) | H3: CP2 (ms) | K3: FT1 (ms) | N3: FT2 (ms)
A4: Category | B4: SubBlock | C4: Pattern | D4: Run If Fail | E4: LV | F4: NV | G4: HV | H4: LV | I4: NV | J4: HV | K4: LV | L4: NV | M4: HV | N4: LV | O4: NV | P4: HV | Q4: Prod CP1 | R4: Prod CP2 | S4: Prod FT1 | T4: Prod FT2 | U4: Mon | V4: T0Tx | W4: RMA Room | X4: RMA Hot
A5: NTSE | B5: NTSEREADT1P1CP1 | C5: PP_KMDA0_S_FULP_AN_MT02_DLL_JTG_COD_ALLFRV_SI_NTSEREAD_T1P1 | F5: 1050.16 | I5: 1050.16 | L5: 1050.16 | O5: 1050.16 | Q5: NV
A6: NTSE | B6: OTHER | C6: NTSE_NTSEREADT1P1CP1_FUSE_PREWRITE_CAL_D_0_CP1 | Q6: NV
A7: NTSE | B7: OTHER | C7: NTSE_NTSEREADT1P1CP1_FUSE_PREWRITE_CAL_VREF_DIG_CP1 | Q7: NV
A8: NTSE | B8: OTHER | C8: NTSE_NTSEREADT1P1FT1_FUSE_PREWRITE_CAL_D_0_FT1 | S8: NV
A9: NTSE | B9: OTHER | C9: NTSE_NTSEREADT1P1FT1_FUSE_READ_CAL_D_0_FT1 | T9: NV
A10: NTSE | B10: OTHER | C10: NTSE_NTSEREADT1P1FT1_FUSE_PREWRITE_CAL_NTSE_TEMP_FT1 | S10: NV
A11: NTSE | B11: OTHER | C11: NTSE_NTSEREADT1P1FT1_FUSE_READ_CAL_NTSE_TEMP_FT1 | T11: NV
A12: NTSE | B12: OTHER | C12: NTSE_NTSEREADT1P1FT2_FUSE_PREWRITE_CAL_VREF_DIG_FT2 | T12: NV
A13: NTSE | B13: OTHER | C13: NTSE_NTSEREADT1P1FT2_FUSE_PREWRITE_CAL_D_0_FT2 | T13: NV
A14: NTSE | B14: OTHER | C14: NTSE_NTSEREADT1P1FT2_FUSE_READ_CAL_D_0_FT2
A15: NTSE | B15: OTHER | C15: NTSE_NTSEREADT1P1FT2_FUSE_PREWRITE_CAL_NTSE_TEMP_FT2 | T15: NV
A16: NTSE | B16: OTHER | C16: NTSE_NTSEREADT1P1FT2_FUSE_READ_CAL_NTSE_TEMP_FT2
A17: NTSE | B17: NTSEREADT1P1FT1 | C17: PP_KMDA0_S_FULP_AN_MT02_DLL_JTG_COD_ALLFRV_SI_NTSEREAD_T1P1 | S17: NV
A18: NTSE | B18: NTSEREADT1P1FT2 | C18: PP_KMDA0_S_FULP_AN_MT02_DLL_JTG_COD_ALLFRV_SI_NTSEREAD_T1P1 | T18: NV
A19: NTSE | B19: NTSEREADT2 | C19: PP_KMDA0_S_FULP_AN_MT02_DLL_JTG_COD_ALLFRV_SI_NTSEREAD_T2 | T19: NV
A20: NTSE | B20: MNNTSEREADT1P0 | C20: MN_KMDA0_S_FULP_AN_MT02_DLL_JTG_COD_ALLFRV_SI_NTSEREAD_T1P0 | F20: 3300.72 | I20: 3300.72 | L20: 3300.72 | O20: 3300.72 | U20: LV,HV

Sheet NTSR
A2: Proposal for TTR | D2: Total (ms) | F2: =SUM(E5:G16) -> 260.48 | I2: =SUM(H5:J16) -> 260.48 | L2: =SUM(K5:M16) -> 260.48 | O2: =SUM(N5:P16) -> 260.48
E3: CP1 (ms) | H3: CP2 (ms) | K3: FT1 (ms) | N3: FT2 (ms)
A4: Category | B4: SubBlock | C4: Pattern | D4: Run If Fail | E4: LV | F4: NV | G4: HV | H4: LV | I4: NV | J4: HV | K4: LV | L4: NV | M4: HV | N4: LV | O4: NV | P4: HV | Q4: Prod CP1 | R4: Prod CP2 | S4: Prod FT1 | T4: Prod FT2 | U4: Mon | V4: T0Tx | W4: RMA Room | X4: RMA Hot
A5: NTSR | B5: NTSRREADT1P1CP1 | C5: PP_KMDA0_S_FULP_AN_MT02_DLL_JTG_COD_ALLFRV_SI_NTSRREAD_T1P1 | F5: 65.49 | I5: 65.49 | L5: 65.49 | O5: 65.49 | Q5: NV
A6: NTSR | B6: OTHER | C6: NTSR_T1P1_CP1_FUSE_PREWRITE_CAL | Q6: NV
A7: NTSR | B7: OTHER | C7: NTSR_T1P1_CP1_FUSE_READ_CAL | R7: NV | S7: NV | T7: NV
A8: NTSR | B8: OTHER | C8: NTSR_T1P1_CP2_FUSE_PREWRITE_CAL | R8: NV
A9: NTSR | B9: OTHER | C9: NTSR_T1P1_CP2_FUSE_READ_CAL | S9: NV | T9: NV
A10: NTSR | B10: OTHER | C10: NTSR_T1P1_FT1_FUSE_PREWRITE_CAL | S10: NV
A11: NTSR | B11: OTHER | C11: NTSR_T1P1_FT1_FUSE_READ_CAL | T11: NV
A12: NTSR | B12: NTSRREADT1P1CP2 | C12: PP_KMDA0_S_FULP_AN_MT02_DLL_JTG_COD_ALLFRV_SI_NTSRREAD_T1P1 | R12: NV
A13: NTSR | B13: NTSRREADT1P1FT1 | C13: PP_KMDA0_S_FULP_AN_MT02_DLL_JTG_COD_ALLFRV_SI_NTSRREAD_T1P1 | S13: NV
A14: NTSR | B14: NTSRREADT1P1FT2 | C14: PP_KMDA0_S_FULP_AN_MT02_DLL_JTG_COD_ALLFRV_SI_NTSRREAD_T1P1 | T14: NV
A15: NTSR | B15: NTSRREADT2 | C15: PP_KMDA0_S_FULP_AN_MT02_DLL_JTG_COD_ALLFRV_SI_NTSRREAD_T2 | T15: NV
A16: NTSR | B16: MNNTSRREADT1P0 | C16: MN_KMDA0_S_FULP_AN_MT02_DLL_JTG_COD_ALLFRV_SI_NTSRREAD_T1P0 | F16: 194.99 | I16: 194.99 | L16: 194.99 | O16: 194.99 | U16: LV,HV

Sheet MISC
A2: Proposal for TTR | D2: Total (ms) | F2: =SUM(E5:G18) -> 373.08 | I2: =SUM(H5:J18) -> 373.08 | L2: =SUM(K5:M18) -> 373.08 | O2: =SUM(N5:P18) -> 373.08
E3: CP1 (ms) | H3: CP2 (ms) | K3: FT1 (ms) | N3: FT2 (ms)
A4: Category | B4: SubBlock | C4: Pattern | D4: Run If Fail | E4: LV | F4: NV | G4: HV | H4: LV | I4: NV | J4: HV | K4: LV | L4: NV | M4: HV | N4: LV | O4: NV | P4: HV | Q4: Prod CP1 | R4: Prod CP2 | S4: Prod FT1 | T4: Prod FT2 | U4: Mon | V4: T0Tx | W4: RMA Room | X4: RMA Hot
A5: MISC | B5: SIOAOP | C5: PP_KMDA0_S_FULP_IO_POPX_NAN_DAA_DIO_ALLFRV_SI_SIO_AOP | E5: 12.65 | G5: 12.48 | H5: 12.65 | J5: 12.48 | K5: 12.65 | M5: 12.48 | N5: 12.65 | P5: 12.48 | Q5: LV,HV | T5: LV,HV
A6: MISC | B6: SIOBSD | C6: PP_KMDA0_S_FULP_IO_POPX_NAN_DAA_DIO_ALLFRV_SI_SIO_BSD | E6: 9.89 | G6: 9.73 | H6: 9.89 | J6: 9.73 | K6: 9.89 | M6: 9.73 | N6: 9.89 | P6: 9.73 | Q6: LV,HV | T6: LV,HV
A7: MISC | B7: SIOSIO | C7: PP_KMDA0_S_FULP_IO_POPX_NAN_DAA_DIO_ALLFRV_SI_SIO_SIO | E7: 9.74 | G7: 10.05 | H7: 9.74 | J7: 10.05 | K7: 9.74 | M7: 10.05 | N7: 9.74 | P7: 10.05 | Q7: LV,HV | T7: LV,HV
A8: MISC | B8: SIOQSPIMC | C8: PP_KMDA0_S_FULP_IO_POPX_NAN_DAA_DIO_ALLFRV_SI_SIO_QSPIMC | E8: 24.94 | G8: 9.57 | H8: 24.94 | J8: 9.57 | K8: 24.94 | M8: 9.57 | N8: 24.94 | P8: 9.57 | Q8: LV,HV | T8: LV,HV
A9: MISC | B9: SIONUB | C9: PP_KMDA0_S_FULP_IO_POPX_NAN_DAA_DIO_ALLFRV_SI_SIO_NUB | E9: 9.79 | G9: 9.95 | H9: 9.79 | J9: 9.95 | K9: 9.79 | M9: 9.95 | N9: 9.79 | P9: 9.95 | Q9: LV,HV | T9: LV,HV
A10: MISC | B10: XX | C10: PP_KMDA0_S_FULP_PW_PTSX_PFF_DAA_PWR_ALLFRV_SI_X_X | E10: 11.01 | G10: 11.99 | H10: 11.01 | J10: 11.99 | K10: 11.01 | M10: 11.99 | N10: 11.01 | P10: 11.99 | Q10: LV,HV | T10: LV,HV
A11: MISC | B11: DELAYEN | C11: PP_KMDA0_S_FULP_PW_PTSX_PFF_DAA_PWR_ALLFRV_SI_DELAY_EN | E11: 28.08 | G11: 28.05 | H11: 28.08 | J11: 28.05 | K11: 28.08 | M11: 28.05 | N11: 28.08 | P11: 28.05 | Q11: LV,HV | T11: LV,HV
A12: MISC | B12: SELSRAMMEMON | C12: PP_KMDA0_S_FULP_PW_PTSX_PFF_DAA_PWR_ALLFRV_SI_SELSRAM_MEMON | E12: 10.73 | G12: 10.83 | H12: 10.73 | J12: 10.83 | K12: 10.73 | M12: 10.83 | N12: 10.73 | P12: 10.83 | Q12: LV,HV | T12: LV,HV
A13: MISC | B13: SELSRAMMEMOFF | C13: PP_KMDA0_S_FULP_PW_PTSX_PFF_DAA_PWR_ALLFRV_SI_SELSRAM_MEMOFF | E13: 10.3 | G13: 10.46 | H13: 10.3 | J13: 10.46 | K13: 10.3 | M13: 10.46 | N13: 10.3 | P13: 10.46 | Q13: LV,HV | T13: LV,HV
A14: MISC | B14: TBBACC | C14: PP_KMDA0_C_FULP_AN_TBBX_PFF_JTG_CAL_ALLFRV_SI_TBB_ACC | E14: 14.47 | G14: 13.58 | H14: 14.47 | J14: 13.58 | K14: 14.47 | M14: 13.58 | N14: 14.47 | P14: 13.58 | Q14: LV,HV | T14: LV,HV
A15: MISC | B15: TBBANE | C15: PP_KMDA0_S_FULP_AN_TBBX_PFF_JTG_CAL_ALLFRV_SI_TBB_ANE | E15: 9.45 | G15: 9.7 | H15: 9.45 | J15: 9.7 | K15: 9.45 | M15: 9.7 | N15: 9.45 | P15: 9.7 | Q15: LV,HV | T15: LV,HV
A16: MISC | B16: TBBDCS | C16: PP_KMDA0_S_FULP_AN_TBBX_PFF_JTG_CAL_ALLFRV_SI_TBB_DCS | E16: 10.38 | G16: 10.56 | H16: 10.38 | J16: 10.56 | K16: 10.38 | M16: 10.56 | N16: 10.38 | P16: 10.56 | Q16: LV,HV | T16: LV,HV
... A19: MISC | B19: ATBOFMS | C19: PP_KMDA0_S_FULP_PW_PTSX_PFF_DAA_PWR_ALLFRV_SI_PWRCHAIN_ACC | E19: 22.26 | G19: 21.59 | H19: 22.26 | J19: 21.59 | K19: 22.26 | M19: 21.59 | N19: 22.26 | P19: 21.59 | Q19: LV,HV | T19: LV,HV

Sheet FRO
A2: Proposal for TTR | D2: Total (ms) | F2: =SUM(E5:G8) -> 14.13 | I2: =SUM(H5:J8) -> 14.13 | L2: =SUM(K5:M8) -> 14.13 | O2: =SUM(N5:P8) -> 14.13
E3: CP1 (ms) | H3: CP2 (ms) | K3: FT1 (ms) | N3: FT2 (ms)
A4: Category | B4: SubBlock | C4: Pattern | D4: Run If Fail | E4: LV | F4: NV | G4: HV | H4: LV | I4: NV | J4: HV | K4: LV | L4: NV | M4: HV | N4: LV | O4: NV | P4: HV | Q4: Prod CP1 | R4: Prod CP2 | S4: Prod FT1 | T4: Prod FT2 | U4: Mon | V4: T0Tx | W4: RMA Room | X4: RMA Hot
A5: FRO | B5: PDDBGFREQMEAS | C5: PP_KMDA0_S_FULP_AN_AR00_FRQ_JTG_FRQ_ALLFRV_SI_PDDBG_FREQMEAS | F5: 14.13 | I5: 14.13 | L5: 14.13 | O5: 14.13 | Q5: NV
A6: FRO | B6: MNPDDEBUG | C6: MN_KMDA0_S_FULP_AN_AR00_FRQ_JTG_FRQ_ALLFRV_SI_PD_DEBUG | U6: LV,HV
A7: FRO | B7: MNPDSEPFRO | C7: MN_KMDA0_S_FULP_AN_AR00_FRQ_JTG_FRQ_ALLFRV_SI_PD_SEPFRO | U7: LV,HV
A8: FRO | B8: MNPDSEPFRO2 | C8: MN_KMDA0_S_FULP_AN_AR00_FRQ_JTG_FRQ_ALLFRV_SI_PD_SEPFRO2 | U8: LV,HV

Sheet CPLL
A2: Proposal for TTR | D2: Total (ms) | F2: =SUM(E5:G80) -> 3466.52 | I2: =SUM(H5:J80) -> 3466.52 | L2: =SUM(K5:M80) -> 3466.52 | O2: =SUM(N5:P80) -> 3466.52
E3: CP1 (ms) | H3: CP2 (ms) | K3: FT1 (ms) | N3: FT2 (ms)
A4: Category | B4: SubBlock | C4: Pattern | D4: Run If Fail | E4: LV | F4: NV | G4: HV | H4: LV | I4: NV | J4: HV | K4: LV | L4: NV | M4: HV | N4: LV | O4: NV | P4: HV | Q4: Prod CP1 | R4: Prod CP2 | S4: Prod FT1 | T4: Prod FT2 | U4: Mon | V4: T0Tx | W4: RMA Room | X4: RMA Hot
A5: CPLL | B5: CPLLT0 | C5: PP_KMDA0_C_FULP_AN_AA00_DLL_JTG_VIX_ALLFRV_SI_CPLL_T0 | F5: 162.04 | I5: 162.04 | L5: 162.04 | O5: 162.04 | Q5: NV | S5: NV
A6: CPLL | B6: OTHER | C6: CPLL_T0_FUSE_PREWRITE_CAL | S6: NV
A7: CPLL | B7: OTHER | C7: CPLL_T0_FUSE_READ_CAL | T7: NV
A8: CPLL | B8: OTHER | C8: CPLL_T1_FUSE_PREWRITE_CAL | S8: NV
A9: CPLL | B9: OTHER | C9: CPLL_T1_FUSE_READ_CAL | T9: NV
A10: CPLL | B10: CPLLT1 | C10: PP_KMDA0_C_FULP_AN_AA00_DLL_JTG_VIX_ALLFRV_SI_CPLL_T1 | F10: 98 | I10: 98 | L10: 98 | O10: 98 | Q10: NV | S10: NV
A11: CPLL | B11: CPLLT2P105G | C11: PP_KMDA0_C_FULP_AN_AA00_DLL_JTG_VIX_ALLFRV_SI_CPLL_T2P105G | E11: 206.13 | G11: 198.84 | H11: 206.13 | J11: 198.84 | K11: 206.13 | M11: 198.84 | N11: 206.13 | P11: 198.84 | Q11: HV | T11: HV
A12: CPLL | B12: CPLLT2P108G | C12: PP_KMDA0_C_FULP_AN_AA00_DLL_JTG_VIX_ALLFRV_SI_CPLL_T2P108G | E12: 188.21 | G12: 190.85 | H12: 188.21 | J12: 190.85 | K12: 188.21 | M12: 190.85 | N12: 188.21 | P12: 190.85 | S12: HV
A13: CPLL | B13: CPLLT2P109G | C13: PP_KMDA0_C_FULP_AN_AA00_DLL_JTG_VIX_ALLFRV_SI_CPLL_T2P109G | E13: 208.82 | G13: 187.22 | H13: 208.82 | J13: 187.22 | K13: 208.82 | M13: 187.22 | N13: 208.82 | P13: 187.22 | T13: HV
A14: CPLL | B14: CPLLT2P110G | C14: PP_KMDA0_C_FULP_AN_AA00_DLL_JTG_VIX_ALLFRV_SI_CPLL_T2P110G | E14: 188.42 | G14: 199.9 | H14: 188.42 | J14: 199.9 | K14: 188.42 | M14: 199.9 | N14: 188.42 | P14: 199.9 | Q14: LV
A15: CPLL | B15: CPLLT2P111G | C15: PP_KMDA0_C_FULP_AN_AA00_DLL_JTG_VIX_ALLFRV_SI_CPLL_T2P111G | E15: 200.65 | G15: 202.81 | H15: 200.65 | J15: 202.81 | K15: 200.65 | M15: 202.81 | N15: 200.65 | P15: 202.81 | S15: LV
A16: CPLL | B16: CPLLT2P112G | C16: PP_KMDA0_C_FULP_AN_AA00_DLL_JTG_VIX_ALLFRV_SI_CPLL_T2P112G | E16: 188.4 | G16: 187.79 | H16: 188.4 | J16: 187.79 | K16: 188.4 | M16: 187.79 | N16: 188.4 | P16: 187.79 | S16: LV | T16: LV
A17: CPLL | B17: CPLLT3 | C17: PP_KMDA0_C_FULP_AN_AA00_DLL_JTG_VIX_ALLFRV_SI_CPLL_T3 | E17: 342.47 | G17: 335.14 | H17: 342.47 | J17: 335.14 | K17: 342.47 | M17: 335.14 | N17: 342.47 | P17: 335.14 | T17: HV
A18: CPLL | B18: CPLLT7 | C18: PP_KMDA0_C_FULP_AN_AA00_DLL_JTG_VIX_ALLFRV_SI_CPLL_T7 | E18: 49.31 | G18: 34.1 | H18: 49.31 | J18: 34.1 | K18: 49.31 | M18: 34.1 | N18: 49.31 | P18: 34.1 | T18: HV
A19: CPLL | B19: CPLLT13P108G | C19: PP_KMDA0_C_FULP_AN_AA00_DLL_JTG_VIX_ALLFRV_SI_CPLL_T13P108G | E19: 20.67 | G19: 17.59 | H19: 20.67 | J19: 17.59 | K19: 20.67 | M19: 17.59 | N19: 20.67 | P19: 17.59 | S19: LV
A20: CPLL | B20: CPLLT13P111G | C20: PP_KMDA0_C_FULP_AN_AA00_DLL_JTG_VIX_ALLFRV_SI_CPLL_T13P111G | E20: 20.93 | G20: 38.23 | H20: 20.93 | J20: 38.23 | K20: 20.93 | M20: 38.23 | N20: 20.93 | P20: 38.23
A21: CPLL | B21: MNCPLLT0 | C21: MN_KMDA0_C_FULP_AN_AA00_DLL_JTG_VIX_ALLFRV_SI_CPLL_T0 | U21: LV,HV
A22: CPLL | B22: MNCPLLT1 | C22: MN_KMDA0_C_FULP_AN_AA00_DLL_JTG_VIX_ALLFRV_SI_CPLL_T1 | U22: LV,HV
A23: CPLL | B23: MNCPLLT2P101G | C23: MN_KMDA0_C_FULP_AN_AA00_DLL_JTG_VIX_ALLFRV_SI_CPLL_T2P101G | U23: LV,HV
A24: CPLL | B24: MNCPLLT2P102G | C24: MN_KMDA0_C_FULP_AN_AA00_DLL_JTG_VIX_ALLFRV_SI_CPLL_T2P102G | U24: LV,HV
A25: CPLL | B25: MNCPLLT2P103G | C25: MN_KMDA0_C_FULP_AN_AA00_DLL_JTG_VIX_ALLFRV_SI_CPLL_T2P103G | U25: LV,HV
A26: CPLL | B26: MNCPLLT2P104G | C26: MN_KMDA0_C_FULP_AN_AA00_DLL_JTG_VIX_ALLFRV_SI_CPLL_T2P104G | U26: LV,HV
A27: CPLL | B27: MNCPLLT2P105G | C27: MN_KMDA0_C_FULP_AN_AA00_DLL_JTG_VIX_ALLFRV_SI_CPLL_T2P105G | U27: LV,HV
A28: CPLL | B28: MNCPLLT2P106G | C28: MN_KMDA0_C_FULP_AN_AA00_DLL_JTG_VIX_ALLFRV_SI_CPLL_T2P106G | U28: LV,HV
A29: CPLL | B29: MNCPLLT2P107G | C29: MN_KMDA0_C_FULP_AN_AA00_DLL_JTG_VIX_ALLFRV_SI_CPLL_T2P107G | U29: LV,HV
A30: CPLL | B30: MNCPLLT2P108G | C30: MN_KMDA0_C_FULP_AN_AA00_DLL_JTG_VIX_ALLFRV_SI_CPLL_T2P108G | U30: LV,HV
A31: CPLL | B31: MNCPLLT2P109G | C31: MN_KMDA0_C_FULP_AN_AA00_DLL_JTG_VIX_ALLFRV_SI_CPLL_T2P109G | U31: LV,HV
A32: CPLL | B32: MNCPLLT2P110G | C32: MN_KMDA0_C_FULP_AN_AA00_DLL_JTG_VIX_ALLFRV_SI_CPLL_T2P110G | U32: LV,HV
... A80: CPLL | B80: MNCPLLT13P810G | C80: MN_KMDA0_C_FULP_AN_AA00_DLL_JTG_VIX_ALLFRV_SI_CPLL_T13P810G | U80: LV,HV

Sheet ADCLK
A2: Proposal for TTR | D2: Total (ms) | F2: =SUM(E5:G57) -> 7787.42 | I2: =SUM(H5:J57) -> 7787.42 | L2: =SUM(K5:M57) -> 7787.42 | O2: =SUM(N5:P57) -> 7787.42
E3: CP1 (ms) | H3: CP2 (ms) | K3: FT1 (ms) | N3: FT2 (ms)
A4: Category | B4: SubBlock | C4: Pattern | D4: Run If Fail | E4: LV | F4: NV | G4: HV | H4: LV | I4: NV | J4: HV | K4: LV | L4: NV | M4: HV | N4: LV | O4: NV | P4: HV | Q4: Prod CP1 | R4: Prod CP2 | S4: Prod FT1 | T4: Prod FT2 | U4: Mon | V4: T0Tx | W4: RMA Room | X4: RMA Hot
A5: ADCLK | B5: ADCLKT1 | C5: PP_KMDA0_C_FULP_AN_AA01_DLL_JTG_CAL_ALLFRV_SI_ADCLK_T1 | F5: 27.32 | I5: 27.32 | L5: 27.32 | O5: 27.32 | Q5: NV | S5: NV
A6: ADCLK | B6: OTHER | C6: ADCLK_T1_FUSE_PREWRITE_CAL1 | S6: NV
A7: ADCLK | B7: OTHER | C7: ADCLK_T1_FUSE_PREWRITE_CAL2 | S7: NV
A8: ADCLK | B8: OTHER | C8: ADCLK_T1_FUSE_PREWRITE_CAL3 | S8: NV
A9: ADCLK | B9: OTHER | C9: ADCLK_T1_FUSE_READ_CAL1 | T9: NV
A10: ADCLK | B10: OTHER | C10: ADCLK_T1_FUSE_READ_CAL2 | T10: NV
A11: ADCLK | B11: OTHER | C11: ADCLK_T1_FUSE_READ_CAL3 | T11: NV
A12: ADCLK | B12: ADCLKT2P1P0B | C12: PP_KMDA0_C_FULP_AN_AA01_DLL_JTG_VIX_ALLFRV_SI_ADCLK_T2P1P0B | E12: 441.85 | G12: 436.87 | H12: 441.85 | J12: 436.87 | K12: 441.85 | M12: 436.87 | N12: 441.85 | P12: 436.87 | Q12: HV | T12: HV
A13: ADCLK | B13: ADCLKT2P2P | C13: PP_KMDA0_C_FULP_AN_AA01_DLL_JTG_VIX_ALLFRV_SI_ADCLK_T2P2P | E13: 414.5 | G13: 422.57 | H13: 414.5 | J13: 422.57 | K13: 414.5 | M13: 422.57 | N13: 414.5 | P13: 422.57 | Q13: LV | T13: LV
A14: ADCLK | B14: ADCLKT2P6P | C14: PP_KMDA0_C_FULP_AN_AA01_DLL_JTG_VIX_ALLFRV_SI_ADCLK_T2P6P | E14: 422.81 | G14: 411.16 | H14: 422.81 | J14: 411.16 | K14: 422.81 | M14: 411.16 | N14: 422.81 | P14: 411.16 | S14: LV
A15: ADCLK | B15: ADCLKT2P7P | C15: PP_KMDA0_C_FULP_AN_AA01_DLL_JTG_VIX_ALLFRV_SI_ADCLK_T2P7P | E15: 426.79 | G15: 428.5 | H15: 426.79 | J15: 428.5 | K15: 426.79 | M15: 428.5 | N15: 426.79 | P15: 428.5 | S15: LV
A16: ADCLK | B16: ADCLKT3 | C16: PP_KMDA0_C_FULP_AN_AA01_MEA_JTG_VMX_ALLFRV_SI_ADCLK_T3 | E16: 1155.04 | G16: 1181.74 | H16: 1155.04 | J16: 1181.74 | K16: 1155.04 | M16: 1181.74 | N16: 1155.04 | P16: 1181.74 | T16: HV
A17: ADCLK | B17: ADCLKT4 | C17: PP_KMDA0_C_FULP_AN_AA01_DLL_JTG_FRQ_ALLFRV_SI_ADCLK_T4 | E17: 41.48 | G17: 40.53 | H17: 41.48 | J17: 40.53 | K17: 41.48 | M17: 40.53 | N17: 41.48 | P17: 40.53 | S17: NV
A18: ADCLK | B18: ADCLKT7P1P | C18: PP_KMDA0_C_FULP_AN_AA01_MEA_JTG_LKK_ALLFRV_SI_ADCLK_T7P1P | E18: 112.41 | G18: 111.37 | H18: 112.41 | J18: 111.37 | K18: 112.41 | M18: 111.37 | N18: 112.41 | P18: 111.37
A19: ADCLK | B19: ADCLKT7P2P | C19: PP_KMDA0_C_FULP_AN_AA01_MEA_JTG_LKK_ALLFRV_SI_ADCLK_T7P2P | E19: 109.62 | G19: 97.11 | H19: 109.62 | J19: 97.11 | K19: 109.62 | M19: 97.11 | N19: 109.62 | P19: 97.11
A20: ADCLK | B20: ADCLKT7P3P | C20: PP_KMDA0_C_FULP_AN_AA01_MEA_JTG_LKK_ALLFRV_SI_ADCLK_T7P3P | E20: 99.9 | G20: 109.56 | H20: 99.9 | J20: 109.56 | K20: 99.9 | M20: 109.56 | N20: 99.9 | P20: 109.56 | Q20: LV | T20: HV
A21: ADCLK | B21: ADCLKT7P4P | C21: PP_KMDA0_C_FULP_AN_AA01_MEA_JTG_LKK_ALLFRV_SI_ADCLK_T7P4P | E21: 111.29 | G21: 95.77 | H21: 111.29 | J21: 95.77 | K21: 111.29 | M21: 95.77 | N21: 111.29 | P21: 95.77
A22: ADCLK | B22: ADCLKT7P5P | C22: PP_KMDA0_C_FULP_AN_AA01_MEA_JTG_LKK_ALLFRV_SI_ADCLK_T7P5P | E22: 111.16 | G22: 110.57 | H22: 111.16 | J22: 110.57 | K22: 111.16 | M22: 110.57 | N22: 111.16 | P22: 110.57
A23: ADCLK | B23: ADCLKT7P6P | C23: PP_KMDA0_C_FULP_AN_AA01_MEA_JTG_LKK_ALLFRV_SI_ADCLK_T7P6P | E23: 94.74 | G23: 110.52 | H23: 94.74 | J23: 110.52 | K23: 94.74 | M23: 110.52 | N23: 94.74 | P23: 110.52
A24: ADCLK | B24: ADCLKT11 | C24: PP_KMDA0_C_FULP_AN_AA01_MEA_JTG_DYC_ALLFRV_SI_ADCLK_T11 | E24: 98.22 | G24: 95.79 | H24: 98.22 | J24: 95.79 | K24: 98.22 | M24: 95.79 | N24: 98.22 | P24: 95.79 | S24: LV
A25: ADCLK | B25: ADCLKT14 | C25: PP_KMDA0_C_FULP_AN_AA01_MEA_JTG_DYC_ALLFRV_SI_ADCLK_T14 | E25: 136.51 | G25: 124.56 | H25: 136.51 | J25: 124.56 | K25: 136.51 | M25: 124.56 | N25: 136.51 | P25: 124.56 | T25: HV
A26: ADCLK | B26: ADCLKT15 | C26: PP_KMDA0_C_FULP_AN_AA01_MEA_JTG_DYC_ALLFRV_SI_ADCLK_T15 | E26: 53.78 | G26: 73.52 | H26: 53.78 | J26: 73.52 | K26: 53.78 | M26: 73.52 | N26: 53.78 | P26: 73.52 | T26: HV
A27: ADCLK | B27: ADCLKT16 | C27: PP_KMDA0_C_FULP_AN_AA01_MEA_JTG_DYC_ALLFRV_SI_ADCLK_T16 | E27: 40.65 | G27: 39.21 | H27: 40.65 | J27: 39.21 | K27: 40.65 | M27: 39.21 | N27: 40.65 | P27: 39.21 | S27: LV
A28: ADCLK | B28: MNADCLKT2P1P0B | C28: MN_KMDA0_C_FULP_AN_AA01_DLL_JTG_VIX_ALLFRV_SI_ADCLK_T2P1P0B | U28: LV,HV
A29: ADCLK | B29: MNADCLKT2P1PHB | C29: MN_KMDA0_C_FULP_AN_AA01_DLL_JTG_VIX_ALLFRV_SI_ADCLK_T2P1PHB | U29: LV,HV
A30: ADCLK | B30: MNADCLKT2P1PQB | C30: MN_KMDA0_C_FULP_AN_AA01_DLL_JTG_VIX_ALLFRV_SI_ADCLK_T2P1PQB | U30: LV,HV
A31: ADCLK | B31: MNADCLKT2P2PHB | C31: MN_KMDA0_C_FULP_AN_AA01_DLL_JTG_VIX_ALLFRV_SI_ADCLK_T2P2PHB | U31: LV,HV
A32: ADCLK | B32: MNADCLKT2P2PQB | C32: MN_KMDA0_C_FULP_AN_AA01_DLL_JTG_VIX_ALLFRV_SI_ADCLK_T2P2PQB | U32: LV,HV
A33: ADCLK | B33: MNADCLKT2P2P | C33: MN_KMDA0_C_FULP_AN_AA01_DLL_JTG_VIX_ALLFRV_SI_ADCLK_T2P2P | U33: LV,HV
A34: ADCLK | B34: MNADCLKT2P3PHB | C34: MN_KMDA0_C_FULP_AN_AA01_DLL_JTG_VIX_ALLFRV_SI_ADCLK_T2P3PHB | U34: LV,HV
A35: ADCLK | B35: MNADCLKT2P3PQB | C35: MN_KMDA0_C_FULP_AN_AA01_DLL_JTG_VIX_ALLFRV_SI_ADCLK_T2P3PQB | U35: LV,HV
A36: ADCLK | B36: MNADCLKT2P3P | C36: MN_KMDA0_C_FULP_AN_AA01_DLL_JTG_VIX_ALLFRV_SI_ADCLK_T2P3P | U36: LV,HV
A37: ADCLK | B37: MNADCLKT2P4PHB | C37: MN_KMDA0_C_FULP_AN_AA01_DLL_JTG_VIX_ALLFRV_SI_ADCLK_T2P4PHB | U37: LV,HV
A38: ADCLK | B38: MNADCLKT2P4P | C38: MN_KMDA0_C_FULP_AN_AA01_DLL_JTG_VIX_ALLFRV_SI_ADCLK_T2P4P | U38: LV,HV
A39: ADCLK | B39: MNADCLKT2P5P | C39: MN_KMDA0_C_FULP_AN_AA01_DLL_JTG_VIX_ALLFRV_SI_ADCLK_T2P5P | U39: LV,HV
... A57: ADCLK | B57: MNADCLKT8P4P | C57: MN_KMDA0_C_FULP_AN_AA01_MEA_JTG_LKK_ALLFRV_SI_ADCLK_T8P4P | U57: LV,HV

Sheet LAPLL
A2: Proposal for TTR | D2: Total (ms) | F2: =SUM(E5:G55) -> 4584.36 | I2: =SUM(H5:J55) -> 4584.36 | L2: =SUM(K5:M55) -> 4584.36 | O2: =SUM(N5:P55) -> 4584.36
E3: CP1 (ms) | H3: CP2 (ms) | K3: FT1 (ms) | N3: FT2 (ms)
A4: Category | B4: SubBlock | C4: Pattern | D4: Run If Fail | E4: LV | F4: NV | G4: HV | H4: LV | I4: NV | J4: HV | K4: LV | L4: NV | M4: HV | N4: LV | O4: NV | P4: HV | Q4: Prod CP1 | R4: Prod CP2 | S4: Prod FT1 | T4: Prod FT2 | U4: Mon | V4: T0Tx | W4: RMA Room | X4: RMA Hot
A5: LAPLL | B5: LAPLLT2P1S | C5: PP_KMDA0_C_FULP_AN_AA06_DLL_JTG_VIX_ALLFRV_SI_LAPLL_T2P1S | E5: 194.25 | G5: 203.02 | H5: 194.25 | J5: 203.02 | K5: 194.25 | M5: 203.02 | N5: 194.25 | P5: 203.02 | Q5: LV,HV | R5: LV,HV | S5: LV,HV | T5: LV,HV
A6: LAPLL | B6: LAPLLT2P2S | C6: PP_KMDA0_C_FULP_AN_AA06_DLL_JTG_VIX_ALLFRV_SI_LAPLL_T2P2S | E6: 200.31 | G6: 200.86 | H6: 200.31 | J6: 200.86 | K6: 200.31 | M6: 200.86 | N6: 200.31 | P6: 200.86 | Q6: LV,HV | R6: LV,HV | S6: LV,HV | T6: LV,HV
A7: LAPLL | B7: LAPLLT2P3S | C7: PP_KMDA0_C_FULP_AN_AA06_DLL_JTG_VIX_ALLFRV_SI_LAPLL_T2P3S | E7: 193.89 | G7: 192.62 | H7: 193.89 | J7: 192.62 | K7: 193.89 | M7: 192.62 | N7: 193.89 | P7: 192.62 | Q7: LV,HV | R7: LV,HV | S7: LV,HV | T7: LV,HV
A8: LAPLL | B8: LAPLLT2P4S | C8: PP_KMDA0_C_FULP_AN_AA06_DLL_JTG_VIX_ALLFRV_SI_LAPLL_T2P4S | E8: 194.74 | G8: 194.66 | H8: 194.74 | J8: 194.66 | K8: 194.74 | M8: 194.66 | N8: 194.74 | P8: 194.66 | Q8: LV,HV | R8: LV,HV | S8: LV,HV | T8: LV,HV
A9: LAPLL | B9: LAPLLT2P5S | C9: PP_KMDA0_C_FULP_AN_AA06_DLL_JTG_VIX_ALLFRV_SI_LAPLL_T2P5S | E9: 178.25 | G9: 179.64 | H9: 178.25 | J9: 179.64 | K9: 178.25 | M9: 179.64 | N9: 178.25 | P9: 179.64 | Q9: LV,HV | R9: LV,HV | S9: LV,HV | T9: LV,HV
A10: LAPLL | B10: LAPLLT2P6S | C10: PP_KMDA0_C_FULP_AN_AA06_DLL_JTG_VIX_ALLFRV_SI_LAPLL_T2P6S | E10: 196.96 | G10: 194.22 | H10: 196.96 | J10: 194.22 | K10: 196.96 | M10: 194.22 | N10: 196.96 | P10: 194.22 | Q10: LV,HV | R10: LV,HV | S10: LV,HV | T10: LV,HV
A11: LAPLL | B11: LAPLLT2P7S | C11: PP_KMDA0_C_FULP_AN_AA06_DLL_JTG_VIX_ALLFRV_SI_LAPLL_T2P7S | E11: 193.46 | G11: 192.23 | H11: 193.46 | J11: 192.23 | K11: 193.46 | M11: 192.23 | N11: 193.46 | P11: 192.23 | Q11: LV,HV | R11: LV,HV | S11: LV,HV | T11: LV,HV
A12: LAPLL | B12: LAPLLT2P8S | C12: PP_KMDA0_C_FULP_AN_AA06_DLL_JTG_VIX_ALLFRV_SI_LAPLL_T2P8S | E12: 201.89 | G12: 193.32 | H12: 201.89 | J12: 193.32 | K12: 201.89 | M12: 193.32 | N12: 201.89 | P12: 193.32 | Q12: LV,HV | R12: LV,HV | S12: LV,HV | T12: LV,HV
A13: LAPLL | B13: LAPLLT2P9S | C13: PP_KMDA0_C_FULP_AN_AA06_DLL_JTG_VIX_ALLFRV_SI_LAPLL_T2P9S | E13: 206.85 | G13: 198.28 | H13: 206.85 | J13: 198.28 | K13: 206.85 | M13: 198.28 | N13: 206.85 | P13: 198.28 | Q13: LV,HV | R13: LV,HV | S13: LV,HV | T13: LV,HV
A14: LAPLL | B14: LAPLLT2P10S | C14: PP_KMDA0_C_FULP_AN_AA06_DLL_JTG_VIX_ALLFRV_SI_LAPLL_T2P10S | E14: 199.35 | G14: 203.88 | H14: 199.35 | J14: 203.88 | K14: 199.35 | M14: 203.88 | N14: 199.35 | P14: 203.88 | Q14: LV,HV | R14: LV,HV | S14: LV,HV | T14: LV,HV
A15: LAPLL | B15: LAPLLT3 | C15: PP_KMDA0_C_FULP_AN_AA06_MEA_JTG_IMX_ALLFRV_SI_LAPLL_T3 | E15: 287 | G15: 287.68 | H15: 287 | J15: 287.68 | K15: 287 | M15: 287.68 | N15: 287 | P15: 287.68 | Q15: LV,HV | R15: LV,HV | S15: LV,HV | T15: LV,HV
A16: LAPLL | B16: LAPLLT4 | C16: PP_KMDA0_C_FULP_AN_AA06_DLL_JTG_FRQ_ALLFRV_SI_LAPLL_T4 | E16: 21.1 | G16: 19.79 | H16: 21.1 | J16: 19.79 | K16: 21.1 | M16: 19.79 | N16: 21.1 | P16: 19.79 | Q16: LV,HV | R16: LV,HV | S16: LV,HV | T16: LV,HV
A17: LAPLL | B17: LAPLLT12 | C17: PP_KMDA0_C_FULP_AN_AA06_DLL_JTG_VIX_ALLFRV_SI_LAPLL_T12 | E17: 25.87 | G17: 30.24 | H17: 25.87 | J17: 30.24 | K17: 25.87 | M17: 30.24 | N17: 25.87 | P17: 30.24 | Q17: LV,HV | R17: LV,HV | S17: LV,HV | T17: LV,HV
A18: LAPLL | B18: MNLAPLLT2P1S | C18: MN_KMDA0_C_FULP_AN_AA06_DLL_JTG_VIX_ALLFRV_SI_LAPLL_T2P1S | U18: LV,HV
A19: LAPLL | B19: MNLAPLLT2P2S | C19: MN_KMDA0_C_FULP_AN_AA06_DLL_JTG_VIX_ALLFRV_SI_LAPLL_T2P2S | U19: LV,HV
A20: LAPLL | B20: MNLAPLLT2P3S | C20: MN_KMDA0_C_FULP_AN_AA06_DLL_JTG_VIX_ALLFRV_SI_LAPLL_T2P3S | U20: LV,HV
A21: LAPLL | B21: MNLAPLLT2P4S | C21: MN_KMDA0_C_FULP_AN_AA06_DLL_JTG_VIX_ALLFRV_SI_LAPLL_T2P4S | U21: LV,HV
A22: LAPLL | B22: MNLAPLLT2P5S | C22: MN_KMDA0_C_FULP_AN_AA06_DLL_JTG_VIX_ALLFRV_SI_LAPLL_T2P5S | U22: LV,HV
A23: LAPLL | B23: MNLAPLLT2P6S | C23: MN_KMDA0_C_FULP_AN_AA06_DLL_JTG_VIX_ALLFRV_SI_LAPLL_T2P6S | U23: LV,HV
A24: LAPLL | B24: MNLAPLLT2P7S | C24: MN_KMDA0_C_FULP_AN_AA06_DLL_JTG_VIX_ALLFRV_SI_LAPLL_T2P7S | U24: LV,HV
A25: LAPLL | B25: MNLAPLLT2P8S | C25: MN_KMDA0_C_FULP_AN_AA06_DLL_JTG_VIX_ALLFRV_SI_LAPLL_T2P8S | U25: LV,HV
A26: LAPLL | B26: MNLAPLLT2P9S | C26: MN_KMDA0_C_FULP_AN_AA06_DLL_JTG_VIX_ALLFRV_SI_LAPLL_T2P9S | U26: LV,HV
A27: LAPLL | B27: MNLAPLLT2P10S | C27: MN_KMDA0_C_FULP_AN_AA06_DLL_JTG_VIX_ALLFRV_SI_LAPLL_T2P10S | U27: LV,HV
A28: LAPLL | B28: MNLAPLLT2P11S | C28: MN_KMDA0_C_FULP_AN_AA06_DLL_JTG_VIX_ALLFRV_SI_LAPLL_T2P11S | U28: LV,HV
A29: LAPLL | B29: MNLAPLLT2P12S | C29: MN_KMDA0_C_FULP_AN_AA06_DLL_JTG_VIX_ALLFRV_SI_LAPLL_T2P12S | U29: LV,HV
... A55: LAPLL | B55: MNLAPLLT12 | C55: MN_KMDA0_C_FULP_AN_AA06_DLL_JTG_VIX_ALLFRV_SI_LAPLL_T12 | U55: LV,HV

Sheet PCIEREFGEN
A2: Proposal for TTR | D2: Total (ms) | F2: =SUM(E5:G16) -> 3739.7 | I2: =SUM(H5:J16) -> 3739.7 | L2: =SUM(K5:M16) -> 3739.7 | O2: =SUM(N5:P16) -> 3739.7
E3: CP1 (ms) | H3: CP2 (ms) | K3: FT1 (ms) | N3: FT2 (ms)
A4: Category | B4: SubBlock | C4: Pattern | D4: HIP_FailRun | E4: LV | F4: NV | G4: HV | H4: LV | I4: NV | J4: HV | K4: LV | L4: NV | M4: HV | N4: LV | O4: NV | P4: HV | Q4: Prod CP1 | R4: Prod CP2 | S4: Prod FT1 | T4: Prod FT2 | U4: Mon | V4: T0Tx | W4: RMA Room | X4: RMA Hot
A5: PCIEREFGEN | B5: REFGENCMNTRIMBGCOARSEMOSI | C5: PP_KMDA0_S_FULP_AN_REFG_MEA_JTG_CAL_ALLFRV_SI_REFGEN_T1 | F5: 28.8 | I5: 28.8 | L5: 28.8 | O5: 28.8 | Q5: NV | S5: NV
A6: PCIEREFGEN | B6: OTHER | C6: PCIEREFGEN_FUSE_PREWRITE_REFGEN_0_MOS_TRIM_I | S6: NV
A7: PCIEREFGEN | B7: OTHER | C7: PCIEREFGEN_FUSE_READ_REFGEN_0_MOS_TRIM_I | T7: NV
A8: PCIEREFGEN | B8: OTHER | C8: PCIEREFGEN_FUSE_PREWRITE_FINE_MOS | S8: NV
A9: PCIEREFGEN | B9: OTHER | C9: PCIEREFGEN_FUSE_READ_FUSE_PREWRITE_FINE_MOS | T9: NV
A10: PCIEREFGEN | B10: OTHER | C10: PCIEREFGEN_SOCREFGEN_FUSE_PREWRITE_REFGEN_0_BJT_TRIM_V | S10: NV
A11: PCIEREFGEN | B11: OTHER | C11: PCIEREFGEN_SOCREFGEN_FUSE_READ_REFGEN_0_BJT_TRIM_V | T11: NV
A12: PCIEREFGEN | B12: REFGENT2P1FINEMOSRUNNVFLOWONLY | C12: PP_KMDA0_S_FULP_AN_REFG_MEA_JTG_CAL_ALLFRV_SI_REFGEN_T2P1 | F12: 117.62 | I12: 117.62 | L12: 117.62 | O12: 117.62 | Q12: NV | S12: NV
A13: PCIEREFGEN | B13: PCIEREFGENCMNTRIMBGFINE | C13: PP_KMDA0_S_FULP_AN_REFG_MEA_JTG_CAL_ALLFRV_SI_REFGEN_T2P2 | F13: 46.95 | I13: 46.95 | L13: 46.95 | O13: 46.95
A14: PCIEREFGEN | B14: REFGENCMNTRIMV2I | C14: PP_KMDA0_S_FULP_AN_REFG_MEA_JTG_CAL_ALLFRV_SI_REFGEN_T3 | F14: 1812.45 | I14: 1812.45 | L14: 1812.45 | O14: 1812.45
A15: PCIEREFGEN | B15: REFGENT4P1MOSANALOGTESTPOINTS | C15: PP_KMDA0_S_FULP_AN_REFG_MEA_JTG_CAL_ALLFRV_SI_REFGEN_T4P1 | F15: 881.21 | I15: 881.21 | L15: 881.21 | O15: 881.21
A16: PCIEREFGEN | B16: REFGENT4P2BJTANALOGTESTPOINTS | C16: PP_KMDA0_S_FULP_AN_REFG_MEA_JTG_CAL_ALLFRV_SI_REFGEN_T4P2 | F16: 852.67 | I16: 852.67 | L16: 852.67 | O16: 852.67

Sheet PCIE5CMN
A2: Proposal for TTR | D2: Total (ms) | F2: =SUM(E5:G18) -> 838.88 | I2: =SUM(H5:J18) -> 838.88 | L2: =SUM(K5:M18) -> 838.88 | O2: =SUM(N5:P18) -> 838.88
E3: CP1 (ms) | H3: CP2 (ms) | K3: FT1 (ms) | N3: FT2 (ms)
A4: Category | B4: SubBlock | C4: Pattern | D4: HIP_FailRun | E4: LV | F4: NV | G4: HV | H4: LV | I4: NV | J4: HV | K4: LV | L4: NV | M4: HV | N4: LV | O4: NV | P4: HV | Q4: Prod CP1 | R4: Prod CP2 | S4: Prod FT1 | T4: Prod FT2 | U4: Mon | V4: T0Tx | W4: RMA Room | X4: RMA Hot
A5: PCIE5CMN | B5: PCIE5CMNTRIMBGCOARSE_MULTIPLE | C5: PP_KMDA0_S_FULP_AN_P5CM_MEA_JTG_CAL_ALLFRV_SI_CMNTRIM_BGCOARSE | F5: 34.14 | I5: 34.14 | L5: 34.14 | O5: 34.14 | Q5: NV | S5: NV
A6: PCIE5CMN | B6: PCIE5CMNTRIMBGFINE_MULTIPLE | C6: PP_KMDA0_S_FULP_AN_P5CM_MEA_JTG_CAL_ALLFRV_SI_CMNTRIM_BGFINE | F6: 36.44 | I6: 36.44 | L6: 36.44 | O6: 36.44 | Q6: NV | S6: NV
A7: PCIE5CMN | B7: OTHER | C7: PCIE5CMN_PCIE5_BGFINE_FUSE_PREWRITE_CAL | S7: NV
A8: PCIE5CMN | B8: OTHER | C8: PCIE5CMN_PCIE5_BGFINE_FUSE_READ_CAL | T8: NV
A9: PCIE5CMN | B9: OTHER | C9: PCIE5CMN_PCIE5_MOSI_FUSE_PREWRITE_CAL | S9: NV
A10: PCIE5CMN | B10: OTHER | C10: PCIE5CMN_PCIE5_MOSI_FUSE_READ_CAL | T10: NV
A11: PCIE5CMN | B11: OTHER | C11: PCIE5CMN_PCIE5_MOSV_FUSE_PREWRITE_CAL | S11: NV
A12: PCIE5CMN | B12: OTHER | C12: PCIE5CMN_PCIE5_MOSV_FUSE_READ_CAL | T12: NV
A13: PCIE5CMN | B13: OTHER | C13: PCIE5CMN_PCIE5_VREGTRIM_FUSE_PREWRITE_CAL | S13: NV
A14: PCIE5CMN | B14: OTHER | C14: PCIE5CMN_PCIE5_VREGTRIM_FUSE_READ_CAL | T14: NV
A15: PCIE5CMN | B15: PCIE5CMNTRIMV2I_MULTIPLE | C15: PP_KMDA0_S_FULP_AN_P5CM_MEA_JTG_CAL_ALLFRV_SI_CMNTRIM_V2I | F15: 33.33 | I15: 33.33 | L15: 33.33 | O15: 33.33 | Q15: NV | S15: NV
A16: PCIE5CMN | B16: PCIE5CMNTRIMMOSI_MULTIPLE | C16: PP_KMDA0_S_FULP_AN_P5CM_MEA_JTG_CAL_ALLFRV_SI_CMNTRIM_MOSI | F16: 34.94 | I16: 34.94 | L16: 34.94 | O16: 34.94 | Q16: NV | S16: NV
A17: PCIE5CMN | B17: PCIE5CMNTRIMMOSV_MULTIPLE | C17: PP_KMDA0_S_FULP_AN_P5CM_MEA_JTG_CAL_ALLFRV_SI_CMNTRIM_MOSV | F17: 173.39 | I17: 173.39 | L17: 173.39 | O17: 173.39 | Q17: NV | S17: NV
A18: PCIE5CMN | B18: PCIE5CMNTRIMVREGTRIM_MULTIPLE | C18: PP_KMDA0_S_FULP_AN_P5CM_MEA_JTG_CAL_ALLFRV_SI_CMNTRIM_VREGTRIM | F18: 526.64 | I18: 526.64 | L18: 526.64 | O18: 526.64 | Q18: NV | S18: NV

Sheet ACIPHYCMN
A2: Proposal for TTR | D2: Total (ms) | F2: =SUM(E5:G18) -> 370.94 | I2: =SUM(H5:J18) -> 370.94 | L2: =SUM(K5:M18) -> 370.94 | O2: =SUM(N5:P18) -> 370.94
E3: CP1 (ms) | H3: CP2 (ms) | K3: FT1 (ms) | N3: FT2 (ms)
A4: Category | B4: SubBlock | C4: Pattern | D4: HIP_FailRun | E4: LV | F4: NV | G4: HV | H4: LV | I4: NV | J4: HV | K4: LV | L4: NV | M4: HV | N4: LV | O4: NV | P4: HV | Q4: Prod CP1 | R4: Prod CP2 | S4: Prod FT1 | T4: Prod FT2 | U4: Mon | V4: T0Tx | W4: RMA Room | X4: RMA Hot
A5: ACIPHYCMN | B5: ACIPHYCMNTRIMBGCOARSE_MULTIPLE | C5: PP_KMDA0_S_FULP_AN_RXCM_MEA_JTG_CAL_ALLFRV_SI_CMNTRIM_BGCOARSE | F5: 27.97 | I5: 27.97 | L5: 27.97 | O5: 27.97 | Q5: NV | S5: NV
A6: ACIPHYCMN | B6: ACIPHYCMNTRIMBGFINE_MULTIPLE | C6: PP_KMDA0_S_FULP_AN_RXCM_MEA_JTG_CAL_ALLFRV_SI_CMNTRIM_BGFINE | F6: 32.03 | I6: 32.03 | L6: 32.03 | O6: 32.03 | Q6: NV | S6: NV
A7: ACIPHYCMN | B7: OTHER | C7: ACIPHYCMN_ACIPHY_BGFINE_FUSE_PREWRITE_CAL | S7: NV
A8: ACIPHYCMN | B8: OTHER | C8: ACIPHYCMN_ACIPHY_BGFINE_FUSE_READ_CAL | T8: NV
A9: ACIPHYCMN | B9: OTHER | C9: ACIPHYCMN_ACIPHY_MOSI_FUSE_PREWRITE_CAL | S9: NV
A10: ACIPHYCMN | B10: OTHER | C10: ACIPHYCMN_ACIPHY_MOSI_FUSE_READ_CAL | T10: NV
A11: ACIPHYCMN | B11: OTHER | C11: ACIPHYCMN_ACIPHY_MOSV_FUSE_PREWRITE_CAL | S11: NV
A12: ACIPHYCMN | B12: OTHER | C12: ACIPHYCMN_ACIPHY_MOSV_FUSE_READ_CAL | T12: NV
A13: ACIPHYCMN | B13: OTHER | C13: ACIPHYCMN_ACIPHY_VREGTRIM_FUSE_PREWRITE_CAL | S13: NV
A14: ACIPHYCMN | B14: OTHER | C14: ACIPHYCMN_ACIPHY_VREGTRIM_FUSE_READ_CAL | T14: NV
A15: ACIPHYCMN | B15: ACIPHYCMNTRIMV2I_MULTIPLE | C15: PP_KMDA0_S_FULP_AN_RXCM_MEA_JTG_CAL_ALLFRV_SI_CMNTRIM_V2I | F15: 28.26 | I15: 28.26 | L15: 28.26 | O15: 28.26 | Q15: NV | S15: NV
A16: ACIPHYCMN | B16: ACIPHYCMNTRIMMOSI_MULTIPLE | C16: PP_KMDA0_S_FULP_AN_RXCM_MEA_JTG_CAL_ALLFRV_SI_CMNTRIM_MOSI | F16: 41.23 | I16: 41.23 | L16: 41.23 | O16: 41.23 | Q16: NV | S16: NV
A17: ACIPHYCMN | B17: ACIPHYCMNTRIMMOSV_MULTIPLE | C17: PP_KMDA0_S_FULP_AN_RXCM_MEA_JTG_CAL_ALLFRV_SI_CMNTRIM_MOSV | F17: 123.19 | I17: 123.19 | L17: 123.19 | O17: 123.19 | Q17: NV | S17: NV
A18: ACIPHYCMN | B18: ACIPHYCMNVREGTRIM_MULTIPLE | C18: PP_KMDA0_S_FULP_AN_RXCM_MEA_JTG_VMX_ALLFRV_SI_CMN_VREGTRIM | F18: 118.26 | I18: 118.26 | L18: 118.26 | O18: 118.26 | Q18: NV | S18: NV

Sheet ACIOPHYCMN
A2: Proposal for TTR | D2: Total (ms) | F2: =SUM(E5:G18) -> 519.85 | I2: =SUM(H5:J18) -> 519.85 | L2: =SUM(K5:M18) -> 519.85 | O2: =SUM(N5:P18) -> 519.85
E3: CP1 (ms) | H3: CP2 (ms) | K3: FT1 (ms) | N3: FT2 (ms)
A4: Category | B4: SubBlock | C4: Pattern | D4: HIP_FailRun | E4: LV | F4: NV | G4: HV | H4: LV | I4: NV | J4: HV | K4: LV | L4: NV | M4: HV | N4: LV | O4: NV | P4: HV | Q4: Prod CP1 | R4: Prod CP2 | S4: Prod FT1 | T4: Prod FT2 | U4: Mon | V4: T0Tx | W4: RMA Room | X4: RMA Hot
A5: ACIOPHYCMN | B5: ACIOPHYCMNTRIMBGCOARSE_MULTIPLE | C5: PP_KMDA0_S_FULP_AN_CICM_MEA_JTG_CAL_ALLFRV_SI_CMNTRIM_BGCOARSE | F5: 38.89 | I5: 38.89 | L5: 38.89 | O5: 38.89 | Q5: NV | S5: NV
A6: ACIOPHYCMN | B6: ACIOPHYCMNTRIMBGFINE_MULTIPLE | C6: PP_KMDA0_S_FULP_AN_CICM_MEA_JTG_CAL_ALLFRV_SI_CMNTRIM_BGFINE | F6: 41.5 | I6: 41.5 | L6: 41.5 | O6: 41.5 | Q6: NV | S6: NV
A7: ACIOPHYCMN | B7: OTHER | C7: ACIOPHYCMN_ACIOPHY_BGFINE_FUSE_PREWRITE_CAL | S7: NV
A8: ACIOPHYCMN | B8: OTHER | C8: ACIOPHYCMN_ACIOPHY_BGFINE_FUSE_READ_CAL | T8: NV
A9: ACIOPHYCMN | B9: OTHER | C9: ACIOPHYCMN_ACIOPHY_MOSI_FUSE_PREWRITE_CAL | S9: NV
A10: ACIOPHYCMN | B10: OTHER | C10: ACIOPHYCMN_ACIOPHY_MOSI_FUSE_READ_CAL | T10: NV
A11: ACIOPHYCMN | B11: OTHER | C11: ACIOPHYCMN_ACIOPHY_MOSV_FUSE_PREWRITE_CAL | S11: NV
A12: ACIOPHYCMN | B12: OTHER | C12: ACIOPHYCMN_ACIOPHY_MOSV_FUSE_READ_CAL | T12: NV
A13: ACIOPHYCMN | B13: OTHER | C13: ACIOPHYCMN_ACIOPHY_VREGTRIM_FUSE_PREWRITE_CAL | S13: NV
A14: ACIOPHYCMN | B14: OTHER | C14: ACIOPHYCMN_ACIOPHY_VREGTRIM_FUSE_READ_CAL | T14: NV
A15: ACIOPHYCMN | B15: ACIOPHYCMNTRIMV2I_MULTIPLE | C15: PP_KMDA0_S_FULP_AN_CICM_MEA_JTG_CAL_ALLFRV_SI_CMNTRIM_V2I | F15: 37.78 | I15: 37.78 | L15: 37.78 | O15: 37.78 | Q15: NV | S15: NV
A16: ACIOPHYCMN | B16: ACIOPHYCMNTRIMMOSI_MULTIPLE | C16: PP_KMDA0_S_FULP_AN_CICM_MEA_JTG_CAL_ALLFRV_SI_CMNTRIM_MOSI | F16: 51.61 | I16: 51.61 | L16: 51.61 | O16: 51.61 | Q16: NV | S16: NV
A17: ACIOPHYCMN | B17: ACIOPHYCMNTRIMMOSV_MULTIPLE | C17: PP_KMDA0_S_FULP_AN_CICM_MEA_JTG_CAL_ALLFRV_SI_CMNTRIM_MOSV | F17: 186.4 | I17: 186.4 | L17: 186.4 | O17: 186.4 | Q17: NV | S17: NV
A18: ACIOPHYCMN | B18: CMNTRIMVREGTRIM_MULTIPLE | C18: PP_KMDA0_S_FULP_AN_CICM_MEA_JTG_CAL_ALLFRV_SI_CMNTRIM_VREGTRIM | F18: 163.67 | I18: 163.67 | L18: 163.67 | O18: 163.67 | Q18: NV | S18: NV

Sheet LPDPTXCMN
A2: Proposal for TTR | D2: Total (ms) | F2: =SUM(E5:G18) -> 381.59 | I2: =SUM(H5:J18) -> 381.59 | L2: =SUM(K5:M18) -> 381.59 | O2: =SUM(N5:P18) -> 381.59
E3: CP1 (ms) | H3: CP2 (ms) | K3: FT1 (ms) | N3: FT2 (ms)
A4: Category | B4: SubBlock | C4: Pattern | D4: HIP_FailRun | E4: LV | F4: NV | G4: HV | H4: LV | I4: NV | J4: HV | K4: LV | L4: NV | M4: HV | N4: LV | O4: NV | P4: HV | Q4: Prod CP1 | R4: Prod CP2 | S4: Prod FT1 | T4: Prod FT2 | U4: Mon | V4: T0Tx | W4: RMA Room | X4: RMA Hot
A5: LPDPTXCMN | B5: LPDPTXCMNTRIMBGCOARSE_MULTIPLE | C5: PP_KMDA0_S_FULP_AN_TXCM_MEA_JTG_CAL_ALLFRV_SI_CMNTRIM_BGCOARSE | F5: 27.39 | I5: 27.39 | L5: 27.39 | O5: 27.39 | Q5: NV | S5: NV
A6: LPDPTXCMN | B6: LPDPTXCMNTRIMBGFINE_MULTIPLE | C6: PP_KMDA0_S_FULP_AN_TXCM_MEA_JTG_CAL_ALLFRV_SI_CMNTRIM_BGFINE | F6: 28.7 | I6: 28.7 | L6: 28.7 | O6: 28.7 | Q6: NV | S6: NV
A7: LPDPTXCMN | B7: OTHER | C7: LPDPTXCMN_LPDPTX_FUSE_PREWRITE_REFGEN_0_BJT_TRIM_V | S7: NV
A8: LPDPTXCMN | B8: OTHER | C8: LPDPTXCMN_LPDPTX_FUSE_READ_REFGEN_0_BJT_TRIM_V | T8: NV
A9: LPDPTXCMN | B9: OTHER | C9: LPDPTXCMN_LPDPTX_FUSE_PREWRITE_REFGEN_0_MOS_TRIM_I | S9: NV
A10: LPDPTXCMN | B10: OTHER | C10: LPDPTXCMN_LPDPTX_FUSE_READ_REFGEN_0_MOS_TRIM_I | T10: NV
A11: LPDPTXCMN | B11: OTHER | C11: LPDPTXCMN_LPDPTX_FUSE_PREWRITE_FINE_MOS | S11: NV
A12: LPDPTXCMN | B12: OTHER | C12: LPDPTXCMN_LPDPTX_FUSE_READ_FUSE_PREWRITE_FINE_MOS | T12: NV
A13: LPDPTXCMN | B13: OTHER | C13: LPDPTXCMN_LPDPTX_FUSE_PREWRITE_CMN_VREG | S13: NV
A14: LPDPTXCMN | B14: OTHER | C14: LPDPTXCMN_LPDPTX_FUSE_READ_FUSE_PREWRITE_CMN_VREG | T14: NV
A15: LPDPTXCMN | B15: LPDPTXCMNTRIMV2I_MULTIPLE | C15: PP_KMDA0_S_FULP_AN_TXCM_MEA_JTG_CAL_ALLFRV_SI_CMNTRIM_V2I | F15: 27.27 | I15: 27.27 | L15: 27.27 | O15: 27.27 | Q15: NV | S15: NV
A16: LPDPTXCMN | B16: LPDPTXCMNTRIMMOSI_MULTIPLE | C16: PP_KMDA0_S_FULP_AN_TXCM_MEA_JTG_CAL_ALLFRV_SI_CMNTRIM_MOSI | F16: 27.47 | I16: 27.47 | L16: 27.47 | O16: 27.47 | Q16: NV | S16: NV
A17: LPDPTXCMN | B17: LPDPTXCMNTRIMMOSV_MULTIPLE | C17: PP_KMDA0_S_FULP_AN_TXCM_MEA_JTG_CAL_ALLFRV_SI_CMNTRIM_MOSV | F17: 155.04 | I17: 155.04 | L17: 155.04 | O17: 155.04 | Q17: NV | S17: NV
