Workbook

Sheet Version History
A1: Version | B1: Date | C1: Edited By | D1: IPs Updated
A2: V1 | B2: 45806 | C2: Venkat | D2: Initial Version
A3: V2 | B3: 45806 | C3: Venkat | D3: NTR, MTRICTS, AMP and AMPCMN Sheets TTR Updated
A4: V3 | B4: 45806 | C4: Venkat | D4: Enabled ACIPHY and PCIE5 highspeed MN for CP and FT at LV.
A5: V4 | B5: 45808 | C5: Venkat | D5: Removed "_" LPDPPLL and CIOCIOPLL
A6: V5 | B6: 45809 | C6: Venkat | D6: Removed "_" LPDPPLL and CIOCIOPLL for sheet name. Removed LV conditions for lower speeds for ACIPHY, PCIE5, ACIOPHY patterns.
A7: V6 | B7: 45809 | C7: Yusuke | D7: Added SEPVMC_fuse_prewrite_sepvmc_vref_rt SEPVMC_fuse_read_sepvmc_vref_rt SEPVMC_fuse_prewrite_sepvmc_trim_vref_ht SEPVMC_fuse_read_sepvmc_trim_vref_ht sepvmc_complt5p1_fuse_read_cal sepvmc_compht5p3_fuse_read_cal into SEPVMC sheet.
A8: V7 | B8: 45809 | C8: Venkat | D8: HSCSAROSC PP Pattern All Intsertion Test Condition Update to HV.
A9: V8 | B9: 45809 | C9: Yusuke | D9: CPLL and CIOCIOPLL Fuse insertion was changed from FT to CP.
A10: V9 | B10: 45810 | C10: Venkat | D10: Removed SHM bases tests due to Victor Memory Issue
A11: V12 | B11: 45820 | C11: Venkat | D11: MTRICTS T5P1 has format issue, “LV,HV.NV” need update to “NV,LV,HV” NTSR MN T1P0 has disabled in PROD TP
A12: V13 | B12: 45824 | C12: Venkat | D12: Added LPDPTX_LITE and ACIPHY_LITE TTR Table. Updates to AMP, ADC, NTSR and CIOCIOPLL
A13: V14 | B13: 45828 | C13: Venkat | D13: AUXTXAUXTMODE_MULTIPLE

Sheet TTR Summary
B2: Single-Site | F2: Multi-Site | G2: 4 | I2: PTE
B3: IP | C3: CP1 TT (s) | D3: Total (s) | F3: CP1 TT (s) | G3: Total (s) | I3: CP1
B4: IO_JTAG | C4: =ROUND(IO_JTAG!F2/1000, 2) -> 12.68 | D4: =SUM(C4:C4) -> 12.68 | I4: =1-(F4-C4)/((G2-1)*C4) -> 1.3333333
B5: ADCDFT | C5: =ROUND(ADCDFT!F2/1000, 2) -> 46.46 | D5: =SUM(C5:C5) -> 46.46 | I5: =1-(F5-C5)/((G2-1)*C5) -> 1.3333333
B6: MTRICTS | C6: =ROUND(MTRICTS!F2/1000, 2) -> 64.83 | D6: =SUM(C6:C6) -> 64.83 | I6: =1-(F6-C6)/((G2-1)*C6) -> 1.3333333
B7: NTSE | C7: =ROUND(NTSE!F2/1000, 2) -> 8.63 | D7: =SUM(C7:C7) -> 8.63 | I7: =1-(F7-C7)/((G2-1)*C7) -> 1.3333333
B8: NTSR | C8: =ROUND(NTSR!F2/1000, 2) -> 1.08 | D8: =SUM(C8:C8) -> 1.08 | I8: =1-(F8-C8)/((G2-1)*C8) -> 1.3333333
B9: MISC | C9: =ROUND(MISC!F2/1000, 2) -> 0.47 | D9: =SUM(C9:C9) -> 0.47 | I9: =1-(F9-C9)/((G2-1)*C9) -> 1.3333333
B10: FRO | C10: =ROUND(FRO!F2/1000, 2) -> 0.63 | D10: =SUM(C10:C10) -> 0.63 | I10: =1-(F10-C10)/((G2-1)*C10) -> 1.3333333
B11: CPLL | C11: =ROUND(CPLL!F2/1000, 2) -> 36.33 | D11: =SUM(C11:C11) -> 36.33 | I11: =1-(F11-C11)/((G2-1)*C11) -> 1.3333333
B12: ADCLK | C12: =ROUND(ADCLK!F2/1000, 2) -> 42.93 | D12: =SUM(C12:C12) -> 42.93 | I12: =1-(F12-C12)/((G2-1)*C12) -> 1.3333333
B13: LAPLL | C13: =ROUND(LAPLL!F2/1000, 2) -> 28.32 | D13: =SUM(C13:C13) -> 28.32 | I13: =1-(F13-C13)/((G2-1)*C13) -> 1.3333333
B14: PCIEREFGEN | C14: =ROUND(PCIEREFGEN!F2/1000, 2) -> 1.59 | D14: =SUM(C14:C14) -> 1.59 | I14: =1-(F14-C14)/((G2-1)*C14) -> 1.3333333
B15: PCIE5CMN | C15: =ROUND(PCIE5CMN!F2/1000, 2) -> 0.48 | D15: =SUM(C15:C15) -> 0.48 | I15: =1-(F15-C15)/((G2-1)*C15) -> 1.3333333
B16: ACIPHYCMN | C16: =ROUND(ACIPHYCMN!F2/1000, 2) -> 0.43 | D16: =SUM(C16:C16) -> 0.43 | I16: =1-(F16-C16)/((G2-1)*C16) -> 1.3333333
B17: ACIOPHYCMN | C17: =ROUND(ACIOPHYCMN!F2/1000, 2) -> 0.39 | D17: =SUM(C17:C17) -> 0.39 | I17: =1-(F17-C17)/((G2-1)*C17) -> 1.3333333
B18: LPDPTXCMN | C18: =ROUND(LPDPTXCMN!F2/1000, 2) -> 0.41 | D18: =SUM(C18:C18) -> 0.41 | I18: =1-(F18-C18)/((G2-1)*C18) -> 1.3333333
B19: AMPCMN | C19: =ROUND(AMPCMN!F2/1000, 2) -> 4.09 | D19: =SUM(C19:C19) -> 4.09 | I19: =1-(F19-C19)/((G2-1)*C19) -> 1.3333333
B20: PCIEREFPLL | C20: =ROUND(PCIEREFPLL!#REF!/1000, 2) -> #REF! | D20: =SUM(C20:C20) -> #REF! | I20: =1-(F20-C20)/((G2-1)*C20) -> #REF!
B21: PCIEPLL | C21: =ROUND(PCIEPLL!F2/1000, 2) -> 5.68 | D21: =SUM(C21:C21) -> 5.68 | I21: =1-(F21-C21)/((G2-1)*C21) -> 1.3333333
B22: CIOCIOPLL_ | C22: =ROUND(CIOCIOPLL!F2/1000, 2) -> 12.28 | D22: =SUM(C22:C22) -> 12.28 | I22: =1-(F22-C22)/((G2-1)*C22) -> 1.3333333
B23: CIODPPLL | C23: =ROUND(CIODPPLL!F2/1000, 2) -> 6.78 | D23: =SUM(C23:C23) -> 6.78 | I23: =1-(F23-C23)/((G2-1)*C23) -> 1.3333333
B24: LPDPDPPLL_ | C24: =ROUND(LPDPDPPLL!F2/1000, 2) -> 16.91 | D24: =SUM(C24:C24) -> 16.91 | I24: =1-(F24-C24)/((G2-1)*C24) -> 1.3333333
B25: LPDDRPLL | C25: =ROUND(LPDDRPLL!F2/1000, 2) -> 24.01 | D25: =SUM(C25:C25) -> 24.01 | I25: =1-(F25-C25)/((G2-1)*C25) -> 1.3333333
B26: HSCSAROSC | C26: =ROUND(HSCSAROSC!F2/1000, 2) -> 1.15 | D26: =SUM(C26:C26) -> 1.15 | I26: =1-(F26-C26)/((G2-1)*C26) -> 1.3333333
B27: ULPPLL | C27: =ROUND(ULPPLL!F2/1000, 2) -> 0.6 | D27: =SUM(C27:C27) -> 0.6 | I27: =1-(F27-C27)/((G2-1)*C27) -> 1.3333333
B28: FLPPLL | C28: =ROUND(FLPPLL!F2/1000, 2) -> 2.55 | D28: =SUM(C28:C28) -> 2.55 | I28: =1-(F28-C28)/((G2-1)*C28) -> 1.3333333
B29: SEPVMC | C29: =ROUND(SEPVMC!F2/1000, 2) -> 6.26 | D29: =SUM(C29:C29) -> 6.26 | I29: =1-(F29-C29)/((G2-1)*C29) -> 1.3333333
B30: SEPF2M | C30: =ROUND(SEPF2M!F2/1000, 2) -> 1.67 | D30: =SUM(C30:C30) -> 1.67 | I30: =1-(F30-C30)/((G2-1)*C30) -> 1.3333333
B31: MIDBIASLDO | C31: =ROUND(MIDBIASLDO!F2/1000, 2) -> 0.26 | D31: =SUM(C31:C31) -> 0.26 | I31: =1-(F31-C31)/((G2-1)*C31) -> 1.3333333
B32: ADC | C32: =ROUND(ADC!F2/1000, 2) -> 9.96 | D32: =SUM(C32:C32) -> 9.96 | I32: =1-(F32-C32)/((G2-1)*C32) -> 1.3333333
B33: ACIOPHY | C33: =ROUND(ACIOPHY!F2/1000, 2) -> 16.16 | D33: =SUM(C33:C33) -> 16.16 | I33: =1-(F33-C33)/((G2-1)*C33) -> 1.3333333
B34: ACIPHY | C34: =ROUND(ACIPHY!F2/1000, 2) -> 148.17 | D34: =SUM(C34:C34) -> 148.17 | I34: =1-(F34-C34)/((G2-1)*C34) -> 1.3333333
B35: LPDPTX | C35: =ROUND(LPDPTX!F2/1000, 2) -> 3.39 | D35: =SUM(C35:C35) -> 3.39 | I35: =1-(F35-C35)/((G2-1)*C35) -> 1.3333333
B36: PCIE5 | C36: =ROUND(PCIE5!F2/1000, 2) -> 104.2 | D36: =SUM(C36:C36) -> 104.2 | I36: =1-(F36-C36)/((G2-1)*C36) -> 1.3333333
B37: NTSX | C37: =ROUND(NTSX!F2/1000, 2) -> 0.06 | D37: =SUM(C37:C37) -> 0.06 | I37: =1-(F37-C37)/((G2-1)*C37) -> 1.3333333
B38: PCIEREFBUF | C38: =ROUND(PCIEREFBUF!F2/1000, 2) -> 0.18 | D38: =SUM(C38:C38) -> 0.18 | I38: =1-(F38-C38)/((G2-1)*C38) -> 1.3333333
B39: USB | C39: =ROUND(USB!F2/1000, 2) -> 3.9 | D39: =SUM(C39:C39) -> 3.9 | I39: =1-(F39-C39)/((G2-1)*C39) -> 1.3333333
B40: DSGRINGS | C40: =ROUND(#REF!/1000, 2) -> #REF! | D40: =SUM(C40:C40) -> #REF! | I40: =1-(F40-C40)/((G2-1)*C40) -> #REF!
B41: NPMS | C41: =ROUND(#REF!/1000, 2) -> #REF! | D41: =SUM(C41:C41) -> #REF! | I41: =1-(F41-C41)/((G2-1)*C41) -> #REF!
...

Sheet IO_JTAG
A2: Proposal for TTR | D2: Total (ms) | F2: =SUM(E5:G18) -> 12678.02
E3: CP1 (ms)
A4: Category | B4: SubBlock | C4: Pattern | D4: HIP_FailRun | E4: LV | F4: NV | G4: HV | H4: Prod CP1 | I4: Prod CP2 | J4: Prod FT1 | K4: Prod FT2 | L4: Mon | M4: T0Tx | N4: RMA Room | O4: RMA Hot
A5: IO_JTAG | B5: TAPBSD | C5: PP_BRNA0_S_FULP_IO_BSCN_BSD_JIO_UNS_ALLFRV_SI_TAP_BSD | E5: 317.4 | F5: 48.33 | G5: 115.44 | H5: LV,HV | I5: LV,HV | J5: NV
A6: IO_JTAG | B6: DAPIDBYP | C6: PP_BRNA0_S_FULP_FU_BSCN_PFF_JTG_JCC_ALLFRV_SI_DAP_IDBYP | E6: 152.59 | F6: 53.44 | G6: 105.33 | I6: LV,HV | K6: LV,HV
A7: IO_JTAG | B7: DCLP | C7: PP_BRNA0_S_FULP_IO_BSCN_DCT_DAA_DIO_ALLFRV_SI_DC_LP | E7: 106.9 | F7: 67.06 | G7: 106.69 | H7: LV,HV | I7: LV,HV
A8: IO_JTAG | B8: FUNCVILH | C8: PP_BRNA0_S_FULP_IO_POPX_NAN_DAA_DIO_ALLFRV_SI_FUNC_VILH | E8: 143.24 | F8: 142.6 | G8: 140.26 | H8: LV,HV | I8: LV,HV
A9: IO_JTAG | B9: IMPDPU | C9: PP_BRNA0_S_FULP_IO_POPU_NAN_DAA_DIO_ALLFRV_SI_IMPD_PU | E9: 732.4 | F9: 769.14 | G9: 641.41 | H9: HV | I9: LV
A10: IO_JTAG | B10: DCDS4D13 | C10: PP_BRNA0_S_FULP_IO_BSCN_DCT_DAA_DIO_ALLFRV_SI_DC_DS4 | E10: 385.19 | F10: 388.03 | G10: 414.77 | H10: HV | I10: LV
A11: IO_JTAG | B11: DCDS4D22 | C11: PP_BRNA0_S_FULP_IO_BSCN_DCT_DAA_DIO_ALLFRV_SI_DC_DS4 | E11: 367.07 | F11: 370.66 | G11: 340.23 | H11: HV | I11: LV
A12: IO_JTAG | B12: DCDS8D13 | C12: PP_BRNA0_S_FULP_IO_BSCN_DCT_DAA_DIO_ALLFRV_SI_DC_DS8 | E12: 381.43 | F12: 404.87 | G12: 438.84 | H12: HV | I12: LV
A13: IO_JTAG | B13: DCDS8D22 | C13: PP_BRNA0_S_FULP_IO_BSCN_DCT_DAA_DIO_ALLFRV_SI_DC_DS8 | E13: 381.9 | F13: 327.16 | G13: 239.17 | H13: HV | I13: LV
A14: IO_JTAG | B14: DCDS14D13 | C14: PP_BRNA0_S_FULP_IO_BSCN_DCT_DAA_DIO_ALLFRV_SI_DC_DS14 | E14: 426.08 | F14: 342.69 | G14: 396.5 | H14: HV | I14: LV
A15: IO_JTAG | B15: DCDS14D22 | C15: PP_BRNA0_S_FULP_IO_BSCN_DCT_DAA_DIO_ALLFRV_SI_DC_DS14 | E15: 284.51 | F15: 286.02 | G15: 236.86 | H15: HV | I15: LV
A16: IO_JTAG | B16: IOLEAK | C16: PP_BRNA0_S_FULP_IO_BSCN_BSD_JIO_UNS_ALLFRV_SI_IO_LEAK | E16: 549.65 | F16: 584.1 | G16: 492.35 | H16: HV | I16: HV
A17: IO_JTAG | B17: FUNCVOLHD13 | C17: PP_BRNA0_S_FULP_IO_BSCN_DCT_DAA_DIO_ALLFRV_SI_FUNC_VOLHD13 | E17: 126.46 | F17: 128.46 | G17: 82.82 | H17: HV | I17: LV
A18: IO_JTAG | B18: FUNCVOLHD22 | C18: PP_BRNA0_S_FULP_IO_BSCN_DCT_DAA_DIO_ALLFRV_SI_FUNC_VOLHD22 | E18: 275.02 | F18: 248.33 | G18: 136.62 | H18: HV | I18: LV

Sheet ADCDFT
A2: Proposal for TTR | D2: Total (ms) | F2: =SUM(E5:G26) -> 46457
E3: CP1 (ms)
A4: Category | B4: SubBlock | C4: Pattern | D4: HIP_FailRun | E4: LV | F4: NV | G4: HV | H4: Prod CP1 | I4: Prod CP2 | J4: Prod FT1 | K4: Prod FT2 | L4: Mon | M4: T0Tx | N4: RMA Room | O4: RMA Hot
A5: ADCDFT | B5: UCSDMT1 | C5: PP_BRNA0_S_FULP_AN_AA07_MEA_JTG_VIX_ALLFRV_SI_UCSDM_T1 | E5: 1855.37 | F5: 2613.76 | G5: 1921.5 | H5: NV | I5: NV | J5: NV | K5: NV
A6: ADCDFT | B6: UCSDMT3A | C6: PP_BRNA0_S_FULP_AN_AA07_MEA_JTG_VIX_ALLFRV_SI_UCSDM_T3A | E6: 497.39 | F6: 443.53 | G6: 403.99 | H6: NV | I6: NV | J6: NV | K6: NV
A7: ADCDFT | B7: UCSDMVER0P139 | C7: PP_BRNA0_S_FULP_AN_AA07_MEA_JTG_VIX_ALLFRV_SI_UCSDM_T3B | E7: 319.63 | F7: 454.26 | G7: 270.64 | H7: NV | I7: NV | J7: NV | K7: NV
A8: ADCDFT | B8: UCSDMVER0P558 | C8: PP_BRNA0_S_FULP_AN_AA07_MEA_JTG_VIX_ALLFRV_SI_UCSDM_T3B | E8: 356.68 | F8: 313.61 | G8: 269.45 | H8: NV | I8: NV | J8: NV | K8: NV
A9: ADCDFT | B9: UCSDMVER0P837 | C9: PP_BRNA0_S_FULP_AN_AA07_MEA_JTG_VIX_ALLFRV_SI_UCSDM_T3B | E9: 327.1 | F9: 490.59 | G9: 269.75 | H9: NV | I9: NV | J9: NV | K9: NV
A10: ADCDFT | B10: UCSDMVER0P976 | C10: PP_BRNA0_S_FULP_AN_AA07_MEA_JTG_VIX_ALLFRV_SI_UCSDM_T3B | E10: 318.81 | F10: 307.92 | G10: 271.64 | H10: NV | I10: NV | J10: NV | K10: NV
A11: ADCDFT | B11: UCSDMT4A | C11: PP_BRNA0_S_FULP_AN_AA07_MEA_JTG_VIX_ALLFRV_SI_UCSDM_T4A | E11: 311.45 | F11: 300.08 | G11: 261.55 | H11: NV
A12: ADCDFT | B12: OTHER | C12: ADCDFT_FUSE_PREWRITE_HSC_UCSDM0_DFT_NREFG | F12: 0.22 | H12: NV
A13: ADCDFT | B13: OTHER | C13: ADCDFT_FUSE_READ_HSC_UCSDM0_DFT_NREFG | F13: 0.66 | I13: NV | J13: NV | K13: NV
A14: ADCDFT | B14: OTHER | C14: ADCDFT_FUSE_PREWRITE_HSC_UCSDM1_DFT_NREFG | F14: 0.19 | H14: NV
A15: ADCDFT | B15: OTHER | C15: ADCDFT_FUSE_READ_HSC_UCSDM1_DFT_NREFG | F15: 0.59 | I15: NV | J15: NV | K15: NV
A16: ADCDFT | B16: UCSDMT4B | C16: PP_BRNA0_S_FULP_AN_AA07_MEA_JTG_VIX_ALLFRV_SI_UCSDM_T4B | E16: 615.12 | F16: 712.6 | G16: 553.31 | H16: NV | I16: NV | J16: NV | K16: NV
A17: ADCDFT | B17: UCSDMT8 | C17: PP_BRNA0_S_FULP_AN_AA07_MEA_JTG_VIX_ALLFRV_SI_UCSDM_T8 | E17: 4920.39 | F17: 4699.65 | G17: 4448.71 | H17: NV | I17: NV | J17: NV | K17: NV
A18: ADCDFT | B18: UCSDMCALT5A | C18: MN_BRNA0_S_FULP_AN_AA07_MEA_JTG_VIX_ALLFRV_SI_UCSDM_T5A | E18: 499.51 | F18: 492.94 | G18: 414.41 | L18: LV,HV
A19: ADCDFT | B19: UCSDMMNVER0P139 | C19: MN_BRNA0_S_FULP_AN_AA07_MEA_JTG_VIX_ALLFRV_SI_UCSDM_T5B | E19: 360.03 | F19: 368.31 | G19: 280.99 | L19: LV,HV
A20: ADCDFT | B20: UCSDMMNVER0P558 | C20: MN_BRNA0_S_FULP_AN_AA07_MEA_JTG_VIX_ALLFRV_SI_UCSDM_T5B | E20: 420.05 | F20: 411.77 | G20: 274.95 | L20: LV,HV
A21: ADCDFT | B21: UCSDMMNVER0P837 | C21: MN_BRNA0_S_FULP_AN_AA07_MEA_JTG_VIX_ALLFRV_SI_UCSDM_T5B | E21: 473.02 | F21: 362.15 | G21: 327.88 | L21: LV,HV
A22: ADCDFT | B22: MNUCSDMT6 | C22: MN_BRNA0_S_FULP_AN_AA07_MEA_JTG_VIX_ALLFRV_SI_UCSDM_T6 | E22: 602.28 | F22: 624.17 | G22: 738.93 | L22: LV,HV
A23: ADCDFT | B23: MNUCSDMT9A | C23: MN_BRNA0_S_FULP_AN_AA07_MEA_JTG_VIX_ALLFRV_SI_UCSDM_T9A | E23: 899.98 | F23: 746.12 | G23: 808.61 | L23: LV,HV
A24: ADCDFT | B24: MNUCSDMT9B | C24: MN_BRNA0_S_FULP_AN_AA07_MEA_JTG_VIX_ALLFRV_SI_UCSDM_T9B | E24: 1014.75 | F24: 851.71 | G24: 1033.03 | L24: LV,HV
A25: ADCDFT | B25: MNUCSDMT9C | C25: MN_BRNA0_S_FULP_AN_AA07_MEA_JTG_VIX_ALLFRV_SI_UCSDM_T9C | E25: 1014.53 | F25: 971 | G25: 1108.99 | L25: LV,HV
A26: ADCDFT | B26: MNUCSDMT9D | C26: MN_BRNA0_S_FULP_AN_AA07_MEA_JTG_VIX_ALLFRV_SI_UCSDM_T9D | E26: 985.13 | F26: 878.13 | G26: 963.49 | L26: LV,HV

Sheet MTRICTS
A2: Proposal for TTR | D2: Total (ms) | F2: =SUM(E5:G29) -> 64833.89
E3: CP1 (ms)
A4: Category | B4: SubBlock | C4: Pattern | D4: HIP_FailRun | E4: LV | F4: NV | G4: HV | H4: Prod CP1 | I4: Prod CP2 | J4: Prod FT1 | K4: Prod FT2 | L4: Mon | M4: T0Tx | N4: RMA Room | O4: RMA Hot
A5: MTRICTS | B5: NBRIDGET2P1 | C5: PP_BRNA0_S_FULP_AN_ICTS_DLL_JTG_COD_ALLFRV_SI_NBRIDGE_T2P1 | F5: 501.97 | H5: NV
A6: MTRICTS | B6: OTHER | C6: MTRICTS_NBRIDGET2P1_FUSE_PREWRITE_CAL | F6: 0.23 | H6: NV
A7: MTRICTS | B7: OTHER | C7: MTRICTS_NBRIDGET2P1_FUSE_READ_CAL | F7: 59.17 | I7: NV | J7: NV | K7: NV
A8: MTRICTS | B8: OTHER | C8: MTRICTS_NBRIDGET2P1P1_FUSE_PREWRITE_CAL | F8: 31.04 | I8: NV
A9: MTRICTS | B9: OTHER | C9: MTRICTS_NBRIDGET2P1P1_FUSE_READ_CAL | F9: 4.89 | J9: NV | K9: NV
A10: MTRICTS | B10: OTHER | C10: MTRICTS_RBRIDGET3P2_FUSE_PREWRITE_CAL | F10: 0.26 | H10: NV
A11: MTRICTS | B11: OTHER | C11: MTRICTS_RBRIDGET3P2_FUSE_READ_CAL | F11: 58.53 | I11: NV | J11: NV | K11: NV
A12: MTRICTS | B12: OTHER | C12: MTRICTS_BPBN_ASSIGMENT | H12: NV
A13: MTRICTS | B13: OTHER | C13: MTRICTS_READT4P1_FUSE_PREWRITE_CAL | F13: 0.25 | H13: NV
A14: MTRICTS | B14: OTHER | C14: MTRICTS_READT4P1_FUSE_READ_CAL | F14: 30.28 | I14: NV | J14: NV | K14: NV
A15: MTRICTS | B15: OTHER | C15: MTRICTS_ICTS_CPE_TEMPERATURE_FUSE_PREWRITE | F15: 0.31 | I15: NV
A16: MTRICTS | B16: OTHER | C16: MTRICTS_ICTS_CPE_TEMPERATURE_FUSE_READ | F16: 0.7
A17: MTRICTS | B17: OTHER | C17: MTRICTS_T5P1P1_FUSE_PREWRITE_CAL | F17: 0.25 | I17: NV
A18: MTRICTS | B18: OTHER | C18: MTRICTS_T5P1P1_FUSE_READ_CAL | F18: 3.64 | J18: NV | K18: NV
A19: MTRICTS | B19: NBRIDGET2P1A | C19: PP_BRNA0_S_FULP_AN_ICTS_DLL_JTG_COD_ALLFRV_SI_NBRIDGE_T2P1A | E19: 237.6 | F19: 335.76 | G19: 238.03 | H19: NV | I19: NV
A20: MTRICTS | B20: NBRIDGET2P1P1 | C20: PP_BRNA0_S_FULP_AN_ICTS_DLL_JTG_COD_ALLFRV_SI_NBRIDGE_T2P1P1 | F20: 84.07 | H20: NV | I20: NV
A21: MTRICTS | B21: RBRIDGET3P1 | C21: PP_BRNA0_S_FULP_AN_ICTS_DLL_JTG_COD_ALLFRV_SI_RBRIDGE_T3P1 | F21: 214.83 | H21: NV
A22: MTRICTS | B22: RBRIDGET3P2 | C22: PP_BRNA0_S_FULP_AN_ICTS_DLL_JTG_COD_ALLFRV_SI_RBRIDGE_T3P2 | F22: 1058.58 | H22: NV
A23: MTRICTS | B23: READT4P1 | C23: PP_BRNA0_S_FULP_AN_ICTS_DLL_JTG_COD_ALLFRV_SI_READ_T4P1 | F23: 646.77 | H23: NV
A24: MTRICTS | B24: TEMPT5P1CP1 | C24: PP_BRNA0_S_FULP_AN_ICTS_DLL_JTG_COD_ALLFRV_SI_TEMP_T5P1 | E24: 3439.35 | F24: 3557.25 | G24: 5159.21 | H24: NV,LV,HV | I24: NV,LV,HV | J24: NV,LV,HV | K24: NV,LV,HV
A25: MTRICTS | B25: TEMPT5P1P1CP1 | C25: PP_BRNA0_S_FULP_AN_ICTS_DLL_JTG_COD_ALLFRV_SI_TEMP_T5P1P1 | E25: 268.28 | F25: 374.38 | G25: 296.69 | H25: NV | I25: NV | J25: NV | K25: NV
A26: MTRICTS | B26: MNPWRT1P1 | C26: MN_BRNA0_S_FULP_AN_ICTS_DLL_JTG_COD_ALLFRV_SI_PWR_T1P1 | E26: 8279.46 | F26: 20696.94 | G26: 8251.13 | L26: LV,HV
A27: MTRICTS | B27: MNIREFT1P2 | C27: MN_BRNA0_S_FULP_AN_ICTS_DLL_JTG_COD_ALLFRV_SI_IREF_T1P2 | F27: 2574.13 | L27: LV,HV
A28: MTRICTS | B28: MNANATESTT1P3NV | C28: MN_BRNA0_S_FULP_AN_ICTS_DLL_JTG_COD_ALLFRV_SI_ANATEST_T1P3 | E28: 1899.68 | F28: 1887.03 | G28: 1971.06 | L28: LV,HV
A29: MTRICTS | B29: MNOSCT6P1 | C29: MN_BRNA0_S_FULP_AN_ICTS_DLL_JTG_COD_ALLFRV_SI_OSC_T6P1 | E29: 921.43 | F29: 885.38 | G29: 865.33 | L29: LV,HV

Sheet NTSE
A2: Proposal for TTR | D2: Total (ms) | F2: =SUM(E5:G20) -> 8631.83
E3: CP1 (ms)
A4: Category | B4: SubBlock | C4: Pattern | D4: HIP_FailRun | E4: LV | F4: NV | G4: HV | H4: Prod CP1 | I4: Prod CP2 | J4: Prod FT1 | K4: Prod FT2 | L4: Mon | M4: T0Tx | N4: RMA Room | O4: RMA Hot
A5: NTSE | B5: NTSEREADT1P1CP1 | C5: PP_BRNA0_S_FULP_AN_MT02_DLL_JTG_COD_ALLFRV_SI_NTSEREAD_T1P1 | F5: 782.98 | H5: NV
A6: NTSE | B6: OTHER | C6: NTSE_NTSEREADT1P1CP1_FUSE_PREWRITE_CAL_D_0_CP1 | F6: 0.31 | H6: NV
A7: NTSE | B7: OTHER | C7: NTSE_NTSEREADT1P1CP1_FUSE_PREWRITE_CAL_VREF_DIG_CP1 | F7: 0.17 | H7: NV
A8: NTSE | B8: OTHER | C8: NTSE_NTSEREADT1P1FT1_FUSE_PREWRITE_CAL_D_0_FT1 | F8: 0.31 | J8: NV
A9: NTSE | B9: OTHER | C9: NTSE_NTSEREADT1P1FT1_FUSE_READ_CAL_D_0_FT1 | F9: 8.43 | K9: NV
A10: NTSE | B10: OTHER | C10: NTSE_NTSEREADT1P1FT1_FUSE_PREWRITE_CAL_NTSE_TEMP_FT1 | F10: 0.22 | J10: NV
A11: NTSE | B11: OTHER | C11: NTSE_NTSEREADT1P1FT1_FUSE_READ_CAL_NTSE_TEMP_FT1 | F11: 8.41 | K11: NV
A12: NTSE | B12: OTHER | C12: NTSE_NTSEREADT1P1FT2_FUSE_PREWRITE_CAL_VREF_DIG_FT2 | F12: 0.32 | K12: NV
A13: NTSE | B13: OTHER | C13: NTSE_NTSEREADT1P1FT2_FUSE_PREWRITE_CAL_D_0_FT2 | F13: 0.17 | K13: NV
A14: NTSE | B14: OTHER | C14: NTSE_NTSEREADT1P1FT2_FUSE_READ_CAL_D_0_FT2 | F14: 8.54
A15: NTSE | B15: OTHER | C15: NTSE_NTSEREADT1P1FT2_FUSE_PREWRITE_CAL_NTSE_TEMP_FT2 | F15: 0.21 | K15: NV
A16: NTSE | B16: OTHER | C16: NTSE_NTSEREADT1P1FT2_FUSE_READ_CAL_NTSE_TEMP_FT2 | F16: 41.98
A17: NTSE | B17: NTSEREADT1P1FT1 | C17: PP_BRNA0_S_FULP_AN_MT02_DLL_JTG_COD_ALLFRV_SI_NTSEREAD_T1P1 | F17: 775.51 | J17: NV
A18: NTSE | B18: NTSEREADT1P1FT2 | C18: PP_BRNA0_S_FULP_AN_MT02_DLL_JTG_COD_ALLFRV_SI_NTSEREAD_T1P1 | F18: 885.21 | K18: NV
A19: NTSE | B19: NTSEREADT2 | C19: PP_BRNA0_S_FULP_AN_MT02_DLL_JTG_COD_ALLFRV_SI_NTSEREAD_T2 | E19: 150.67 | F19: 109.52 | G19: 171.92 | K19: NV
A20: NTSE | B20: MNNTSEREADT1P0 | C20: MN_BRNA0_S_FULP_AN_MT02_DLL_JTG_COD_ALLFRV_SI_NTSEREAD_T1P0 | E20: 1898.97 | F20: 1900.84 | G20: 1887.14 | H20: NV | I20: NV | J20: NV | K20: NV | L20: LV,HV

Sheet NTSR
A2: Proposal for TTR | D2: Total (ms) | F2: =SUM(E5:G16) -> 1084.34
E3: CP1 (ms)
A4: Category | B4: SubBlock | C4: Pattern | D4: HIP_FailRun | E4: LV | F4: NV | G4: HV | H4: Prod CP1 | I4: Prod CP2 | J4: Prod FT1 | K4: Prod FT2 | L4: Mon | M4: T0Tx | N4: RMA Room | O4: RMA Hot
A5: NTSR | B5: NTSRREADT1P1CP1 | C5: PP_BRNA0_S_FULP_AN_MT02_DLL_JTG_COD_ALLFRV_SI_NTSRREAD_T1P1 | F5: 56.22 | H5: NV
A6: NTSR | B6: OTHER | C6: NTSR_T1P1_CP1_FUSE_PREWRITE_CAL | F6: 0.27 | H6: NV
A7: NTSR | B7: OTHER | C7: NTSR_T1P1_CP1_FUSE_READ_CAL | F7: 121.5 | I7: NV | J7: NV | K7: NV
A8: NTSR | B8: OTHER | C8: NTSR_T1P1_FT1_FUSE_PREWRITE_CAL | F8: 0.29 | J8: NV
A9: NTSR | B9: OTHER | C9: NTSR_T1P1_FT1_FUSE_READ_CAL | F9: 1.1 | K9: NV
A10: NTSR | B10: OTHER | C10: NTSR_T1P1_CP2_FUSE_PREWRITE_CAL | F10: 0.29 | I10: NV
A11: NTSR | B11: OTHER | C11: NTSR_T1P1_CP2_FUSE_READ_CAL | F11: 1.06 | J11: NV | K11: NV
A12: NTSR | B12: NTSRREADT1P1FT1 | C12: PP_BRNA0_S_FULP_AN_MT02_DLL_JTG_COD_ALLFRV_SI_NTSRREAD_T1P1 | F12: 48.24 | J12: NV
A13: NTSR | B13: NTSRREADT1P1CP2 | C13: PP_BRNA0_S_FULP_AN_MT02_DLL_JTG_COD_ALLFRV_SI_NTSRREAD_T1P1 | F13: 45.8 | I13: NV
A14: NTSR | B14: NTSRREADT1P1FT2 | C14: PP_BRNA0_S_FULP_AN_MT02_DLL_JTG_COD_ALLFRV_SI_NTSRREAD_T1P1 | E14: 90.86 | F14: 50.74 | G14: 58.92 | K14: NV
A15: NTSR | B15: NTSRREADT2 | C15: PP_BRNA0_S_FULP_AN_MT02_DLL_JTG_COD_ALLFRV_SI_NTSRREAD_T2 | E15: 21.96 | F15: 21.49 | G15: 21.48 | J15: NV | K15: NV
A16: NTSR | B16: MNNTSRREADT1P0 | C16: MN_BRNA0_S_FULP_AN_MT02_DLL_JTG_COD_ALLFRV_SI_NTSRREAD_T1P0 | E16: 170.92 | F16: 170.64 | G16: 202.56 | L16: LV,HV

Sheet MISC
A2: Proposal for TTR | D2: Total (ms) | F2: =SUM(E5:G18) -> 473.15
E3: CP1 (ms)
A4: Category | B4: SubBlock | C4: Pattern | D4: HIP_FailRun | E4: LV | F4: NV | G4: HV | H4: Prod CP1 | I4: Prod CP2 | J4: Prod FT1 | K4: Prod FT2 | L4: Mon | M4: T0Tx | N4: RMA Room | O4: RMA Hot
A5: MISC | B5: SIOAOP | C5: PP_BRNA0_S_FULP_IO_POPX_NAN_DAA_DIO_ALLFRV_SI_SIO_AOP | E5: 18.18 | F5: 18.05 | G5: 18.13 | H5: LV,HV | I5: LV,HV | K5: LV,HV
A6: MISC | B6: SIOMTP | C6: PP_BRNA0_S_FULP_IO_POPX_NAN_DAA_DIO_ALLFRV_SI_SIO_MTP | E6: 8.85 | F6: 8.96 | G6: 8.71 | H6: LV,HV | I6: LV,HV | K6: LV,HV
A7: MISC | B7: SIOSIO | C7: PP_BRNA0_S_FULP_IO_POPX_NAN_DAA_DIO_ALLFRV_SI_SIO_SIO | E7: 8.76 | F7: 8.72 | G7: 8.68 | H7: LV,HV | I7: LV,HV | K7: LV,HV
A8: MISC | B8: SIOQSPIMC | C8: PP_BRNA0_S_FULP_IO_POPX_NAN_DAA_DIO_ALLFRV_SI_SIO_QSPIMC | E8: 8.52 | F8: 8.52 | G8: 8.49 | H8: LV,HV | I8: LV,HV | K8: LV,HV
A9: MISC | B9: SIODISP | C9: PP_BRNA0_S_FULP_IO_POPX_NAN_DAA_DIO_ALLFRV_SI_SIO_DISP | E9: 8.59 | F9: 8.54 | G9: 8.5 | H9: LV,HV | I9: LV,HV | K9: LV,HV
A10: MISC | B10: SIODISPSEC | C10: PP_BRNA0_S_FULP_IO_POPX_NAN_DAA_DIO_ALLFRV_SI_SIO_DISPSEC | E10: 36.37 | F10: 8.57 | G10: 8.54 | H10: LV,HV | I10: LV,HV | K10: LV,HV
A11: MISC | B11: XX | C11: PP_BRNA0_S_FULP_PW_PTSX_PFF_DAA_PWR_ALLFRV_SI_X_X | E11: 13.9 | F11: 8.36 | G11: 8.34 | H11: LV,HV | I11: LV,HV | K11: LV,HV
A12: MISC | B12: DELAYEN | C12: PP_BRNA0_S_FULP_PW_PTSX_PFF_DAA_PWR_ALLFRV_SI_DELAY_EN | E12: 20.06 | F12: 19.54 | G12: 19.52 | H12: LV,HV | I12: LV,HV | K12: LV,HV
A13: MISC | B13: SELSRAMMEMON | C13: PP_BRNA0_S_FULP_PW_PTSX_PFF_DAA_PWR_ALLFRV_SI_SELSRAM_MEMON | E13: 8.34 | F13: 8.19 | G13: 8.11 | H13: LV,HV | I13: LV,HV | K13: LV,HV
A14: MISC | B14: SELSRAMMEMOFF | C14: PP_BRNA0_S_FULP_PW_PTSX_PFF_DAA_PWR_ALLFRV_SI_SELSRAM_MEMOFF | E14: 8.26 | F14: 8.2 | G14: 8.19 | H14: LV,HV | I14: LV,HV | K14: LV,HV
A15: MISC | B15: TBBACC | C15: PP_BRNA0_C_FULP_AN_TBBX_PFF_JTG_CAL_ALLFRV_SI_TBB_ACC | E15: 9.4 | F15: 9.44 | G15: 9.38 | H15: LV,HV | I15: LV,HV | K15: LV,HV
A16: MISC | B16: TBBANE | C16: PP_BRNA0_S_FULP_AN_TBBX_PFF_JTG_CAL_ALLFRV_SI_TBB_ANE | E16: 7.38 | F16: 7.52 | G16: 7.37 | H16: LV,HV | I16: LV,HV | K16: LV,HV
... A18: MISC | B18: ATBOFMS | C18: PP_BRNA0_C_FULP_AN_AATB_MEA_JTG_IMX_ALLFRV_SI_ATB_OFMS | E18: 16.23 | F18: 16.52 | G18: 16.01 | H18: LV,HV | I18: LV,HV | K18: LV,HV

Sheet FRO
A2: Proposal for TTR | D2: Total (ms) | F2: =SUM(E5:G8) -> 633.69
E3: CP1 (ms)
A4: Category | B4: SubBlock | C4: Pattern | D4: HIP_FailRun | E4: LV | F4: NV | G4: HV | H4: Prod CP1 | I4: Prod CP2 | J4: Prod FT1 | K4: Prod FT2 | L4: Mon | M4: T0Tx | N4: RMA Room | O4: RMA Hot
A5: FRO | B5: PDDBGFREQMEAS | C5: PP_BRNA0_S_FULP_AN_AR00_FRQ_JTG_FRQ_ALLFRV_SI_PDDBG_FREQMEAS | E5: 20.32 | F5: 20.9 | G5: 21.1 | H5: NV
A6: FRO | B6: MNPDDEBUG | C6: MN_BRNA0_S_FULP_AN_AR00_FRQ_JTG_FRQ_ALLFRV_SI_PD_DEBUG | E6: 60.7 | F6: 60.64 | G6: 60.95 | L6: LV,HV
A7: FRO | B7: MNPDSEPFRO | C7: MN_BRNA0_S_FULP_AN_AR00_FRQ_JTG_FRQ_ALLFRV_SI_PD_SEPFRO | E7: 70.28 | F7: 108.1 | G7: 68.63 | L7: LV,HV
A8: FRO | B8: MNPDSEPFRO2 | C8: MN_BRNA0_S_FULP_AN_AR00_FRQ_JTG_FRQ_ALLFRV_SI_PD_SEPFRO2 | E8: 67.54 | F8: 38.07 | G8: 36.46 | L8: LV,HV

Sheet CPLL
A2: Proposal for TTR | D2: Total (ms) | F2: =SUM(E5:G131) -> 36334.6
E3: CP1 (ms)
A4: Category | B4: SubBlock | C4: Pattern | D4: HIP_FailRun | E4: LV | F4: NV | G4: HV | H4: Prod CP1 | I4: Prod CP2 | J4: Prod FT1 | K4: Prod FT2 | L4: Mon | M4: T0Tx | N4: RMA Room | O4: RMA Hot
A5: CPLL | B5: CPLLDST0PD | C5: PP_BRNA0_C_FULP_AN_AA00_DLL_JTG_VIX_ALLFRV_SI_CPLLDS_T0PD | F5: 185.92 | H5: NV | I5: NV | J5: NV
A6: CPLL | B6: OTHER | C6: CPLL_CPLL01_T0_FUSE_PREWRITE_CAL | F6: 0.24 | H6: NV
A7: CPLL | B7: OTHER | C7: CPLL_CPLL01_T0_FUSE_READ_CAL | F7: 1.04 | I7: NV | J7: NV | K7: NV
A8: CPLL | B8: OTHER | C8: CPLL_CPLL01_T1_FUSE_PREWRITE_CAL | F8: 0.24 | H8: NV
A9: CPLL | B9: OTHER | C9: CPLL_CPLL01_T1_FUSE_READ_CAL | F9: 0.99 | I9: NV | J9: NV | K9: NV
A10: CPLL | B10: OTHER | C10: CPLL_CPLL23_T0_FUSE_PREWRITE_CAL | F10: 0.24 | H10: NV
A11: CPLL | B11: OTHER | C11: CPLL_CPLL23_T0_FUSE_READ_CAL | F11: 1.07 | I11: NV | J11: NV | K11: NV
A12: CPLL | B12: OTHER | C12: CPLL_CPLL23_T1_FUSE_PREWRITE_CAL | F12: 0.24 | H12: NV
A13: CPLL | B13: OTHER | C13: CPLL_CPLL23_T1_FUSE_READ_CAL | F13: 1.05 | I13: NV | J13: NV | K13: NV
A14: CPLL | B14: CPLLDST1PD | C14: PP_BRNA0_C_FULP_AN_AA00_DLL_JTG_VIX_ALLFRV_SI_CPLLDS_T1PD | E14: 132.02 | F14: 123.97 | G14: 130.9 | H14: NV | I14: NV | J14: NV
A15: CPLL | B15: CPLLDST2P103D | C15: PP_BRNA0_C_FULP_AN_AA00_DLL_JTG_VIX_ALLFRV_SI_CPLLDS_T2P103D | E15: 60.71 | F15: 60.89 | G15: 61.06 | H15: LV,HV | I15: LV,HV | J15: LV,HV | K15: LV,HV
A16: CPLL | B16: CPLLDST2P107D | C16: PP_BRNA0_C_FULP_AN_AA00_DLL_JTG_VIX_ALLFRV_SI_CPLLDS_T2P107D | E16: 69.39 | F16: 68.55 | G16: 67.89 | H16: LV,HV | I16: LV,HV | J16: LV,HV | K16: LV,HV
A17: CPLL | B17: CPLLDST2P108D | C17: PP_BRNA0_C_FULP_AN_AA00_DLL_JTG_VIX_ALLFRV_SI_CPLLDS_T2P108D | E17: 101.14 | F17: 68.86 | G17: 67.8 | H17: LV,HV | I17: LV,HV | J17: LV,HV | K17: LV,HV
A18: CPLL | B18: CPLLDST2P109D | C18: PP_BRNA0_C_FULP_AN_AA00_DLL_JTG_VIX_ALLFRV_SI_CPLLDS_T2P109D | E18: 68.75 | F18: 106.89 | G18: 102.57 | H18: LV,HV | I18: LV,HV | J18: LV,HV | K18: LV,HV
A19: CPLL | B19: CPLLDST2P110D | C19: PP_BRNA0_C_FULP_AN_AA00_DLL_JTG_VIX_ALLFRV_SI_CPLLDS_T2P110D | E19: 68.33 | F19: 69.72 | G19: 68.48 | H19: LV,HV | I19: LV,HV | J19: LV,HV | K19: LV,HV
A20: CPLL | B20: CPLLDST2P112D | C20: PP_BRNA0_C_FULP_AN_AA00_DLL_JTG_VIX_ALLFRV_SI_CPLLDS_T2P112D | E20: 69.26 | F20: 68.87 | G20: 67.95 | H20: LV,HV | I20: LV,HV | J20: LV,HV | K20: LV,HV
A21: CPLL | B21: CPLLDST3P108D | C21: PP_BRNA0_C_FULP_AN_AA00_DLL_JTG_VIX_ALLFRV_SI_CPLLDS_T3P108D | E21: 122.21 | F21: 85.19 | G21: 85.06 | H21: LV,HV | I21: LV,HV | J21: LV,HV | K21: LV,HV
A22: CPLL | B22: CPLLDST13P107D | C22: PP_BRNA0_C_FULP_AN_AA00_DLL_JTG_VIX_ALLFRV_SI_CPLLDS_T13P107D | E22: 26.46 | F22: 25.92 | G22: 25.68 | H22: LV,HV | I22: LV,HV | J22: LV,HV | K22: LV,HV
A23: CPLL | B23: CPLLDST13P110D | C23: PP_BRNA0_C_FULP_AN_AA00_DLL_JTG_VIX_ALLFRV_SI_CPLLDS_T13P110D | E23: 16.33 | F23: 54.86 | G23: 16.95 | H23: LV,HV | I23: LV,HV | J23: LV,HV | K23: LV,HV
A24: CPLL | B24: CPLLSST0PS | C24: PP_BRNA0_C_FULP_AN_AA00_DLL_JTG_VIX_ALLFRV_SI_CPLLSS_T0PS | F24: 149.92 | H24: NV | I24: NV | J24: NV
A25: CPLL | B25: CPLLSST1PS | C25: PP_BRNA0_C_FULP_AN_AA00_DLL_JTG_VIX_ALLFRV_SI_CPLLSS_T1PS | F25: 119.66 | H25: NV | I25: NV | J25: NV
A26: CPLL | B26: CPLLSST2P101S | C26: PP_BRNA0_C_FULP_AN_AA00_DLL_JTG_VIX_ALLFRV_SI_CPLLSS_T2P101S | E26: 58.97 | F26: 60.72 | G26: 98.72 | H26: LV,HV | I26: LV,HV | J26: LV,HV | K26: LV,HV
A27: CPLL | B27: CPLLSST2P102S | C27: PP_BRNA0_C_FULP_AN_AA00_DLL_JTG_VIX_ALLFRV_SI_CPLLSS_T2P102S | E27: 68.19 | F27: 68.7 | G27: 68.24 | H27: LV,HV | I27: LV,HV | J27: LV,HV | K27: LV,HV
A28: CPLL | B28: CPLLSST2P104S | C28: PP_BRNA0_C_FULP_AN_AA00_DLL_JTG_VIX_ALLFRV_SI_CPLLSS_T2P104S | E28: 102.24 | F28: 102.65 | G28: 67.26 | H28: LV,HV | I28: LV,HV | J28: LV,HV | K28: LV,HV
A29: CPLL | B29: CPLLSST2P105S | C29: PP_BRNA0_C_FULP_AN_AA00_DLL_JTG_VIX_ALLFRV_SI_CPLLSS_T2P105S | E29: 74.83 | F29: 68.55 | G29: 67.67 | H29: LV,HV | I29: LV,HV | J29: LV,HV | K29: LV,HV
A30: CPLL | B30: CPLLSST2P106S | C30: PP_BRNA0_C_FULP_AN_AA00_DLL_JTG_VIX_ALLFRV_SI_CPLLSS_T2P106S | E30: 69.09 | F30: 69.78 | G30: 101.99 | H30: LV,HV | I30: LV,HV | J30: LV,HV | K30: LV,HV
A31: CPLL | B31: CPLLSST2P111S | C31: PP_BRNA0_C_FULP_AN_AA00_DLL_JTG_VIX_ALLFRV_SI_CPLLSS_T2P111S | E31: 68.94 | F31: 69.6 | G31: 68.84 | H31: LV,HV | I31: LV,HV | J31: LV,HV | K31: LV,HV
A32: CPLL | B32: CPLLSST2P113S | C32: PP_BRNA0_C_FULP_AN_AA00_DLL_JTG_VIX_ALLFRV_SI_CPLLSS_T2P113S | E32: 68.63 | F32: 121.2 | G32: 68.09 | H32: LV,HV | I32: LV,HV | J32: LV,HV | K32: LV,HV
A33: CPLL | B33: CPLLSST3P108S | C33: PP_BRNA0_C_FULP_AN_AA00_DLL_JTG_VIX_ALLFRV_SI_CPLLSS_T3P108S | E33: 120.43 | F33: 85.35 | G33: 85.17 | H33: LV,HV | I33: LV,HV | J33: LV,HV | K33: LV,HV
A34: CPLL | B34: CPLLSST7PS | C34: PP_BRNA0_C_FULP_AN_AA00_DLL_JTG_VIX_ALLFRV_SI_CPLLSS_T7PS | E34: 32.42 | F34: 32.65 | G34: 68.81 | H34: LV,HV | I34: LV,HV | J34: LV,HV | K34: LV,HV
A35: CPLL | B35: CPLLSST13P104S | C35: PP_BRNA0_C_FULP_AN_AA00_DLL_JTG_VIX_ALLFRV_SI_CPLLSS_T13P104S | E35: 16.86 | F35: 16.81 | G35: 18.71 | H35: LV,HV | I35: LV,HV | J35: LV,HV | K35: LV,HV
A36: CPLL | B36: CPLLSST13P111S | C36: PP_BRNA0_C_FULP_AN_AA00_DLL_JTG_VIX_ALLFRV_SI_CPLLSS_T13P111S | E36: 16.14 | F36: 16.3 | G36: 17.08 | H36: LV,HV | I36: LV,HV | J36: LV,HV | K36: LV,HV
A37: CPLL | B37: MNCPLLDST0PD | C37: MN_BRNA0_C_FULP_AN_AA00_DLL_JTG_VIX_ALLFRV_SI_CPLLDS_T0PD | E37: 341.05 | F37: 347.59 | G37: 312.46 | L37: LV,HV
A38: CPLL | B38: MNCPLLDST1PD | C38: MN_BRNA0_C_FULP_AN_AA00_DLL_JTG_VIX_ALLFRV_SI_CPLLDS_T1PD | E38: 192.96 | F38: 192.33 | G38: 189.61 | L38: LV,HV
A39: CPLL | B39: MNCPLLDST2P101D | C39: MN_BRNA0_C_FULP_AN_AA00_DLL_JTG_VIX_ALLFRV_SI_CPLLDS_T2P101D | E39: 99.08 | F39: 99.96 | G39: 128.6 | L39: LV,HV
A40: CPLL | B40: MNCPLLDST2P102D | C40: MN_BRNA0_C_FULP_AN_AA00_DLL_JTG_VIX_ALLFRV_SI_CPLLDS_T2P102D | E40: 142.67 | F40: 144.9 | G40: 107.57 | L40: LV,HV
A41: CPLL | B41: MNCPLLDST2P103D | C41: MN_BRNA0_C_FULP_AN_AA00_DLL_JTG_VIX_ALLFRV_SI_CPLLDS_T2P103D | E41: 107.56 | F41: 140.76 | G41: 138.74 | L41: LV,HV
...

Sheet ADCLK
A2: Proposal for TTR | D2: Total (ms) | F2: =SUM(E5:G69) -> 42934.67
E3: CP1 (ms)
A4: Category | B4: SubBlock | C4: Pattern | D4: HIP_FailRun | E4: LV | F4: NV | G4: HV | H4: Prod CP1 | I4: Prod CP2 | J4: Prod FT1 | K4: Prod FT2 | L4: Mon | M4: T0Tx | N4: RMA Room | O4: RMA Hot
A5: ADCLK | B5: ADCLKT1 | C5: PP_BRNA0_C_FULP_AN_AA01_DLL_JTG_CAL_ALLFRV_SI_ADCLK_T1 | F5: 29.67 | H5: NV | I5: NV | J5: NV
A6: ADCLK | B6: OTHER | C6: ADCLK_ADCLKT1_FUSE_PREWRITE_CAL1 | F6: 0.22 | H6: NV
A7: ADCLK | B7: OTHER | C7: ADCLK_ADCLKT1_FUSE_PREWRITE_CAL2 | F7: 0.16 | H7: NV
A8: ADCLK | B8: OTHER | C8: ADCLK_ADCLKT1_FUSE_PREWRITE_CAL3 | F8: 0.15 | H8: NV
A9: ADCLK | B9: OTHER | C9: ADCLK_ADCLKT1_FUSE_READ_CAL1 | F9: 2.03 | I9: NV | J9: NV | K9: NV
A10: ADCLK | B10: OTHER | C10: ADCLK_ADCLKT1_FUSE_READ_CAL2 | F10: 0.92 | I10: NV | J10: NV | K10: NV
A11: ADCLK | B11: OTHER | C11: ADCLK_ADCLKT1_FUSE_READ_CAL3 | F11: 0.95 | I11: NV | J11: NV | K11: NV
A12: ADCLK | B12: ADCLKT2P1P0B | C12: PP_BRNA0_C_FULP_AN_AA01_DLL_JTG_VIX_ALLFRV_SI_ADCLK_T2P1P0B | E12: 329.23 | F12: 287.51 | G12: 303.54 | H12: LV,HV | I12: LV,HV | J12: LV,HV | K12: LV,HV
A13: ADCLK | B13: ADCLKT2P2P | C13: PP_BRNA0_C_FULP_AN_AA01_DLL_JTG_VIX_ALLFRV_SI_ADCLK_T2P2P | E13: 301.19 | F13: 333.09 | G13: 301.83 | H13: LV,HV | I13: LV,HV | J13: LV,HV | K13: LV,HV
A14: ADCLK | B14: ADCLKT2P6P | C14: PP_BRNA0_C_FULP_AN_AA01_DLL_JTG_VIX_ALLFRV_SI_ADCLK_T2P6P | E14: 301.46 | F14: 300.99 | G14: 303.14 | H14: LV,HV | I14: LV,HV | J14: LV,HV | K14: LV,HV
A15: ADCLK | B15: ADCLKT2P7P | C15: PP_BRNA0_C_FULP_AN_AA01_DLL_JTG_VIX_ALLFRV_SI_ADCLK_T2P7P | E15: 304.25 | F15: 302.2 | G15: 298.5 | H15: LV,HV | I15: LV,HV | J15: LV,HV | K15: LV,HV
A16: ADCLK | B16: ADCLKT3 | C16: PP_BRNA0_C_FULP_AN_AA01_MEA_JTG_VMX_ALLFRV_SI_ADCLK_T3 | E16: 621.83 | F16: 588.7 | G16: 614.96 | H16: LV,HV | I16: LV,HV | J16: LV,HV | K16: LV,HV
A17: ADCLK | B17: ADCLKT4 | C17: PP_BRNA0_C_FULP_AN_AA01_DLL_JTG_FRQ_ALLFRV_SI_ADCLK_T4 | E17: 46.07 | F17: 46.87 | G17: 44.88 | H17: LV,HV | I17: LV,HV | J17: LV,HV | K17: LV,HV
A18: ADCLK | B18: ADCLKT7P1P | C18: PP_BRNA0_C_FULP_AN_AA01_MEA_JTG_LKK_ALLFRV_SI_ADCLK_T7P1P | E18: 86.69 | F18: 129.11 | G18: 86.54 | H18: LV,HV | I18: LV,HV | J18: LV,HV | K18: LV,HV
A19: ADCLK | B19: ADCLKT7P2P | C19: PP_BRNA0_C_FULP_AN_AA01_MEA_JTG_LKK_ALLFRV_SI_ADCLK_T7P2P | E19: 121.24 | F19: 119.92 | G19: 122.14 | H19: LV,HV | I19: LV,HV | J19: LV,HV | K19: LV,HV
A20: ADCLK | B20: ADCLKT7P3P | C20: PP_BRNA0_C_FULP_AN_AA01_MEA_JTG_LKK_ALLFRV_SI_ADCLK_T7P3P | E20: 116.88 | F20: 87.65 | G20: 113.88 | H20: LV,HV | I20: LV,HV | J20: LV,HV | K20: LV,HV
A21: ADCLK | B21: ADCLKT7P4P | C21: PP_BRNA0_C_FULP_AN_AA01_MEA_JTG_LKK_ALLFRV_SI_ADCLK_T7P4P | E21: 88.15 | F21: 115.83 | G21: 86.48 | H21: LV,HV | I21: LV,HV | J21: LV,HV | K21: LV,HV
A22: ADCLK | B22: ADCLKT7P5P | C22: PP_BRNA0_C_FULP_AN_AA01_MEA_JTG_LKK_ALLFRV_SI_ADCLK_T7P5P | E22: 116.86 | F22: 87.9 | G22: 116.42 | H22: LV,HV | I22: LV,HV | J22: LV,HV | K22: LV,HV
A23: ADCLK | B23: ADCLKT7P6P | C23: PP_BRNA0_C_FULP_AN_AA01_MEA_JTG_LKK_ALLFRV_SI_ADCLK_T7P6P | E23: 87.82 | F23: 116.67 | G23: 88.13 | H23: LV,HV | I23: LV,HV | J23: LV,HV | K23: LV,HV
... A27: ADCLK | B27: ADCLKT16 | C27: PP_BRNA0_C_FULP_AN_AA01_MEA_JTG_DYC_ALLFRV_SI_ADCLK_T16 | E27: 38.83 | F27: 70.04 | G27: 38.18 | H27: LV,HV | I27: LV,HV | J27: LV,HV | K27: LV,HV
A28: ADCLK | B28: MNADCLKT2P1P0B | C28: MN_BRNA0_C_FULP_AN_AA01_DLL_JTG_VIX_ALLFRV_SI_ADCLK_T2P1P0B | E28: 341.57 | F28: 345.44 | G28: 340 | L28: LV,HV
A29: ADCLK | B29: MNADCLKT2P1PHB | C29: MN_BRNA0_C_FULP_AN_AA01_DLL_JTG_VIX_ALLFRV_SI_ADCLK_T2P1PHB | E29: 377.71 | F29: 342.39 | G29: 377.05 | L29: LV,HV
A30: ADCLK | B30: MNADCLKT2P1PQB | C30: MN_BRNA0_C_FULP_AN_AA01_DLL_JTG_VIX_ALLFRV_SI_ADCLK_T2P1PQB | E30: 347.61 | F30: 389.59 | G30: 342.2 | L30: LV,HV
A31: ADCLK | B31: MNADCLKT2P2PHB | C31: MN_BRNA0_C_FULP_AN_AA01_DLL_JTG_VIX_ALLFRV_SI_ADCLK_T2P2PHB | E31: 345.78 | F31: 347.83 | G31: 373.49 | L31: LV,HV
A32: ADCLK | B32: MNADCLKT2P2PQB | C32: MN_BRNA0_C_FULP_AN_AA01_DLL_JTG_VIX_ALLFRV_SI_ADCLK_T2P2PQB | E32: 384.82 | F32: 375.65 | G32: 346.62 | L32: LV,HV
A33: ADCLK | B33: MNADCLKT2P2P | C33: MN_BRNA0_C_FULP_AN_AA01_DLL_JTG_VIX_ALLFRV_SI_ADCLK_T2P2P | E33: 349.03 | F33: 344.43 | G33: 344.44 | L33: LV,HV
A34: ADCLK | B34: MNADCLKT2P3PHB | C34: MN_BRNA0_C_FULP_AN_AA01_DLL_JTG_VIX_ALLFRV_SI_ADCLK_T2P3PHB | E34: 378.29 | F34: 354.36 | G34: 386.34 | L34: LV,HV
A35: ADCLK | B35: MNADCLKT2P3PQB | C35: MN_BRNA0_C_FULP_AN_AA01_DLL_JTG_VIX_ALLFRV_SI_ADCLK_T2P3PQB | E35: 351.23 | F35: 388.67 | G35: 346.69 | L35: LV,HV
A36: ADCLK | B36: MNADCLKT2P3P | C36: MN_BRNA0_C_FULP_AN_AA01_DLL_JTG_VIX_ALLFRV_SI_ADCLK_T2P3P | E36: 346.13 | F36: 349.37 | G36: 371.9 | L36: LV,HV
A37: ADCLK | B37: MNADCLKT2P4PHB | C37: MN_BRNA0_C_FULP_AN_AA01_DLL_JTG_VIX_ALLFRV_SI_ADCLK_T2P4PHB | E37: 377.81 | F37: 376.78 | G37: 343.79 | L37: LV,HV
A38: ADCLK | B38: MNADCLKT2P4P | C38: MN_BRNA0_C_FULP_AN_AA01_DLL_JTG_VIX_ALLFRV_SI_ADCLK_T2P4P | E38: 348.87 | F38: 352.79 | G38: 346.17 | L38: LV,HV
A39: ADCLK | B39: MNADCLKT2P5P | C39: MN_BRNA0_C_FULP_AN_AA01_DLL_JTG_VIX_ALLFRV_SI_ADCLK_T2P5P | E39: 375.18 | F39: 347.46 | G39: 377.21 | L39: LV,HV
... A69: ADCLK | B69: MNADCLKT16 | C69: MN_BRNA0_C_FULP_AN_AA01_MEA_JTG_DYC_ALLFRV_SI_ADCLK_T16 | E69: 67.94 | F69: 38.21 | G69: 38.77 | L69: LV,HV

Sheet LAPLL
A2: Proposal for TTR | D2: Total (ms) | F2: =SUM(E5:G55) -> 28316.25
E3: CP1 (ms)
A4: Category | B4: SubBlock | C4: Pattern | D4: HIP_FailRun | E4: LV | F4: NV | G4: HV | H4: Prod CP1 | I4: Prod CP2 | J4: Prod FT1 | K4: Prod FT2 | L4: Mon | M4: T0Tx | N4: RMA Room | O4: RMA Hot
A5: LAPLL | B5: LAPLLT2P1S | C5: PP_BRNA0_C_FULP_AN_AA06_DLL_JTG_VIX_ALLFRV_SI_LAPLL_T2P1S | E5: 82.91 | F5: 84.84 | G5: 82.8 | H5: LV,HV | I5: LV,HV | J5: LV,HV | K5: LV,HV
A6: LAPLL | B6: LAPLLT2P2S | C6: PP_BRNA0_C_FULP_AN_AA06_DLL_JTG_VIX_ALLFRV_SI_LAPLL_T2P2S | E6: 115.11 | F6: 117.76 | G6: 81.22 | H6: LV,HV | I6: LV,HV | J6: LV,HV | K6: LV,HV
A7: LAPLL | B7: LAPLLT2P3S | C7: PP_BRNA0_C_FULP_AN_AA06_DLL_JTG_VIX_ALLFRV_SI_LAPLL_T2P3S | E7: 82.32 | F7: 82.14 | G7: 110.45 | H7: LV,HV | I7: LV,HV | J7: LV,HV | K7: LV,HV
A8: LAPLL | B8: LAPLLT2P4S | C8: PP_BRNA0_C_FULP_AN_AA06_DLL_JTG_VIX_ALLFRV_SI_LAPLL_T2P4S | E8: 83.58 | F8: 81.9 | G8: 81.97 | H8: LV,HV | I8: LV,HV | J8: LV,HV | K8: LV,HV
A9: LAPLL | B9: LAPLLT2P5S | C9: PP_BRNA0_C_FULP_AN_AA06_DLL_JTG_VIX_ALLFRV_SI_LAPLL_T2P5S | E9: 111.97 | F9: 114.94 | G9: 81.02 | H9: LV,HV | I9: LV,HV | J9: LV,HV | K9: LV,HV
A10: LAPLL | B10: LAPLLT2P6S | C10: PP_BRNA0_C_FULP_AN_AA06_DLL_JTG_VIX_ALLFRV_SI_LAPLL_T2P6S | E10: 81.96 | F10: 81.93 | G10: 109.4 | H10: LV,HV | I10: LV,HV | J10: LV,HV | K10: LV,HV
A11: LAPLL | B11: LAPLLT2P7S | C11: PP_BRNA0_C_FULP_AN_AA06_DLL_JTG_VIX_ALLFRV_SI_LAPLL_T2P7S | E11: 113.86 | F11: 81.32 | G11: 75.81 | H11: LV,HV | I11: LV,HV | J11: LV,HV | K11: LV,HV
A12: LAPLL | B12: LAPLLT2P8S | C12: PP_BRNA0_C_FULP_AN_AA06_DLL_JTG_VIX_ALLFRV_SI_LAPLL_T2P8S | E12: 83.78 | F12: 114.31 | G12: 113.52 | H12: LV,HV | I12: LV,HV | J12: LV,HV | K12: LV,HV
A13: LAPLL | B13: LAPLLT2P9S | C13: PP_BRNA0_C_FULP_AN_AA06_DLL_JTG_VIX_ALLFRV_SI_LAPLL_T2P9S | E13: 82.99 | F13: 82.58 | G13: 82.87 | H13: LV,HV | I13: LV,HV | J13: LV,HV | K13: LV,HV
A14: LAPLL | B14: LAPLLT2P10S | C14: PP_BRNA0_C_FULP_AN_AA06_DLL_JTG_VIX_ALLFRV_SI_LAPLL_T2P10S | E14: 113.46 | F14: 117.97 | G14: 82.28 | H14: LV,HV | I14: LV,HV | J14: LV,HV | K14: LV,HV
A15: LAPLL | B15: LAPLLT3 | C15: PP_BRNA0_C_FULP_AN_AA06_MEA_JTG_IMX_ALLFRV_SI_LAPLL_T3 | E15: 86.47 | F15: 88.38 | G15: 117.35 | H15: LV,HV | I15: LV,HV | J15: LV,HV | K15: LV,HV
A16: LAPLL | B16: LAPLLT4 | C16: PP_BRNA0_C_FULP_AN_AA06_DLL_JTG_FRQ_ALLFRV_SI_LAPLL_T4 | E16: 20.02 | F16: 20.32 | G16: 19.28 | H16: LV,HV | I16: LV,HV | J16: LV,HV | K16: LV,HV
A17: LAPLL | B17: LAPLLT12 | C17: PP_BRNA0_C_FULP_AN_AA06_DLL_JTG_VIX_ALLFRV_SI_LAPLL_T12 | E17: 15.76 | F17: 15.81 | G17: 15.98 | H17: LV,HV | I17: LV,HV | J17: LV,HV | K17: LV,HV
A18: LAPLL | B18: MNLAPLLT2P1S | C18: MN_BRNA0_C_FULP_AN_AA06_DLL_JTG_VIX_ALLFRV_SI_LAPLL_T2P1S | E18: 244.83 | F18: 247.32 | G18: 219.42 | L18: LV,HV
A19: LAPLL | B19: MNLAPLLT2P2S | C19: MN_BRNA0_C_FULP_AN_AA06_DLL_JTG_VIX_ALLFRV_SI_LAPLL_T2P2S | E19: 222.77 | F19: 224.8 | G19: 253.03 | L19: LV,HV
A20: LAPLL | B20: MNLAPLLT2P3S | C20: MN_BRNA0_C_FULP_AN_AA06_DLL_JTG_VIX_ALLFRV_SI_LAPLL_T2P3S | E20: 254.52 | F20: 227.24 | G20: 257 | L20: LV,HV
A21: LAPLL | B21: MNLAPLLT2P4S | C21: MN_BRNA0_C_FULP_AN_AA06_DLL_JTG_VIX_ALLFRV_SI_LAPLL_T2P4S | E21: 226.8 | F21: 265.59 | G21: 224 | L21: LV,HV
A22: LAPLL | B22: MNLAPLLT2P5S | C22: MN_BRNA0_C_FULP_AN_AA06_DLL_JTG_VIX_ALLFRV_SI_LAPLL_T2P5S | E22: 259.75 | F22: 253.97 | G22: 256.96 | L22: LV,HV
A23: LAPLL | B23: MNLAPLLT2P6S | C23: MN_BRNA0_C_FULP_AN_AA06_DLL_JTG_VIX_ALLFRV_SI_LAPLL_T2P6S | E23: 229.36 | F23: 222.81 | G23: 255.15 | L23: LV,HV
A24: LAPLL | B24: MNLAPLLT2P7S | C24: MN_BRNA0_C_FULP_AN_AA06_DLL_JTG_VIX_ALLFRV_SI_LAPLL_T2P7S | E24: 250.7 | F24: 228.11 | G24: 225.54 | L24: LV,HV
A25: LAPLL | B25: MNLAPLLT2P8S | C25: MN_BRNA0_C_FULP_AN_AA06_DLL_JTG_VIX_ALLFRV_SI_LAPLL_T2P8S | E25: 258.65 | F25: 260.11 | G25: 228.35 | L25: LV,HV
A26: LAPLL | B26: MNLAPLLT2P9S | C26: MN_BRNA0_C_FULP_AN_AA06_DLL_JTG_VIX_ALLFRV_SI_LAPLL_T2P9S | E26: 223.48 | F26: 227.59 | G26: 260.27 | L26: LV,HV
A27: LAPLL | B27: MNLAPLLT2P10S | C27: MN_BRNA0_C_FULP_AN_AA06_DLL_JTG_VIX_ALLFRV_SI_LAPLL_T2P10S | E27: 257.69 | F27: 253.54 | G27: 256.34 | L27: LV,HV
A28: LAPLL | B28: MNLAPLLT2P11S | C28: MN_BRNA0_C_FULP_AN_AA06_DLL_JTG_VIX_ALLFRV_SI_LAPLL_T2P11S | E28: 254.74 | F28: 252.98 | G28: 220.78 | L28: LV,HV
A29: LAPLL | B29: MNLAPLLT2P12S | C29: MN_BRNA0_C_FULP_AN_AA06_DLL_JTG_VIX_ALLFRV_SI_LAPLL_T2P12S | E29: 224.01 | F29: 223.08 | G29: 262.54 | L29: LV,HV
... A55: LAPLL | B55: MNLAPLLT12 | C55: MN_BRNA0_C_FULP_AN_AA06_DLL_JTG_VIX_ALLFRV_SI_LAPLL_T12 | E55: 239.24 | F55: 239.66 | G55: 245.04 | L55: LV,HV

Sheet PCIEREFGEN
A2: Proposal for TTR | D2: Total (ms) | F2: =SUM(E5:G16) -> 1587.59
E3: CP1 (ms)
A4: Category | B4: SubBlock | C4: Pattern | D4: HIP_FailRun | E4: LV | F4: NV | G4: HV | H4: Prod CP1 | I4: Prod CP2 | J4: Prod FT1 | K4: Prod FT2 | L4: Mon | M4: T0Tx | N4: RMA Room | O4: RMA Hot
A5: PCIEREFGEN | B5: REFGENCMNTRIMBGCOARSEMOSI | C5: PP_BRNA0_S_FULP_AN_REFG_MEA_JTG_CAL_ALLFRV_SI_REFGEN_T1 | E5: 29.43 | F5: 31.52 | G5: 29.52 | H5: NV | I5: NV | J5: NV
A6: PCIEREFGEN | B6: OTHER | C6: PCIEREFGEN_FUSE_PREWRITE_REFGEN_0_MOS_TRIM_I | F6: 0.23 | J6: NV
A7: PCIEREFGEN | B7: OTHER | C7: PCIEREFGEN_FUSE_READ_REFGEN_0_MOS_TRIM_I | F7: 0.63 | K7: NV
A8: PCIEREFGEN | B8: OTHER | C8: PCIEREFGEN_FUSE_PREWRITE_FINE_MOS | F8: 0.22 | J8: NV
A9: PCIEREFGEN | B9: OTHER | C9: PCIEREFGEN_FUSE_READ_FUSE_PREWRITE_FINE_MOS | F9: 0.67 | K9: NV
A10: PCIEREFGEN | B10: OTHER | C10: PCIEREFGEN_SOCREFGEN_FUSE_PREWRITE_REFGEN_0_BJT_TRIM_V | F10: 0.24 | J10: NV
A11: PCIEREFGEN | B11: OTHER | C11: PCIEREFGEN_SOCREFGEN_FUSE_READ_REFGEN_0_BJT_TRIM_V | F11: 0.7 | K11: NV
A12: PCIEREFGEN | B12: REFGENT2P1FINEMOS | C12: PP_BRNA0_S_FULP_AN_REFG_MEA_JTG_CAL_ALLFRV_SI_REFGEN_T2P1 | F12: 80.66 | H12: NV | I12: NV | J12: NV
A13: PCIEREFGEN | B13: PCIEREFGENCMNTRIMBGFINE | C13: PP_BRNA0_S_FULP_AN_REFG_MEA_JTG_CAL_ALLFRV_SI_REFGEN_T2P2 | E13: 51.19 | F13: 16.72 | G13: 16.82 | H13: NV | I13: NV | J13: NV
A14: PCIEREFGEN | B14: REFGENCMNTRIMV2I | C14: PP_BRNA0_S_FULP_AN_REFG_MEA_JTG_CAL_ALLFRV_SI_REFGEN_T3 | E14: 198.92 | F14: 204.09 | G14: 201.75 | H14: NV | I14: NV | J14: NV
A15: PCIEREFGEN | B15: REFGENT4P1MOSANALOGTESTPOINTS | C15: MN_BRNA0_S_FULP_AN_REFG_MEA_JTG_CAL_ALLFRV_SI_REFGEN_T4P1 | E15: 34.49 | F15: 34.65 | G15: 34.61 | H15: NV | I15: NV | J15: NV
A16: PCIEREFGEN | B16: REFGENT4P2BJTANALOGTESTPOINTS | C16: MN_BRNA0_S_FULP_AN_REFG_MEA_JTG_CAL_ALLFRV_SI_REFGEN_T4P2 | E16: 205.12 | F16: 207.15 | G16: 208.26 | H16: NV | I16: NV | J16: NV

Sheet PCIE5CMN
A2: Proposal for TTR | D2: Total (ms) | F2: =SUM(E5:G18) -> 480.05
E3: CP1 (ms)
A4: Category | B4: SubBlock | C4: Pattern | D4: HIP_FailRun | E4: LV | F4: NV | G4: HV | H4: Prod CP1 | I4: Prod CP2 | J4: Prod FT1 | K4: Prod FT2 | L4: Mon | M4: T0Tx | N4: RMA Room | O4: RMA Hot
A5: PCIE5CMN | B5: CMNTRIMBGCOARSE_MULTIPLE | C5: PP_BRNA0_S_FULP_AN_P5CM_MEA_JTG_CAL_ALLFRV_SI_CMNTRIM_BGCOARSE | F5: 40.44 | H5: NV | I5: NV | J5: NV
A6: PCIE5CMN | B6: CMNTRIMBGFINE_MULTIPLE | C6: PP_BRNA0_S_FULP_AN_P5CM_MEA_JTG_CAL_ALLFRV_SI_CMNTRIM_BGFINE | F6: 27.8 | H6: NV | I6: NV | J6: NV
A7: PCIE5CMN | B7: OTHER | C7: PCIE5CMN_PCIE5_CMNTRIMBGFINE_FUSE_PREWRITE_CAL | F7: 0.24 | J7: NV
A8: PCIE5CMN | B8: OTHER | C8: PCIE5CMN_PCIE5_CMNTRIMBGFINE_FUSE_READ_CAL | F8: 0.66 | K8: NV
A9: PCIE5CMN | B9: OTHER | C9: PCIE5CMN_PCIE5_CMNTRIMMOSI_FUSE_PREWRITE_CAL | F9: 0.24 | J9: NV
A10: PCIE5CMN | B10: OTHER | C10: PCIE5CMN_PCIE5_CMNTRIMMOSI_FUSE_READ_CAL | F10: 0.66 | K10: NV
A11: PCIE5CMN | B11: OTHER | C11: PCIE5CMN_PCIE5_CMNTRIMMOSV_FUSE_PREWRITE_CAL | F11: 0.23 | J11: NV
A12: PCIE5CMN | B12: OTHER | C12: PCIE5CMN_PCIE5_CMNTRIMMOSV_FUSE_READ_CAL | F12: 0.66 | K12: NV
A13: PCIE5CMN | B13: OTHER | C13: PCIE5CMN_PCIE5_CMNTRIMVREGTRIM_FUSE_PREWRITE_CAL | F13: 0.24 | J13: NV
A14: PCIE5CMN | B14: OTHER | C14: PCIE5CMN_PCIE5_CMNTRIMVREGTRIM_FUSE_READ_CAL | F14: 0.74 | K14: NV
A15: PCIE5CMN | B15: CMNTRIMMOSI_MULTIPLE | C15: PP_BRNA0_S_FULP_AN_P5CM_MEA_JTG_CAL_ALLFRV_SI_CMNTRIM_MOSI | F15: 57.36 | H15: NV | I15: NV | J15: NV
A16: PCIE5CMN | B16: CMNTRIMMOSV_MULTIPLE | C16: PP_BRNA0_S_FULP_AN_P5CM_MEA_JTG_CAL_ALLFRV_SI_CMNTRIM_MOSV | F16: 158.49 | H16: NV | I16: NV | J16: NV
A17: PCIE5CMN | B17: CMNTRIMV2I_MULTIPLE | C17: PP_BRNA0_S_FULP_AN_P5CM_MEA_JTG_CAL_ALLFRV_SI_CMNTRIM_V2I | F17: 27.48 | H17: NV | I17: NV | J17: NV
A18: PCIE5CMN | B18: CMNTRIMVREGTRIM_MULTIPLE | C18: PP_BRNA0_S_FULP_AN_P5CM_MEA_JTG_CAL_ALLFRV_SI_CMNTRIM_VREGTRIM | F18: 164.81 | H18: NV | I18: NV | J18: NV

Sheet ACIPHYCMN
A2: Proposal for TTR | D2: Total (ms) | F2: =SUM(E5:G18) -> 431.7
E3: CP1 (ms)
A4: Category | B4: SubBlock | C4: Pattern | D4: HIP_FailRun | E4: LV | F4: NV | G4: HV | H4: Prod CP1 | I4: Prod CP2 | J4: Prod FT1 | K4: Prod FT2 | L4: Mon | M4: T0Tx | N4: RMA Room | O4: RMA Hot
A5: ACIPHYCMN | B5: CMNTRIMBGCOARSE_MULTIPLE | C5: PP_BRNA0_S_FULP_AN_RXCM_MEA_JTG_CAL_ALLFRV_SI_CMNTRIM_BGCOARSE | F5: 57.84 | H5: NV | I5: NV | J5: NV
A6: ACIPHYCMN | B6: CMNTRIMBGFINE_MULTIPLE | C6: PP_BRNA0_S_FULP_AN_RXCM_MEA_JTG_CAL_ALLFRV_SI_CMNTRIM_BGFINE | F6: 25.65 | H6: NV | I6: NV | J6: NV
A7: ACIPHYCMN | B7: OTHER | C7: ACIPHYCMN_ACIPHY_CMNTRIMBGFINE_FUSE_PREWRITE_CAL | F7: 0.21 | J7: NV
A8: ACIPHYCMN | B8: OTHER | C8: ACIPHYCMN_ACIPHY_CMNTRIMBGFINE_FUSE_READ_CAL | F8: 1.01 | K8: NV
A9: ACIPHYCMN | B9: OTHER | C9: ACIPHYCMN_ACIPHY_CMNTRIMMOSI_FUSE_PREWRITE_CAL | F9: 0.22 | J9: NV
A10: ACIPHYCMN | B10: OTHER | C10: ACIPHYCMN_ACIPHY_CMNTRIMMOSI_FUSE_READ_CAL | F10: 0.97 | K10: NV
A11: ACIPHYCMN | B11: OTHER | C11: ACIPHYCMN_ACIPHY_CMNTRIMMOSV_FUSE_PREWRITE_CAL | F11: 0.27 | J11: NV
A12: ACIPHYCMN | B12: OTHER | C12: ACIPHYCMN_ACIPHY_CMNTRIMMOSV_FUSE_READ_CAL | F12: 1.14 | K12: NV
A13: ACIPHYCMN | B13: OTHER | C13: ACIPHYCMN_ACIPHY_CMNVREGTRIM_FUSE_PREWRITE_CAL | F13: 0.26 | J13: NV
A14: ACIPHYCMN | B14: OTHER | C14: ACIPHYCMN_ACIPHY_CMNVREGTRIM_FUSE_READ_CAL | F14: 1.02 | K14: NV
A15: ACIPHYCMN | B15: CMNTRIMV2I_MULTIPLE | C15: PP_BRNA0_S_FULP_AN_RXCM_MEA_JTG_CAL_ALLFRV_SI_CMNTRIM_V2I | F15: 24.81 | H15: NV | I15: NV | J15: NV
A16: ACIPHYCMN | B16: CMNTRIMMOSI_MULTIPLE | C16: PP_BRNA0_S_FULP_AN_RXCM_MEA_JTG_CAL_ALLFRV_SI_CMNTRIM_MOSI | F16: 24.82 | H16: NV | I16: NV | J16: NV
A17: ACIPHYCMN | B17: CMNTRIMMOSV_MULTIPLE | C17: PP_BRNA0_S_FULP_AN_RXCM_MEA_JTG_CAL_ALLFRV_SI_CMNTRIM_MOSV | F17: 168.39 | H17: NV | I17: NV | J17: NV
A18: ACIPHYCMN | B18: CMNVREGTRIM_MULTIPLE | C18: PP_BRNA0_S_FULP_AN_RXCM_MEA_JTG_VMX_ALLFRV_SI_CMN_VREGTRIM | F18: 125.09 | H18: NV | I18: NV | J18: NV

Sheet ACIOPHYCMN
A2: Proposal for TTR | D2: Total (ms) | F2: =SUM(E5:G18) -> 390.32
E3: CP1 (ms)
A4: Category | B4: SubBlock | C4: Pattern | D4: HIP_FailRun | E4: LV | F4: NV | G4: HV | H4: Prod CP1 | I4: Prod CP2 | J4: Prod FT1 | K4: Prod FT2 | L4: Mon | M4: T0Tx | N4: RMA Room | O4: RMA Hot
A5: ACIOPHYCMN | B5: CMNTRIMBGCOARSE_MULTIPLE | C5: PP_BRNA0_S_FULP_AN_CICM_MEA_JTG_CAL_ALLFRV_SI_CMNTRIM_BGCOARSE | F5: 25.81 | H5: NV | I5: NV | J5: NV
A6: ACIOPHYCMN | B6: CMNTRIMBGFINE_MULTIPLE | C6: PP_BRNA0_S_FULP_AN_CICM_MEA_JTG_CAL_ALLFRV_SI_CMNTRIM_BGFINE | F6: 25.12 | H6: NV | I6: NV | J6: NV
A7: ACIOPHYCMN | B7: OTHER | C7: ACIOPHYCMN_ACIOPHY_CMNTRIMBGFINE_FUSE_PREWRITE_CAL | F7: 0.2 | J7: NV
A8: ACIOPHYCMN | B8: OTHER | C8: ACIOPHYCMN_ACIOPHY_CMNTRIMBGFINE_FUSE_READ_CAL | F8: 0.62 | K8: NV
A9: ACIOPHYCMN | B9: OTHER | C9: ACIOPHYCMN_ACIOPHY_CMNTRIMMOSI_FUSE_PREWRITE_CAL | F9: 0.25 | J9: NV
A10: ACIOPHYCMN | B10: OTHER | C10: ACIOPHYCMN_ACIOPHY_CMNTRIMMOSI_FUSE_READ_CAL | F10: 0.67 | K10: NV
A11: ACIOPHYCMN | B11: OTHER | C11: ACIOPHYCMN_ACIOPHY_CMNTRIMMOSV_FUSE_PREWRITE_CAL | F11: 0.24 | J11: NV
A12: ACIOPHYCMN | B12: OTHER | C12: ACIOPHYCMN_ACIOPHY_CMNTRIMMOSV_FUSE_READ_CAL | F12: 0.7 | K12: NV
A13: ACIOPHYCMN | B13: OTHER | C13: ACIOPHYCMN_ACIOPHY_CMNTRIMVREGTRIM_FUSE_PREWRITE_CAL | F13: 0.25 | J13: NV
A14: ACIOPHYCMN | B14: OTHER | C14: ACIOPHYCMN_ACIOPHY_CMNTRIMVREGTRIM_FUSE_READ_CAL | F14: 0.66 | K14: NV
A15: ACIOPHYCMN | B15: CMNTRIMV2I_MULTIPLE | C15: PP_BRNA0_S_FULP_AN_CICM_MEA_JTG_CAL_ALLFRV_SI_CMNTRIM_V2I | F15: 24.48 | H15: NV | I15: NV | J15: NV
A16: ACIOPHYCMN | B16: CMNTRIMMOSI_MULTIPLE | C16: PP_BRNA0_S_FULP_AN_CICM_MEA_JTG_CAL_ALLFRV_SI_CMNTRIM_MOSI | F16: 50.45 | H16: NV | I16: NV | J16: NV
A17: ACIOPHYCMN | B17: CMNTRIMMOSV_MULTIPLE | C17: PP_BRNA0_S_FULP_AN_CICM_MEA_JTG_CAL_ALLFRV_SI_CMNTRIM_MOSV | F17: 139.78 | H17: NV | I17: NV | J17: NV
A18: ACIOPHYCMN | B18: CMNTRIMVREGTRIM_MULTIPLE | C18: PP_BRNA0_S_FULP_AN_CICM_MEA_JTG_CAL_ALLFRV_SI_CMNTRIM_VREGTRIM | F18: 121.09 | H18: NV | I18: NV | J18: NV

Sheet LPDPTXCMN
A2: Proposal for TTR | D2: Total (ms) | F2: =SUM(E5:G18) -> 412.7
E3: CP1 (ms)
A4: Category | B4: SubBlock | C4: Pattern | D4: HIP_FailRun | E4: LV | F4: NV | G4: HV | H4: Prod CP1 | I4: Prod CP2 | J4: Prod FT1 | K4: Prod FT2 | L4: Mon | M4: T0Tx | N4: RMA Room | O4: RMA Hot
A5: LPDPTXCMN | B5: CMNTRIMBGCOARSE_MULTIPLE | C5: PP_BRNA0_S_FULP_AN_TXCM_MEA_JTG_CAL_ALLFRV_SI_CMNTRIM_BGCOARSE | F5: 26.84 | H5: NV | I5: NV | J5: NV
A6: LPDPTXCMN | B6: CMNTRIMBGFINE_MULTIPLE | C6: PP_BRNA0_S_FULP_AN_TXCM_MEA_JTG_CAL_ALLFRV_SI_CMNTRIM_BGFINE | F6: 26 | H6: NV | I6: NV | J6: NV
A7: LPDPTXCMN | B7: OTHER | C7: LPDPTXCMN_LPDPTX_CMNTRIMBGFINE_FUSE_PREWRITE_CAL | F7: 0.23 | J7: NV
A8: LPDPTXCMN | B8: OTHER | C8: LPDPTXCMN_LPDPTX_CMNTRIMBGFINE_FUSE_READ_CAL | F8: 0.98 | K8: NV
A9: LPDPTXCMN | B9: OTHER | C9: LPDPTXCMN_LPDPTX_CMNTRIMMOSI_FUSE_PREWRITE_CAL | F9: 0.23 | J9: NV
A10: LPDPTXCMN | B10: OTHER | C10: LPDPTXCMN_LPDPTX_CMNTRIMMOSI_FUSE_READ_CAL | F10: 1.1 | K10: NV
A11: LPDPTXCMN | B11: OTHER | C11: LPDPTXCMN_LPDPTX_CMNTRIMMOSV_FUSE_PREWRITE_CAL | F11: 0.23 | J11: NV
A12: LPDPTXCMN | B12: OTHER | C12: LPDPTXCMN_LPDPTX_CMNTRIMMOSV_FUSE_READ_CAL | F12: 1.03 | K12: NV
A13: LPDPTXCMN | B13: OTHER | C13: LPDPTXCMN_LPDPTX_CMNTRIMVREGTRIM_FUSE_PREWRITE_CAL | F13: 0.23 | J13: NV
A14: LPDPTXCMN | B14: OTHER | C14: LPDPTXCMN_LPDPTX_CMNTRIMVREGTRIM_FUSE_READ_CAL | F14: 1.02 | K14: NV
A15: LPDPTXCMN | B15: CMNTRIMV2I_MULTIPLE | C15: PP_BRNA0_S_FULP_AN_TXCM_MEA_JTG_CAL_ALLFRV_SI_CMNTRIM_V2I | F15: 25.47 | H15: NV | I15: NV | J15: NV
A16: LPDPTXCMN | B16: CMNTRIMMOSI_MULTIPLE | C16: PP_BRNA0_S_FULP_AN_TXCM_MEA_JTG_CAL_ALLFRV_SI_CMNTRIM_MOSI | F16: 27.13 | H16: NV | I16: NV | J16: NV
A17: LPDPTXCMN | B17: CMNTRIMMOSV_MULTIPLE | C17: PP_BRNA0_S_FULP_AN_TXCM_MEA_JTG_CAL_ALLFRV_SI_CMNTRIM_MOSV | F17: 176.51 | H17: NV | I17: NV | J17: NV
A18: LPDPTXCMN | B18: CMNTRIMVREGTRIM_MULTIPLE | C18: PP_BRNA0_S_FULP_AN_TXCM_MEA_JTG_CAL_ALLFRV_SI_CMNTRIM_VREGTRIM | F18: 125.7 | H18: NV | I18: NV | J18: NV

Sheet AMPCMN
A2: Proposal for TTR | D2: Total (ms) | F2: =SUM(E5:G12) -> 4085.66
E3: CP1 (ms)
A4: Category | B4: SubBlock | C4: Pattern | D4: HIP_FailRun | E4: LV | F4: NV | G4: HV | H4: Prod CP1 | I4: Prod CP2 | J4: Prod FT1 | K4: Prod FT2 | L4: Mon | M4: T0Tx | N4: RMA Room | O4: RMA Hot
A5: AMPCMN | B5: OTHER | C5: RELAYON_K100_K102_K104_RELAYOFF_K15_K19_K17 | F5: 27.78 | H5: NV,LV,HV | I5: NV,LV,HV | J5: NV,LV,HV | K5: NV,LV,HV | L5: NV,LV,HV | M5: NV,LV,HV | N5: NV,LV,HV | O5: NV,LV,HV
A6: AMPCMN | B6: OTHER | C6: RELAYON_K15_K19_K17_RELAYOFF_K100_K102_K104 | F6: 17.9 | H6: NV,LV,HV | I6: NV,LV,HV | J6: NV,LV,HV | K6: NV,LV,HV | L6: NV,LV,HV | M6: NV,LV,HV | N6: NV,LV,HV | O6: NV,LV,HV
A7: AMPCMN | B7: REFGENT1 | C7: PP_BRNA0_S_FULP_AN_DDIO_MEA_JTG_LP5_MDX009_SI_REFGEN_T1 | F7: 40.64 | H7: NV | I7: NV | J7: NV
A8: AMPCMN | B8: REFGENT2P1 | C8: PP_BRNA0_S_FULP_AN_DDIO_MEA_JTG_LP5_MDX009_SI_REFGEN_T2P1 | F8: 194.33 | H8: NV | I8: NV | J8: NV
A9: AMPCMN | B9: REFGENT2P2 | C9: PP_BRNA0_S_FULP_AN_DDIO_MEA_JTG_LP5_MDX009_SI_REFGEN_T2P2 | F9: 26.34 | H9: NV | I9: NV | J9: NV
A10: AMPCMN | B10: REFGENT3 | C10: PP_BRNA0_S_FULP_AN_DDIO_MEA_JTG_LP5_MDX009_SI_REFGEN_T3 | F10: 526.34 | H10: NV | I10: NV | J10: NV
A11: AMPCMN | B11: MNREFGENT4P1 | C11: MN_BRNA0_S_FULP_AN_DDIO_MEA_JTG_LP5_MDX009_SI_REFGEN_T4P1 | E11: 565.4 | F11: 524.18 | G11: 535.22 | L11: LV,NV
A12: AMPCMN | B12: MNREFGENT4P2 | C12: MN_BRNA0_S_FULP_AN_DDIO_MEA_JTG_LP5_MDX009_SI_REFGEN_T4P2 | E12: 532.01 | F12: 532.23 | G12: 563.29 | L12: LV,NV

Sheet PCIEREFPLL
A2: Proposal for TTR
A4: Category | B4: SubBlock | C4: Pattern | D4: Prod CP1 | E4: Prod CP2 | F4: Prod FT1 | G4: Prod FT2 | H4: Mon | I4: T0Tx | J4: RMA Room | K4: RMA Hot
A5: PCIEREFPLL | B5: CIOPLLT1P1R | C5: PP_BRNA0_C_FULP_AN_AA22_FRQ_JTG_DYC_ALLFRV_SI_CIOPLL_T1P1R | D5: NV | E5: NV | F5: NV
A6: PCIEREFPLL | B6: OTHER | C6: PCIEREFPLL_CIOPLLT1P1R_FUSE_PREWRITE_CAL | D6: NV
A7: PCIEREFPLL | B7: OTHER | C7: PCIEREFPLL_CIOPLLT1P1R_FUSE_READ_CAL | E7: NV | F7: NV | G7: NV
A8: PCIEREFPLL | B8: CIOPLLT2P1R | C8: PP_BRNA0_C_FULP_AN_AA22_FRQ_JTG_DYC_ALLFRV_SI_CIOPLL_T2P1R | D8: LV,HV | E8: LV,HV | F8: LV,HV | G8: LV,HV
A9: PCIEREFPLL | B9: CIOPLLT2P2R | C9: PP_BRNA0_C_FULP_AN_AA22_FRQ_JTG_DYC_ALLFRV_SI_CIOPLL_T2P2R | D9: LV,HV | E9: LV,HV | F9: LV,HV | G9: LV,HV
A10: PCIEREFPLL | B10: CIOPLLT3P1R | C10: PP_BRNA0_C_FULP_AN_AA22_FRQ_JTG_DYC_ALLFRV_SI_CIOPLL_T3P1R | D10: LV,HV | E10: LV,HV | F10: LV,HV | G10: LV,HV
A11: PCIEREFPLL | B11: CIOPLLT11PR | C11: PP_BRNA0_C_FULP_AN_AA22_FRQ_JTG_DYC_ALLFRV_SI_CIOPLL_T11PR | D11: LV,HV | E11: LV,HV | F11: LV,HV | G11: LV,HV
A12: PCIEREFPLL | B12: CIOPLLT13PR | C12: PP_BRNA0_C_FULP_AN_AA22_FRQ_JTG_DYC_ALLFRV_SI_CIOPLL_T13PR | D12: LV,HV | E12: LV,HV | F12: LV,HV | G12: LV,HV
A13: PCIEREFPLL | B13: MNCIOPLLT1P1R | C13: MN_BRNA0_C_FULP_AN_AA22_FRQ_JTG_DYC_ALLFRV_SI_CIOPLL_T1P1R | H13: LV,HV
A14: PCIEREFPLL | B14: MNCIOPLLT2P1R | C14: MN_BRNA0_C_FULP_AN_AA22_FRQ_JTG_DYC_ALLFRV_SI_CIOPLL_T2P1R | H14: LV,HV
A15: PCIEREFPLL | B15: MNCIOPLLT2P2R | C15: MN_BRNA0_C_FULP_AN_AA22_FRQ_JTG_DYC_ALLFRV_SI_CIOPLL_T2P2R | H15: LV,HV
A16: PCIEREFPLL | B16: MNCIOPLLT10PR | C16: MN_BRNA0_C_FULP_AN_AA22_FRQ_JTG_DYC_ALLFRV_SI_CIOPLL_T10PR | H16: LV,HV
A17: PCIEREFPLL | B17: MNCIOPLLT11PR | C17: MN_BRNA0_C_FULP_AN_AA22_FRQ_JTG_DYC_ALLFRV_SI_CIOPLL_T11PR | H17: LV,HV
A18: PCIEREFPLL | B18: MNCIOPLLT13PR | C18: MN_BRNA0_C_FULP_AN_AA22_FRQ_JTG_DYC_ALLFRV_SI_CIOPLL_T13PR | H18: LV,HV

Sheet PCIEPLL
A2: Proposal for TTR | D2: Total (ms) | F2: =SUM(E5:G32) -> 5680.31
E3: CP1 (ms)
A4: Category | B4: SubBlock | C4: Pattern | D4: HIP_FailRun | E4: LV | F4: NV | G4: HV | H4: Prod CP1 | I4: Prod CP2 | J4: Prod FT1 | K4: Prod FT2 | L4: Mon | M4: T0Tx | N4: RMA Room | O4: RMA Hot
A5: PCIEPLL | B5: PCIEPLLT1P1P | C5: PP_BRNA0_C_FULP_AN_AA24_DLL_JTG_CAL_ALLFRV_SI_PCIEPLL_T1P1P | F5: 46.79 | H5: NV | I5: NV | J5: NV
A6: PCIEPLL | B6: OTHER | C6: PCIEPLL_PCIEPLLT1P1P_FUSE_PREWRITE_CAL | F6: 0.27 | H6: NV
A7: PCIEPLL | B7: OTHER | C7: PCIEPLL_PCIEPLLT1P1P_FUSE_READ_CAL | F7: 0.69 | I7: NV | J7: NV | K7: NV
A8: PCIEPLL | B8: OTHER | C8: PCIEPLL_PCIEPLLT1P2P_FUSE_PREWRITE_CAL | F8: 0.29 | H8: NV
A9: PCIEPLL | B9: OTHER | C9: PCIEPLL_PCIEPLLT1P2P_FUSE_READ_CAL | F9: 0.71 | I9: NV | J9: NV | K9: NV
A10: PCIEPLL | B10: PCIEPLLT1P2P | C10: PP_BRNA0_C_FULP_AN_AA24_DLL_JTG_CAL_ALLFRV_SI_PCIEPLL_T1P2P | F10: 65.91 | H10: NV | I10: NV | J10: NV
A11: PCIEPLL | B11: PCIEPLLT2P4P | C11: PP_BRNA0_C_FULP_AN_AA24_DLL_JTG_VIX_ALLFRV_SI_PCIEPLL_T2P4P | E11: 52.54 | F11: 43.49 | G11: 53.26 | H11: LV,HV | I11: LV,HV | J11: LV,HV | K11: LV,HV
A12: PCIEPLL | B12: PCIEPLLT3 | C12: PP_BRNA0_C_FULP_AN_AA24_MEA_JTG_IMX_ALLFRV_SI_PCIEPLL_T3 | E12: 85.41 | F12: 85.23 | G12: 86.34 | H12: LV,HV | I12: LV,HV | J12: LV,HV | K12: LV,HV
A13: PCIEPLL | B13: PCIEPLLT11P1P | C13: PP_BRNA0_C_FULP_AN_AA24_FRQ_JTG_COD_ALLFRV_SI_PCIEPLL_T11P1P | E13: 42.16 | F13: 42.55 | G13: 43.07 | H13: LV,HV | I13: LV,HV | J13: LV,HV | K13: LV,HV
A14: PCIEPLL | B14: PCIEPLLT11P2P | C14: PP_BRNA0_C_FULP_AN_AA24_FRQ_JTG_COD_ALLFRV_SI_PCIEPLL_T11P2P | E14: 41.97 | F14: 41.5 | G14: 42.74 | H14: LV,HV | I14: LV,HV | J14: LV,HV | K14: LV,HV
A15: PCIEPLL | B15: PCIEPLLT11P3P | C15: PP_BRNA0_C_FULP_AN_AA24_FRQ_JTG_COD_ALLFRV_SI_PCIEPLL_T11P3P | E15: 41.39 | F15: 41.36 | G15: 41.86 | H15: LV,HV | I15: LV,HV | J15: LV,HV | K15: LV,HV
A16: PCIEPLL | B16: PCIEPLLT11P4P | C16: PP_BRNA0_C_FULP_AN_AA24_FRQ_JTG_COD_ALLFRV_SI_PCIEPLL_T11P4P | E16: 73.03 | F16: 72.05 | G16: 41.16 | H16: LV,HV | I16: LV,HV | J16: LV,HV | K16: LV,HV
A17: PCIEPLL | B17: PCIEPLLT16 | C17: PP_BRNA0_C_FULP_AN_AA24_FRQ_JTG_COD_ALLFRV_SI_PCIEPLL_T16 | E17: 44.16 | F17: 45.31 | G17: 76.86 | H17: LV,HV | I17: LV,HV | J17: LV,HV | K17: LV,HV
A18: PCIEPLL | B18: MNPCIEPLLT1P1P | C18: MN_BRNA0_C_FULP_AN_AA24_DLL_JTG_CAL_ALLFRV_SI_PCIEPLL_T1P1P | E18: 194.73 | F18: 192.36 | G18: 160.71 | L18: LV,HV
A19: PCIEPLL | B19: MNPCIEPLLT1P2P | C19: MN_BRNA0_C_FULP_AN_AA24_DLL_JTG_CAL_ALLFRV_SI_PCIEPLL_T1P2P | E19: 170.46 | F19: 168.83 | G19: 202.47 | L19: LV,HV
A20: PCIEPLL | B20: MNPCIEPLLT2P1P | C20: MN_BRNA0_C_FULP_AN_AA24_DLL_JTG_VIX_ALLFRV_SI_PCIEPLL_T2P1P | E20: 111.96 | F20: 115.85 | G20: 111.97 | L20: LV,HV
A21: PCIEPLL | B21: MNPCIEPLLT2P2P | C21: MN_BRNA0_C_FULP_AN_AA24_DLL_JTG_VIX_ALLFRV_SI_PCIEPLL_T2P2P | E21: 83.5 | F21: 84.02 | G21: 82.41 | L21: LV,HV
A22: PCIEPLL | B22: MNPCIEPLLT2P3P | C22: MN_BRNA0_C_FULP_AN_AA24_DLL_JTG_VIX_ALLFRV_SI_PCIEPLL_T2P3P | E22: 113.75 | F22: 113.19 | G22: 81.57 | L22: LV,HV
A23: PCIEPLL | B23: MNPCIEPLLT2P4P | C23: MN_BRNA0_C_FULP_AN_AA24_DLL_JTG_VIX_ALLFRV_SI_PCIEPLL_T2P4P | E23: 83.06 | F23: 83.58 | G23: 112.34 | L23: LV,HV
A24: PCIEPLL | B24: MNPCIEPLLT3 | C24: MN_BRNA0_C_FULP_AN_AA24_MEA_JTG_IMX_ALLFRV_SI_PCIEPLL_T3 | E24: 93.41 | F24: 93.06 | G24: 92.89 | L24: LV,HV
A25: PCIEPLL | B25: MNPCIEPLLT10P2P | C25: MN_BRNA0_C_FULP_AN_AA24_FRQ_JTG_COD_ALLFRV_SI_PCIEPLL_T10P2P | E25: 120.43 | F25: 114.46 | G25: 85.61 | L25: LV,HV
A26: PCIEPLL | B26: MNPCIEPLLT11P1P | C26: MN_BRNA0_C_FULP_AN_AA24_FRQ_JTG_COD_ALLFRV_SI_PCIEPLL_T11P1P | E26: 83.41 | F26: 85.74 | G26: 114.92 | L26: LV,HV
A27: PCIEPLL | B27: MNPCIEPLLT11P2P | C27: MN_BRNA0_C_FULP_AN_AA24_FRQ_JTG_COD_ALLFRV_SI_PCIEPLL_T11P2P | E27: 83.44 | F27: 82.78 | G27: 81.12 | L27: LV,HV
A28: PCIEPLL | B28: MNPCIEPLLT11P3P | C28: MN_BRNA0_C_FULP_AN_AA24_FRQ_JTG_COD_ALLFRV_SI_PCIEPLL_T11P3P | E28: 112.86 | F28: 115.8 | G28: 111.35 | L28: LV,HV
A29: PCIEPLL | B29: MNPCIEPLLT11P4P | C29: MN_BRNA0_C_FULP_AN_AA24_FRQ_JTG_COD_ALLFRV_SI_PCIEPLL_T11P4P | E29: 83.11 | F29: 82.97 | G29: 81.91 | L29: LV,HV
A30: PCIEPLL | B30: MNPCIEPLLT13P3P | C30: MN_BRNA0_C_FULP_AN_AA24_FRQ_JTG_COD_ALLFRV_SI_PCIEPLL_T13P3P | E30: 31.99 | F30: 32.07 | G30: 30.96 | L30: LV,HV
A31: PCIEPLL | B31: MNPCIEPLLT15 | C31: MN_BRNA0_C_FULP_AN_AA24_FRQ_JTG_COD_ALLFRV_SI_PCIEPLL_T15 | F31: 35.21 | L31: LV,HV
A32: PCIEPLL | B32: MNPCIEPLLT16 | C32: MN_BRNA0_C_FULP_AN_AA24_FRQ_JTG_COD_ALLFRV_SI_PCIEPLL_T16 | E32: 116.42 | F32: 110.22 | G32: 85.31 | L32: LV,HV

Sheet CIOCIOPLL
A2: Proposal for TTR | D2: Total (ms) | F2: =SUM(E5:G47) -> 12277.26
E3: CP1 (ms)
A4: Category | B4: SubBlock | C4: Pattern | D4: HIP_FailRun | E4: LV | F4: NV | G4: HV | H4: Prod CP1 | I4: Prod CP2 | J4: Prod FT1 | K4: Prod FT2 | L4: Mon | M4: T0Tx | N4: RMA Room | O4: RMA Hot
A5: CIOCIOPLL | B5: CIOPLLT1P1U_MULTIPLE | C5: PP_BRNA0_C_FULP_AN_AA10_DLL_JTG_VIX_ALLFRV_SI_CIOPLL_T1P1U | F5: 78.6 | H5: NV | I5: NV | J5: NV
A6: CIOCIOPLL | B6: OTHER | C6: CIOCIOPLL_CIOPLLT1P1U_FUSE_PREWRITE_CAL | F6: 0.25 | H6: NV
A7: CIOCIOPLL | B7: OTHER | C7: CIOCIOPLL_CIOPLLT1P1U_FUSE_READ_CAL | F7: 1.01 | I7: NV | J7: NV | K7: NV
A8: CIOCIOPLL | B8: CIOPLLT1P2C80_MULTIPLE | C8: PP_BRNA0_C_FULP_AN_AA10_DLL_JTG_VIX_ALLFRV_SI_CIOPLL_T1P2C80 | F8: 36.98 | H8: NV | I8: NV | J8: NV | K8: NV
A9: CIOCIOPLL | B9: CIOPLLT2P1U_MULTIPLE | C9: PP_BRNA0_C_FULP_AN_AA10_DLL_JTG_VIX_ALLFRV_SI_CIOPLL_T2P1U | E9: 84.15 | F9: 106.67 | G9: 85.26 | H9: LV,HV | I9: LV,HV | J9: LV,HV | K9: LV,HV
A10: CIOCIOPLL | B10: CIOPLLT2P3U_MULTIPLE | C10: PP_BRNA0_C_FULP_AN_AA10_DLL_JTG_VIX_ALLFRV_SI_CIOPLL_T2P3U | E10: 119.57 | F10: 85.42 | G10: 83.09 | H10: LV,HV | I10: LV,HV | J10: LV,HV | K10: LV,HV
A11: CIOCIOPLL | B11: CIOPLLT2P6U_MULTIPLE | C11: PP_BRNA0_C_FULP_AN_AA10_DLL_JTG_VIX_ALLFRV_SI_CIOPLL_T2P6U | E11: 84.35 | F11: 84.34 | G11: 116.5 | H11: LV,HV | I11: LV,HV | J11: LV,HV | K11: LV,HV
A12: CIOCIOPLL | B12: CIOPLLT2P2CL_MULTIPLE | C12: PP_BRNA0_C_FULP_AN_AA10_DLL_JTG_VIX_ALLFRV_SI_CIOPLL_T2P2CL | E12: 83.95 | F12: 84.49 | G12: 82.7 | H12: LV,HV | I12: LV,HV | J12: LV,HV | K12: LV,HV
A13: CIOCIOPLL | B13: CIOPLLT2P4CL_MULTIPLE | C13: PP_BRNA0_C_FULP_AN_AA10_DLL_JTG_VIX_ALLFRV_SI_CIOPLL_T2P4CL | E13: 83.54 | F13: 125.29 | G13: 82.56 | H13: LV,HV | I13: LV,HV | J13: LV,HV | K13: LV,HV
A14: CIOCIOPLL | B14: CIOPLLT2P1C80_MULTIPLE | C14: PP_BRNA0_C_FULP_AN_AA10_DLL_JTG_VIX_ALLFRV_SI_CIOPLL_T2P1C80 | E14: 123.53 | F14: 83.94 | G14: 122.3 | H14: LV,HV | I14: LV,HV | J14: LV,HV | K14: LV,HV
A15: CIOCIOPLL | B15: CIOPLLT2P2C80_MULTIPLE | C15: PP_BRNA0_C_FULP_AN_AA10_DLL_JTG_VIX_ALLFRV_SI_CIOPLL_T2P2C80 | E15: 85.13 | F15: 84.31 | G15: 83.88 | H15: LV,HV | I15: LV,HV | J15: LV,HV | K15: LV,HV
A16: CIOCIOPLL | B16: CIOPLLT3P1U_MULTIPLE | C16: PP_BRNA0_C_FULP_AN_AA10_MEA_JTG_IMX_ALLFRV_SI_CIOPLL_T3P1U | E16: 122.64 | F16: 155.47 | G16: 121.49 | H16: LV,HV | I16: LV,HV | J16: LV,HV | K16: LV,HV
A17: CIOCIOPLL | B17: CIOPLLT11P3U_MULTIPLE | C17: PP_BRNA0_C_FULP_AN_AA10_MEA_JTG_VIX_ALLFRV_SI_CIOPLL_T11P3U | E17: 128.02 | F17: 94.69 | G17: 86.97 | H17: LV,HV | I17: LV,HV | J17: LV,HV | K17: LV,HV
A18: CIOCIOPLL | B18: CIOPLLT11P2CL_MULTIPLE | C18: PP_BRNA0_C_FULP_AN_AA10_MEA_JTG_VIX_ALLFRV_SI_CIOPLL_T11P2CL | E18: 87.83 | F18: 87.07 | G18: 128.58 | H18: LV,HV | I18: LV,HV | J18: LV,HV | K18: LV,HV
A19: CIOCIOPLL | B19: CIOPLLT11PC80_MULTIPLE | C19: PP_BRNA0_C_FULP_AN_AA10_MEA_JTG_VIX_ALLFRV_SI_CIOPLL_T11PC80 | E19: 87.77 | F19: 86.86 | G19: 87.18 | H19: LV,HV | I19: LV,HV | J19: LV,HV | K19: LV,HV
A20: CIOCIOPLL | B20: CIOPLLT13PU_MULTIPLE | C20: PP_BRNA0_C_FULP_AN_AA10_MEA_JTG_VIX_ALLFRV_SI_CIOPLL_T13PU | E20: 26.62 | F20: 25.59 | G20: 25.03 | H20: LV,HV | I20: LV,HV | J20: LV,HV | K20: LV,HV
